{
 "cells": [
  {
   "cell_type": "code",
   "execution_count": 13,
   "metadata": {
    "collapsed": true
   },
   "outputs": [],
   "source": [
    "import requests\n",
    "from bs4 import BeautifulSoup\n",
    "import re\n",
    "from collections import Counter\n",
    "global static #增加一個全域變數用來紀錄統計結果\n",
    "import threading\n",
    "static={}"
   ]
  },
  {
   "cell_type": "code",
   "execution_count": 14,
   "metadata": {
    "collapsed": true
   },
   "outputs": [],
   "source": [
    "import _thread\n",
    "import time\n"
   ]
  },
  {
   "cell_type": "code",
   "execution_count": 15,
   "metadata": {
    "scrolled": true
   },
   "outputs": [
    {
     "data": {
      "text/plain": [
       "['Java',\n",
       " 'C#',\n",
       " 'Word',\n",
       " 'Excel',\n",
       " 'PowerPoint',\n",
       " 'Outlook',\n",
       " 'MS',\n",
       " 'SQL',\n",
       " 'Delphi',\n",
       " 'C']"
      ]
     },
     "execution_count": 15,
     "metadata": {},
     "output_type": "execute_result"
    }
   ],
   "source": [
    "with open('./lan.text') as f: #打開我們要比對的字典檔\n",
    "    wordlen = f.read().split('\\n')\n",
    "del wordlen[0]\n",
    "wordlen[:10] "
   ]
  },
  {
   "cell_type": "code",
   "execution_count": 16,
   "metadata": {
    "collapsed": true
   },
   "outputs": [],
   "source": [
    "def innerURL(url): #一個用來分析內頁的function\n",
    "    \n",
    "    inner = requests.get(url)  #用get連到網頁\n",
    "    innersoup = BeautifulSoup(inner.text, 'lxml')  #放到BeautifulSoup解析\n",
    "    innerselect = str(innersoup.select('div.job-detail-box > dl'))  #.upper()  \n",
    "    #找到可能會出現找尋目標的區塊將全部英文變大寫\n",
    "\n",
    "    lan1=re.findall('[A-Z]+[+#?]*' , innerselect)\n",
    "    #用正規法抓出每個英文單字\n",
    "    \n",
    "#     #將兩個list合併\n",
    "#     lan1.extend(lan2)\n",
    "#     #排除調內文出現的雜訊\n",
    "#     if 'HTML#' in lan1:\n",
    "#         lan1.remove('HTML#')\n",
    "#     if 'HTML?' in lan1:\n",
    "#         lan1.remove('HTML?')\n",
    "   \n",
    "    lan1 = list(set(lan1))     #list(set( list ))\n",
    "    #清除調list內重複的部份\n",
    "    \n",
    "    for i in lan1: \n",
    "        if i in wordlen: \n",
    "            if i in static: \n",
    "                static[i] += 1\n",
    "            else:\n",
    "                static[i] = 1 \n",
    "    return static\n"
   ]
  },
  {
   "cell_type": "code",
   "execution_count": 17,
   "metadata": {
    "collapsed": true
   },
   "outputs": [],
   "source": [
    "def pageURL(url):  \n",
    "    res = requests.get(url)\n",
    "    soup = BeautifulSoup(res.text, 'lxml')\n",
    "    links = soup.select('li.title > a')\n",
    "    for link in links:\n",
    "        innerURL(str(link['href']))  #throw in innerURL function\n",
    "    return static\n",
    "    "
   ]
  },
  {
   "cell_type": "code",
   "execution_count": 18,
   "metadata": {
    "collapsed": true
   },
   "outputs": [],
   "source": [
    "class MyThread (threading.Thread): # 繼承 Thread 類別\n",
    "    def __init__(self,number):\n",
    "        threading.Thread.__init__(self)\n",
    "        self.number=number\n",
    "    def run(self): \n",
    "        pageURL('https://www.518.com.tw/job-index-P-'+str(self.number)+'.html?i=1&am=1&ab=2032001,2032002,') \n",
    "        #throw in pageURL function\n",
    "        print('[Debug] Page {} is finished'.format(self.number))"
   ]
  },
  {
   "cell_type": "code",
   "execution_count": null,
   "metadata": {
    "collapsed": true
   },
   "outputs": [],
   "source": []
  },
  {
   "cell_type": "code",
   "execution_count": 19,
   "metadata": {
    "scrolled": true
   },
   "outputs": [
    {
     "name": "stdout",
     "output_type": "stream",
     "text": [
      "[Debug] Page 54 is finished\n",
      "[Debug] Page 53 is finished\n",
      "[Debug] Page 16 is finished\n"
     ]
    },
    {
     "name": "stderr",
     "output_type": "stream",
     "text": [
      "Exception in thread Thread-22:\n",
      "Traceback (most recent call last):\n",
      "  File \"/home/ubuntu/.pyenv/versions/3.6.1/lib/python3.6/site-packages/requests/packages/urllib3/connection.py\", line 141, in _new_conn\n",
      "    (self.host, self.port), self.timeout, **extra_kw)\n",
      "  File \"/home/ubuntu/.pyenv/versions/3.6.1/lib/python3.6/site-packages/requests/packages/urllib3/util/connection.py\", line 60, in create_connection\n",
      "    for res in socket.getaddrinfo(host, port, family, socket.SOCK_STREAM):\n",
      "  File \"/home/ubuntu/.pyenv/versions/3.6.1/lib/python3.6/socket.py\", line 743, in getaddrinfo\n",
      "    for res in _socket.getaddrinfo(host, port, family, type, proto, flags):\n",
      "socket.gaierror: [Errno -3] Temporary failure in name resolution\n",
      "\n",
      "During handling of the above exception, another exception occurred:\n",
      "\n",
      "Traceback (most recent call last):\n",
      "  File \"/home/ubuntu/.pyenv/versions/3.6.1/lib/python3.6/site-packages/requests/packages/urllib3/connectionpool.py\", line 600, in urlopen\n",
      "    chunked=chunked)\n",
      "  File \"/home/ubuntu/.pyenv/versions/3.6.1/lib/python3.6/site-packages/requests/packages/urllib3/connectionpool.py\", line 345, in _make_request\n",
      "    self._validate_conn(conn)\n",
      "  File \"/home/ubuntu/.pyenv/versions/3.6.1/lib/python3.6/site-packages/requests/packages/urllib3/connectionpool.py\", line 844, in _validate_conn\n",
      "    conn.connect()\n",
      "  File \"/home/ubuntu/.pyenv/versions/3.6.1/lib/python3.6/site-packages/requests/packages/urllib3/connection.py\", line 284, in connect\n",
      "    conn = self._new_conn()\n",
      "  File \"/home/ubuntu/.pyenv/versions/3.6.1/lib/python3.6/site-packages/requests/packages/urllib3/connection.py\", line 150, in _new_conn\n",
      "    self, \"Failed to establish a new connection: %s\" % e)\n",
      "requests.packages.urllib3.exceptions.NewConnectionError: <requests.packages.urllib3.connection.VerifiedHTTPSConnection object at 0x7f244f89ff60>: Failed to establish a new connection: [Errno -3] Temporary failure in name resolution\n",
      "\n",
      "During handling of the above exception, another exception occurred:\n",
      "\n",
      "Traceback (most recent call last):\n",
      "  File \"/home/ubuntu/.pyenv/versions/3.6.1/lib/python3.6/site-packages/requests/adapters.py\", line 423, in send\n",
      "    timeout=timeout\n",
      "  File \"/home/ubuntu/.pyenv/versions/3.6.1/lib/python3.6/site-packages/requests/packages/urllib3/connectionpool.py\", line 649, in urlopen\n",
      "    _stacktrace=sys.exc_info()[2])\n",
      "  File \"/home/ubuntu/.pyenv/versions/3.6.1/lib/python3.6/site-packages/requests/packages/urllib3/util/retry.py\", line 376, in increment\n",
      "    raise MaxRetryError(_pool, url, error or ResponseError(cause))\n",
      "requests.packages.urllib3.exceptions.MaxRetryError: HTTPSConnectionPool(host='www.518.com.tw', port=443): Max retries exceeded with url: /IOS%E8%BB%9F%E9%AB%94%E8%A8%AD%E8%A8%88%E5%B7%A5%E7%A8%8B%E5%B8%AB-%E6%96%B0%E5%8C%97%E5%B8%82-%E4%B8%89%E9%87%8D%E5%8D%80-job-1212106.html?kw=&pi=19 (Caused by NewConnectionError('<requests.packages.urllib3.connection.VerifiedHTTPSConnection object at 0x7f244f89ff60>: Failed to establish a new connection: [Errno -3] Temporary failure in name resolution',))\n",
      "\n",
      "During handling of the above exception, another exception occurred:\n",
      "\n",
      "Traceback (most recent call last):\n",
      "  File \"/home/ubuntu/.pyenv/versions/3.6.1/lib/python3.6/threading.py\", line 916, in _bootstrap_inner\n",
      "    self.run()\n",
      "  File \"<ipython-input-18-c76fc6bf8299>\", line 6, in run\n",
      "    pageURL('https://www.518.com.tw/job-index-P-'+str(self.number)+'.html?i=1&am=1&ab=2032001,2032002,')\n",
      "  File \"<ipython-input-17-696307882546>\", line 6, in pageURL\n",
      "    innerURL(str(link['href']))  #throw in innerURL function\n",
      "  File \"<ipython-input-16-1d4840fd97cd>\", line 3, in innerURL\n",
      "    inner = requests.get(url)  #用get連到網頁\n",
      "  File \"/home/ubuntu/.pyenv/versions/3.6.1/lib/python3.6/site-packages/requests/api.py\", line 70, in get\n",
      "    return request('get', url, params=params, **kwargs)\n",
      "  File \"/home/ubuntu/.pyenv/versions/3.6.1/lib/python3.6/site-packages/requests/api.py\", line 56, in request\n",
      "    return session.request(method=method, url=url, **kwargs)\n",
      "  File \"/home/ubuntu/.pyenv/versions/3.6.1/lib/python3.6/site-packages/requests/sessions.py\", line 488, in request\n",
      "    resp = self.send(prep, **send_kwargs)\n",
      "  File \"/home/ubuntu/.pyenv/versions/3.6.1/lib/python3.6/site-packages/requests/sessions.py\", line 609, in send\n",
      "    r = adapter.send(request, **kwargs)\n",
      "  File \"/home/ubuntu/.pyenv/versions/3.6.1/lib/python3.6/site-packages/requests/adapters.py\", line 487, in send\n",
      "    raise ConnectionError(e, request=request)\n",
      "requests.exceptions.ConnectionError: HTTPSConnectionPool(host='www.518.com.tw', port=443): Max retries exceeded with url: /IOS%E8%BB%9F%E9%AB%94%E8%A8%AD%E8%A8%88%E5%B7%A5%E7%A8%8B%E5%B8%AB-%E6%96%B0%E5%8C%97%E5%B8%82-%E4%B8%89%E9%87%8D%E5%8D%80-job-1212106.html?kw=&pi=19 (Caused by NewConnectionError('<requests.packages.urllib3.connection.VerifiedHTTPSConnection object at 0x7f244f89ff60>: Failed to establish a new connection: [Errno -3] Temporary failure in name resolution',))\n",
      "\n",
      "Exception in thread Thread-20:\n",
      "Traceback (most recent call last):\n",
      "  File \"/home/ubuntu/.pyenv/versions/3.6.1/lib/python3.6/site-packages/requests/packages/urllib3/connection.py\", line 141, in _new_conn\n",
      "    (self.host, self.port), self.timeout, **extra_kw)\n",
      "  File \"/home/ubuntu/.pyenv/versions/3.6.1/lib/python3.6/site-packages/requests/packages/urllib3/util/connection.py\", line 60, in create_connection\n",
      "    for res in socket.getaddrinfo(host, port, family, socket.SOCK_STREAM):\n",
      "  File \"/home/ubuntu/.pyenv/versions/3.6.1/lib/python3.6/socket.py\", line 743, in getaddrinfo\n",
      "    for res in _socket.getaddrinfo(host, port, family, type, proto, flags):\n",
      "socket.gaierror: [Errno -3] Temporary failure in name resolution\n",
      "\n",
      "During handling of the above exception, another exception occurred:\n",
      "\n",
      "Traceback (most recent call last):\n",
      "  File \"/home/ubuntu/.pyenv/versions/3.6.1/lib/python3.6/site-packages/requests/packages/urllib3/connectionpool.py\", line 600, in urlopen\n",
      "    chunked=chunked)\n",
      "  File \"/home/ubuntu/.pyenv/versions/3.6.1/lib/python3.6/site-packages/requests/packages/urllib3/connectionpool.py\", line 356, in _make_request\n",
      "    conn.request(method, url, **httplib_request_kw)\n",
      "  File \"/home/ubuntu/.pyenv/versions/3.6.1/lib/python3.6/http/client.py\", line 1239, in request\n",
      "    self._send_request(method, url, body, headers, encode_chunked)\n",
      "  File \"/home/ubuntu/.pyenv/versions/3.6.1/lib/python3.6/http/client.py\", line 1285, in _send_request\n",
      "    self.endheaders(body, encode_chunked=encode_chunked)\n",
      "  File \"/home/ubuntu/.pyenv/versions/3.6.1/lib/python3.6/http/client.py\", line 1234, in endheaders\n",
      "    self._send_output(message_body, encode_chunked=encode_chunked)\n",
      "  File \"/home/ubuntu/.pyenv/versions/3.6.1/lib/python3.6/http/client.py\", line 1026, in _send_output\n",
      "    self.send(msg)\n",
      "  File \"/home/ubuntu/.pyenv/versions/3.6.1/lib/python3.6/http/client.py\", line 964, in send\n",
      "    self.connect()\n",
      "  File \"/home/ubuntu/.pyenv/versions/3.6.1/lib/python3.6/site-packages/requests/packages/urllib3/connection.py\", line 166, in connect\n",
      "    conn = self._new_conn()\n",
      "  File \"/home/ubuntu/.pyenv/versions/3.6.1/lib/python3.6/site-packages/requests/packages/urllib3/connection.py\", line 150, in _new_conn\n",
      "    self, \"Failed to establish a new connection: %s\" % e)\n",
      "requests.packages.urllib3.exceptions.NewConnectionError: <requests.packages.urllib3.connection.HTTPConnection object at 0x7f244f2e0be0>: Failed to establish a new connection: [Errno -3] Temporary failure in name resolution\n",
      "\n",
      "During handling of the above exception, another exception occurred:\n",
      "\n",
      "Traceback (most recent call last):\n",
      "  File \"/home/ubuntu/.pyenv/versions/3.6.1/lib/python3.6/site-packages/requests/adapters.py\", line 423, in send\n",
      "    timeout=timeout\n",
      "  File \"/home/ubuntu/.pyenv/versions/3.6.1/lib/python3.6/site-packages/requests/packages/urllib3/connectionpool.py\", line 649, in urlopen\n",
      "    _stacktrace=sys.exc_info()[2])\n",
      "  File \"/home/ubuntu/.pyenv/versions/3.6.1/lib/python3.6/site-packages/requests/packages/urllib3/util/retry.py\", line 376, in increment\n",
      "    raise MaxRetryError(_pool, url, error or ResponseError(cause))\n",
      "requests.packages.urllib3.exceptions.MaxRetryError: HTTPConnectionPool(host='case.518.com.tw', port=80): Max retries exceeded with url: /casepage-detail-124325.html?from=518&a_id=2183 (Caused by NewConnectionError('<requests.packages.urllib3.connection.HTTPConnection object at 0x7f244f2e0be0>: Failed to establish a new connection: [Errno -3] Temporary failure in name resolution',))\n",
      "\n",
      "During handling of the above exception, another exception occurred:\n",
      "\n",
      "Traceback (most recent call last):\n",
      "  File \"/home/ubuntu/.pyenv/versions/3.6.1/lib/python3.6/threading.py\", line 916, in _bootstrap_inner\n",
      "    self.run()\n",
      "  File \"<ipython-input-18-c76fc6bf8299>\", line 6, in run\n",
      "    pageURL('https://www.518.com.tw/job-index-P-'+str(self.number)+'.html?i=1&am=1&ab=2032001,2032002,')\n",
      "  File \"<ipython-input-17-696307882546>\", line 6, in pageURL\n",
      "    innerURL(str(link['href']))  #throw in innerURL function\n",
      "  File \"<ipython-input-16-1d4840fd97cd>\", line 3, in innerURL\n",
      "    inner = requests.get(url)  #用get連到網頁\n",
      "  File \"/home/ubuntu/.pyenv/versions/3.6.1/lib/python3.6/site-packages/requests/api.py\", line 70, in get\n",
      "    return request('get', url, params=params, **kwargs)\n",
      "  File \"/home/ubuntu/.pyenv/versions/3.6.1/lib/python3.6/site-packages/requests/api.py\", line 56, in request\n",
      "    return session.request(method=method, url=url, **kwargs)\n",
      "  File \"/home/ubuntu/.pyenv/versions/3.6.1/lib/python3.6/site-packages/requests/sessions.py\", line 488, in request\n",
      "    resp = self.send(prep, **send_kwargs)\n",
      "  File \"/home/ubuntu/.pyenv/versions/3.6.1/lib/python3.6/site-packages/requests/sessions.py\", line 609, in send\n",
      "    r = adapter.send(request, **kwargs)\n",
      "  File \"/home/ubuntu/.pyenv/versions/3.6.1/lib/python3.6/site-packages/requests/adapters.py\", line 487, in send\n",
      "    raise ConnectionError(e, request=request)\n",
      "requests.exceptions.ConnectionError: HTTPConnectionPool(host='case.518.com.tw', port=80): Max retries exceeded with url: /casepage-detail-124325.html?from=518&a_id=2183 (Caused by NewConnectionError('<requests.packages.urllib3.connection.HTTPConnection object at 0x7f244f2e0be0>: Failed to establish a new connection: [Errno -3] Temporary failure in name resolution',))\n",
      "\n",
      "Exception in thread Thread-52:\n",
      "Traceback (most recent call last):\n",
      "  File \"/home/ubuntu/.pyenv/versions/3.6.1/lib/python3.6/site-packages/requests/packages/urllib3/connection.py\", line 141, in _new_conn\n",
      "    (self.host, self.port), self.timeout, **extra_kw)\n",
      "  File \"/home/ubuntu/.pyenv/versions/3.6.1/lib/python3.6/site-packages/requests/packages/urllib3/util/connection.py\", line 60, in create_connection\n",
      "    for res in socket.getaddrinfo(host, port, family, socket.SOCK_STREAM):\n",
      "  File \"/home/ubuntu/.pyenv/versions/3.6.1/lib/python3.6/socket.py\", line 743, in getaddrinfo\n",
      "    for res in _socket.getaddrinfo(host, port, family, type, proto, flags):\n",
      "socket.gaierror: [Errno -3] Temporary failure in name resolution\n",
      "\n",
      "During handling of the above exception, another exception occurred:\n",
      "\n",
      "Traceback (most recent call last):\n",
      "  File \"/home/ubuntu/.pyenv/versions/3.6.1/lib/python3.6/site-packages/requests/packages/urllib3/connectionpool.py\", line 600, in urlopen\n",
      "    chunked=chunked)\n",
      "  File \"/home/ubuntu/.pyenv/versions/3.6.1/lib/python3.6/site-packages/requests/packages/urllib3/connectionpool.py\", line 345, in _make_request\n",
      "    self._validate_conn(conn)\n",
      "  File \"/home/ubuntu/.pyenv/versions/3.6.1/lib/python3.6/site-packages/requests/packages/urllib3/connectionpool.py\", line 844, in _validate_conn\n",
      "    conn.connect()\n",
      "  File \"/home/ubuntu/.pyenv/versions/3.6.1/lib/python3.6/site-packages/requests/packages/urllib3/connection.py\", line 284, in connect\n",
      "    conn = self._new_conn()\n",
      "  File \"/home/ubuntu/.pyenv/versions/3.6.1/lib/python3.6/site-packages/requests/packages/urllib3/connection.py\", line 150, in _new_conn\n",
      "    self, \"Failed to establish a new connection: %s\" % e)\n",
      "requests.packages.urllib3.exceptions.NewConnectionError: <requests.packages.urllib3.connection.VerifiedHTTPSConnection object at 0x7f2450a848d0>: Failed to establish a new connection: [Errno -3] Temporary failure in name resolution\n",
      "\n",
      "During handling of the above exception, another exception occurred:\n",
      "\n",
      "Traceback (most recent call last):\n",
      "  File \"/home/ubuntu/.pyenv/versions/3.6.1/lib/python3.6/site-packages/requests/adapters.py\", line 423, in send\n",
      "    timeout=timeout\n",
      "  File \"/home/ubuntu/.pyenv/versions/3.6.1/lib/python3.6/site-packages/requests/packages/urllib3/connectionpool.py\", line 649, in urlopen\n",
      "    _stacktrace=sys.exc_info()[2])\n",
      "  File \"/home/ubuntu/.pyenv/versions/3.6.1/lib/python3.6/site-packages/requests/packages/urllib3/util/retry.py\", line 376, in increment\n",
      "    raise MaxRetryError(_pool, url, error or ResponseError(cause))\n",
      "requests.packages.urllib3.exceptions.MaxRetryError: HTTPSConnectionPool(host='www.518.com.tw', port=443): Max retries exceeded with url: /%E7%A8%8B%E5%BC%8F%E8%A8%AD%E8%A8%88%E5%B8%AB-%E6%96%B0%E5%8C%97%E5%B8%82-%E6%A8%B9%E6%9E%97%E5%8D%80-job-381205.html?kw=&pi=49 (Caused by NewConnectionError('<requests.packages.urllib3.connection.VerifiedHTTPSConnection object at 0x7f2450a848d0>: Failed to establish a new connection: [Errno -3] Temporary failure in name resolution',))\n",
      "\n",
      "During handling of the above exception, another exception occurred:\n",
      "\n",
      "Traceback (most recent call last):\n",
      "  File \"/home/ubuntu/.pyenv/versions/3.6.1/lib/python3.6/threading.py\", line 916, in _bootstrap_inner\n",
      "    self.run()\n",
      "  File \"<ipython-input-18-c76fc6bf8299>\", line 6, in run\n",
      "    pageURL('https://www.518.com.tw/job-index-P-'+str(self.number)+'.html?i=1&am=1&ab=2032001,2032002,')\n",
      "  File \"<ipython-input-17-696307882546>\", line 6, in pageURL\n",
      "    innerURL(str(link['href']))  #throw in innerURL function\n",
      "  File \"<ipython-input-16-1d4840fd97cd>\", line 3, in innerURL\n",
      "    inner = requests.get(url)  #用get連到網頁\n",
      "  File \"/home/ubuntu/.pyenv/versions/3.6.1/lib/python3.6/site-packages/requests/api.py\", line 70, in get\n",
      "    return request('get', url, params=params, **kwargs)\n",
      "  File \"/home/ubuntu/.pyenv/versions/3.6.1/lib/python3.6/site-packages/requests/api.py\", line 56, in request\n",
      "    return session.request(method=method, url=url, **kwargs)\n",
      "  File \"/home/ubuntu/.pyenv/versions/3.6.1/lib/python3.6/site-packages/requests/sessions.py\", line 488, in request\n",
      "    resp = self.send(prep, **send_kwargs)\n",
      "  File \"/home/ubuntu/.pyenv/versions/3.6.1/lib/python3.6/site-packages/requests/sessions.py\", line 609, in send\n",
      "    r = adapter.send(request, **kwargs)\n",
      "  File \"/home/ubuntu/.pyenv/versions/3.6.1/lib/python3.6/site-packages/requests/adapters.py\", line 487, in send\n",
      "    raise ConnectionError(e, request=request)\n",
      "requests.exceptions.ConnectionError: HTTPSConnectionPool(host='www.518.com.tw', port=443): Max retries exceeded with url: /%E7%A8%8B%E5%BC%8F%E8%A8%AD%E8%A8%88%E5%B8%AB-%E6%96%B0%E5%8C%97%E5%B8%82-%E6%A8%B9%E6%9E%97%E5%8D%80-job-381205.html?kw=&pi=49 (Caused by NewConnectionError('<requests.packages.urllib3.connection.VerifiedHTTPSConnection object at 0x7f2450a848d0>: Failed to establish a new connection: [Errno -3] Temporary failure in name resolution',))\n",
      "\n",
      "Exception in thread Thread-39:\n",
      "Traceback (most recent call last):\n",
      "  File \"/home/ubuntu/.pyenv/versions/3.6.1/lib/python3.6/site-packages/requests/packages/urllib3/connection.py\", line 141, in _new_conn\n",
      "    (self.host, self.port), self.timeout, **extra_kw)\n",
      "  File \"/home/ubuntu/.pyenv/versions/3.6.1/lib/python3.6/site-packages/requests/packages/urllib3/util/connection.py\", line 60, in create_connection\n",
      "    for res in socket.getaddrinfo(host, port, family, socket.SOCK_STREAM):\n",
      "  File \"/home/ubuntu/.pyenv/versions/3.6.1/lib/python3.6/socket.py\", line 743, in getaddrinfo\n",
      "    for res in _socket.getaddrinfo(host, port, family, type, proto, flags):\n",
      "socket.gaierror: [Errno -3] Temporary failure in name resolution\n",
      "\n",
      "During handling of the above exception, another exception occurred:\n",
      "\n",
      "Traceback (most recent call last):\n",
      "  File \"/home/ubuntu/.pyenv/versions/3.6.1/lib/python3.6/site-packages/requests/packages/urllib3/connectionpool.py\", line 600, in urlopen\n",
      "    chunked=chunked)\n",
      "  File \"/home/ubuntu/.pyenv/versions/3.6.1/lib/python3.6/site-packages/requests/packages/urllib3/connectionpool.py\", line 356, in _make_request\n",
      "    conn.request(method, url, **httplib_request_kw)\n",
      "  File \"/home/ubuntu/.pyenv/versions/3.6.1/lib/python3.6/http/client.py\", line 1239, in request\n",
      "    self._send_request(method, url, body, headers, encode_chunked)\n",
      "  File \"/home/ubuntu/.pyenv/versions/3.6.1/lib/python3.6/http/client.py\", line 1285, in _send_request\n",
      "    self.endheaders(body, encode_chunked=encode_chunked)\n",
      "  File \"/home/ubuntu/.pyenv/versions/3.6.1/lib/python3.6/http/client.py\", line 1234, in endheaders\n",
      "    self._send_output(message_body, encode_chunked=encode_chunked)\n",
      "  File \"/home/ubuntu/.pyenv/versions/3.6.1/lib/python3.6/http/client.py\", line 1026, in _send_output\n",
      "    self.send(msg)\n",
      "  File \"/home/ubuntu/.pyenv/versions/3.6.1/lib/python3.6/http/client.py\", line 964, in send\n",
      "    self.connect()\n",
      "  File \"/home/ubuntu/.pyenv/versions/3.6.1/lib/python3.6/site-packages/requests/packages/urllib3/connection.py\", line 166, in connect\n",
      "    conn = self._new_conn()\n",
      "  File \"/home/ubuntu/.pyenv/versions/3.6.1/lib/python3.6/site-packages/requests/packages/urllib3/connection.py\", line 150, in _new_conn\n",
      "    self, \"Failed to establish a new connection: %s\" % e)\n",
      "requests.packages.urllib3.exceptions.NewConnectionError: <requests.packages.urllib3.connection.HTTPConnection object at 0x7f2450adbef0>: Failed to establish a new connection: [Errno -3] Temporary failure in name resolution\n",
      "\n",
      "During handling of the above exception, another exception occurred:\n",
      "\n",
      "Traceback (most recent call last):\n",
      "  File \"/home/ubuntu/.pyenv/versions/3.6.1/lib/python3.6/site-packages/requests/adapters.py\", line 423, in send\n",
      "    timeout=timeout\n",
      "  File \"/home/ubuntu/.pyenv/versions/3.6.1/lib/python3.6/site-packages/requests/packages/urllib3/connectionpool.py\", line 649, in urlopen\n",
      "    _stacktrace=sys.exc_info()[2])\n",
      "  File \"/home/ubuntu/.pyenv/versions/3.6.1/lib/python3.6/site-packages/requests/packages/urllib3/util/retry.py\", line 376, in increment\n",
      "    raise MaxRetryError(_pool, url, error or ResponseError(cause))\n",
      "requests.packages.urllib3.exceptions.MaxRetryError: HTTPConnectionPool(host='case.518.com.tw', port=80): Max retries exceeded with url: /casepage-detail-123396.html?from=518&a_id=2183 (Caused by NewConnectionError('<requests.packages.urllib3.connection.HTTPConnection object at 0x7f2450adbef0>: Failed to establish a new connection: [Errno -3] Temporary failure in name resolution',))\n",
      "\n",
      "During handling of the above exception, another exception occurred:\n",
      "\n",
      "Traceback (most recent call last):\n",
      "  File \"/home/ubuntu/.pyenv/versions/3.6.1/lib/python3.6/threading.py\", line 916, in _bootstrap_inner\n",
      "    self.run()\n",
      "  File \"<ipython-input-18-c76fc6bf8299>\", line 6, in run\n",
      "    pageURL('https://www.518.com.tw/job-index-P-'+str(self.number)+'.html?i=1&am=1&ab=2032001,2032002,')\n",
      "  File \"<ipython-input-17-696307882546>\", line 6, in pageURL\n",
      "    innerURL(str(link['href']))  #throw in innerURL function\n",
      "  File \"<ipython-input-16-1d4840fd97cd>\", line 3, in innerURL\n",
      "    inner = requests.get(url)  #用get連到網頁\n",
      "  File \"/home/ubuntu/.pyenv/versions/3.6.1/lib/python3.6/site-packages/requests/api.py\", line 70, in get\n",
      "    return request('get', url, params=params, **kwargs)\n",
      "  File \"/home/ubuntu/.pyenv/versions/3.6.1/lib/python3.6/site-packages/requests/api.py\", line 56, in request\n",
      "    return session.request(method=method, url=url, **kwargs)\n",
      "  File \"/home/ubuntu/.pyenv/versions/3.6.1/lib/python3.6/site-packages/requests/sessions.py\", line 488, in request\n",
      "    resp = self.send(prep, **send_kwargs)\n",
      "  File \"/home/ubuntu/.pyenv/versions/3.6.1/lib/python3.6/site-packages/requests/sessions.py\", line 609, in send\n",
      "    r = adapter.send(request, **kwargs)\n",
      "  File \"/home/ubuntu/.pyenv/versions/3.6.1/lib/python3.6/site-packages/requests/adapters.py\", line 487, in send\n",
      "    raise ConnectionError(e, request=request)\n",
      "requests.exceptions.ConnectionError: HTTPConnectionPool(host='case.518.com.tw', port=80): Max retries exceeded with url: /casepage-detail-123396.html?from=518&a_id=2183 (Caused by NewConnectionError('<requests.packages.urllib3.connection.HTTPConnection object at 0x7f2450adbef0>: Failed to establish a new connection: [Errno -3] Temporary failure in name resolution',))\n",
      "\n"
     ]
    },
    {
     "name": "stderr",
     "output_type": "stream",
     "text": [
      "Exception in thread Thread-54:\n",
      "Traceback (most recent call last):\n",
      "  File \"/home/ubuntu/.pyenv/versions/3.6.1/lib/python3.6/site-packages/requests/packages/urllib3/connection.py\", line 141, in _new_conn\n",
      "    (self.host, self.port), self.timeout, **extra_kw)\n",
      "  File \"/home/ubuntu/.pyenv/versions/3.6.1/lib/python3.6/site-packages/requests/packages/urllib3/util/connection.py\", line 60, in create_connection\n",
      "    for res in socket.getaddrinfo(host, port, family, socket.SOCK_STREAM):\n",
      "  File \"/home/ubuntu/.pyenv/versions/3.6.1/lib/python3.6/socket.py\", line 743, in getaddrinfo\n",
      "    for res in _socket.getaddrinfo(host, port, family, type, proto, flags):\n",
      "socket.gaierror: [Errno -3] Temporary failure in name resolution\n",
      "\n",
      "During handling of the above exception, another exception occurred:\n",
      "\n",
      "Traceback (most recent call last):\n",
      "  File \"/home/ubuntu/.pyenv/versions/3.6.1/lib/python3.6/site-packages/requests/packages/urllib3/connectionpool.py\", line 600, in urlopen\n",
      "    chunked=chunked)\n",
      "  File \"/home/ubuntu/.pyenv/versions/3.6.1/lib/python3.6/site-packages/requests/packages/urllib3/connectionpool.py\", line 345, in _make_request\n",
      "    self._validate_conn(conn)\n",
      "  File \"/home/ubuntu/.pyenv/versions/3.6.1/lib/python3.6/site-packages/requests/packages/urllib3/connectionpool.py\", line 844, in _validate_conn\n",
      "    conn.connect()\n",
      "  File \"/home/ubuntu/.pyenv/versions/3.6.1/lib/python3.6/site-packages/requests/packages/urllib3/connection.py\", line 284, in connect\n",
      "    conn = self._new_conn()\n",
      "  File \"/home/ubuntu/.pyenv/versions/3.6.1/lib/python3.6/site-packages/requests/packages/urllib3/connection.py\", line 150, in _new_conn\n",
      "    self, \"Failed to establish a new connection: %s\" % e)\n",
      "requests.packages.urllib3.exceptions.NewConnectionError: <requests.packages.urllib3.connection.VerifiedHTTPSConnection object at 0x7f2451193278>: Failed to establish a new connection: [Errno -3] Temporary failure in name resolution\n",
      "\n",
      "During handling of the above exception, another exception occurred:\n",
      "\n",
      "Traceback (most recent call last):\n",
      "  File \"/home/ubuntu/.pyenv/versions/3.6.1/lib/python3.6/site-packages/requests/adapters.py\", line 423, in send\n",
      "    timeout=timeout\n",
      "  File \"/home/ubuntu/.pyenv/versions/3.6.1/lib/python3.6/site-packages/requests/packages/urllib3/connectionpool.py\", line 649, in urlopen\n",
      "    _stacktrace=sys.exc_info()[2])\n",
      "  File \"/home/ubuntu/.pyenv/versions/3.6.1/lib/python3.6/site-packages/requests/packages/urllib3/util/retry.py\", line 376, in increment\n",
      "    raise MaxRetryError(_pool, url, error or ResponseError(cause))\n",
      "requests.packages.urllib3.exceptions.MaxRetryError: HTTPSConnectionPool(host='www.518.com.tw', port=443): Max retries exceeded with url: /%E7%B6%B2%E7%AB%99%E7%A8%8B%E5%BC%8F%E8%A8%AD%E8%A8%88%E5%B8%AB-%E6%96%B0%E5%8C%97%E5%B8%82-%E6%9D%BF%E6%A9%8B%E5%8D%80-job-1134117.html?kw=&pi=51 (Caused by NewConnectionError('<requests.packages.urllib3.connection.VerifiedHTTPSConnection object at 0x7f2451193278>: Failed to establish a new connection: [Errno -3] Temporary failure in name resolution',))\n",
      "\n",
      "During handling of the above exception, another exception occurred:\n",
      "\n",
      "Traceback (most recent call last):\n",
      "  File \"/home/ubuntu/.pyenv/versions/3.6.1/lib/python3.6/threading.py\", line 916, in _bootstrap_inner\n",
      "    self.run()\n",
      "  File \"<ipython-input-18-c76fc6bf8299>\", line 6, in run\n",
      "    pageURL('https://www.518.com.tw/job-index-P-'+str(self.number)+'.html?i=1&am=1&ab=2032001,2032002,')\n",
      "  File \"<ipython-input-17-696307882546>\", line 6, in pageURL\n",
      "    innerURL(str(link['href']))  #throw in innerURL function\n",
      "  File \"<ipython-input-16-1d4840fd97cd>\", line 3, in innerURL\n",
      "    inner = requests.get(url)  #用get連到網頁\n",
      "  File \"/home/ubuntu/.pyenv/versions/3.6.1/lib/python3.6/site-packages/requests/api.py\", line 70, in get\n",
      "    return request('get', url, params=params, **kwargs)\n",
      "  File \"/home/ubuntu/.pyenv/versions/3.6.1/lib/python3.6/site-packages/requests/api.py\", line 56, in request\n",
      "    return session.request(method=method, url=url, **kwargs)\n",
      "  File \"/home/ubuntu/.pyenv/versions/3.6.1/lib/python3.6/site-packages/requests/sessions.py\", line 488, in request\n",
      "    resp = self.send(prep, **send_kwargs)\n",
      "  File \"/home/ubuntu/.pyenv/versions/3.6.1/lib/python3.6/site-packages/requests/sessions.py\", line 609, in send\n",
      "    r = adapter.send(request, **kwargs)\n",
      "  File \"/home/ubuntu/.pyenv/versions/3.6.1/lib/python3.6/site-packages/requests/adapters.py\", line 487, in send\n",
      "    raise ConnectionError(e, request=request)\n",
      "requests.exceptions.ConnectionError: HTTPSConnectionPool(host='www.518.com.tw', port=443): Max retries exceeded with url: /%E7%B6%B2%E7%AB%99%E7%A8%8B%E5%BC%8F%E8%A8%AD%E8%A8%88%E5%B8%AB-%E6%96%B0%E5%8C%97%E5%B8%82-%E6%9D%BF%E6%A9%8B%E5%8D%80-job-1134117.html?kw=&pi=51 (Caused by NewConnectionError('<requests.packages.urllib3.connection.VerifiedHTTPSConnection object at 0x7f2451193278>: Failed to establish a new connection: [Errno -3] Temporary failure in name resolution',))\n",
      "\n",
      "Exception in thread Thread-40:\n",
      "Traceback (most recent call last):\n",
      "  File \"/home/ubuntu/.pyenv/versions/3.6.1/lib/python3.6/site-packages/requests/packages/urllib3/connection.py\", line 141, in _new_conn\n",
      "    (self.host, self.port), self.timeout, **extra_kw)\n",
      "  File \"/home/ubuntu/.pyenv/versions/3.6.1/lib/python3.6/site-packages/requests/packages/urllib3/util/connection.py\", line 60, in create_connection\n",
      "    for res in socket.getaddrinfo(host, port, family, socket.SOCK_STREAM):\n",
      "  File \"/home/ubuntu/.pyenv/versions/3.6.1/lib/python3.6/socket.py\", line 743, in getaddrinfo\n",
      "    for res in _socket.getaddrinfo(host, port, family, type, proto, flags):\n",
      "socket.gaierror: [Errno -3] Temporary failure in name resolution\n",
      "\n",
      "During handling of the above exception, another exception occurred:\n",
      "\n",
      "Traceback (most recent call last):\n",
      "  File \"/home/ubuntu/.pyenv/versions/3.6.1/lib/python3.6/site-packages/requests/packages/urllib3/connectionpool.py\", line 600, in urlopen\n",
      "    chunked=chunked)\n",
      "  File \"/home/ubuntu/.pyenv/versions/3.6.1/lib/python3.6/site-packages/requests/packages/urllib3/connectionpool.py\", line 345, in _make_request\n",
      "    self._validate_conn(conn)\n",
      "  File \"/home/ubuntu/.pyenv/versions/3.6.1/lib/python3.6/site-packages/requests/packages/urllib3/connectionpool.py\", line 844, in _validate_conn\n",
      "    conn.connect()\n",
      "  File \"/home/ubuntu/.pyenv/versions/3.6.1/lib/python3.6/site-packages/requests/packages/urllib3/connection.py\", line 284, in connect\n",
      "    conn = self._new_conn()\n",
      "  File \"/home/ubuntu/.pyenv/versions/3.6.1/lib/python3.6/site-packages/requests/packages/urllib3/connection.py\", line 150, in _new_conn\n",
      "    self, \"Failed to establish a new connection: %s\" % e)\n",
      "requests.packages.urllib3.exceptions.NewConnectionError: <requests.packages.urllib3.connection.VerifiedHTTPSConnection object at 0x7f24513b9a58>: Failed to establish a new connection: [Errno -3] Temporary failure in name resolution\n",
      "\n",
      "During handling of the above exception, another exception occurred:\n",
      "\n",
      "Traceback (most recent call last):\n",
      "  File \"/home/ubuntu/.pyenv/versions/3.6.1/lib/python3.6/site-packages/requests/adapters.py\", line 423, in send\n",
      "    timeout=timeout\n",
      "  File \"/home/ubuntu/.pyenv/versions/3.6.1/lib/python3.6/site-packages/requests/packages/urllib3/connectionpool.py\", line 649, in urlopen\n",
      "    _stacktrace=sys.exc_info()[2])\n",
      "  File \"/home/ubuntu/.pyenv/versions/3.6.1/lib/python3.6/site-packages/requests/packages/urllib3/util/retry.py\", line 376, in increment\n",
      "    raise MaxRetryError(_pool, url, error or ResponseError(cause))\n",
      "requests.packages.urllib3.exceptions.MaxRetryError: HTTPSConnectionPool(host='www.518.com.tw', port=443): Max retries exceeded with url: /%E7%94%A2%E5%93%81%E9%96%8B%E7%99%BC%E8%BB%9F%E9%AB%94%E5%84%B2%E5%82%99%E5%B9%B9%E9%83%A8-%E5%8F%B0%E5%8C%97%E5%B8%82-%E5%A4%A7%E5%90%8C%E5%8D%80-job-294380.html?kw=&pi=37 (Caused by NewConnectionError('<requests.packages.urllib3.connection.VerifiedHTTPSConnection object at 0x7f24513b9a58>: Failed to establish a new connection: [Errno -3] Temporary failure in name resolution',))\n",
      "\n",
      "During handling of the above exception, another exception occurred:\n",
      "\n",
      "Traceback (most recent call last):\n",
      "  File \"/home/ubuntu/.pyenv/versions/3.6.1/lib/python3.6/threading.py\", line 916, in _bootstrap_inner\n",
      "    self.run()\n",
      "  File \"<ipython-input-18-c76fc6bf8299>\", line 6, in run\n",
      "    pageURL('https://www.518.com.tw/job-index-P-'+str(self.number)+'.html?i=1&am=1&ab=2032001,2032002,')\n",
      "  File \"<ipython-input-17-696307882546>\", line 6, in pageURL\n",
      "    innerURL(str(link['href']))  #throw in innerURL function\n",
      "  File \"<ipython-input-16-1d4840fd97cd>\", line 3, in innerURL\n",
      "    inner = requests.get(url)  #用get連到網頁\n",
      "  File \"/home/ubuntu/.pyenv/versions/3.6.1/lib/python3.6/site-packages/requests/api.py\", line 70, in get\n",
      "    return request('get', url, params=params, **kwargs)\n",
      "  File \"/home/ubuntu/.pyenv/versions/3.6.1/lib/python3.6/site-packages/requests/api.py\", line 56, in request\n",
      "    return session.request(method=method, url=url, **kwargs)\n",
      "  File \"/home/ubuntu/.pyenv/versions/3.6.1/lib/python3.6/site-packages/requests/sessions.py\", line 488, in request\n",
      "    resp = self.send(prep, **send_kwargs)\n",
      "  File \"/home/ubuntu/.pyenv/versions/3.6.1/lib/python3.6/site-packages/requests/sessions.py\", line 609, in send\n",
      "    r = adapter.send(request, **kwargs)\n",
      "  File \"/home/ubuntu/.pyenv/versions/3.6.1/lib/python3.6/site-packages/requests/adapters.py\", line 487, in send\n",
      "    raise ConnectionError(e, request=request)\n",
      "requests.exceptions.ConnectionError: HTTPSConnectionPool(host='www.518.com.tw', port=443): Max retries exceeded with url: /%E7%94%A2%E5%93%81%E9%96%8B%E7%99%BC%E8%BB%9F%E9%AB%94%E5%84%B2%E5%82%99%E5%B9%B9%E9%83%A8-%E5%8F%B0%E5%8C%97%E5%B8%82-%E5%A4%A7%E5%90%8C%E5%8D%80-job-294380.html?kw=&pi=37 (Caused by NewConnectionError('<requests.packages.urllib3.connection.VerifiedHTTPSConnection object at 0x7f24513b9a58>: Failed to establish a new connection: [Errno -3] Temporary failure in name resolution',))\n",
      "\n",
      "Exception in thread Thread-25:\n",
      "Traceback (most recent call last):\n",
      "  File \"/home/ubuntu/.pyenv/versions/3.6.1/lib/python3.6/site-packages/requests/packages/urllib3/connection.py\", line 141, in _new_conn\n",
      "    (self.host, self.port), self.timeout, **extra_kw)\n",
      "  File \"/home/ubuntu/.pyenv/versions/3.6.1/lib/python3.6/site-packages/requests/packages/urllib3/util/connection.py\", line 60, in create_connection\n",
      "    for res in socket.getaddrinfo(host, port, family, socket.SOCK_STREAM):\n",
      "  File \"/home/ubuntu/.pyenv/versions/3.6.1/lib/python3.6/socket.py\", line 743, in getaddrinfo\n",
      "    for res in _socket.getaddrinfo(host, port, family, type, proto, flags):\n",
      "socket.gaierror: [Errno -3] Temporary failure in name resolution\n",
      "\n",
      "During handling of the above exception, another exception occurred:\n",
      "\n",
      "Traceback (most recent call last):\n",
      "  File \"/home/ubuntu/.pyenv/versions/3.6.1/lib/python3.6/site-packages/requests/packages/urllib3/connectionpool.py\", line 600, in urlopen\n",
      "    chunked=chunked)\n",
      "  File \"/home/ubuntu/.pyenv/versions/3.6.1/lib/python3.6/site-packages/requests/packages/urllib3/connectionpool.py\", line 345, in _make_request\n",
      "    self._validate_conn(conn)\n",
      "  File \"/home/ubuntu/.pyenv/versions/3.6.1/lib/python3.6/site-packages/requests/packages/urllib3/connectionpool.py\", line 844, in _validate_conn\n",
      "    conn.connect()\n",
      "  File \"/home/ubuntu/.pyenv/versions/3.6.1/lib/python3.6/site-packages/requests/packages/urllib3/connection.py\", line 284, in connect\n",
      "    conn = self._new_conn()\n",
      "  File \"/home/ubuntu/.pyenv/versions/3.6.1/lib/python3.6/site-packages/requests/packages/urllib3/connection.py\", line 150, in _new_conn\n",
      "    self, \"Failed to establish a new connection: %s\" % e)\n",
      "requests.packages.urllib3.exceptions.NewConnectionError: <requests.packages.urllib3.connection.VerifiedHTTPSConnection object at 0x7f2458efb748>: Failed to establish a new connection: [Errno -3] Temporary failure in name resolution\n",
      "\n",
      "During handling of the above exception, another exception occurred:\n",
      "\n",
      "Traceback (most recent call last):\n",
      "  File \"/home/ubuntu/.pyenv/versions/3.6.1/lib/python3.6/site-packages/requests/adapters.py\", line 423, in send\n",
      "    timeout=timeout\n",
      "  File \"/home/ubuntu/.pyenv/versions/3.6.1/lib/python3.6/site-packages/requests/packages/urllib3/connectionpool.py\", line 649, in urlopen\n",
      "    _stacktrace=sys.exc_info()[2])\n",
      "  File \"/home/ubuntu/.pyenv/versions/3.6.1/lib/python3.6/site-packages/requests/packages/urllib3/util/retry.py\", line 376, in increment\n",
      "    raise MaxRetryError(_pool, url, error or ResponseError(cause))\n",
      "requests.packages.urllib3.exceptions.MaxRetryError: HTTPSConnectionPool(host='www.518.com.tw', port=443): Max retries exceeded with url: /%E8%B3%87%E8%A8%8A%E9%A7%90%E9%BB%9E%E4%BA%BA%E5%93%A1-%E5%8F%B0%E4%B8%AD%E5%B8%82-%E5%8D%97%E5%8D%80-job-1035978.html?kw=&pi=22 (Caused by NewConnectionError('<requests.packages.urllib3.connection.VerifiedHTTPSConnection object at 0x7f2458efb748>: Failed to establish a new connection: [Errno -3] Temporary failure in name resolution',))\n",
      "\n",
      "During handling of the above exception, another exception occurred:\n",
      "\n",
      "Traceback (most recent call last):\n",
      "  File \"/home/ubuntu/.pyenv/versions/3.6.1/lib/python3.6/threading.py\", line 916, in _bootstrap_inner\n",
      "    self.run()\n",
      "  File \"<ipython-input-18-c76fc6bf8299>\", line 6, in run\n",
      "    pageURL('https://www.518.com.tw/job-index-P-'+str(self.number)+'.html?i=1&am=1&ab=2032001,2032002,')\n",
      "  File \"<ipython-input-17-696307882546>\", line 6, in pageURL\n",
      "    innerURL(str(link['href']))  #throw in innerURL function\n",
      "  File \"<ipython-input-16-1d4840fd97cd>\", line 3, in innerURL\n",
      "    inner = requests.get(url)  #用get連到網頁\n",
      "  File \"/home/ubuntu/.pyenv/versions/3.6.1/lib/python3.6/site-packages/requests/api.py\", line 70, in get\n",
      "    return request('get', url, params=params, **kwargs)\n",
      "  File \"/home/ubuntu/.pyenv/versions/3.6.1/lib/python3.6/site-packages/requests/api.py\", line 56, in request\n",
      "    return session.request(method=method, url=url, **kwargs)\n",
      "  File \"/home/ubuntu/.pyenv/versions/3.6.1/lib/python3.6/site-packages/requests/sessions.py\", line 488, in request\n",
      "    resp = self.send(prep, **send_kwargs)\n",
      "  File \"/home/ubuntu/.pyenv/versions/3.6.1/lib/python3.6/site-packages/requests/sessions.py\", line 609, in send\n",
      "    r = adapter.send(request, **kwargs)\n",
      "  File \"/home/ubuntu/.pyenv/versions/3.6.1/lib/python3.6/site-packages/requests/adapters.py\", line 487, in send\n",
      "    raise ConnectionError(e, request=request)\n",
      "requests.exceptions.ConnectionError: HTTPSConnectionPool(host='www.518.com.tw', port=443): Max retries exceeded with url: /%E8%B3%87%E8%A8%8A%E9%A7%90%E9%BB%9E%E4%BA%BA%E5%93%A1-%E5%8F%B0%E4%B8%AD%E5%B8%82-%E5%8D%97%E5%8D%80-job-1035978.html?kw=&pi=22 (Caused by NewConnectionError('<requests.packages.urllib3.connection.VerifiedHTTPSConnection object at 0x7f2458efb748>: Failed to establish a new connection: [Errno -3] Temporary failure in name resolution',))\n",
      "\n",
      "Exception in thread Thread-6:\n",
      "Traceback (most recent call last):\n",
      "  File \"/home/ubuntu/.pyenv/versions/3.6.1/lib/python3.6/site-packages/requests/packages/urllib3/connection.py\", line 141, in _new_conn\n",
      "    (self.host, self.port), self.timeout, **extra_kw)\n",
      "  File \"/home/ubuntu/.pyenv/versions/3.6.1/lib/python3.6/site-packages/requests/packages/urllib3/util/connection.py\", line 60, in create_connection\n",
      "    for res in socket.getaddrinfo(host, port, family, socket.SOCK_STREAM):\n",
      "  File \"/home/ubuntu/.pyenv/versions/3.6.1/lib/python3.6/socket.py\", line 743, in getaddrinfo\n",
      "    for res in _socket.getaddrinfo(host, port, family, type, proto, flags):\n",
      "socket.gaierror: [Errno -3] Temporary failure in name resolution\n",
      "\n",
      "During handling of the above exception, another exception occurred:\n",
      "\n",
      "Traceback (most recent call last):\n",
      "  File \"/home/ubuntu/.pyenv/versions/3.6.1/lib/python3.6/site-packages/requests/packages/urllib3/connectionpool.py\", line 600, in urlopen\n",
      "    chunked=chunked)\n",
      "  File \"/home/ubuntu/.pyenv/versions/3.6.1/lib/python3.6/site-packages/requests/packages/urllib3/connectionpool.py\", line 356, in _make_request\n",
      "    conn.request(method, url, **httplib_request_kw)\n",
      "  File \"/home/ubuntu/.pyenv/versions/3.6.1/lib/python3.6/http/client.py\", line 1239, in request\n",
      "    self._send_request(method, url, body, headers, encode_chunked)\n",
      "  File \"/home/ubuntu/.pyenv/versions/3.6.1/lib/python3.6/http/client.py\", line 1285, in _send_request\n",
      "    self.endheaders(body, encode_chunked=encode_chunked)\n",
      "  File \"/home/ubuntu/.pyenv/versions/3.6.1/lib/python3.6/http/client.py\", line 1234, in endheaders\n",
      "    self._send_output(message_body, encode_chunked=encode_chunked)\n",
      "  File \"/home/ubuntu/.pyenv/versions/3.6.1/lib/python3.6/http/client.py\", line 1026, in _send_output\n",
      "    self.send(msg)\n",
      "  File \"/home/ubuntu/.pyenv/versions/3.6.1/lib/python3.6/http/client.py\", line 964, in send\n",
      "    self.connect()\n",
      "  File \"/home/ubuntu/.pyenv/versions/3.6.1/lib/python3.6/site-packages/requests/packages/urllib3/connection.py\", line 166, in connect\n",
      "    conn = self._new_conn()\n",
      "  File \"/home/ubuntu/.pyenv/versions/3.6.1/lib/python3.6/site-packages/requests/packages/urllib3/connection.py\", line 150, in _new_conn\n",
      "    self, \"Failed to establish a new connection: %s\" % e)\n",
      "requests.packages.urllib3.exceptions.NewConnectionError: <requests.packages.urllib3.connection.HTTPConnection object at 0x7f24532c54e0>: Failed to establish a new connection: [Errno -3] Temporary failure in name resolution\n",
      "\n",
      "During handling of the above exception, another exception occurred:\n",
      "\n",
      "Traceback (most recent call last):\n",
      "  File \"/home/ubuntu/.pyenv/versions/3.6.1/lib/python3.6/site-packages/requests/adapters.py\", line 423, in send\n",
      "    timeout=timeout\n",
      "  File \"/home/ubuntu/.pyenv/versions/3.6.1/lib/python3.6/site-packages/requests/packages/urllib3/connectionpool.py\", line 649, in urlopen\n",
      "    _stacktrace=sys.exc_info()[2])\n",
      "  File \"/home/ubuntu/.pyenv/versions/3.6.1/lib/python3.6/site-packages/requests/packages/urllib3/util/retry.py\", line 376, in increment\n",
      "    raise MaxRetryError(_pool, url, error or ResponseError(cause))\n",
      "requests.packages.urllib3.exceptions.MaxRetryError: HTTPConnectionPool(host='case.518.com.tw', port=80): Max retries exceeded with url: /casepage-detail-124778.html?from=518&a_id=2183 (Caused by NewConnectionError('<requests.packages.urllib3.connection.HTTPConnection object at 0x7f24532c54e0>: Failed to establish a new connection: [Errno -3] Temporary failure in name resolution',))\n",
      "\n",
      "During handling of the above exception, another exception occurred:\n",
      "\n",
      "Traceback (most recent call last):\n",
      "  File \"/home/ubuntu/.pyenv/versions/3.6.1/lib/python3.6/threading.py\", line 916, in _bootstrap_inner\n",
      "    self.run()\n",
      "  File \"<ipython-input-18-c76fc6bf8299>\", line 6, in run\n",
      "    pageURL('https://www.518.com.tw/job-index-P-'+str(self.number)+'.html?i=1&am=1&ab=2032001,2032002,')\n",
      "  File \"<ipython-input-17-696307882546>\", line 6, in pageURL\n",
      "    innerURL(str(link['href']))  #throw in innerURL function\n",
      "  File \"<ipython-input-16-1d4840fd97cd>\", line 3, in innerURL\n",
      "    inner = requests.get(url)  #用get連到網頁\n",
      "  File \"/home/ubuntu/.pyenv/versions/3.6.1/lib/python3.6/site-packages/requests/api.py\", line 70, in get\n",
      "    return request('get', url, params=params, **kwargs)\n",
      "  File \"/home/ubuntu/.pyenv/versions/3.6.1/lib/python3.6/site-packages/requests/api.py\", line 56, in request\n",
      "    return session.request(method=method, url=url, **kwargs)\n",
      "  File \"/home/ubuntu/.pyenv/versions/3.6.1/lib/python3.6/site-packages/requests/sessions.py\", line 488, in request\n",
      "    resp = self.send(prep, **send_kwargs)\n",
      "  File \"/home/ubuntu/.pyenv/versions/3.6.1/lib/python3.6/site-packages/requests/sessions.py\", line 609, in send\n",
      "    r = adapter.send(request, **kwargs)\n",
      "  File \"/home/ubuntu/.pyenv/versions/3.6.1/lib/python3.6/site-packages/requests/adapters.py\", line 487, in send\n",
      "    raise ConnectionError(e, request=request)\n",
      "requests.exceptions.ConnectionError: HTTPConnectionPool(host='case.518.com.tw', port=80): Max retries exceeded with url: /casepage-detail-124778.html?from=518&a_id=2183 (Caused by NewConnectionError('<requests.packages.urllib3.connection.HTTPConnection object at 0x7f24532c54e0>: Failed to establish a new connection: [Errno -3] Temporary failure in name resolution',))\n",
      "\n",
      "Exception in thread Thread-49:\n",
      "Traceback (most recent call last):\n",
      "  File \"/home/ubuntu/.pyenv/versions/3.6.1/lib/python3.6/site-packages/requests/packages/urllib3/connection.py\", line 141, in _new_conn\n",
      "    (self.host, self.port), self.timeout, **extra_kw)\n",
      "  File \"/home/ubuntu/.pyenv/versions/3.6.1/lib/python3.6/site-packages/requests/packages/urllib3/util/connection.py\", line 60, in create_connection\n",
      "    for res in socket.getaddrinfo(host, port, family, socket.SOCK_STREAM):\n",
      "  File \"/home/ubuntu/.pyenv/versions/3.6.1/lib/python3.6/socket.py\", line 743, in getaddrinfo\n",
      "    for res in _socket.getaddrinfo(host, port, family, type, proto, flags):\n",
      "socket.gaierror: [Errno -3] Temporary failure in name resolution\n",
      "\n",
      "During handling of the above exception, another exception occurred:\n",
      "\n",
      "Traceback (most recent call last):\n",
      "  File \"/home/ubuntu/.pyenv/versions/3.6.1/lib/python3.6/site-packages/requests/packages/urllib3/connectionpool.py\", line 600, in urlopen\n",
      "    chunked=chunked)\n",
      "  File \"/home/ubuntu/.pyenv/versions/3.6.1/lib/python3.6/site-packages/requests/packages/urllib3/connectionpool.py\", line 345, in _make_request\n",
      "    self._validate_conn(conn)\n",
      "  File \"/home/ubuntu/.pyenv/versions/3.6.1/lib/python3.6/site-packages/requests/packages/urllib3/connectionpool.py\", line 844, in _validate_conn\n",
      "    conn.connect()\n",
      "  File \"/home/ubuntu/.pyenv/versions/3.6.1/lib/python3.6/site-packages/requests/packages/urllib3/connection.py\", line 284, in connect\n",
      "    conn = self._new_conn()\n",
      "  File \"/home/ubuntu/.pyenv/versions/3.6.1/lib/python3.6/site-packages/requests/packages/urllib3/connection.py\", line 150, in _new_conn\n",
      "    self, \"Failed to establish a new connection: %s\" % e)\n",
      "requests.packages.urllib3.exceptions.NewConnectionError: <requests.packages.urllib3.connection.VerifiedHTTPSConnection object at 0x7f244f179ac8>: Failed to establish a new connection: [Errno -3] Temporary failure in name resolution\n",
      "\n",
      "During handling of the above exception, another exception occurred:\n",
      "\n",
      "Traceback (most recent call last):\n",
      "  File \"/home/ubuntu/.pyenv/versions/3.6.1/lib/python3.6/site-packages/requests/adapters.py\", line 423, in send\n",
      "    timeout=timeout\n",
      "  File \"/home/ubuntu/.pyenv/versions/3.6.1/lib/python3.6/site-packages/requests/packages/urllib3/connectionpool.py\", line 649, in urlopen\n",
      "    _stacktrace=sys.exc_info()[2])\n",
      "  File \"/home/ubuntu/.pyenv/versions/3.6.1/lib/python3.6/site-packages/requests/packages/urllib3/util/retry.py\", line 376, in increment\n",
      "    raise MaxRetryError(_pool, url, error or ResponseError(cause))\n",
      "requests.packages.urllib3.exceptions.MaxRetryError: HTTPSConnectionPool(host='www.518.com.tw', port=443): Max retries exceeded with url: /%E5%B9%B3%E5%8F%B0%E6%8A%80%E8%A1%93%20%E7%B6%B2%E9%A0%81%E5%B7%A5%E7%A8%8B%E5%B8%AB-%E5%8F%B0%E5%8C%97%E5%B8%82-%E5%85%A7%E6%B9%96%E5%8D%80-job-832724.html?kw=&pi=46 (Caused by NewConnectionError('<requests.packages.urllib3.connection.VerifiedHTTPSConnection object at 0x7f244f179ac8>: Failed to establish a new connection: [Errno -3] Temporary failure in name resolution',))\n",
      "\n",
      "During handling of the above exception, another exception occurred:\n",
      "\n",
      "Traceback (most recent call last):\n",
      "  File \"/home/ubuntu/.pyenv/versions/3.6.1/lib/python3.6/threading.py\", line 916, in _bootstrap_inner\n",
      "    self.run()\n",
      "  File \"<ipython-input-18-c76fc6bf8299>\", line 6, in run\n",
      "    pageURL('https://www.518.com.tw/job-index-P-'+str(self.number)+'.html?i=1&am=1&ab=2032001,2032002,')\n",
      "  File \"<ipython-input-17-696307882546>\", line 6, in pageURL\n",
      "    innerURL(str(link['href']))  #throw in innerURL function\n",
      "  File \"<ipython-input-16-1d4840fd97cd>\", line 3, in innerURL\n",
      "    inner = requests.get(url)  #用get連到網頁\n",
      "  File \"/home/ubuntu/.pyenv/versions/3.6.1/lib/python3.6/site-packages/requests/api.py\", line 70, in get\n",
      "    return request('get', url, params=params, **kwargs)\n",
      "  File \"/home/ubuntu/.pyenv/versions/3.6.1/lib/python3.6/site-packages/requests/api.py\", line 56, in request\n",
      "    return session.request(method=method, url=url, **kwargs)\n",
      "  File \"/home/ubuntu/.pyenv/versions/3.6.1/lib/python3.6/site-packages/requests/sessions.py\", line 488, in request\n",
      "    resp = self.send(prep, **send_kwargs)\n",
      "  File \"/home/ubuntu/.pyenv/versions/3.6.1/lib/python3.6/site-packages/requests/sessions.py\", line 609, in send\n",
      "    r = adapter.send(request, **kwargs)\n",
      "  File \"/home/ubuntu/.pyenv/versions/3.6.1/lib/python3.6/site-packages/requests/adapters.py\", line 487, in send\n",
      "    raise ConnectionError(e, request=request)\n",
      "requests.exceptions.ConnectionError: HTTPSConnectionPool(host='www.518.com.tw', port=443): Max retries exceeded with url: /%E5%B9%B3%E5%8F%B0%E6%8A%80%E8%A1%93%20%E7%B6%B2%E9%A0%81%E5%B7%A5%E7%A8%8B%E5%B8%AB-%E5%8F%B0%E5%8C%97%E5%B8%82-%E5%85%A7%E6%B9%96%E5%8D%80-job-832724.html?kw=&pi=46 (Caused by NewConnectionError('<requests.packages.urllib3.connection.VerifiedHTTPSConnection object at 0x7f244f179ac8>: Failed to establish a new connection: [Errno -3] Temporary failure in name resolution',))\n",
      "\n",
      "Exception in thread Thread-14:\n",
      "Traceback (most recent call last):\n",
      "  File \"/home/ubuntu/.pyenv/versions/3.6.1/lib/python3.6/site-packages/requests/packages/urllib3/connection.py\", line 141, in _new_conn\n",
      "    (self.host, self.port), self.timeout, **extra_kw)\n",
      "  File \"/home/ubuntu/.pyenv/versions/3.6.1/lib/python3.6/site-packages/requests/packages/urllib3/util/connection.py\", line 60, in create_connection\n",
      "    for res in socket.getaddrinfo(host, port, family, socket.SOCK_STREAM):\n",
      "  File \"/home/ubuntu/.pyenv/versions/3.6.1/lib/python3.6/socket.py\", line 743, in getaddrinfo\n",
      "    for res in _socket.getaddrinfo(host, port, family, type, proto, flags):\n",
      "socket.gaierror: [Errno -3] Temporary failure in name resolution\n",
      "\n",
      "During handling of the above exception, another exception occurred:\n",
      "\n",
      "Traceback (most recent call last):\n",
      "  File \"/home/ubuntu/.pyenv/versions/3.6.1/lib/python3.6/site-packages/requests/packages/urllib3/connectionpool.py\", line 600, in urlopen\n",
      "    chunked=chunked)\n",
      "  File \"/home/ubuntu/.pyenv/versions/3.6.1/lib/python3.6/site-packages/requests/packages/urllib3/connectionpool.py\", line 345, in _make_request\n",
      "    self._validate_conn(conn)\n",
      "  File \"/home/ubuntu/.pyenv/versions/3.6.1/lib/python3.6/site-packages/requests/packages/urllib3/connectionpool.py\", line 844, in _validate_conn\n",
      "    conn.connect()\n",
      "  File \"/home/ubuntu/.pyenv/versions/3.6.1/lib/python3.6/site-packages/requests/packages/urllib3/connection.py\", line 284, in connect\n",
      "    conn = self._new_conn()\n",
      "  File \"/home/ubuntu/.pyenv/versions/3.6.1/lib/python3.6/site-packages/requests/packages/urllib3/connection.py\", line 150, in _new_conn\n",
      "    self, \"Failed to establish a new connection: %s\" % e)\n",
      "requests.packages.urllib3.exceptions.NewConnectionError: <requests.packages.urllib3.connection.VerifiedHTTPSConnection object at 0x7f245078ab70>: Failed to establish a new connection: [Errno -3] Temporary failure in name resolution\n",
      "\n",
      "During handling of the above exception, another exception occurred:\n",
      "\n",
      "Traceback (most recent call last):\n",
      "  File \"/home/ubuntu/.pyenv/versions/3.6.1/lib/python3.6/site-packages/requests/adapters.py\", line 423, in send\n",
      "    timeout=timeout\n",
      "  File \"/home/ubuntu/.pyenv/versions/3.6.1/lib/python3.6/site-packages/requests/packages/urllib3/connectionpool.py\", line 649, in urlopen\n",
      "    _stacktrace=sys.exc_info()[2])\n",
      "  File \"/home/ubuntu/.pyenv/versions/3.6.1/lib/python3.6/site-packages/requests/packages/urllib3/util/retry.py\", line 376, in increment\n",
      "    raise MaxRetryError(_pool, url, error or ResponseError(cause))\n",
      "requests.packages.urllib3.exceptions.MaxRetryError: HTTPSConnectionPool(host='www.518.com.tw', port=443): Max retries exceeded with url: /Internet%E7%A8%8B%E5%BC%8F%E8%A8%AD%E8%A8%88%E5%B8%AB-%E5%8F%B0%E5%8C%97%E5%B8%82-%E6%9D%BE%E5%B1%B1%E5%8D%80-job-1069596.html?kw=&pi=11 (Caused by NewConnectionError('<requests.packages.urllib3.connection.VerifiedHTTPSConnection object at 0x7f245078ab70>: Failed to establish a new connection: [Errno -3] Temporary failure in name resolution',))\n",
      "\n",
      "During handling of the above exception, another exception occurred:\n",
      "\n",
      "Traceback (most recent call last):\n",
      "  File \"/home/ubuntu/.pyenv/versions/3.6.1/lib/python3.6/threading.py\", line 916, in _bootstrap_inner\n",
      "    self.run()\n",
      "  File \"<ipython-input-18-c76fc6bf8299>\", line 6, in run\n",
      "    pageURL('https://www.518.com.tw/job-index-P-'+str(self.number)+'.html?i=1&am=1&ab=2032001,2032002,')\n",
      "  File \"<ipython-input-17-696307882546>\", line 6, in pageURL\n",
      "    innerURL(str(link['href']))  #throw in innerURL function\n",
      "  File \"<ipython-input-16-1d4840fd97cd>\", line 3, in innerURL\n",
      "    inner = requests.get(url)  #用get連到網頁\n",
      "  File \"/home/ubuntu/.pyenv/versions/3.6.1/lib/python3.6/site-packages/requests/api.py\", line 70, in get\n",
      "    return request('get', url, params=params, **kwargs)\n",
      "  File \"/home/ubuntu/.pyenv/versions/3.6.1/lib/python3.6/site-packages/requests/api.py\", line 56, in request\n",
      "    return session.request(method=method, url=url, **kwargs)\n",
      "  File \"/home/ubuntu/.pyenv/versions/3.6.1/lib/python3.6/site-packages/requests/sessions.py\", line 488, in request\n",
      "    resp = self.send(prep, **send_kwargs)\n",
      "  File \"/home/ubuntu/.pyenv/versions/3.6.1/lib/python3.6/site-packages/requests/sessions.py\", line 609, in send\n",
      "    r = adapter.send(request, **kwargs)\n",
      "  File \"/home/ubuntu/.pyenv/versions/3.6.1/lib/python3.6/site-packages/requests/adapters.py\", line 487, in send\n",
      "    raise ConnectionError(e, request=request)\n",
      "requests.exceptions.ConnectionError: HTTPSConnectionPool(host='www.518.com.tw', port=443): Max retries exceeded with url: /Internet%E7%A8%8B%E5%BC%8F%E8%A8%AD%E8%A8%88%E5%B8%AB-%E5%8F%B0%E5%8C%97%E5%B8%82-%E6%9D%BE%E5%B1%B1%E5%8D%80-job-1069596.html?kw=&pi=11 (Caused by NewConnectionError('<requests.packages.urllib3.connection.VerifiedHTTPSConnection object at 0x7f245078ab70>: Failed to establish a new connection: [Errno -3] Temporary failure in name resolution',))\n",
      "\n",
      "Exception in thread Thread-12:\n",
      "Traceback (most recent call last):\n",
      "  File \"/home/ubuntu/.pyenv/versions/3.6.1/lib/python3.6/site-packages/requests/packages/urllib3/connection.py\", line 141, in _new_conn\n",
      "    (self.host, self.port), self.timeout, **extra_kw)\n",
      "  File \"/home/ubuntu/.pyenv/versions/3.6.1/lib/python3.6/site-packages/requests/packages/urllib3/util/connection.py\", line 60, in create_connection\n",
      "    for res in socket.getaddrinfo(host, port, family, socket.SOCK_STREAM):\n",
      "  File \"/home/ubuntu/.pyenv/versions/3.6.1/lib/python3.6/socket.py\", line 743, in getaddrinfo\n",
      "    for res in _socket.getaddrinfo(host, port, family, type, proto, flags):\n",
      "socket.gaierror: [Errno -3] Temporary failure in name resolution\n",
      "\n",
      "During handling of the above exception, another exception occurred:\n",
      "\n",
      "Traceback (most recent call last):\n",
      "  File \"/home/ubuntu/.pyenv/versions/3.6.1/lib/python3.6/site-packages/requests/packages/urllib3/connectionpool.py\", line 600, in urlopen\n",
      "    chunked=chunked)\n",
      "  File \"/home/ubuntu/.pyenv/versions/3.6.1/lib/python3.6/site-packages/requests/packages/urllib3/connectionpool.py\", line 345, in _make_request\n",
      "    self._validate_conn(conn)\n",
      "  File \"/home/ubuntu/.pyenv/versions/3.6.1/lib/python3.6/site-packages/requests/packages/urllib3/connectionpool.py\", line 844, in _validate_conn\n",
      "    conn.connect()\n",
      "  File \"/home/ubuntu/.pyenv/versions/3.6.1/lib/python3.6/site-packages/requests/packages/urllib3/connection.py\", line 284, in connect\n",
      "    conn = self._new_conn()\n",
      "  File \"/home/ubuntu/.pyenv/versions/3.6.1/lib/python3.6/site-packages/requests/packages/urllib3/connection.py\", line 150, in _new_conn\n",
      "    self, \"Failed to establish a new connection: %s\" % e)\n",
      "requests.packages.urllib3.exceptions.NewConnectionError: <requests.packages.urllib3.connection.VerifiedHTTPSConnection object at 0x7f24500717f0>: Failed to establish a new connection: [Errno -3] Temporary failure in name resolution\n",
      "\n",
      "During handling of the above exception, another exception occurred:\n",
      "\n",
      "Traceback (most recent call last):\n",
      "  File \"/home/ubuntu/.pyenv/versions/3.6.1/lib/python3.6/site-packages/requests/adapters.py\", line 423, in send\n",
      "    timeout=timeout\n",
      "  File \"/home/ubuntu/.pyenv/versions/3.6.1/lib/python3.6/site-packages/requests/packages/urllib3/connectionpool.py\", line 649, in urlopen\n",
      "    _stacktrace=sys.exc_info()[2])\n",
      "  File \"/home/ubuntu/.pyenv/versions/3.6.1/lib/python3.6/site-packages/requests/packages/urllib3/util/retry.py\", line 376, in increment\n",
      "    raise MaxRetryError(_pool, url, error or ResponseError(cause))\n",
      "requests.packages.urllib3.exceptions.MaxRetryError: HTTPSConnectionPool(host='www.518.com.tw', port=443): Max retries exceeded with url: /%E7%A0%94%E7%99%BC%E6%8A%80%E8%A1%93%E4%B8%BB%E7%AE%A1-%E5%8F%B0%E5%8C%97%E5%B8%82-%E5%85%A7%E6%B9%96%E5%8D%80-job-1276962.html?kw=&pi=9 (Caused by NewConnectionError('<requests.packages.urllib3.connection.VerifiedHTTPSConnection object at 0x7f24500717f0>: Failed to establish a new connection: [Errno -3] Temporary failure in name resolution',))\n",
      "\n",
      "During handling of the above exception, another exception occurred:\n",
      "\n",
      "Traceback (most recent call last):\n",
      "  File \"/home/ubuntu/.pyenv/versions/3.6.1/lib/python3.6/threading.py\", line 916, in _bootstrap_inner\n",
      "    self.run()\n",
      "  File \"<ipython-input-18-c76fc6bf8299>\", line 6, in run\n",
      "    pageURL('https://www.518.com.tw/job-index-P-'+str(self.number)+'.html?i=1&am=1&ab=2032001,2032002,')\n",
      "  File \"<ipython-input-17-696307882546>\", line 6, in pageURL\n",
      "    innerURL(str(link['href']))  #throw in innerURL function\n",
      "  File \"<ipython-input-16-1d4840fd97cd>\", line 3, in innerURL\n",
      "    inner = requests.get(url)  #用get連到網頁\n",
      "  File \"/home/ubuntu/.pyenv/versions/3.6.1/lib/python3.6/site-packages/requests/api.py\", line 70, in get\n",
      "    return request('get', url, params=params, **kwargs)\n",
      "  File \"/home/ubuntu/.pyenv/versions/3.6.1/lib/python3.6/site-packages/requests/api.py\", line 56, in request\n",
      "    return session.request(method=method, url=url, **kwargs)\n",
      "  File \"/home/ubuntu/.pyenv/versions/3.6.1/lib/python3.6/site-packages/requests/sessions.py\", line 488, in request\n",
      "    resp = self.send(prep, **send_kwargs)\n",
      "  File \"/home/ubuntu/.pyenv/versions/3.6.1/lib/python3.6/site-packages/requests/sessions.py\", line 609, in send\n",
      "    r = adapter.send(request, **kwargs)\n",
      "  File \"/home/ubuntu/.pyenv/versions/3.6.1/lib/python3.6/site-packages/requests/adapters.py\", line 487, in send\n",
      "    raise ConnectionError(e, request=request)\n",
      "requests.exceptions.ConnectionError: HTTPSConnectionPool(host='www.518.com.tw', port=443): Max retries exceeded with url: /%E7%A0%94%E7%99%BC%E6%8A%80%E8%A1%93%E4%B8%BB%E7%AE%A1-%E5%8F%B0%E5%8C%97%E5%B8%82-%E5%85%A7%E6%B9%96%E5%8D%80-job-1276962.html?kw=&pi=9 (Caused by NewConnectionError('<requests.packages.urllib3.connection.VerifiedHTTPSConnection object at 0x7f24500717f0>: Failed to establish a new connection: [Errno -3] Temporary failure in name resolution',))\n",
      "\n",
      "Exception in thread Thread-4:\n",
      "Traceback (most recent call last):\n",
      "  File \"/home/ubuntu/.pyenv/versions/3.6.1/lib/python3.6/site-packages/requests/packages/urllib3/connection.py\", line 141, in _new_conn\n",
      "    (self.host, self.port), self.timeout, **extra_kw)\n",
      "  File \"/home/ubuntu/.pyenv/versions/3.6.1/lib/python3.6/site-packages/requests/packages/urllib3/util/connection.py\", line 60, in create_connection\n",
      "    for res in socket.getaddrinfo(host, port, family, socket.SOCK_STREAM):\n",
      "  File \"/home/ubuntu/.pyenv/versions/3.6.1/lib/python3.6/socket.py\", line 743, in getaddrinfo\n",
      "    for res in _socket.getaddrinfo(host, port, family, type, proto, flags):\n",
      "socket.gaierror: [Errno -3] Temporary failure in name resolution\n",
      "\n",
      "During handling of the above exception, another exception occurred:\n",
      "\n",
      "Traceback (most recent call last):\n",
      "  File \"/home/ubuntu/.pyenv/versions/3.6.1/lib/python3.6/site-packages/requests/packages/urllib3/connectionpool.py\", line 600, in urlopen\n",
      "    chunked=chunked)\n",
      "  File \"/home/ubuntu/.pyenv/versions/3.6.1/lib/python3.6/site-packages/requests/packages/urllib3/connectionpool.py\", line 345, in _make_request\n",
      "    self._validate_conn(conn)\n",
      "  File \"/home/ubuntu/.pyenv/versions/3.6.1/lib/python3.6/site-packages/requests/packages/urllib3/connectionpool.py\", line 844, in _validate_conn\n",
      "    conn.connect()\n",
      "  File \"/home/ubuntu/.pyenv/versions/3.6.1/lib/python3.6/site-packages/requests/packages/urllib3/connection.py\", line 284, in connect\n",
      "    conn = self._new_conn()\n",
      "  File \"/home/ubuntu/.pyenv/versions/3.6.1/lib/python3.6/site-packages/requests/packages/urllib3/connection.py\", line 150, in _new_conn\n",
      "    self, \"Failed to establish a new connection: %s\" % e)\n",
      "requests.packages.urllib3.exceptions.NewConnectionError: <requests.packages.urllib3.connection.VerifiedHTTPSConnection object at 0x7f244ff1e198>: Failed to establish a new connection: [Errno -3] Temporary failure in name resolution\n",
      "\n",
      "During handling of the above exception, another exception occurred:\n",
      "\n",
      "Traceback (most recent call last):\n",
      "  File \"/home/ubuntu/.pyenv/versions/3.6.1/lib/python3.6/site-packages/requests/adapters.py\", line 423, in send\n",
      "    timeout=timeout\n",
      "  File \"/home/ubuntu/.pyenv/versions/3.6.1/lib/python3.6/site-packages/requests/packages/urllib3/connectionpool.py\", line 649, in urlopen\n",
      "    _stacktrace=sys.exc_info()[2])\n",
      "  File \"/home/ubuntu/.pyenv/versions/3.6.1/lib/python3.6/site-packages/requests/packages/urllib3/util/retry.py\", line 376, in increment\n",
      "    raise MaxRetryError(_pool, url, error or ResponseError(cause))\n",
      "requests.packages.urllib3.exceptions.MaxRetryError: HTTPSConnectionPool(host='www.518.com.tw', port=443): Max retries exceeded with url: /%E6%A5%AD%E5%8B%99%E5%B7%A5%E7%A8%8B%E5%B8%AB-%E5%8F%B0%E5%8C%97%E5%B8%82-%E5%85%A7%E6%B9%96%E5%8D%80-job-1226440.html?kw=&pi=1 (Caused by NewConnectionError('<requests.packages.urllib3.connection.VerifiedHTTPSConnection object at 0x7f244ff1e198>: Failed to establish a new connection: [Errno -3] Temporary failure in name resolution',))\n",
      "\n",
      "During handling of the above exception, another exception occurred:\n",
      "\n",
      "Traceback (most recent call last):\n",
      "  File \"/home/ubuntu/.pyenv/versions/3.6.1/lib/python3.6/threading.py\", line 916, in _bootstrap_inner\n",
      "    self.run()\n",
      "  File \"<ipython-input-18-c76fc6bf8299>\", line 6, in run\n",
      "    pageURL('https://www.518.com.tw/job-index-P-'+str(self.number)+'.html?i=1&am=1&ab=2032001,2032002,')\n",
      "  File \"<ipython-input-17-696307882546>\", line 6, in pageURL\n",
      "    innerURL(str(link['href']))  #throw in innerURL function\n",
      "  File \"<ipython-input-16-1d4840fd97cd>\", line 3, in innerURL\n",
      "    inner = requests.get(url)  #用get連到網頁\n",
      "  File \"/home/ubuntu/.pyenv/versions/3.6.1/lib/python3.6/site-packages/requests/api.py\", line 70, in get\n",
      "    return request('get', url, params=params, **kwargs)\n",
      "  File \"/home/ubuntu/.pyenv/versions/3.6.1/lib/python3.6/site-packages/requests/api.py\", line 56, in request\n",
      "    return session.request(method=method, url=url, **kwargs)\n",
      "  File \"/home/ubuntu/.pyenv/versions/3.6.1/lib/python3.6/site-packages/requests/sessions.py\", line 488, in request\n",
      "    resp = self.send(prep, **send_kwargs)\n",
      "  File \"/home/ubuntu/.pyenv/versions/3.6.1/lib/python3.6/site-packages/requests/sessions.py\", line 609, in send\n",
      "    r = adapter.send(request, **kwargs)\n",
      "  File \"/home/ubuntu/.pyenv/versions/3.6.1/lib/python3.6/site-packages/requests/adapters.py\", line 487, in send\n",
      "    raise ConnectionError(e, request=request)\n",
      "requests.exceptions.ConnectionError: HTTPSConnectionPool(host='www.518.com.tw', port=443): Max retries exceeded with url: /%E6%A5%AD%E5%8B%99%E5%B7%A5%E7%A8%8B%E5%B8%AB-%E5%8F%B0%E5%8C%97%E5%B8%82-%E5%85%A7%E6%B9%96%E5%8D%80-job-1226440.html?kw=&pi=1 (Caused by NewConnectionError('<requests.packages.urllib3.connection.VerifiedHTTPSConnection object at 0x7f244ff1e198>: Failed to establish a new connection: [Errno -3] Temporary failure in name resolution',))\n",
      "\n",
      "Exception in thread Thread-45:\n",
      "Traceback (most recent call last):\n",
      "  File \"/home/ubuntu/.pyenv/versions/3.6.1/lib/python3.6/site-packages/requests/packages/urllib3/connection.py\", line 141, in _new_conn\n",
      "    (self.host, self.port), self.timeout, **extra_kw)\n",
      "  File \"/home/ubuntu/.pyenv/versions/3.6.1/lib/python3.6/site-packages/requests/packages/urllib3/util/connection.py\", line 60, in create_connection\n",
      "    for res in socket.getaddrinfo(host, port, family, socket.SOCK_STREAM):\n",
      "  File \"/home/ubuntu/.pyenv/versions/3.6.1/lib/python3.6/socket.py\", line 743, in getaddrinfo\n",
      "    for res in _socket.getaddrinfo(host, port, family, type, proto, flags):\n",
      "socket.gaierror: [Errno -3] Temporary failure in name resolution\n",
      "\n",
      "During handling of the above exception, another exception occurred:\n",
      "\n",
      "Traceback (most recent call last):\n",
      "  File \"/home/ubuntu/.pyenv/versions/3.6.1/lib/python3.6/site-packages/requests/packages/urllib3/connectionpool.py\", line 600, in urlopen\n",
      "    chunked=chunked)\n",
      "  File \"/home/ubuntu/.pyenv/versions/3.6.1/lib/python3.6/site-packages/requests/packages/urllib3/connectionpool.py\", line 345, in _make_request\n",
      "    self._validate_conn(conn)\n",
      "  File \"/home/ubuntu/.pyenv/versions/3.6.1/lib/python3.6/site-packages/requests/packages/urllib3/connectionpool.py\", line 844, in _validate_conn\n",
      "    conn.connect()\n",
      "  File \"/home/ubuntu/.pyenv/versions/3.6.1/lib/python3.6/site-packages/requests/packages/urllib3/connection.py\", line 284, in connect\n",
      "    conn = self._new_conn()\n",
      "  File \"/home/ubuntu/.pyenv/versions/3.6.1/lib/python3.6/site-packages/requests/packages/urllib3/connection.py\", line 150, in _new_conn\n",
      "    self, \"Failed to establish a new connection: %s\" % e)\n",
      "requests.packages.urllib3.exceptions.NewConnectionError: <requests.packages.urllib3.connection.VerifiedHTTPSConnection object at 0x7f2450036320>: Failed to establish a new connection: [Errno -3] Temporary failure in name resolution\n",
      "\n",
      "During handling of the above exception, another exception occurred:\n",
      "\n",
      "Traceback (most recent call last):\n",
      "  File \"/home/ubuntu/.pyenv/versions/3.6.1/lib/python3.6/site-packages/requests/adapters.py\", line 423, in send\n",
      "    timeout=timeout\n",
      "  File \"/home/ubuntu/.pyenv/versions/3.6.1/lib/python3.6/site-packages/requests/packages/urllib3/connectionpool.py\", line 649, in urlopen\n",
      "    _stacktrace=sys.exc_info()[2])\n",
      "  File \"/home/ubuntu/.pyenv/versions/3.6.1/lib/python3.6/site-packages/requests/packages/urllib3/util/retry.py\", line 376, in increment\n",
      "    raise MaxRetryError(_pool, url, error or ResponseError(cause))\n",
      "requests.packages.urllib3.exceptions.MaxRetryError: HTTPSConnectionPool(host='www.518.com.tw', port=443): Max retries exceeded with url: /%E9%A7%90%E9%BB%9E%E6%A9%9F%E6%88%BFOP%E4%BA%BA%E5%93%A1(%E5%85%A7%E6%B9%96)-%E5%8F%B0%E5%8C%97%E5%B8%82-%E5%85%A7%E6%B9%96%E5%8D%80-job-929010.html?kw=&pi=42 (Caused by NewConnectionError('<requests.packages.urllib3.connection.VerifiedHTTPSConnection object at 0x7f2450036320>: Failed to establish a new connection: [Errno -3] Temporary failure in name resolution',))\n",
      "\n",
      "During handling of the above exception, another exception occurred:\n",
      "\n",
      "Traceback (most recent call last):\n",
      "  File \"/home/ubuntu/.pyenv/versions/3.6.1/lib/python3.6/threading.py\", line 916, in _bootstrap_inner\n",
      "    self.run()\n",
      "  File \"<ipython-input-18-c76fc6bf8299>\", line 6, in run\n",
      "    pageURL('https://www.518.com.tw/job-index-P-'+str(self.number)+'.html?i=1&am=1&ab=2032001,2032002,')\n",
      "  File \"<ipython-input-17-696307882546>\", line 6, in pageURL\n",
      "    innerURL(str(link['href']))  #throw in innerURL function\n",
      "  File \"<ipython-input-16-1d4840fd97cd>\", line 3, in innerURL\n",
      "    inner = requests.get(url)  #用get連到網頁\n",
      "  File \"/home/ubuntu/.pyenv/versions/3.6.1/lib/python3.6/site-packages/requests/api.py\", line 70, in get\n",
      "    return request('get', url, params=params, **kwargs)\n",
      "  File \"/home/ubuntu/.pyenv/versions/3.6.1/lib/python3.6/site-packages/requests/api.py\", line 56, in request\n",
      "    return session.request(method=method, url=url, **kwargs)\n",
      "  File \"/home/ubuntu/.pyenv/versions/3.6.1/lib/python3.6/site-packages/requests/sessions.py\", line 488, in request\n",
      "    resp = self.send(prep, **send_kwargs)\n",
      "  File \"/home/ubuntu/.pyenv/versions/3.6.1/lib/python3.6/site-packages/requests/sessions.py\", line 609, in send\n",
      "    r = adapter.send(request, **kwargs)\n",
      "  File \"/home/ubuntu/.pyenv/versions/3.6.1/lib/python3.6/site-packages/requests/adapters.py\", line 487, in send\n",
      "    raise ConnectionError(e, request=request)\n",
      "requests.exceptions.ConnectionError: HTTPSConnectionPool(host='www.518.com.tw', port=443): Max retries exceeded with url: /%E9%A7%90%E9%BB%9E%E6%A9%9F%E6%88%BFOP%E4%BA%BA%E5%93%A1(%E5%85%A7%E6%B9%96)-%E5%8F%B0%E5%8C%97%E5%B8%82-%E5%85%A7%E6%B9%96%E5%8D%80-job-929010.html?kw=&pi=42 (Caused by NewConnectionError('<requests.packages.urllib3.connection.VerifiedHTTPSConnection object at 0x7f2450036320>: Failed to establish a new connection: [Errno -3] Temporary failure in name resolution',))\n",
      "\n"
     ]
    },
    {
     "name": "stderr",
     "output_type": "stream",
     "text": [
      "Exception in thread Thread-15:\n",
      "Traceback (most recent call last):\n",
      "  File \"/home/ubuntu/.pyenv/versions/3.6.1/lib/python3.6/site-packages/requests/packages/urllib3/connection.py\", line 141, in _new_conn\n",
      "    (self.host, self.port), self.timeout, **extra_kw)\n",
      "  File \"/home/ubuntu/.pyenv/versions/3.6.1/lib/python3.6/site-packages/requests/packages/urllib3/util/connection.py\", line 60, in create_connection\n",
      "    for res in socket.getaddrinfo(host, port, family, socket.SOCK_STREAM):\n",
      "  File \"/home/ubuntu/.pyenv/versions/3.6.1/lib/python3.6/socket.py\", line 743, in getaddrinfo\n",
      "    for res in _socket.getaddrinfo(host, port, family, type, proto, flags):\n",
      "socket.gaierror: [Errno -3] Temporary failure in name resolution\n",
      "\n",
      "During handling of the above exception, another exception occurred:\n",
      "\n",
      "Traceback (most recent call last):\n",
      "  File \"/home/ubuntu/.pyenv/versions/3.6.1/lib/python3.6/site-packages/requests/packages/urllib3/connectionpool.py\", line 600, in urlopen\n",
      "    chunked=chunked)\n",
      "  File \"/home/ubuntu/.pyenv/versions/3.6.1/lib/python3.6/site-packages/requests/packages/urllib3/connectionpool.py\", line 345, in _make_request\n",
      "    self._validate_conn(conn)\n",
      "  File \"/home/ubuntu/.pyenv/versions/3.6.1/lib/python3.6/site-packages/requests/packages/urllib3/connectionpool.py\", line 844, in _validate_conn\n",
      "    conn.connect()\n",
      "  File \"/home/ubuntu/.pyenv/versions/3.6.1/lib/python3.6/site-packages/requests/packages/urllib3/connection.py\", line 284, in connect\n",
      "    conn = self._new_conn()\n",
      "  File \"/home/ubuntu/.pyenv/versions/3.6.1/lib/python3.6/site-packages/requests/packages/urllib3/connection.py\", line 150, in _new_conn\n",
      "    self, \"Failed to establish a new connection: %s\" % e)\n",
      "requests.packages.urllib3.exceptions.NewConnectionError: <requests.packages.urllib3.connection.VerifiedHTTPSConnection object at 0x7f24502e0e48>: Failed to establish a new connection: [Errno -3] Temporary failure in name resolution\n",
      "\n",
      "During handling of the above exception, another exception occurred:\n",
      "\n",
      "Traceback (most recent call last):\n",
      "  File \"/home/ubuntu/.pyenv/versions/3.6.1/lib/python3.6/site-packages/requests/adapters.py\", line 423, in send\n",
      "    timeout=timeout\n",
      "  File \"/home/ubuntu/.pyenv/versions/3.6.1/lib/python3.6/site-packages/requests/packages/urllib3/connectionpool.py\", line 649, in urlopen\n",
      "    _stacktrace=sys.exc_info()[2])\n",
      "  File \"/home/ubuntu/.pyenv/versions/3.6.1/lib/python3.6/site-packages/requests/packages/urllib3/util/retry.py\", line 376, in increment\n",
      "    raise MaxRetryError(_pool, url, error or ResponseError(cause))\n",
      "requests.packages.urllib3.exceptions.MaxRetryError: HTTPSConnectionPool(host='www.518.com.tw', port=443): Max retries exceeded with url: /%E7%B3%BB%E7%B5%B1%E7%B6%AD%E8%AD%B7%E5%B7%A5%E7%A8%8B%E5%B8%AB-%E5%8F%B0%E4%B8%AD%E5%B8%82-%E8%A5%BF%E5%B1%AF%E5%8D%80-job-278763.html?kw=&pi=12 (Caused by NewConnectionError('<requests.packages.urllib3.connection.VerifiedHTTPSConnection object at 0x7f24502e0e48>: Failed to establish a new connection: [Errno -3] Temporary failure in name resolution',))\n",
      "\n",
      "During handling of the above exception, another exception occurred:\n",
      "\n",
      "Traceback (most recent call last):\n",
      "  File \"/home/ubuntu/.pyenv/versions/3.6.1/lib/python3.6/threading.py\", line 916, in _bootstrap_inner\n",
      "    self.run()\n",
      "  File \"<ipython-input-18-c76fc6bf8299>\", line 6, in run\n",
      "    pageURL('https://www.518.com.tw/job-index-P-'+str(self.number)+'.html?i=1&am=1&ab=2032001,2032002,')\n",
      "  File \"<ipython-input-17-696307882546>\", line 6, in pageURL\n",
      "    innerURL(str(link['href']))  #throw in innerURL function\n",
      "  File \"<ipython-input-16-1d4840fd97cd>\", line 3, in innerURL\n",
      "    inner = requests.get(url)  #用get連到網頁\n",
      "  File \"/home/ubuntu/.pyenv/versions/3.6.1/lib/python3.6/site-packages/requests/api.py\", line 70, in get\n",
      "    return request('get', url, params=params, **kwargs)\n",
      "  File \"/home/ubuntu/.pyenv/versions/3.6.1/lib/python3.6/site-packages/requests/api.py\", line 56, in request\n",
      "    return session.request(method=method, url=url, **kwargs)\n",
      "  File \"/home/ubuntu/.pyenv/versions/3.6.1/lib/python3.6/site-packages/requests/sessions.py\", line 488, in request\n",
      "    resp = self.send(prep, **send_kwargs)\n",
      "  File \"/home/ubuntu/.pyenv/versions/3.6.1/lib/python3.6/site-packages/requests/sessions.py\", line 609, in send\n",
      "    r = adapter.send(request, **kwargs)\n",
      "  File \"/home/ubuntu/.pyenv/versions/3.6.1/lib/python3.6/site-packages/requests/adapters.py\", line 487, in send\n",
      "    raise ConnectionError(e, request=request)\n",
      "requests.exceptions.ConnectionError: HTTPSConnectionPool(host='www.518.com.tw', port=443): Max retries exceeded with url: /%E7%B3%BB%E7%B5%B1%E7%B6%AD%E8%AD%B7%E5%B7%A5%E7%A8%8B%E5%B8%AB-%E5%8F%B0%E4%B8%AD%E5%B8%82-%E8%A5%BF%E5%B1%AF%E5%8D%80-job-278763.html?kw=&pi=12 (Caused by NewConnectionError('<requests.packages.urllib3.connection.VerifiedHTTPSConnection object at 0x7f24502e0e48>: Failed to establish a new connection: [Errno -3] Temporary failure in name resolution',))\n",
      "\n",
      "Exception in thread Thread-27:\n",
      "Traceback (most recent call last):\n",
      "  File \"/home/ubuntu/.pyenv/versions/3.6.1/lib/python3.6/site-packages/requests/packages/urllib3/connection.py\", line 141, in _new_conn\n",
      "    (self.host, self.port), self.timeout, **extra_kw)\n",
      "  File \"/home/ubuntu/.pyenv/versions/3.6.1/lib/python3.6/site-packages/requests/packages/urllib3/util/connection.py\", line 60, in create_connection\n",
      "    for res in socket.getaddrinfo(host, port, family, socket.SOCK_STREAM):\n",
      "  File \"/home/ubuntu/.pyenv/versions/3.6.1/lib/python3.6/socket.py\", line 743, in getaddrinfo\n",
      "    for res in _socket.getaddrinfo(host, port, family, type, proto, flags):\n",
      "socket.gaierror: [Errno -3] Temporary failure in name resolution\n",
      "\n",
      "During handling of the above exception, another exception occurred:\n",
      "\n",
      "Traceback (most recent call last):\n",
      "  File \"/home/ubuntu/.pyenv/versions/3.6.1/lib/python3.6/site-packages/requests/packages/urllib3/connectionpool.py\", line 600, in urlopen\n",
      "    chunked=chunked)\n",
      "  File \"/home/ubuntu/.pyenv/versions/3.6.1/lib/python3.6/site-packages/requests/packages/urllib3/connectionpool.py\", line 356, in _make_request\n",
      "    conn.request(method, url, **httplib_request_kw)\n",
      "  File \"/home/ubuntu/.pyenv/versions/3.6.1/lib/python3.6/http/client.py\", line 1239, in request\n",
      "    self._send_request(method, url, body, headers, encode_chunked)\n",
      "  File \"/home/ubuntu/.pyenv/versions/3.6.1/lib/python3.6/http/client.py\", line 1285, in _send_request\n",
      "    self.endheaders(body, encode_chunked=encode_chunked)\n",
      "  File \"/home/ubuntu/.pyenv/versions/3.6.1/lib/python3.6/http/client.py\", line 1234, in endheaders\n",
      "    self._send_output(message_body, encode_chunked=encode_chunked)\n",
      "  File \"/home/ubuntu/.pyenv/versions/3.6.1/lib/python3.6/http/client.py\", line 1026, in _send_output\n",
      "    self.send(msg)\n",
      "  File \"/home/ubuntu/.pyenv/versions/3.6.1/lib/python3.6/http/client.py\", line 964, in send\n",
      "    self.connect()\n",
      "  File \"/home/ubuntu/.pyenv/versions/3.6.1/lib/python3.6/site-packages/requests/packages/urllib3/connection.py\", line 166, in connect\n",
      "    conn = self._new_conn()\n",
      "  File \"/home/ubuntu/.pyenv/versions/3.6.1/lib/python3.6/site-packages/requests/packages/urllib3/connection.py\", line 150, in _new_conn\n",
      "    self, \"Failed to establish a new connection: %s\" % e)\n",
      "requests.packages.urllib3.exceptions.NewConnectionError: <requests.packages.urllib3.connection.HTTPConnection object at 0x7f244ffa72e8>: Failed to establish a new connection: [Errno -3] Temporary failure in name resolution\n",
      "\n",
      "During handling of the above exception, another exception occurred:\n",
      "\n",
      "Traceback (most recent call last):\n",
      "  File \"/home/ubuntu/.pyenv/versions/3.6.1/lib/python3.6/site-packages/requests/adapters.py\", line 423, in send\n",
      "    timeout=timeout\n",
      "  File \"/home/ubuntu/.pyenv/versions/3.6.1/lib/python3.6/site-packages/requests/packages/urllib3/connectionpool.py\", line 649, in urlopen\n",
      "    _stacktrace=sys.exc_info()[2])\n",
      "  File \"/home/ubuntu/.pyenv/versions/3.6.1/lib/python3.6/site-packages/requests/packages/urllib3/util/retry.py\", line 376, in increment\n",
      "    raise MaxRetryError(_pool, url, error or ResponseError(cause))\n",
      "requests.packages.urllib3.exceptions.MaxRetryError: HTTPConnectionPool(host='case.518.com.tw', port=80): Max retries exceeded with url: /casepage-detail-123980.html?from=518&a_id=2183 (Caused by NewConnectionError('<requests.packages.urllib3.connection.HTTPConnection object at 0x7f244ffa72e8>: Failed to establish a new connection: [Errno -3] Temporary failure in name resolution',))\n",
      "\n",
      "During handling of the above exception, another exception occurred:\n",
      "\n",
      "Traceback (most recent call last):\n",
      "  File \"/home/ubuntu/.pyenv/versions/3.6.1/lib/python3.6/threading.py\", line 916, in _bootstrap_inner\n",
      "    self.run()\n",
      "  File \"<ipython-input-18-c76fc6bf8299>\", line 6, in run\n",
      "    pageURL('https://www.518.com.tw/job-index-P-'+str(self.number)+'.html?i=1&am=1&ab=2032001,2032002,')\n",
      "  File \"<ipython-input-17-696307882546>\", line 6, in pageURL\n",
      "    innerURL(str(link['href']))  #throw in innerURL function\n",
      "  File \"<ipython-input-16-1d4840fd97cd>\", line 3, in innerURL\n",
      "    inner = requests.get(url)  #用get連到網頁\n",
      "  File \"/home/ubuntu/.pyenv/versions/3.6.1/lib/python3.6/site-packages/requests/api.py\", line 70, in get\n",
      "    return request('get', url, params=params, **kwargs)\n",
      "  File \"/home/ubuntu/.pyenv/versions/3.6.1/lib/python3.6/site-packages/requests/api.py\", line 56, in request\n",
      "    return session.request(method=method, url=url, **kwargs)\n",
      "  File \"/home/ubuntu/.pyenv/versions/3.6.1/lib/python3.6/site-packages/requests/sessions.py\", line 488, in request\n",
      "    resp = self.send(prep, **send_kwargs)\n",
      "  File \"/home/ubuntu/.pyenv/versions/3.6.1/lib/python3.6/site-packages/requests/sessions.py\", line 609, in send\n",
      "    r = adapter.send(request, **kwargs)\n",
      "  File \"/home/ubuntu/.pyenv/versions/3.6.1/lib/python3.6/site-packages/requests/adapters.py\", line 487, in send\n",
      "    raise ConnectionError(e, request=request)\n",
      "requests.exceptions.ConnectionError: HTTPConnectionPool(host='case.518.com.tw', port=80): Max retries exceeded with url: /casepage-detail-123980.html?from=518&a_id=2183 (Caused by NewConnectionError('<requests.packages.urllib3.connection.HTTPConnection object at 0x7f244ffa72e8>: Failed to establish a new connection: [Errno -3] Temporary failure in name resolution',))\n",
      "\n",
      "Exception in thread Thread-36:\n",
      "Traceback (most recent call last):\n",
      "  File \"/home/ubuntu/.pyenv/versions/3.6.1/lib/python3.6/site-packages/requests/packages/urllib3/connection.py\", line 141, in _new_conn\n",
      "    (self.host, self.port), self.timeout, **extra_kw)\n",
      "  File \"/home/ubuntu/.pyenv/versions/3.6.1/lib/python3.6/site-packages/requests/packages/urllib3/util/connection.py\", line 60, in create_connection\n",
      "    for res in socket.getaddrinfo(host, port, family, socket.SOCK_STREAM):\n",
      "  File \"/home/ubuntu/.pyenv/versions/3.6.1/lib/python3.6/socket.py\", line 743, in getaddrinfo\n",
      "    for res in _socket.getaddrinfo(host, port, family, type, proto, flags):\n",
      "socket.gaierror: [Errno -3] Temporary failure in name resolution\n",
      "\n",
      "During handling of the above exception, another exception occurred:\n",
      "\n",
      "Traceback (most recent call last):\n",
      "  File \"/home/ubuntu/.pyenv/versions/3.6.1/lib/python3.6/site-packages/requests/packages/urllib3/connectionpool.py\", line 600, in urlopen\n",
      "    chunked=chunked)\n",
      "  File \"/home/ubuntu/.pyenv/versions/3.6.1/lib/python3.6/site-packages/requests/packages/urllib3/connectionpool.py\", line 356, in _make_request\n",
      "    conn.request(method, url, **httplib_request_kw)\n",
      "  File \"/home/ubuntu/.pyenv/versions/3.6.1/lib/python3.6/http/client.py\", line 1239, in request\n",
      "    self._send_request(method, url, body, headers, encode_chunked)\n",
      "  File \"/home/ubuntu/.pyenv/versions/3.6.1/lib/python3.6/http/client.py\", line 1285, in _send_request\n",
      "    self.endheaders(body, encode_chunked=encode_chunked)\n",
      "  File \"/home/ubuntu/.pyenv/versions/3.6.1/lib/python3.6/http/client.py\", line 1234, in endheaders\n",
      "    self._send_output(message_body, encode_chunked=encode_chunked)\n",
      "  File \"/home/ubuntu/.pyenv/versions/3.6.1/lib/python3.6/http/client.py\", line 1026, in _send_output\n",
      "    self.send(msg)\n",
      "  File \"/home/ubuntu/.pyenv/versions/3.6.1/lib/python3.6/http/client.py\", line 964, in send\n",
      "    self.connect()\n",
      "  File \"/home/ubuntu/.pyenv/versions/3.6.1/lib/python3.6/site-packages/requests/packages/urllib3/connection.py\", line 166, in connect\n",
      "    conn = self._new_conn()\n",
      "  File \"/home/ubuntu/.pyenv/versions/3.6.1/lib/python3.6/site-packages/requests/packages/urllib3/connection.py\", line 150, in _new_conn\n",
      "    self, \"Failed to establish a new connection: %s\" % e)\n",
      "requests.packages.urllib3.exceptions.NewConnectionError: <requests.packages.urllib3.connection.HTTPConnection object at 0x7f24534efda0>: Failed to establish a new connection: [Errno -3] Temporary failure in name resolution\n",
      "\n",
      "During handling of the above exception, another exception occurred:\n",
      "\n",
      "Traceback (most recent call last):\n",
      "  File \"/home/ubuntu/.pyenv/versions/3.6.1/lib/python3.6/site-packages/requests/adapters.py\", line 423, in send\n",
      "    timeout=timeout\n",
      "  File \"/home/ubuntu/.pyenv/versions/3.6.1/lib/python3.6/site-packages/requests/packages/urllib3/connectionpool.py\", line 649, in urlopen\n",
      "    _stacktrace=sys.exc_info()[2])\n",
      "  File \"/home/ubuntu/.pyenv/versions/3.6.1/lib/python3.6/site-packages/requests/packages/urllib3/util/retry.py\", line 376, in increment\n",
      "    raise MaxRetryError(_pool, url, error or ResponseError(cause))\n",
      "requests.packages.urllib3.exceptions.MaxRetryError: HTTPConnectionPool(host='case.518.com.tw', port=80): Max retries exceeded with url: /casepage-detail-123560.html?from=518&a_id=2183 (Caused by NewConnectionError('<requests.packages.urllib3.connection.HTTPConnection object at 0x7f24534efda0>: Failed to establish a new connection: [Errno -3] Temporary failure in name resolution',))\n",
      "\n",
      "During handling of the above exception, another exception occurred:\n",
      "\n",
      "Traceback (most recent call last):\n",
      "  File \"/home/ubuntu/.pyenv/versions/3.6.1/lib/python3.6/threading.py\", line 916, in _bootstrap_inner\n",
      "    self.run()\n",
      "  File \"<ipython-input-18-c76fc6bf8299>\", line 6, in run\n",
      "    pageURL('https://www.518.com.tw/job-index-P-'+str(self.number)+'.html?i=1&am=1&ab=2032001,2032002,')\n",
      "  File \"<ipython-input-17-696307882546>\", line 6, in pageURL\n",
      "    innerURL(str(link['href']))  #throw in innerURL function\n",
      "  File \"<ipython-input-16-1d4840fd97cd>\", line 3, in innerURL\n",
      "    inner = requests.get(url)  #用get連到網頁\n",
      "  File \"/home/ubuntu/.pyenv/versions/3.6.1/lib/python3.6/site-packages/requests/api.py\", line 70, in get\n",
      "    return request('get', url, params=params, **kwargs)\n",
      "  File \"/home/ubuntu/.pyenv/versions/3.6.1/lib/python3.6/site-packages/requests/api.py\", line 56, in request\n",
      "    return session.request(method=method, url=url, **kwargs)\n",
      "  File \"/home/ubuntu/.pyenv/versions/3.6.1/lib/python3.6/site-packages/requests/sessions.py\", line 488, in request\n",
      "    resp = self.send(prep, **send_kwargs)\n",
      "  File \"/home/ubuntu/.pyenv/versions/3.6.1/lib/python3.6/site-packages/requests/sessions.py\", line 609, in send\n",
      "    r = adapter.send(request, **kwargs)\n",
      "  File \"/home/ubuntu/.pyenv/versions/3.6.1/lib/python3.6/site-packages/requests/adapters.py\", line 487, in send\n",
      "    raise ConnectionError(e, request=request)\n",
      "requests.exceptions.ConnectionError: HTTPConnectionPool(host='case.518.com.tw', port=80): Max retries exceeded with url: /casepage-detail-123560.html?from=518&a_id=2183 (Caused by NewConnectionError('<requests.packages.urllib3.connection.HTTPConnection object at 0x7f24534efda0>: Failed to establish a new connection: [Errno -3] Temporary failure in name resolution',))\n",
      "\n",
      "Exception in thread Thread-21:\n",
      "Traceback (most recent call last):\n",
      "  File \"/home/ubuntu/.pyenv/versions/3.6.1/lib/python3.6/site-packages/requests/packages/urllib3/connection.py\", line 141, in _new_conn\n",
      "    (self.host, self.port), self.timeout, **extra_kw)\n",
      "  File \"/home/ubuntu/.pyenv/versions/3.6.1/lib/python3.6/site-packages/requests/packages/urllib3/util/connection.py\", line 60, in create_connection\n",
      "    for res in socket.getaddrinfo(host, port, family, socket.SOCK_STREAM):\n",
      "  File \"/home/ubuntu/.pyenv/versions/3.6.1/lib/python3.6/socket.py\", line 743, in getaddrinfo\n",
      "    for res in _socket.getaddrinfo(host, port, family, type, proto, flags):\n",
      "socket.gaierror: [Errno -3] Temporary failure in name resolution\n",
      "\n",
      "During handling of the above exception, another exception occurred:\n",
      "\n",
      "Traceback (most recent call last):\n",
      "  File \"/home/ubuntu/.pyenv/versions/3.6.1/lib/python3.6/site-packages/requests/packages/urllib3/connectionpool.py\", line 600, in urlopen\n",
      "    chunked=chunked)\n",
      "  File \"/home/ubuntu/.pyenv/versions/3.6.1/lib/python3.6/site-packages/requests/packages/urllib3/connectionpool.py\", line 345, in _make_request\n",
      "    self._validate_conn(conn)\n",
      "  File \"/home/ubuntu/.pyenv/versions/3.6.1/lib/python3.6/site-packages/requests/packages/urllib3/connectionpool.py\", line 844, in _validate_conn\n",
      "    conn.connect()\n",
      "  File \"/home/ubuntu/.pyenv/versions/3.6.1/lib/python3.6/site-packages/requests/packages/urllib3/connection.py\", line 284, in connect\n",
      "    conn = self._new_conn()\n",
      "  File \"/home/ubuntu/.pyenv/versions/3.6.1/lib/python3.6/site-packages/requests/packages/urllib3/connection.py\", line 150, in _new_conn\n",
      "    self, \"Failed to establish a new connection: %s\" % e)\n",
      "requests.packages.urllib3.exceptions.NewConnectionError: <requests.packages.urllib3.connection.VerifiedHTTPSConnection object at 0x7f24503d0e80>: Failed to establish a new connection: [Errno -3] Temporary failure in name resolution\n",
      "\n",
      "During handling of the above exception, another exception occurred:\n",
      "\n",
      "Traceback (most recent call last):\n",
      "  File \"/home/ubuntu/.pyenv/versions/3.6.1/lib/python3.6/site-packages/requests/adapters.py\", line 423, in send\n",
      "    timeout=timeout\n",
      "  File \"/home/ubuntu/.pyenv/versions/3.6.1/lib/python3.6/site-packages/requests/packages/urllib3/connectionpool.py\", line 649, in urlopen\n",
      "    _stacktrace=sys.exc_info()[2])\n",
      "  File \"/home/ubuntu/.pyenv/versions/3.6.1/lib/python3.6/site-packages/requests/packages/urllib3/util/retry.py\", line 376, in increment\n",
      "    raise MaxRetryError(_pool, url, error or ResponseError(cause))\n",
      "requests.packages.urllib3.exceptions.MaxRetryError: HTTPSConnectionPool(host='www.518.com.tw', port=443): Max retries exceeded with url: /%E7%94%9F%E7%AE%A1%E9%81%8E%E7%A3%85%E5%84%B2%E5%82%99%E5%B9%B9%E9%83%A8-%E6%A1%83%E5%9C%92%E5%B8%82-%E8%98%86%E7%AB%B9%E5%8D%80-job-964726.html?kw=&pi=18 (Caused by NewConnectionError('<requests.packages.urllib3.connection.VerifiedHTTPSConnection object at 0x7f24503d0e80>: Failed to establish a new connection: [Errno -3] Temporary failure in name resolution',))\n",
      "\n",
      "During handling of the above exception, another exception occurred:\n",
      "\n",
      "Traceback (most recent call last):\n",
      "  File \"/home/ubuntu/.pyenv/versions/3.6.1/lib/python3.6/threading.py\", line 916, in _bootstrap_inner\n",
      "    self.run()\n",
      "  File \"<ipython-input-18-c76fc6bf8299>\", line 6, in run\n",
      "    pageURL('https://www.518.com.tw/job-index-P-'+str(self.number)+'.html?i=1&am=1&ab=2032001,2032002,')\n",
      "  File \"<ipython-input-17-696307882546>\", line 6, in pageURL\n",
      "    innerURL(str(link['href']))  #throw in innerURL function\n",
      "  File \"<ipython-input-16-1d4840fd97cd>\", line 3, in innerURL\n",
      "    inner = requests.get(url)  #用get連到網頁\n",
      "  File \"/home/ubuntu/.pyenv/versions/3.6.1/lib/python3.6/site-packages/requests/api.py\", line 70, in get\n",
      "    return request('get', url, params=params, **kwargs)\n",
      "  File \"/home/ubuntu/.pyenv/versions/3.6.1/lib/python3.6/site-packages/requests/api.py\", line 56, in request\n",
      "    return session.request(method=method, url=url, **kwargs)\n",
      "  File \"/home/ubuntu/.pyenv/versions/3.6.1/lib/python3.6/site-packages/requests/sessions.py\", line 488, in request\n",
      "    resp = self.send(prep, **send_kwargs)\n",
      "  File \"/home/ubuntu/.pyenv/versions/3.6.1/lib/python3.6/site-packages/requests/sessions.py\", line 609, in send\n",
      "    r = adapter.send(request, **kwargs)\n",
      "  File \"/home/ubuntu/.pyenv/versions/3.6.1/lib/python3.6/site-packages/requests/adapters.py\", line 487, in send\n",
      "    raise ConnectionError(e, request=request)\n",
      "requests.exceptions.ConnectionError: HTTPSConnectionPool(host='www.518.com.tw', port=443): Max retries exceeded with url: /%E7%94%9F%E7%AE%A1%E9%81%8E%E7%A3%85%E5%84%B2%E5%82%99%E5%B9%B9%E9%83%A8-%E6%A1%83%E5%9C%92%E5%B8%82-%E8%98%86%E7%AB%B9%E5%8D%80-job-964726.html?kw=&pi=18 (Caused by NewConnectionError('<requests.packages.urllib3.connection.VerifiedHTTPSConnection object at 0x7f24503d0e80>: Failed to establish a new connection: [Errno -3] Temporary failure in name resolution',))\n",
      "\n",
      "Exception in thread Thread-32:\n",
      "Traceback (most recent call last):\n",
      "  File \"/home/ubuntu/.pyenv/versions/3.6.1/lib/python3.6/site-packages/requests/packages/urllib3/connection.py\", line 141, in _new_conn\n",
      "    (self.host, self.port), self.timeout, **extra_kw)\n",
      "  File \"/home/ubuntu/.pyenv/versions/3.6.1/lib/python3.6/site-packages/requests/packages/urllib3/util/connection.py\", line 60, in create_connection\n",
      "    for res in socket.getaddrinfo(host, port, family, socket.SOCK_STREAM):\n",
      "  File \"/home/ubuntu/.pyenv/versions/3.6.1/lib/python3.6/socket.py\", line 743, in getaddrinfo\n",
      "    for res in _socket.getaddrinfo(host, port, family, type, proto, flags):\n",
      "socket.gaierror: [Errno -3] Temporary failure in name resolution\n",
      "\n",
      "During handling of the above exception, another exception occurred:\n",
      "\n",
      "Traceback (most recent call last):\n",
      "  File \"/home/ubuntu/.pyenv/versions/3.6.1/lib/python3.6/site-packages/requests/packages/urllib3/connectionpool.py\", line 600, in urlopen\n",
      "    chunked=chunked)\n",
      "  File \"/home/ubuntu/.pyenv/versions/3.6.1/lib/python3.6/site-packages/requests/packages/urllib3/connectionpool.py\", line 345, in _make_request\n",
      "    self._validate_conn(conn)\n",
      "  File \"/home/ubuntu/.pyenv/versions/3.6.1/lib/python3.6/site-packages/requests/packages/urllib3/connectionpool.py\", line 844, in _validate_conn\n",
      "    conn.connect()\n",
      "  File \"/home/ubuntu/.pyenv/versions/3.6.1/lib/python3.6/site-packages/requests/packages/urllib3/connection.py\", line 284, in connect\n",
      "    conn = self._new_conn()\n",
      "  File \"/home/ubuntu/.pyenv/versions/3.6.1/lib/python3.6/site-packages/requests/packages/urllib3/connection.py\", line 150, in _new_conn\n",
      "    self, \"Failed to establish a new connection: %s\" % e)\n",
      "requests.packages.urllib3.exceptions.NewConnectionError: <requests.packages.urllib3.connection.VerifiedHTTPSConnection object at 0x7f2452415240>: Failed to establish a new connection: [Errno -3] Temporary failure in name resolution\n",
      "\n",
      "During handling of the above exception, another exception occurred:\n",
      "\n",
      "Traceback (most recent call last):\n",
      "  File \"/home/ubuntu/.pyenv/versions/3.6.1/lib/python3.6/site-packages/requests/adapters.py\", line 423, in send\n",
      "    timeout=timeout\n",
      "  File \"/home/ubuntu/.pyenv/versions/3.6.1/lib/python3.6/site-packages/requests/packages/urllib3/connectionpool.py\", line 649, in urlopen\n",
      "    _stacktrace=sys.exc_info()[2])\n",
      "  File \"/home/ubuntu/.pyenv/versions/3.6.1/lib/python3.6/site-packages/requests/packages/urllib3/util/retry.py\", line 376, in increment\n",
      "    raise MaxRetryError(_pool, url, error or ResponseError(cause))\n",
      "requests.packages.urllib3.exceptions.MaxRetryError: HTTPSConnectionPool(host='www.518.com.tw', port=443): Max retries exceeded with url: /%E8%BB%9F%E9%AB%94%E5%B7%A5%E7%A8%8B%E5%B8%AB-%E8%8B%97%E6%A0%97%E7%B8%A3-%E4%B8%89%E7%BE%A9%E9%84%89-job-828856.html?kw=&pi=29 (Caused by NewConnectionError('<requests.packages.urllib3.connection.VerifiedHTTPSConnection object at 0x7f2452415240>: Failed to establish a new connection: [Errno -3] Temporary failure in name resolution',))\n",
      "\n",
      "During handling of the above exception, another exception occurred:\n",
      "\n",
      "Traceback (most recent call last):\n",
      "  File \"/home/ubuntu/.pyenv/versions/3.6.1/lib/python3.6/threading.py\", line 916, in _bootstrap_inner\n",
      "    self.run()\n",
      "  File \"<ipython-input-18-c76fc6bf8299>\", line 6, in run\n",
      "    pageURL('https://www.518.com.tw/job-index-P-'+str(self.number)+'.html?i=1&am=1&ab=2032001,2032002,')\n",
      "  File \"<ipython-input-17-696307882546>\", line 6, in pageURL\n",
      "    innerURL(str(link['href']))  #throw in innerURL function\n",
      "  File \"<ipython-input-16-1d4840fd97cd>\", line 3, in innerURL\n",
      "    inner = requests.get(url)  #用get連到網頁\n",
      "  File \"/home/ubuntu/.pyenv/versions/3.6.1/lib/python3.6/site-packages/requests/api.py\", line 70, in get\n",
      "    return request('get', url, params=params, **kwargs)\n",
      "  File \"/home/ubuntu/.pyenv/versions/3.6.1/lib/python3.6/site-packages/requests/api.py\", line 56, in request\n",
      "    return session.request(method=method, url=url, **kwargs)\n",
      "  File \"/home/ubuntu/.pyenv/versions/3.6.1/lib/python3.6/site-packages/requests/sessions.py\", line 488, in request\n",
      "    resp = self.send(prep, **send_kwargs)\n",
      "  File \"/home/ubuntu/.pyenv/versions/3.6.1/lib/python3.6/site-packages/requests/sessions.py\", line 609, in send\n",
      "    r = adapter.send(request, **kwargs)\n",
      "  File \"/home/ubuntu/.pyenv/versions/3.6.1/lib/python3.6/site-packages/requests/adapters.py\", line 487, in send\n",
      "    raise ConnectionError(e, request=request)\n",
      "requests.exceptions.ConnectionError: HTTPSConnectionPool(host='www.518.com.tw', port=443): Max retries exceeded with url: /%E8%BB%9F%E9%AB%94%E5%B7%A5%E7%A8%8B%E5%B8%AB-%E8%8B%97%E6%A0%97%E7%B8%A3-%E4%B8%89%E7%BE%A9%E9%84%89-job-828856.html?kw=&pi=29 (Caused by NewConnectionError('<requests.packages.urllib3.connection.VerifiedHTTPSConnection object at 0x7f2452415240>: Failed to establish a new connection: [Errno -3] Temporary failure in name resolution',))\n",
      "\n",
      "Exception in thread Thread-46:\n",
      "Traceback (most recent call last):\n",
      "  File \"/home/ubuntu/.pyenv/versions/3.6.1/lib/python3.6/site-packages/requests/packages/urllib3/connection.py\", line 141, in _new_conn\n",
      "    (self.host, self.port), self.timeout, **extra_kw)\n",
      "  File \"/home/ubuntu/.pyenv/versions/3.6.1/lib/python3.6/site-packages/requests/packages/urllib3/util/connection.py\", line 60, in create_connection\n",
      "    for res in socket.getaddrinfo(host, port, family, socket.SOCK_STREAM):\n",
      "  File \"/home/ubuntu/.pyenv/versions/3.6.1/lib/python3.6/socket.py\", line 743, in getaddrinfo\n",
      "    for res in _socket.getaddrinfo(host, port, family, type, proto, flags):\n",
      "socket.gaierror: [Errno -3] Temporary failure in name resolution\n",
      "\n",
      "During handling of the above exception, another exception occurred:\n",
      "\n",
      "Traceback (most recent call last):\n",
      "  File \"/home/ubuntu/.pyenv/versions/3.6.1/lib/python3.6/site-packages/requests/packages/urllib3/connectionpool.py\", line 600, in urlopen\n",
      "    chunked=chunked)\n",
      "  File \"/home/ubuntu/.pyenv/versions/3.6.1/lib/python3.6/site-packages/requests/packages/urllib3/connectionpool.py\", line 345, in _make_request\n",
      "    self._validate_conn(conn)\n",
      "  File \"/home/ubuntu/.pyenv/versions/3.6.1/lib/python3.6/site-packages/requests/packages/urllib3/connectionpool.py\", line 844, in _validate_conn\n",
      "    conn.connect()\n",
      "  File \"/home/ubuntu/.pyenv/versions/3.6.1/lib/python3.6/site-packages/requests/packages/urllib3/connection.py\", line 284, in connect\n",
      "    conn = self._new_conn()\n",
      "  File \"/home/ubuntu/.pyenv/versions/3.6.1/lib/python3.6/site-packages/requests/packages/urllib3/connection.py\", line 150, in _new_conn\n",
      "    self, \"Failed to establish a new connection: %s\" % e)\n",
      "requests.packages.urllib3.exceptions.NewConnectionError: <requests.packages.urllib3.connection.VerifiedHTTPSConnection object at 0x7f2452dd3cc0>: Failed to establish a new connection: [Errno -3] Temporary failure in name resolution\n",
      "\n",
      "During handling of the above exception, another exception occurred:\n",
      "\n",
      "Traceback (most recent call last):\n",
      "  File \"/home/ubuntu/.pyenv/versions/3.6.1/lib/python3.6/site-packages/requests/adapters.py\", line 423, in send\n",
      "    timeout=timeout\n",
      "  File \"/home/ubuntu/.pyenv/versions/3.6.1/lib/python3.6/site-packages/requests/packages/urllib3/connectionpool.py\", line 649, in urlopen\n",
      "    _stacktrace=sys.exc_info()[2])\n",
      "  File \"/home/ubuntu/.pyenv/versions/3.6.1/lib/python3.6/site-packages/requests/packages/urllib3/util/retry.py\", line 376, in increment\n",
      "    raise MaxRetryError(_pool, url, error or ResponseError(cause))\n",
      "requests.packages.urllib3.exceptions.MaxRetryError: HTTPSConnectionPool(host='www.518.com.tw', port=443): Max retries exceeded with url: /Senior%20C%20.net%20Engineer-%E6%96%B0%E5%8C%97%E5%B8%82-%E5%9C%9F%E5%9F%8E%E5%8D%80-job-1198440.html?kw=&pi=43 (Caused by NewConnectionError('<requests.packages.urllib3.connection.VerifiedHTTPSConnection object at 0x7f2452dd3cc0>: Failed to establish a new connection: [Errno -3] Temporary failure in name resolution',))\n",
      "\n",
      "During handling of the above exception, another exception occurred:\n",
      "\n",
      "Traceback (most recent call last):\n",
      "  File \"/home/ubuntu/.pyenv/versions/3.6.1/lib/python3.6/threading.py\", line 916, in _bootstrap_inner\n",
      "    self.run()\n",
      "  File \"<ipython-input-18-c76fc6bf8299>\", line 6, in run\n",
      "    pageURL('https://www.518.com.tw/job-index-P-'+str(self.number)+'.html?i=1&am=1&ab=2032001,2032002,')\n",
      "  File \"<ipython-input-17-696307882546>\", line 6, in pageURL\n",
      "    innerURL(str(link['href']))  #throw in innerURL function\n",
      "  File \"<ipython-input-16-1d4840fd97cd>\", line 3, in innerURL\n",
      "    inner = requests.get(url)  #用get連到網頁\n",
      "  File \"/home/ubuntu/.pyenv/versions/3.6.1/lib/python3.6/site-packages/requests/api.py\", line 70, in get\n",
      "    return request('get', url, params=params, **kwargs)\n",
      "  File \"/home/ubuntu/.pyenv/versions/3.6.1/lib/python3.6/site-packages/requests/api.py\", line 56, in request\n",
      "    return session.request(method=method, url=url, **kwargs)\n",
      "  File \"/home/ubuntu/.pyenv/versions/3.6.1/lib/python3.6/site-packages/requests/sessions.py\", line 488, in request\n",
      "    resp = self.send(prep, **send_kwargs)\n",
      "  File \"/home/ubuntu/.pyenv/versions/3.6.1/lib/python3.6/site-packages/requests/sessions.py\", line 609, in send\n",
      "    r = adapter.send(request, **kwargs)\n",
      "  File \"/home/ubuntu/.pyenv/versions/3.6.1/lib/python3.6/site-packages/requests/adapters.py\", line 487, in send\n",
      "    raise ConnectionError(e, request=request)\n",
      "requests.exceptions.ConnectionError: HTTPSConnectionPool(host='www.518.com.tw', port=443): Max retries exceeded with url: /Senior%20C%20.net%20Engineer-%E6%96%B0%E5%8C%97%E5%B8%82-%E5%9C%9F%E5%9F%8E%E5%8D%80-job-1198440.html?kw=&pi=43 (Caused by NewConnectionError('<requests.packages.urllib3.connection.VerifiedHTTPSConnection object at 0x7f2452dd3cc0>: Failed to establish a new connection: [Errno -3] Temporary failure in name resolution',))\n",
      "\n",
      "Exception in thread Thread-16:\n",
      "Traceback (most recent call last):\n",
      "  File \"/home/ubuntu/.pyenv/versions/3.6.1/lib/python3.6/site-packages/requests/packages/urllib3/connection.py\", line 141, in _new_conn\n",
      "    (self.host, self.port), self.timeout, **extra_kw)\n",
      "  File \"/home/ubuntu/.pyenv/versions/3.6.1/lib/python3.6/site-packages/requests/packages/urllib3/util/connection.py\", line 60, in create_connection\n",
      "    for res in socket.getaddrinfo(host, port, family, socket.SOCK_STREAM):\n",
      "  File \"/home/ubuntu/.pyenv/versions/3.6.1/lib/python3.6/socket.py\", line 743, in getaddrinfo\n",
      "    for res in _socket.getaddrinfo(host, port, family, type, proto, flags):\n",
      "socket.gaierror: [Errno -3] Temporary failure in name resolution\n",
      "\n",
      "During handling of the above exception, another exception occurred:\n",
      "\n",
      "Traceback (most recent call last):\n",
      "  File \"/home/ubuntu/.pyenv/versions/3.6.1/lib/python3.6/site-packages/requests/packages/urllib3/connectionpool.py\", line 600, in urlopen\n",
      "    chunked=chunked)\n",
      "  File \"/home/ubuntu/.pyenv/versions/3.6.1/lib/python3.6/site-packages/requests/packages/urllib3/connectionpool.py\", line 356, in _make_request\n",
      "    conn.request(method, url, **httplib_request_kw)\n",
      "  File \"/home/ubuntu/.pyenv/versions/3.6.1/lib/python3.6/http/client.py\", line 1239, in request\n",
      "    self._send_request(method, url, body, headers, encode_chunked)\n",
      "  File \"/home/ubuntu/.pyenv/versions/3.6.1/lib/python3.6/http/client.py\", line 1285, in _send_request\n",
      "    self.endheaders(body, encode_chunked=encode_chunked)\n",
      "  File \"/home/ubuntu/.pyenv/versions/3.6.1/lib/python3.6/http/client.py\", line 1234, in endheaders\n",
      "    self._send_output(message_body, encode_chunked=encode_chunked)\n",
      "  File \"/home/ubuntu/.pyenv/versions/3.6.1/lib/python3.6/http/client.py\", line 1026, in _send_output\n",
      "    self.send(msg)\n",
      "  File \"/home/ubuntu/.pyenv/versions/3.6.1/lib/python3.6/http/client.py\", line 964, in send\n",
      "    self.connect()\n",
      "  File \"/home/ubuntu/.pyenv/versions/3.6.1/lib/python3.6/site-packages/requests/packages/urllib3/connection.py\", line 166, in connect\n",
      "    conn = self._new_conn()\n",
      "  File \"/home/ubuntu/.pyenv/versions/3.6.1/lib/python3.6/site-packages/requests/packages/urllib3/connection.py\", line 150, in _new_conn\n",
      "    self, \"Failed to establish a new connection: %s\" % e)\n",
      "requests.packages.urllib3.exceptions.NewConnectionError: <requests.packages.urllib3.connection.HTTPConnection object at 0x7f244f0e04e0>: Failed to establish a new connection: [Errno -3] Temporary failure in name resolution\n",
      "\n",
      "During handling of the above exception, another exception occurred:\n",
      "\n",
      "Traceback (most recent call last):\n",
      "  File \"/home/ubuntu/.pyenv/versions/3.6.1/lib/python3.6/site-packages/requests/adapters.py\", line 423, in send\n",
      "    timeout=timeout\n",
      "  File \"/home/ubuntu/.pyenv/versions/3.6.1/lib/python3.6/site-packages/requests/packages/urllib3/connectionpool.py\", line 649, in urlopen\n",
      "    _stacktrace=sys.exc_info()[2])\n",
      "  File \"/home/ubuntu/.pyenv/versions/3.6.1/lib/python3.6/site-packages/requests/packages/urllib3/util/retry.py\", line 376, in increment\n",
      "    raise MaxRetryError(_pool, url, error or ResponseError(cause))\n",
      "requests.packages.urllib3.exceptions.MaxRetryError: HTTPConnectionPool(host='case.518.com.tw', port=80): Max retries exceeded with url: /casepage-detail-124518.html?from=518&a_id=2183 (Caused by NewConnectionError('<requests.packages.urllib3.connection.HTTPConnection object at 0x7f244f0e04e0>: Failed to establish a new connection: [Errno -3] Temporary failure in name resolution',))\n",
      "\n",
      "During handling of the above exception, another exception occurred:\n",
      "\n",
      "Traceback (most recent call last):\n",
      "  File \"/home/ubuntu/.pyenv/versions/3.6.1/lib/python3.6/threading.py\", line 916, in _bootstrap_inner\n",
      "    self.run()\n",
      "  File \"<ipython-input-18-c76fc6bf8299>\", line 6, in run\n",
      "    pageURL('https://www.518.com.tw/job-index-P-'+str(self.number)+'.html?i=1&am=1&ab=2032001,2032002,')\n",
      "  File \"<ipython-input-17-696307882546>\", line 6, in pageURL\n",
      "    innerURL(str(link['href']))  #throw in innerURL function\n",
      "  File \"<ipython-input-16-1d4840fd97cd>\", line 3, in innerURL\n",
      "    inner = requests.get(url)  #用get連到網頁\n",
      "  File \"/home/ubuntu/.pyenv/versions/3.6.1/lib/python3.6/site-packages/requests/api.py\", line 70, in get\n",
      "    return request('get', url, params=params, **kwargs)\n",
      "  File \"/home/ubuntu/.pyenv/versions/3.6.1/lib/python3.6/site-packages/requests/api.py\", line 56, in request\n",
      "    return session.request(method=method, url=url, **kwargs)\n",
      "  File \"/home/ubuntu/.pyenv/versions/3.6.1/lib/python3.6/site-packages/requests/sessions.py\", line 488, in request\n",
      "    resp = self.send(prep, **send_kwargs)\n",
      "  File \"/home/ubuntu/.pyenv/versions/3.6.1/lib/python3.6/site-packages/requests/sessions.py\", line 609, in send\n",
      "    r = adapter.send(request, **kwargs)\n",
      "  File \"/home/ubuntu/.pyenv/versions/3.6.1/lib/python3.6/site-packages/requests/adapters.py\", line 487, in send\n",
      "    raise ConnectionError(e, request=request)\n",
      "requests.exceptions.ConnectionError: HTTPConnectionPool(host='case.518.com.tw', port=80): Max retries exceeded with url: /casepage-detail-124518.html?from=518&a_id=2183 (Caused by NewConnectionError('<requests.packages.urllib3.connection.HTTPConnection object at 0x7f244f0e04e0>: Failed to establish a new connection: [Errno -3] Temporary failure in name resolution',))\n",
      "\n",
      "Exception in thread Thread-29:\n",
      "Traceback (most recent call last):\n",
      "  File \"/home/ubuntu/.pyenv/versions/3.6.1/lib/python3.6/site-packages/requests/packages/urllib3/connection.py\", line 141, in _new_conn\n",
      "    (self.host, self.port), self.timeout, **extra_kw)\n",
      "  File \"/home/ubuntu/.pyenv/versions/3.6.1/lib/python3.6/site-packages/requests/packages/urllib3/util/connection.py\", line 60, in create_connection\n",
      "    for res in socket.getaddrinfo(host, port, family, socket.SOCK_STREAM):\n",
      "  File \"/home/ubuntu/.pyenv/versions/3.6.1/lib/python3.6/socket.py\", line 743, in getaddrinfo\n",
      "    for res in _socket.getaddrinfo(host, port, family, type, proto, flags):\n",
      "socket.gaierror: [Errno -3] Temporary failure in name resolution\n",
      "\n",
      "During handling of the above exception, another exception occurred:\n",
      "\n",
      "Traceback (most recent call last):\n",
      "  File \"/home/ubuntu/.pyenv/versions/3.6.1/lib/python3.6/site-packages/requests/packages/urllib3/connectionpool.py\", line 600, in urlopen\n",
      "    chunked=chunked)\n",
      "  File \"/home/ubuntu/.pyenv/versions/3.6.1/lib/python3.6/site-packages/requests/packages/urllib3/connectionpool.py\", line 345, in _make_request\n",
      "    self._validate_conn(conn)\n",
      "  File \"/home/ubuntu/.pyenv/versions/3.6.1/lib/python3.6/site-packages/requests/packages/urllib3/connectionpool.py\", line 844, in _validate_conn\n",
      "    conn.connect()\n",
      "  File \"/home/ubuntu/.pyenv/versions/3.6.1/lib/python3.6/site-packages/requests/packages/urllib3/connection.py\", line 284, in connect\n",
      "    conn = self._new_conn()\n",
      "  File \"/home/ubuntu/.pyenv/versions/3.6.1/lib/python3.6/site-packages/requests/packages/urllib3/connection.py\", line 150, in _new_conn\n",
      "    self, \"Failed to establish a new connection: %s\" % e)\n",
      "requests.packages.urllib3.exceptions.NewConnectionError: <requests.packages.urllib3.connection.VerifiedHTTPSConnection object at 0x7f244f8c5978>: Failed to establish a new connection: [Errno -3] Temporary failure in name resolution\n",
      "\n",
      "During handling of the above exception, another exception occurred:\n",
      "\n",
      "Traceback (most recent call last):\n",
      "  File \"/home/ubuntu/.pyenv/versions/3.6.1/lib/python3.6/site-packages/requests/adapters.py\", line 423, in send\n",
      "    timeout=timeout\n",
      "  File \"/home/ubuntu/.pyenv/versions/3.6.1/lib/python3.6/site-packages/requests/packages/urllib3/connectionpool.py\", line 649, in urlopen\n",
      "    _stacktrace=sys.exc_info()[2])\n",
      "  File \"/home/ubuntu/.pyenv/versions/3.6.1/lib/python3.6/site-packages/requests/packages/urllib3/util/retry.py\", line 376, in increment\n",
      "    raise MaxRetryError(_pool, url, error or ResponseError(cause))\n",
      "requests.packages.urllib3.exceptions.MaxRetryError: HTTPSConnectionPool(host='www.518.com.tw', port=443): Max retries exceeded with url: /%E7%B3%BB%E7%B5%B1%E8%A8%AD%E8%A8%88%E9%96%8B%E7%99%BC%E7%AE%A1%E7%90%86%E5%B8%AB-%E6%A1%83%E5%9C%92%E5%B8%82-%E8%98%86%E7%AB%B9%E5%8D%80-job-963732.html?kw=&pi=26 (Caused by NewConnectionError('<requests.packages.urllib3.connection.VerifiedHTTPSConnection object at 0x7f244f8c5978>: Failed to establish a new connection: [Errno -3] Temporary failure in name resolution',))\n",
      "\n",
      "During handling of the above exception, another exception occurred:\n",
      "\n",
      "Traceback (most recent call last):\n",
      "  File \"/home/ubuntu/.pyenv/versions/3.6.1/lib/python3.6/threading.py\", line 916, in _bootstrap_inner\n",
      "    self.run()\n",
      "  File \"<ipython-input-18-c76fc6bf8299>\", line 6, in run\n",
      "    pageURL('https://www.518.com.tw/job-index-P-'+str(self.number)+'.html?i=1&am=1&ab=2032001,2032002,')\n",
      "  File \"<ipython-input-17-696307882546>\", line 6, in pageURL\n",
      "    innerURL(str(link['href']))  #throw in innerURL function\n",
      "  File \"<ipython-input-16-1d4840fd97cd>\", line 3, in innerURL\n",
      "    inner = requests.get(url)  #用get連到網頁\n",
      "  File \"/home/ubuntu/.pyenv/versions/3.6.1/lib/python3.6/site-packages/requests/api.py\", line 70, in get\n",
      "    return request('get', url, params=params, **kwargs)\n",
      "  File \"/home/ubuntu/.pyenv/versions/3.6.1/lib/python3.6/site-packages/requests/api.py\", line 56, in request\n",
      "    return session.request(method=method, url=url, **kwargs)\n",
      "  File \"/home/ubuntu/.pyenv/versions/3.6.1/lib/python3.6/site-packages/requests/sessions.py\", line 488, in request\n",
      "    resp = self.send(prep, **send_kwargs)\n",
      "  File \"/home/ubuntu/.pyenv/versions/3.6.1/lib/python3.6/site-packages/requests/sessions.py\", line 609, in send\n",
      "    r = adapter.send(request, **kwargs)\n",
      "  File \"/home/ubuntu/.pyenv/versions/3.6.1/lib/python3.6/site-packages/requests/adapters.py\", line 487, in send\n",
      "    raise ConnectionError(e, request=request)\n",
      "requests.exceptions.ConnectionError: HTTPSConnectionPool(host='www.518.com.tw', port=443): Max retries exceeded with url: /%E7%B3%BB%E7%B5%B1%E8%A8%AD%E8%A8%88%E9%96%8B%E7%99%BC%E7%AE%A1%E7%90%86%E5%B8%AB-%E6%A1%83%E5%9C%92%E5%B8%82-%E8%98%86%E7%AB%B9%E5%8D%80-job-963732.html?kw=&pi=26 (Caused by NewConnectionError('<requests.packages.urllib3.connection.VerifiedHTTPSConnection object at 0x7f244f8c5978>: Failed to establish a new connection: [Errno -3] Temporary failure in name resolution',))\n",
      "\n",
      "Exception in thread Thread-50:\n",
      "Traceback (most recent call last):\n",
      "  File \"/home/ubuntu/.pyenv/versions/3.6.1/lib/python3.6/site-packages/requests/packages/urllib3/connection.py\", line 141, in _new_conn\n",
      "    (self.host, self.port), self.timeout, **extra_kw)\n",
      "  File \"/home/ubuntu/.pyenv/versions/3.6.1/lib/python3.6/site-packages/requests/packages/urllib3/util/connection.py\", line 60, in create_connection\n",
      "    for res in socket.getaddrinfo(host, port, family, socket.SOCK_STREAM):\n",
      "  File \"/home/ubuntu/.pyenv/versions/3.6.1/lib/python3.6/socket.py\", line 743, in getaddrinfo\n",
      "    for res in _socket.getaddrinfo(host, port, family, type, proto, flags):\n",
      "socket.gaierror: [Errno -3] Temporary failure in name resolution\n",
      "\n",
      "During handling of the above exception, another exception occurred:\n",
      "\n",
      "Traceback (most recent call last):\n",
      "  File \"/home/ubuntu/.pyenv/versions/3.6.1/lib/python3.6/site-packages/requests/packages/urllib3/connectionpool.py\", line 600, in urlopen\n",
      "    chunked=chunked)\n",
      "  File \"/home/ubuntu/.pyenv/versions/3.6.1/lib/python3.6/site-packages/requests/packages/urllib3/connectionpool.py\", line 345, in _make_request\n",
      "    self._validate_conn(conn)\n",
      "  File \"/home/ubuntu/.pyenv/versions/3.6.1/lib/python3.6/site-packages/requests/packages/urllib3/connectionpool.py\", line 844, in _validate_conn\n",
      "    conn.connect()\n",
      "  File \"/home/ubuntu/.pyenv/versions/3.6.1/lib/python3.6/site-packages/requests/packages/urllib3/connection.py\", line 284, in connect\n",
      "    conn = self._new_conn()\n",
      "  File \"/home/ubuntu/.pyenv/versions/3.6.1/lib/python3.6/site-packages/requests/packages/urllib3/connection.py\", line 150, in _new_conn\n",
      "    self, \"Failed to establish a new connection: %s\" % e)\n",
      "requests.packages.urllib3.exceptions.NewConnectionError: <requests.packages.urllib3.connection.VerifiedHTTPSConnection object at 0x7f244f6e4f98>: Failed to establish a new connection: [Errno -3] Temporary failure in name resolution\n",
      "\n",
      "During handling of the above exception, another exception occurred:\n",
      "\n",
      "Traceback (most recent call last):\n",
      "  File \"/home/ubuntu/.pyenv/versions/3.6.1/lib/python3.6/site-packages/requests/adapters.py\", line 423, in send\n",
      "    timeout=timeout\n",
      "  File \"/home/ubuntu/.pyenv/versions/3.6.1/lib/python3.6/site-packages/requests/packages/urllib3/connectionpool.py\", line 649, in urlopen\n",
      "    _stacktrace=sys.exc_info()[2])\n",
      "  File \"/home/ubuntu/.pyenv/versions/3.6.1/lib/python3.6/site-packages/requests/packages/urllib3/util/retry.py\", line 376, in increment\n",
      "    raise MaxRetryError(_pool, url, error or ResponseError(cause))\n",
      "requests.packages.urllib3.exceptions.MaxRetryError: HTTPSConnectionPool(host='www.518.com.tw', port=443): Max retries exceeded with url: /%E6%8A%80%E8%A1%93%E5%B7%A5%E7%A8%8B%E4%BA%BA%E5%93%A1-%E6%A1%83%E5%9C%92%E5%B8%82-%E4%B8%AD%E5%A3%A2%E5%8D%80-job-664507.html?kw=&pi=47 (Caused by NewConnectionError('<requests.packages.urllib3.connection.VerifiedHTTPSConnection object at 0x7f244f6e4f98>: Failed to establish a new connection: [Errno -3] Temporary failure in name resolution',))\n",
      "\n",
      "During handling of the above exception, another exception occurred:\n",
      "\n",
      "Traceback (most recent call last):\n",
      "  File \"/home/ubuntu/.pyenv/versions/3.6.1/lib/python3.6/threading.py\", line 916, in _bootstrap_inner\n",
      "    self.run()\n",
      "  File \"<ipython-input-18-c76fc6bf8299>\", line 6, in run\n",
      "    pageURL('https://www.518.com.tw/job-index-P-'+str(self.number)+'.html?i=1&am=1&ab=2032001,2032002,')\n",
      "  File \"<ipython-input-17-696307882546>\", line 6, in pageURL\n",
      "    innerURL(str(link['href']))  #throw in innerURL function\n",
      "  File \"<ipython-input-16-1d4840fd97cd>\", line 3, in innerURL\n",
      "    inner = requests.get(url)  #用get連到網頁\n",
      "  File \"/home/ubuntu/.pyenv/versions/3.6.1/lib/python3.6/site-packages/requests/api.py\", line 70, in get\n",
      "    return request('get', url, params=params, **kwargs)\n",
      "  File \"/home/ubuntu/.pyenv/versions/3.6.1/lib/python3.6/site-packages/requests/api.py\", line 56, in request\n",
      "    return session.request(method=method, url=url, **kwargs)\n",
      "  File \"/home/ubuntu/.pyenv/versions/3.6.1/lib/python3.6/site-packages/requests/sessions.py\", line 488, in request\n",
      "    resp = self.send(prep, **send_kwargs)\n",
      "  File \"/home/ubuntu/.pyenv/versions/3.6.1/lib/python3.6/site-packages/requests/sessions.py\", line 609, in send\n",
      "    r = adapter.send(request, **kwargs)\n",
      "  File \"/home/ubuntu/.pyenv/versions/3.6.1/lib/python3.6/site-packages/requests/adapters.py\", line 487, in send\n",
      "    raise ConnectionError(e, request=request)\n",
      "requests.exceptions.ConnectionError: HTTPSConnectionPool(host='www.518.com.tw', port=443): Max retries exceeded with url: /%E6%8A%80%E8%A1%93%E5%B7%A5%E7%A8%8B%E4%BA%BA%E5%93%A1-%E6%A1%83%E5%9C%92%E5%B8%82-%E4%B8%AD%E5%A3%A2%E5%8D%80-job-664507.html?kw=&pi=47 (Caused by NewConnectionError('<requests.packages.urllib3.connection.VerifiedHTTPSConnection object at 0x7f244f6e4f98>: Failed to establish a new connection: [Errno -3] Temporary failure in name resolution',))\n",
      "\n",
      "Exception in thread Thread-51:\n",
      "Traceback (most recent call last):\n",
      "  File \"/home/ubuntu/.pyenv/versions/3.6.1/lib/python3.6/site-packages/requests/packages/urllib3/connection.py\", line 141, in _new_conn\n",
      "    (self.host, self.port), self.timeout, **extra_kw)\n",
      "  File \"/home/ubuntu/.pyenv/versions/3.6.1/lib/python3.6/site-packages/requests/packages/urllib3/util/connection.py\", line 60, in create_connection\n",
      "    for res in socket.getaddrinfo(host, port, family, socket.SOCK_STREAM):\n",
      "  File \"/home/ubuntu/.pyenv/versions/3.6.1/lib/python3.6/socket.py\", line 743, in getaddrinfo\n",
      "    for res in _socket.getaddrinfo(host, port, family, type, proto, flags):\n",
      "socket.gaierror: [Errno -3] Temporary failure in name resolution\n",
      "\n",
      "During handling of the above exception, another exception occurred:\n",
      "\n",
      "Traceback (most recent call last):\n",
      "  File \"/home/ubuntu/.pyenv/versions/3.6.1/lib/python3.6/site-packages/requests/packages/urllib3/connectionpool.py\", line 600, in urlopen\n",
      "    chunked=chunked)\n",
      "  File \"/home/ubuntu/.pyenv/versions/3.6.1/lib/python3.6/site-packages/requests/packages/urllib3/connectionpool.py\", line 345, in _make_request\n",
      "    self._validate_conn(conn)\n",
      "  File \"/home/ubuntu/.pyenv/versions/3.6.1/lib/python3.6/site-packages/requests/packages/urllib3/connectionpool.py\", line 844, in _validate_conn\n",
      "    conn.connect()\n",
      "  File \"/home/ubuntu/.pyenv/versions/3.6.1/lib/python3.6/site-packages/requests/packages/urllib3/connection.py\", line 284, in connect\n",
      "    conn = self._new_conn()\n",
      "  File \"/home/ubuntu/.pyenv/versions/3.6.1/lib/python3.6/site-packages/requests/packages/urllib3/connection.py\", line 150, in _new_conn\n",
      "    self, \"Failed to establish a new connection: %s\" % e)\n",
      "requests.packages.urllib3.exceptions.NewConnectionError: <requests.packages.urllib3.connection.VerifiedHTTPSConnection object at 0x7f24503f1b70>: Failed to establish a new connection: [Errno -3] Temporary failure in name resolution\n",
      "\n",
      "During handling of the above exception, another exception occurred:\n",
      "\n",
      "Traceback (most recent call last):\n",
      "  File \"/home/ubuntu/.pyenv/versions/3.6.1/lib/python3.6/site-packages/requests/adapters.py\", line 423, in send\n",
      "    timeout=timeout\n",
      "  File \"/home/ubuntu/.pyenv/versions/3.6.1/lib/python3.6/site-packages/requests/packages/urllib3/connectionpool.py\", line 649, in urlopen\n",
      "    _stacktrace=sys.exc_info()[2])\n",
      "  File \"/home/ubuntu/.pyenv/versions/3.6.1/lib/python3.6/site-packages/requests/packages/urllib3/util/retry.py\", line 376, in increment\n",
      "    raise MaxRetryError(_pool, url, error or ResponseError(cause))\n",
      "requests.packages.urllib3.exceptions.MaxRetryError: HTTPSConnectionPool(host='www.518.com.tw', port=443): Max retries exceeded with url: /%E8%BB%9F%E9%AB%94%E6%A5%AD%E5%8B%99%20%E8%A1%8C%E9%8A%B7%E4%BA%BA%E5%93%A1-%E6%A1%83%E5%9C%92%E5%B8%82-%E5%85%AB%E5%BE%B7%E5%8D%80-job-1029284.html?kw=&pi=48 (Caused by NewConnectionError('<requests.packages.urllib3.connection.VerifiedHTTPSConnection object at 0x7f24503f1b70>: Failed to establish a new connection: [Errno -3] Temporary failure in name resolution',))\n",
      "\n",
      "During handling of the above exception, another exception occurred:\n",
      "\n",
      "Traceback (most recent call last):\n",
      "  File \"/home/ubuntu/.pyenv/versions/3.6.1/lib/python3.6/threading.py\", line 916, in _bootstrap_inner\n",
      "    self.run()\n",
      "  File \"<ipython-input-18-c76fc6bf8299>\", line 6, in run\n",
      "    pageURL('https://www.518.com.tw/job-index-P-'+str(self.number)+'.html?i=1&am=1&ab=2032001,2032002,')\n",
      "  File \"<ipython-input-17-696307882546>\", line 6, in pageURL\n",
      "    innerURL(str(link['href']))  #throw in innerURL function\n",
      "  File \"<ipython-input-16-1d4840fd97cd>\", line 3, in innerURL\n",
      "    inner = requests.get(url)  #用get連到網頁\n",
      "  File \"/home/ubuntu/.pyenv/versions/3.6.1/lib/python3.6/site-packages/requests/api.py\", line 70, in get\n",
      "    return request('get', url, params=params, **kwargs)\n",
      "  File \"/home/ubuntu/.pyenv/versions/3.6.1/lib/python3.6/site-packages/requests/api.py\", line 56, in request\n",
      "    return session.request(method=method, url=url, **kwargs)\n",
      "  File \"/home/ubuntu/.pyenv/versions/3.6.1/lib/python3.6/site-packages/requests/sessions.py\", line 488, in request\n",
      "    resp = self.send(prep, **send_kwargs)\n",
      "  File \"/home/ubuntu/.pyenv/versions/3.6.1/lib/python3.6/site-packages/requests/sessions.py\", line 609, in send\n",
      "    r = adapter.send(request, **kwargs)\n",
      "  File \"/home/ubuntu/.pyenv/versions/3.6.1/lib/python3.6/site-packages/requests/adapters.py\", line 487, in send\n",
      "    raise ConnectionError(e, request=request)\n",
      "requests.exceptions.ConnectionError: HTTPSConnectionPool(host='www.518.com.tw', port=443): Max retries exceeded with url: /%E8%BB%9F%E9%AB%94%E6%A5%AD%E5%8B%99%20%E8%A1%8C%E9%8A%B7%E4%BA%BA%E5%93%A1-%E6%A1%83%E5%9C%92%E5%B8%82-%E5%85%AB%E5%BE%B7%E5%8D%80-job-1029284.html?kw=&pi=48 (Caused by NewConnectionError('<requests.packages.urllib3.connection.VerifiedHTTPSConnection object at 0x7f24503f1b70>: Failed to establish a new connection: [Errno -3] Temporary failure in name resolution',))\n",
      "\n",
      "Exception in thread Thread-28:\n",
      "Traceback (most recent call last):\n",
      "  File \"/home/ubuntu/.pyenv/versions/3.6.1/lib/python3.6/site-packages/requests/packages/urllib3/connection.py\", line 141, in _new_conn\n",
      "    (self.host, self.port), self.timeout, **extra_kw)\n",
      "  File \"/home/ubuntu/.pyenv/versions/3.6.1/lib/python3.6/site-packages/requests/packages/urllib3/util/connection.py\", line 60, in create_connection\n",
      "    for res in socket.getaddrinfo(host, port, family, socket.SOCK_STREAM):\n",
      "  File \"/home/ubuntu/.pyenv/versions/3.6.1/lib/python3.6/socket.py\", line 743, in getaddrinfo\n",
      "    for res in _socket.getaddrinfo(host, port, family, type, proto, flags):\n",
      "socket.gaierror: [Errno -3] Temporary failure in name resolution\n",
      "\n",
      "During handling of the above exception, another exception occurred:\n",
      "\n",
      "Traceback (most recent call last):\n",
      "  File \"/home/ubuntu/.pyenv/versions/3.6.1/lib/python3.6/site-packages/requests/packages/urllib3/connectionpool.py\", line 600, in urlopen\n",
      "    chunked=chunked)\n",
      "  File \"/home/ubuntu/.pyenv/versions/3.6.1/lib/python3.6/site-packages/requests/packages/urllib3/connectionpool.py\", line 345, in _make_request\n",
      "    self._validate_conn(conn)\n",
      "  File \"/home/ubuntu/.pyenv/versions/3.6.1/lib/python3.6/site-packages/requests/packages/urllib3/connectionpool.py\", line 844, in _validate_conn\n",
      "    conn.connect()\n",
      "  File \"/home/ubuntu/.pyenv/versions/3.6.1/lib/python3.6/site-packages/requests/packages/urllib3/connection.py\", line 284, in connect\n",
      "    conn = self._new_conn()\n",
      "  File \"/home/ubuntu/.pyenv/versions/3.6.1/lib/python3.6/site-packages/requests/packages/urllib3/connection.py\", line 150, in _new_conn\n",
      "    self, \"Failed to establish a new connection: %s\" % e)\n",
      "requests.packages.urllib3.exceptions.NewConnectionError: <requests.packages.urllib3.connection.VerifiedHTTPSConnection object at 0x7f2450859b00>: Failed to establish a new connection: [Errno -3] Temporary failure in name resolution\n",
      "\n",
      "During handling of the above exception, another exception occurred:\n",
      "\n",
      "Traceback (most recent call last):\n",
      "  File \"/home/ubuntu/.pyenv/versions/3.6.1/lib/python3.6/site-packages/requests/adapters.py\", line 423, in send\n",
      "    timeout=timeout\n",
      "  File \"/home/ubuntu/.pyenv/versions/3.6.1/lib/python3.6/site-packages/requests/packages/urllib3/connectionpool.py\", line 649, in urlopen\n",
      "    _stacktrace=sys.exc_info()[2])\n",
      "  File \"/home/ubuntu/.pyenv/versions/3.6.1/lib/python3.6/site-packages/requests/packages/urllib3/util/retry.py\", line 376, in increment\n",
      "    raise MaxRetryError(_pool, url, error or ResponseError(cause))\n",
      "requests.packages.urllib3.exceptions.MaxRetryError: HTTPSConnectionPool(host='www.518.com.tw', port=443): Max retries exceeded with url: /%E6%B0%B4%E9%9B%BB%E5%B7%A5%E7%A8%8B%E5%B8%AB-%E5%8F%B0%E5%8C%97%E5%B8%82-%E5%85%A8%E5%8D%80-job-686478.html?kw=&pi=25 (Caused by NewConnectionError('<requests.packages.urllib3.connection.VerifiedHTTPSConnection object at 0x7f2450859b00>: Failed to establish a new connection: [Errno -3] Temporary failure in name resolution',))\n",
      "\n",
      "During handling of the above exception, another exception occurred:\n",
      "\n",
      "Traceback (most recent call last):\n",
      "  File \"/home/ubuntu/.pyenv/versions/3.6.1/lib/python3.6/threading.py\", line 916, in _bootstrap_inner\n",
      "    self.run()\n",
      "  File \"<ipython-input-18-c76fc6bf8299>\", line 6, in run\n",
      "    pageURL('https://www.518.com.tw/job-index-P-'+str(self.number)+'.html?i=1&am=1&ab=2032001,2032002,')\n",
      "  File \"<ipython-input-17-696307882546>\", line 6, in pageURL\n",
      "    innerURL(str(link['href']))  #throw in innerURL function\n",
      "  File \"<ipython-input-16-1d4840fd97cd>\", line 3, in innerURL\n",
      "    inner = requests.get(url)  #用get連到網頁\n",
      "  File \"/home/ubuntu/.pyenv/versions/3.6.1/lib/python3.6/site-packages/requests/api.py\", line 70, in get\n",
      "    return request('get', url, params=params, **kwargs)\n",
      "  File \"/home/ubuntu/.pyenv/versions/3.6.1/lib/python3.6/site-packages/requests/api.py\", line 56, in request\n",
      "    return session.request(method=method, url=url, **kwargs)\n",
      "  File \"/home/ubuntu/.pyenv/versions/3.6.1/lib/python3.6/site-packages/requests/sessions.py\", line 488, in request\n",
      "    resp = self.send(prep, **send_kwargs)\n",
      "  File \"/home/ubuntu/.pyenv/versions/3.6.1/lib/python3.6/site-packages/requests/sessions.py\", line 609, in send\n",
      "    r = adapter.send(request, **kwargs)\n",
      "  File \"/home/ubuntu/.pyenv/versions/3.6.1/lib/python3.6/site-packages/requests/adapters.py\", line 487, in send\n",
      "    raise ConnectionError(e, request=request)\n",
      "requests.exceptions.ConnectionError: HTTPSConnectionPool(host='www.518.com.tw', port=443): Max retries exceeded with url: /%E6%B0%B4%E9%9B%BB%E5%B7%A5%E7%A8%8B%E5%B8%AB-%E5%8F%B0%E5%8C%97%E5%B8%82-%E5%85%A8%E5%8D%80-job-686478.html?kw=&pi=25 (Caused by NewConnectionError('<requests.packages.urllib3.connection.VerifiedHTTPSConnection object at 0x7f2450859b00>: Failed to establish a new connection: [Errno -3] Temporary failure in name resolution',))\n",
      "\n",
      "Exception in thread Thread-35:\n",
      "Traceback (most recent call last):\n",
      "  File \"/home/ubuntu/.pyenv/versions/3.6.1/lib/python3.6/site-packages/requests/packages/urllib3/connection.py\", line 141, in _new_conn\n",
      "    (self.host, self.port), self.timeout, **extra_kw)\n",
      "  File \"/home/ubuntu/.pyenv/versions/3.6.1/lib/python3.6/site-packages/requests/packages/urllib3/util/connection.py\", line 60, in create_connection\n",
      "    for res in socket.getaddrinfo(host, port, family, socket.SOCK_STREAM):\n",
      "  File \"/home/ubuntu/.pyenv/versions/3.6.1/lib/python3.6/socket.py\", line 743, in getaddrinfo\n",
      "    for res in _socket.getaddrinfo(host, port, family, type, proto, flags):\n",
      "socket.gaierror: [Errno -3] Temporary failure in name resolution\n",
      "\n",
      "During handling of the above exception, another exception occurred:\n",
      "\n",
      "Traceback (most recent call last):\n",
      "  File \"/home/ubuntu/.pyenv/versions/3.6.1/lib/python3.6/site-packages/requests/packages/urllib3/connectionpool.py\", line 600, in urlopen\n",
      "    chunked=chunked)\n",
      "  File \"/home/ubuntu/.pyenv/versions/3.6.1/lib/python3.6/site-packages/requests/packages/urllib3/connectionpool.py\", line 345, in _make_request\n",
      "    self._validate_conn(conn)\n",
      "  File \"/home/ubuntu/.pyenv/versions/3.6.1/lib/python3.6/site-packages/requests/packages/urllib3/connectionpool.py\", line 844, in _validate_conn\n",
      "    conn.connect()\n",
      "  File \"/home/ubuntu/.pyenv/versions/3.6.1/lib/python3.6/site-packages/requests/packages/urllib3/connection.py\", line 284, in connect\n",
      "    conn = self._new_conn()\n",
      "  File \"/home/ubuntu/.pyenv/versions/3.6.1/lib/python3.6/site-packages/requests/packages/urllib3/connection.py\", line 150, in _new_conn\n",
      "    self, \"Failed to establish a new connection: %s\" % e)\n",
      "requests.packages.urllib3.exceptions.NewConnectionError: <requests.packages.urllib3.connection.VerifiedHTTPSConnection object at 0x7f2450339828>: Failed to establish a new connection: [Errno -3] Temporary failure in name resolution\n",
      "\n",
      "During handling of the above exception, another exception occurred:\n",
      "\n",
      "Traceback (most recent call last):\n",
      "  File \"/home/ubuntu/.pyenv/versions/3.6.1/lib/python3.6/site-packages/requests/adapters.py\", line 423, in send\n",
      "    timeout=timeout\n",
      "  File \"/home/ubuntu/.pyenv/versions/3.6.1/lib/python3.6/site-packages/requests/packages/urllib3/connectionpool.py\", line 649, in urlopen\n",
      "    _stacktrace=sys.exc_info()[2])\n",
      "  File \"/home/ubuntu/.pyenv/versions/3.6.1/lib/python3.6/site-packages/requests/packages/urllib3/util/retry.py\", line 376, in increment\n",
      "    raise MaxRetryError(_pool, url, error or ResponseError(cause))\n",
      "requests.packages.urllib3.exceptions.MaxRetryError: HTTPSConnectionPool(host='www.518.com.tw', port=443): Max retries exceeded with url: /Java%20%E8%BB%9F%E9%AB%94%E5%B7%A5%E7%A8%8B%E5%B8%AB[%E5%8F%B0%E4%B8%AD]-%E5%8F%B0%E4%B8%AD%E5%B8%82-%E5%8D%97%E5%8D%80-job-697324.html?kw=&pi=32 (Caused by NewConnectionError('<requests.packages.urllib3.connection.VerifiedHTTPSConnection object at 0x7f2450339828>: Failed to establish a new connection: [Errno -3] Temporary failure in name resolution',))\n",
      "\n",
      "During handling of the above exception, another exception occurred:\n",
      "\n",
      "Traceback (most recent call last):\n",
      "  File \"/home/ubuntu/.pyenv/versions/3.6.1/lib/python3.6/threading.py\", line 916, in _bootstrap_inner\n",
      "    self.run()\n",
      "  File \"<ipython-input-18-c76fc6bf8299>\", line 6, in run\n",
      "    pageURL('https://www.518.com.tw/job-index-P-'+str(self.number)+'.html?i=1&am=1&ab=2032001,2032002,')\n",
      "  File \"<ipython-input-17-696307882546>\", line 6, in pageURL\n",
      "    innerURL(str(link['href']))  #throw in innerURL function\n",
      "  File \"<ipython-input-16-1d4840fd97cd>\", line 3, in innerURL\n",
      "    inner = requests.get(url)  #用get連到網頁\n",
      "  File \"/home/ubuntu/.pyenv/versions/3.6.1/lib/python3.6/site-packages/requests/api.py\", line 70, in get\n",
      "    return request('get', url, params=params, **kwargs)\n",
      "  File \"/home/ubuntu/.pyenv/versions/3.6.1/lib/python3.6/site-packages/requests/api.py\", line 56, in request\n",
      "    return session.request(method=method, url=url, **kwargs)\n",
      "  File \"/home/ubuntu/.pyenv/versions/3.6.1/lib/python3.6/site-packages/requests/sessions.py\", line 488, in request\n",
      "    resp = self.send(prep, **send_kwargs)\n",
      "  File \"/home/ubuntu/.pyenv/versions/3.6.1/lib/python3.6/site-packages/requests/sessions.py\", line 609, in send\n",
      "    r = adapter.send(request, **kwargs)\n",
      "  File \"/home/ubuntu/.pyenv/versions/3.6.1/lib/python3.6/site-packages/requests/adapters.py\", line 487, in send\n",
      "    raise ConnectionError(e, request=request)\n",
      "requests.exceptions.ConnectionError: HTTPSConnectionPool(host='www.518.com.tw', port=443): Max retries exceeded with url: /Java%20%E8%BB%9F%E9%AB%94%E5%B7%A5%E7%A8%8B%E5%B8%AB[%E5%8F%B0%E4%B8%AD]-%E5%8F%B0%E4%B8%AD%E5%B8%82-%E5%8D%97%E5%8D%80-job-697324.html?kw=&pi=32 (Caused by NewConnectionError('<requests.packages.urllib3.connection.VerifiedHTTPSConnection object at 0x7f2450339828>: Failed to establish a new connection: [Errno -3] Temporary failure in name resolution',))\n",
      "\n",
      "Exception in thread Thread-18:\n",
      "Traceback (most recent call last):\n",
      "  File \"/home/ubuntu/.pyenv/versions/3.6.1/lib/python3.6/site-packages/requests/packages/urllib3/connection.py\", line 141, in _new_conn\n",
      "    (self.host, self.port), self.timeout, **extra_kw)\n",
      "  File \"/home/ubuntu/.pyenv/versions/3.6.1/lib/python3.6/site-packages/requests/packages/urllib3/util/connection.py\", line 60, in create_connection\n",
      "    for res in socket.getaddrinfo(host, port, family, socket.SOCK_STREAM):\n",
      "  File \"/home/ubuntu/.pyenv/versions/3.6.1/lib/python3.6/socket.py\", line 743, in getaddrinfo\n",
      "    for res in _socket.getaddrinfo(host, port, family, type, proto, flags):\n",
      "socket.gaierror: [Errno -3] Temporary failure in name resolution\n",
      "\n",
      "During handling of the above exception, another exception occurred:\n",
      "\n",
      "Traceback (most recent call last):\n",
      "  File \"/home/ubuntu/.pyenv/versions/3.6.1/lib/python3.6/site-packages/requests/packages/urllib3/connectionpool.py\", line 600, in urlopen\n",
      "    chunked=chunked)\n",
      "  File \"/home/ubuntu/.pyenv/versions/3.6.1/lib/python3.6/site-packages/requests/packages/urllib3/connectionpool.py\", line 345, in _make_request\n",
      "    self._validate_conn(conn)\n",
      "  File \"/home/ubuntu/.pyenv/versions/3.6.1/lib/python3.6/site-packages/requests/packages/urllib3/connectionpool.py\", line 844, in _validate_conn\n",
      "    conn.connect()\n",
      "  File \"/home/ubuntu/.pyenv/versions/3.6.1/lib/python3.6/site-packages/requests/packages/urllib3/connection.py\", line 284, in connect\n",
      "    conn = self._new_conn()\n",
      "  File \"/home/ubuntu/.pyenv/versions/3.6.1/lib/python3.6/site-packages/requests/packages/urllib3/connection.py\", line 150, in _new_conn\n",
      "    self, \"Failed to establish a new connection: %s\" % e)\n",
      "requests.packages.urllib3.exceptions.NewConnectionError: <requests.packages.urllib3.connection.VerifiedHTTPSConnection object at 0x7f24564187f0>: Failed to establish a new connection: [Errno -3] Temporary failure in name resolution\n",
      "\n",
      "During handling of the above exception, another exception occurred:\n",
      "\n",
      "Traceback (most recent call last):\n",
      "  File \"/home/ubuntu/.pyenv/versions/3.6.1/lib/python3.6/site-packages/requests/adapters.py\", line 423, in send\n",
      "    timeout=timeout\n",
      "  File \"/home/ubuntu/.pyenv/versions/3.6.1/lib/python3.6/site-packages/requests/packages/urllib3/connectionpool.py\", line 649, in urlopen\n",
      "    _stacktrace=sys.exc_info()[2])\n",
      "  File \"/home/ubuntu/.pyenv/versions/3.6.1/lib/python3.6/site-packages/requests/packages/urllib3/util/retry.py\", line 376, in increment\n",
      "    raise MaxRetryError(_pool, url, error or ResponseError(cause))\n",
      "requests.packages.urllib3.exceptions.MaxRetryError: HTTPSConnectionPool(host='www.518.com.tw', port=443): Max retries exceeded with url: /%E8%BB%9F%E9%AB%94%E5%B7%A5%E7%A8%8B%E5%B8%AB-%E6%96%B0%E5%8C%97%E5%B8%82-%E4%B8%AD%E5%92%8C%E5%8D%80-job-880777.html?kw=&pi=15 (Caused by NewConnectionError('<requests.packages.urllib3.connection.VerifiedHTTPSConnection object at 0x7f24564187f0>: Failed to establish a new connection: [Errno -3] Temporary failure in name resolution',))\n",
      "\n",
      "During handling of the above exception, another exception occurred:\n",
      "\n",
      "Traceback (most recent call last):\n",
      "  File \"/home/ubuntu/.pyenv/versions/3.6.1/lib/python3.6/threading.py\", line 916, in _bootstrap_inner\n",
      "    self.run()\n",
      "  File \"<ipython-input-18-c76fc6bf8299>\", line 6, in run\n",
      "    pageURL('https://www.518.com.tw/job-index-P-'+str(self.number)+'.html?i=1&am=1&ab=2032001,2032002,')\n",
      "  File \"<ipython-input-17-696307882546>\", line 6, in pageURL\n",
      "    innerURL(str(link['href']))  #throw in innerURL function\n",
      "  File \"<ipython-input-16-1d4840fd97cd>\", line 3, in innerURL\n",
      "    inner = requests.get(url)  #用get連到網頁\n",
      "  File \"/home/ubuntu/.pyenv/versions/3.6.1/lib/python3.6/site-packages/requests/api.py\", line 70, in get\n",
      "    return request('get', url, params=params, **kwargs)\n",
      "  File \"/home/ubuntu/.pyenv/versions/3.6.1/lib/python3.6/site-packages/requests/api.py\", line 56, in request\n",
      "    return session.request(method=method, url=url, **kwargs)\n",
      "  File \"/home/ubuntu/.pyenv/versions/3.6.1/lib/python3.6/site-packages/requests/sessions.py\", line 488, in request\n",
      "    resp = self.send(prep, **send_kwargs)\n",
      "  File \"/home/ubuntu/.pyenv/versions/3.6.1/lib/python3.6/site-packages/requests/sessions.py\", line 609, in send\n",
      "    r = adapter.send(request, **kwargs)\n",
      "  File \"/home/ubuntu/.pyenv/versions/3.6.1/lib/python3.6/site-packages/requests/adapters.py\", line 487, in send\n",
      "    raise ConnectionError(e, request=request)\n",
      "requests.exceptions.ConnectionError: HTTPSConnectionPool(host='www.518.com.tw', port=443): Max retries exceeded with url: /%E8%BB%9F%E9%AB%94%E5%B7%A5%E7%A8%8B%E5%B8%AB-%E6%96%B0%E5%8C%97%E5%B8%82-%E4%B8%AD%E5%92%8C%E5%8D%80-job-880777.html?kw=&pi=15 (Caused by NewConnectionError('<requests.packages.urllib3.connection.VerifiedHTTPSConnection object at 0x7f24564187f0>: Failed to establish a new connection: [Errno -3] Temporary failure in name resolution',))\n",
      "\n",
      "Exception in thread Thread-47:\n",
      "Traceback (most recent call last):\n",
      "  File \"/home/ubuntu/.pyenv/versions/3.6.1/lib/python3.6/site-packages/requests/packages/urllib3/connection.py\", line 141, in _new_conn\n",
      "    (self.host, self.port), self.timeout, **extra_kw)\n",
      "  File \"/home/ubuntu/.pyenv/versions/3.6.1/lib/python3.6/site-packages/requests/packages/urllib3/util/connection.py\", line 60, in create_connection\n",
      "    for res in socket.getaddrinfo(host, port, family, socket.SOCK_STREAM):\n",
      "  File \"/home/ubuntu/.pyenv/versions/3.6.1/lib/python3.6/socket.py\", line 743, in getaddrinfo\n",
      "    for res in _socket.getaddrinfo(host, port, family, type, proto, flags):\n",
      "socket.gaierror: [Errno -3] Temporary failure in name resolution\n",
      "\n",
      "During handling of the above exception, another exception occurred:\n",
      "\n",
      "Traceback (most recent call last):\n",
      "  File \"/home/ubuntu/.pyenv/versions/3.6.1/lib/python3.6/site-packages/requests/packages/urllib3/connectionpool.py\", line 600, in urlopen\n",
      "    chunked=chunked)\n",
      "  File \"/home/ubuntu/.pyenv/versions/3.6.1/lib/python3.6/site-packages/requests/packages/urllib3/connectionpool.py\", line 345, in _make_request\n",
      "    self._validate_conn(conn)\n",
      "  File \"/home/ubuntu/.pyenv/versions/3.6.1/lib/python3.6/site-packages/requests/packages/urllib3/connectionpool.py\", line 844, in _validate_conn\n",
      "    conn.connect()\n",
      "  File \"/home/ubuntu/.pyenv/versions/3.6.1/lib/python3.6/site-packages/requests/packages/urllib3/connection.py\", line 284, in connect\n",
      "    conn = self._new_conn()\n",
      "  File \"/home/ubuntu/.pyenv/versions/3.6.1/lib/python3.6/site-packages/requests/packages/urllib3/connection.py\", line 150, in _new_conn\n",
      "    self, \"Failed to establish a new connection: %s\" % e)\n",
      "requests.packages.urllib3.exceptions.NewConnectionError: <requests.packages.urllib3.connection.VerifiedHTTPSConnection object at 0x7f2450070668>: Failed to establish a new connection: [Errno -3] Temporary failure in name resolution\n",
      "\n",
      "During handling of the above exception, another exception occurred:\n",
      "\n",
      "Traceback (most recent call last):\n",
      "  File \"/home/ubuntu/.pyenv/versions/3.6.1/lib/python3.6/site-packages/requests/adapters.py\", line 423, in send\n",
      "    timeout=timeout\n",
      "  File \"/home/ubuntu/.pyenv/versions/3.6.1/lib/python3.6/site-packages/requests/packages/urllib3/connectionpool.py\", line 649, in urlopen\n",
      "    _stacktrace=sys.exc_info()[2])\n",
      "  File \"/home/ubuntu/.pyenv/versions/3.6.1/lib/python3.6/site-packages/requests/packages/urllib3/util/retry.py\", line 376, in increment\n",
      "    raise MaxRetryError(_pool, url, error or ResponseError(cause))\n",
      "requests.packages.urllib3.exceptions.MaxRetryError: HTTPSConnectionPool(host='www.518.com.tw', port=443): Max retries exceeded with url: /%E7%B6%B2%E6%8B%8D%E8%B3%87%E6%96%99%E8%99%95%E7%90%86%E4%BA%BA%E5%93%A1-%E5%8D%97%E6%8A%95%E7%B8%A3-%E8%8D%89%E5%B1%AF%E9%8E%AE-job-715483.html?kw=&pi=44 (Caused by NewConnectionError('<requests.packages.urllib3.connection.VerifiedHTTPSConnection object at 0x7f2450070668>: Failed to establish a new connection: [Errno -3] Temporary failure in name resolution',))\n",
      "\n",
      "During handling of the above exception, another exception occurred:\n",
      "\n",
      "Traceback (most recent call last):\n",
      "  File \"/home/ubuntu/.pyenv/versions/3.6.1/lib/python3.6/threading.py\", line 916, in _bootstrap_inner\n",
      "    self.run()\n",
      "  File \"<ipython-input-18-c76fc6bf8299>\", line 6, in run\n",
      "    pageURL('https://www.518.com.tw/job-index-P-'+str(self.number)+'.html?i=1&am=1&ab=2032001,2032002,')\n",
      "  File \"<ipython-input-17-696307882546>\", line 6, in pageURL\n",
      "    innerURL(str(link['href']))  #throw in innerURL function\n",
      "  File \"<ipython-input-16-1d4840fd97cd>\", line 3, in innerURL\n",
      "    inner = requests.get(url)  #用get連到網頁\n",
      "  File \"/home/ubuntu/.pyenv/versions/3.6.1/lib/python3.6/site-packages/requests/api.py\", line 70, in get\n",
      "    return request('get', url, params=params, **kwargs)\n",
      "  File \"/home/ubuntu/.pyenv/versions/3.6.1/lib/python3.6/site-packages/requests/api.py\", line 56, in request\n",
      "    return session.request(method=method, url=url, **kwargs)\n",
      "  File \"/home/ubuntu/.pyenv/versions/3.6.1/lib/python3.6/site-packages/requests/sessions.py\", line 488, in request\n",
      "    resp = self.send(prep, **send_kwargs)\n",
      "  File \"/home/ubuntu/.pyenv/versions/3.6.1/lib/python3.6/site-packages/requests/sessions.py\", line 609, in send\n",
      "    r = adapter.send(request, **kwargs)\n",
      "  File \"/home/ubuntu/.pyenv/versions/3.6.1/lib/python3.6/site-packages/requests/adapters.py\", line 487, in send\n",
      "    raise ConnectionError(e, request=request)\n",
      "requests.exceptions.ConnectionError: HTTPSConnectionPool(host='www.518.com.tw', port=443): Max retries exceeded with url: /%E7%B6%B2%E6%8B%8D%E8%B3%87%E6%96%99%E8%99%95%E7%90%86%E4%BA%BA%E5%93%A1-%E5%8D%97%E6%8A%95%E7%B8%A3-%E8%8D%89%E5%B1%AF%E9%8E%AE-job-715483.html?kw=&pi=44 (Caused by NewConnectionError('<requests.packages.urllib3.connection.VerifiedHTTPSConnection object at 0x7f2450070668>: Failed to establish a new connection: [Errno -3] Temporary failure in name resolution',))\n",
      "\n",
      "Exception in thread Thread-34:\n",
      "Traceback (most recent call last):\n",
      "  File \"/home/ubuntu/.pyenv/versions/3.6.1/lib/python3.6/site-packages/requests/packages/urllib3/connection.py\", line 141, in _new_conn\n",
      "    (self.host, self.port), self.timeout, **extra_kw)\n",
      "  File \"/home/ubuntu/.pyenv/versions/3.6.1/lib/python3.6/site-packages/requests/packages/urllib3/util/connection.py\", line 60, in create_connection\n",
      "    for res in socket.getaddrinfo(host, port, family, socket.SOCK_STREAM):\n",
      "  File \"/home/ubuntu/.pyenv/versions/3.6.1/lib/python3.6/socket.py\", line 743, in getaddrinfo\n",
      "    for res in _socket.getaddrinfo(host, port, family, type, proto, flags):\n",
      "socket.gaierror: [Errno -3] Temporary failure in name resolution\n",
      "\n",
      "During handling of the above exception, another exception occurred:\n",
      "\n",
      "Traceback (most recent call last):\n",
      "  File \"/home/ubuntu/.pyenv/versions/3.6.1/lib/python3.6/site-packages/requests/packages/urllib3/connectionpool.py\", line 600, in urlopen\n",
      "    chunked=chunked)\n",
      "  File \"/home/ubuntu/.pyenv/versions/3.6.1/lib/python3.6/site-packages/requests/packages/urllib3/connectionpool.py\", line 356, in _make_request\n",
      "    conn.request(method, url, **httplib_request_kw)\n",
      "  File \"/home/ubuntu/.pyenv/versions/3.6.1/lib/python3.6/http/client.py\", line 1239, in request\n",
      "    self._send_request(method, url, body, headers, encode_chunked)\n",
      "  File \"/home/ubuntu/.pyenv/versions/3.6.1/lib/python3.6/http/client.py\", line 1285, in _send_request\n",
      "    self.endheaders(body, encode_chunked=encode_chunked)\n",
      "  File \"/home/ubuntu/.pyenv/versions/3.6.1/lib/python3.6/http/client.py\", line 1234, in endheaders\n",
      "    self._send_output(message_body, encode_chunked=encode_chunked)\n",
      "  File \"/home/ubuntu/.pyenv/versions/3.6.1/lib/python3.6/http/client.py\", line 1026, in _send_output\n",
      "    self.send(msg)\n",
      "  File \"/home/ubuntu/.pyenv/versions/3.6.1/lib/python3.6/http/client.py\", line 964, in send\n",
      "    self.connect()\n",
      "  File \"/home/ubuntu/.pyenv/versions/3.6.1/lib/python3.6/site-packages/requests/packages/urllib3/connection.py\", line 166, in connect\n",
      "    conn = self._new_conn()\n",
      "  File \"/home/ubuntu/.pyenv/versions/3.6.1/lib/python3.6/site-packages/requests/packages/urllib3/connection.py\", line 150, in _new_conn\n",
      "    self, \"Failed to establish a new connection: %s\" % e)\n",
      "requests.packages.urllib3.exceptions.NewConnectionError: <requests.packages.urllib3.connection.HTTPConnection object at 0x7f244f0db0b8>: Failed to establish a new connection: [Errno -3] Temporary failure in name resolution\n",
      "\n",
      "During handling of the above exception, another exception occurred:\n",
      "\n",
      "Traceback (most recent call last):\n",
      "  File \"/home/ubuntu/.pyenv/versions/3.6.1/lib/python3.6/site-packages/requests/adapters.py\", line 423, in send\n",
      "    timeout=timeout\n",
      "  File \"/home/ubuntu/.pyenv/versions/3.6.1/lib/python3.6/site-packages/requests/packages/urllib3/connectionpool.py\", line 649, in urlopen\n",
      "    _stacktrace=sys.exc_info()[2])\n",
      "  File \"/home/ubuntu/.pyenv/versions/3.6.1/lib/python3.6/site-packages/requests/packages/urllib3/util/retry.py\", line 376, in increment\n",
      "    raise MaxRetryError(_pool, url, error or ResponseError(cause))\n",
      "requests.packages.urllib3.exceptions.MaxRetryError: HTTPConnectionPool(host='case.518.com.tw', port=80): Max retries exceeded with url: /casepage-detail-123633.html?from=518&a_id=2183 (Caused by NewConnectionError('<requests.packages.urllib3.connection.HTTPConnection object at 0x7f244f0db0b8>: Failed to establish a new connection: [Errno -3] Temporary failure in name resolution',))\n",
      "\n",
      "During handling of the above exception, another exception occurred:\n",
      "\n",
      "Traceback (most recent call last):\n",
      "  File \"/home/ubuntu/.pyenv/versions/3.6.1/lib/python3.6/threading.py\", line 916, in _bootstrap_inner\n",
      "    self.run()\n",
      "  File \"<ipython-input-18-c76fc6bf8299>\", line 6, in run\n",
      "    pageURL('https://www.518.com.tw/job-index-P-'+str(self.number)+'.html?i=1&am=1&ab=2032001,2032002,')\n",
      "  File \"<ipython-input-17-696307882546>\", line 6, in pageURL\n",
      "    innerURL(str(link['href']))  #throw in innerURL function\n",
      "  File \"<ipython-input-16-1d4840fd97cd>\", line 3, in innerURL\n",
      "    inner = requests.get(url)  #用get連到網頁\n",
      "  File \"/home/ubuntu/.pyenv/versions/3.6.1/lib/python3.6/site-packages/requests/api.py\", line 70, in get\n",
      "    return request('get', url, params=params, **kwargs)\n",
      "  File \"/home/ubuntu/.pyenv/versions/3.6.1/lib/python3.6/site-packages/requests/api.py\", line 56, in request\n",
      "    return session.request(method=method, url=url, **kwargs)\n",
      "  File \"/home/ubuntu/.pyenv/versions/3.6.1/lib/python3.6/site-packages/requests/sessions.py\", line 488, in request\n",
      "    resp = self.send(prep, **send_kwargs)\n",
      "  File \"/home/ubuntu/.pyenv/versions/3.6.1/lib/python3.6/site-packages/requests/sessions.py\", line 609, in send\n",
      "    r = adapter.send(request, **kwargs)\n",
      "  File \"/home/ubuntu/.pyenv/versions/3.6.1/lib/python3.6/site-packages/requests/adapters.py\", line 487, in send\n",
      "    raise ConnectionError(e, request=request)\n",
      "requests.exceptions.ConnectionError: HTTPConnectionPool(host='case.518.com.tw', port=80): Max retries exceeded with url: /casepage-detail-123633.html?from=518&a_id=2183 (Caused by NewConnectionError('<requests.packages.urllib3.connection.HTTPConnection object at 0x7f244f0db0b8>: Failed to establish a new connection: [Errno -3] Temporary failure in name resolution',))\n",
      "\n",
      "Exception in thread Thread-31:\n",
      "Traceback (most recent call last):\n",
      "  File \"/home/ubuntu/.pyenv/versions/3.6.1/lib/python3.6/site-packages/requests/packages/urllib3/connection.py\", line 141, in _new_conn\n",
      "    (self.host, self.port), self.timeout, **extra_kw)\n",
      "  File \"/home/ubuntu/.pyenv/versions/3.6.1/lib/python3.6/site-packages/requests/packages/urllib3/util/connection.py\", line 60, in create_connection\n",
      "    for res in socket.getaddrinfo(host, port, family, socket.SOCK_STREAM):\n",
      "  File \"/home/ubuntu/.pyenv/versions/3.6.1/lib/python3.6/socket.py\", line 743, in getaddrinfo\n",
      "    for res in _socket.getaddrinfo(host, port, family, type, proto, flags):\n",
      "socket.gaierror: [Errno -3] Temporary failure in name resolution\n",
      "\n",
      "During handling of the above exception, another exception occurred:\n",
      "\n",
      "Traceback (most recent call last):\n",
      "  File \"/home/ubuntu/.pyenv/versions/3.6.1/lib/python3.6/site-packages/requests/packages/urllib3/connectionpool.py\", line 600, in urlopen\n",
      "    chunked=chunked)\n",
      "  File \"/home/ubuntu/.pyenv/versions/3.6.1/lib/python3.6/site-packages/requests/packages/urllib3/connectionpool.py\", line 356, in _make_request\n",
      "    conn.request(method, url, **httplib_request_kw)\n",
      "  File \"/home/ubuntu/.pyenv/versions/3.6.1/lib/python3.6/http/client.py\", line 1239, in request\n",
      "    self._send_request(method, url, body, headers, encode_chunked)\n",
      "  File \"/home/ubuntu/.pyenv/versions/3.6.1/lib/python3.6/http/client.py\", line 1285, in _send_request\n",
      "    self.endheaders(body, encode_chunked=encode_chunked)\n",
      "  File \"/home/ubuntu/.pyenv/versions/3.6.1/lib/python3.6/http/client.py\", line 1234, in endheaders\n",
      "    self._send_output(message_body, encode_chunked=encode_chunked)\n",
      "  File \"/home/ubuntu/.pyenv/versions/3.6.1/lib/python3.6/http/client.py\", line 1026, in _send_output\n",
      "    self.send(msg)\n",
      "  File \"/home/ubuntu/.pyenv/versions/3.6.1/lib/python3.6/http/client.py\", line 964, in send\n",
      "    self.connect()\n",
      "  File \"/home/ubuntu/.pyenv/versions/3.6.1/lib/python3.6/site-packages/requests/packages/urllib3/connection.py\", line 166, in connect\n",
      "    conn = self._new_conn()\n",
      "  File \"/home/ubuntu/.pyenv/versions/3.6.1/lib/python3.6/site-packages/requests/packages/urllib3/connection.py\", line 150, in _new_conn\n",
      "    self, \"Failed to establish a new connection: %s\" % e)\n",
      "requests.packages.urllib3.exceptions.NewConnectionError: <requests.packages.urllib3.connection.HTTPConnection object at 0x7f244f9a78d0>: Failed to establish a new connection: [Errno -3] Temporary failure in name resolution\n",
      "\n",
      "During handling of the above exception, another exception occurred:\n",
      "\n",
      "Traceback (most recent call last):\n",
      "  File \"/home/ubuntu/.pyenv/versions/3.6.1/lib/python3.6/site-packages/requests/adapters.py\", line 423, in send\n",
      "    timeout=timeout\n",
      "  File \"/home/ubuntu/.pyenv/versions/3.6.1/lib/python3.6/site-packages/requests/packages/urllib3/connectionpool.py\", line 649, in urlopen\n",
      "    _stacktrace=sys.exc_info()[2])\n",
      "  File \"/home/ubuntu/.pyenv/versions/3.6.1/lib/python3.6/site-packages/requests/packages/urllib3/util/retry.py\", line 376, in increment\n",
      "    raise MaxRetryError(_pool, url, error or ResponseError(cause))\n",
      "requests.packages.urllib3.exceptions.MaxRetryError: HTTPConnectionPool(host='case.518.com.tw', port=80): Max retries exceeded with url: /casepage-detail-123802.html?from=518&a_id=2183 (Caused by NewConnectionError('<requests.packages.urllib3.connection.HTTPConnection object at 0x7f244f9a78d0>: Failed to establish a new connection: [Errno -3] Temporary failure in name resolution',))\n",
      "\n",
      "During handling of the above exception, another exception occurred:\n",
      "\n",
      "Traceback (most recent call last):\n",
      "  File \"/home/ubuntu/.pyenv/versions/3.6.1/lib/python3.6/threading.py\", line 916, in _bootstrap_inner\n",
      "    self.run()\n",
      "  File \"<ipython-input-18-c76fc6bf8299>\", line 6, in run\n",
      "    pageURL('https://www.518.com.tw/job-index-P-'+str(self.number)+'.html?i=1&am=1&ab=2032001,2032002,')\n",
      "  File \"<ipython-input-17-696307882546>\", line 6, in pageURL\n",
      "    innerURL(str(link['href']))  #throw in innerURL function\n",
      "  File \"<ipython-input-16-1d4840fd97cd>\", line 3, in innerURL\n",
      "    inner = requests.get(url)  #用get連到網頁\n",
      "  File \"/home/ubuntu/.pyenv/versions/3.6.1/lib/python3.6/site-packages/requests/api.py\", line 70, in get\n",
      "    return request('get', url, params=params, **kwargs)\n",
      "  File \"/home/ubuntu/.pyenv/versions/3.6.1/lib/python3.6/site-packages/requests/api.py\", line 56, in request\n",
      "    return session.request(method=method, url=url, **kwargs)\n",
      "  File \"/home/ubuntu/.pyenv/versions/3.6.1/lib/python3.6/site-packages/requests/sessions.py\", line 488, in request\n",
      "    resp = self.send(prep, **send_kwargs)\n",
      "  File \"/home/ubuntu/.pyenv/versions/3.6.1/lib/python3.6/site-packages/requests/sessions.py\", line 609, in send\n",
      "    r = adapter.send(request, **kwargs)\n",
      "  File \"/home/ubuntu/.pyenv/versions/3.6.1/lib/python3.6/site-packages/requests/adapters.py\", line 487, in send\n",
      "    raise ConnectionError(e, request=request)\n",
      "requests.exceptions.ConnectionError: HTTPConnectionPool(host='case.518.com.tw', port=80): Max retries exceeded with url: /casepage-detail-123802.html?from=518&a_id=2183 (Caused by NewConnectionError('<requests.packages.urllib3.connection.HTTPConnection object at 0x7f244f9a78d0>: Failed to establish a new connection: [Errno -3] Temporary failure in name resolution',))\n",
      "\n",
      "Exception in thread Thread-42:\n",
      "Traceback (most recent call last):\n",
      "  File \"/home/ubuntu/.pyenv/versions/3.6.1/lib/python3.6/site-packages/requests/packages/urllib3/connection.py\", line 141, in _new_conn\n",
      "    (self.host, self.port), self.timeout, **extra_kw)\n",
      "  File \"/home/ubuntu/.pyenv/versions/3.6.1/lib/python3.6/site-packages/requests/packages/urllib3/util/connection.py\", line 60, in create_connection\n",
      "    for res in socket.getaddrinfo(host, port, family, socket.SOCK_STREAM):\n",
      "  File \"/home/ubuntu/.pyenv/versions/3.6.1/lib/python3.6/socket.py\", line 743, in getaddrinfo\n",
      "    for res in _socket.getaddrinfo(host, port, family, type, proto, flags):\n",
      "socket.gaierror: [Errno -3] Temporary failure in name resolution\n",
      "\n",
      "During handling of the above exception, another exception occurred:\n",
      "\n",
      "Traceback (most recent call last):\n",
      "  File \"/home/ubuntu/.pyenv/versions/3.6.1/lib/python3.6/site-packages/requests/packages/urllib3/connectionpool.py\", line 600, in urlopen\n",
      "    chunked=chunked)\n",
      "  File \"/home/ubuntu/.pyenv/versions/3.6.1/lib/python3.6/site-packages/requests/packages/urllib3/connectionpool.py\", line 356, in _make_request\n",
      "    conn.request(method, url, **httplib_request_kw)\n",
      "  File \"/home/ubuntu/.pyenv/versions/3.6.1/lib/python3.6/http/client.py\", line 1239, in request\n",
      "    self._send_request(method, url, body, headers, encode_chunked)\n",
      "  File \"/home/ubuntu/.pyenv/versions/3.6.1/lib/python3.6/http/client.py\", line 1285, in _send_request\n",
      "    self.endheaders(body, encode_chunked=encode_chunked)\n",
      "  File \"/home/ubuntu/.pyenv/versions/3.6.1/lib/python3.6/http/client.py\", line 1234, in endheaders\n",
      "    self._send_output(message_body, encode_chunked=encode_chunked)\n",
      "  File \"/home/ubuntu/.pyenv/versions/3.6.1/lib/python3.6/http/client.py\", line 1026, in _send_output\n",
      "    self.send(msg)\n",
      "  File \"/home/ubuntu/.pyenv/versions/3.6.1/lib/python3.6/http/client.py\", line 964, in send\n",
      "    self.connect()\n",
      "  File \"/home/ubuntu/.pyenv/versions/3.6.1/lib/python3.6/site-packages/requests/packages/urllib3/connection.py\", line 166, in connect\n",
      "    conn = self._new_conn()\n",
      "  File \"/home/ubuntu/.pyenv/versions/3.6.1/lib/python3.6/site-packages/requests/packages/urllib3/connection.py\", line 150, in _new_conn\n",
      "    self, \"Failed to establish a new connection: %s\" % e)\n",
      "requests.packages.urllib3.exceptions.NewConnectionError: <requests.packages.urllib3.connection.HTTPConnection object at 0x7f245a5fd860>: Failed to establish a new connection: [Errno -3] Temporary failure in name resolution\n",
      "\n",
      "During handling of the above exception, another exception occurred:\n",
      "\n",
      "Traceback (most recent call last):\n",
      "  File \"/home/ubuntu/.pyenv/versions/3.6.1/lib/python3.6/site-packages/requests/adapters.py\", line 423, in send\n",
      "    timeout=timeout\n",
      "  File \"/home/ubuntu/.pyenv/versions/3.6.1/lib/python3.6/site-packages/requests/packages/urllib3/connectionpool.py\", line 649, in urlopen\n",
      "    _stacktrace=sys.exc_info()[2])\n",
      "  File \"/home/ubuntu/.pyenv/versions/3.6.1/lib/python3.6/site-packages/requests/packages/urllib3/util/retry.py\", line 376, in increment\n",
      "    raise MaxRetryError(_pool, url, error or ResponseError(cause))\n",
      "requests.packages.urllib3.exceptions.MaxRetryError: HTTPConnectionPool(host='case.518.com.tw', port=80): Max retries exceeded with url: /casepage-detail-123176.html?from=518&a_id=2183 (Caused by NewConnectionError('<requests.packages.urllib3.connection.HTTPConnection object at 0x7f245a5fd860>: Failed to establish a new connection: [Errno -3] Temporary failure in name resolution',))\n",
      "\n",
      "During handling of the above exception, another exception occurred:\n",
      "\n",
      "Traceback (most recent call last):\n",
      "  File \"/home/ubuntu/.pyenv/versions/3.6.1/lib/python3.6/threading.py\", line 916, in _bootstrap_inner\n",
      "    self.run()\n",
      "  File \"<ipython-input-18-c76fc6bf8299>\", line 6, in run\n",
      "    pageURL('https://www.518.com.tw/job-index-P-'+str(self.number)+'.html?i=1&am=1&ab=2032001,2032002,')\n",
      "  File \"<ipython-input-17-696307882546>\", line 6, in pageURL\n",
      "    innerURL(str(link['href']))  #throw in innerURL function\n",
      "  File \"<ipython-input-16-1d4840fd97cd>\", line 3, in innerURL\n",
      "    inner = requests.get(url)  #用get連到網頁\n",
      "  File \"/home/ubuntu/.pyenv/versions/3.6.1/lib/python3.6/site-packages/requests/api.py\", line 70, in get\n",
      "    return request('get', url, params=params, **kwargs)\n",
      "  File \"/home/ubuntu/.pyenv/versions/3.6.1/lib/python3.6/site-packages/requests/api.py\", line 56, in request\n",
      "    return session.request(method=method, url=url, **kwargs)\n",
      "  File \"/home/ubuntu/.pyenv/versions/3.6.1/lib/python3.6/site-packages/requests/sessions.py\", line 488, in request\n",
      "    resp = self.send(prep, **send_kwargs)\n",
      "  File \"/home/ubuntu/.pyenv/versions/3.6.1/lib/python3.6/site-packages/requests/sessions.py\", line 609, in send\n",
      "    r = adapter.send(request, **kwargs)\n",
      "  File \"/home/ubuntu/.pyenv/versions/3.6.1/lib/python3.6/site-packages/requests/adapters.py\", line 487, in send\n",
      "    raise ConnectionError(e, request=request)\n",
      "requests.exceptions.ConnectionError: HTTPConnectionPool(host='case.518.com.tw', port=80): Max retries exceeded with url: /casepage-detail-123176.html?from=518&a_id=2183 (Caused by NewConnectionError('<requests.packages.urllib3.connection.HTTPConnection object at 0x7f245a5fd860>: Failed to establish a new connection: [Errno -3] Temporary failure in name resolution',))\n",
      "\n"
     ]
    },
    {
     "name": "stdout",
     "output_type": "stream",
     "text": [
      "[Debug] Page 45 is finished\n",
      "[Debug] Page 34 is finished\n",
      "[Debug] Page 23 is finished\n",
      "[Debug] Page 52 is finished\n",
      "[Debug] Page 7 is finished\n",
      "[Debug] Page 8 is finished\n",
      "[Debug] Page 41 is finished\n",
      "[Debug] Page 30 is finished\n",
      "[Debug] Page 35 is finished\n"
     ]
    },
    {
     "name": "stderr",
     "output_type": "stream",
     "text": [
      "Exception in thread Thread-7:\n",
      "Traceback (most recent call last):\n",
      "  File \"/home/ubuntu/.pyenv/versions/3.6.1/lib/python3.6/site-packages/requests/packages/urllib3/contrib/pyopenssl.py\", line 436, in wrap_socket\n",
      "    cnx.do_handshake()\n",
      "  File \"/home/ubuntu/.pyenv/versions/3.6.1/lib/python3.6/site-packages/OpenSSL/SSL.py\", line 1638, in do_handshake\n",
      "    self._raise_ssl_error(self._ssl, result)\n",
      "  File \"/home/ubuntu/.pyenv/versions/3.6.1/lib/python3.6/site-packages/OpenSSL/SSL.py\", line 1371, in _raise_ssl_error\n",
      "    raise SysCallError(-1, \"Unexpected EOF\")\n",
      "OpenSSL.SSL.SysCallError: (-1, 'Unexpected EOF')\n",
      "\n",
      "During handling of the above exception, another exception occurred:\n",
      "\n",
      "Traceback (most recent call last):\n",
      "  File \"/home/ubuntu/.pyenv/versions/3.6.1/lib/python3.6/site-packages/requests/packages/urllib3/connectionpool.py\", line 600, in urlopen\n",
      "    chunked=chunked)\n",
      "  File \"/home/ubuntu/.pyenv/versions/3.6.1/lib/python3.6/site-packages/requests/packages/urllib3/connectionpool.py\", line 345, in _make_request\n",
      "    self._validate_conn(conn)\n",
      "  File \"/home/ubuntu/.pyenv/versions/3.6.1/lib/python3.6/site-packages/requests/packages/urllib3/connectionpool.py\", line 844, in _validate_conn\n",
      "    conn.connect()\n",
      "  File \"/home/ubuntu/.pyenv/versions/3.6.1/lib/python3.6/site-packages/requests/packages/urllib3/connection.py\", line 326, in connect\n",
      "    ssl_context=context)\n",
      "  File \"/home/ubuntu/.pyenv/versions/3.6.1/lib/python3.6/site-packages/requests/packages/urllib3/util/ssl_.py\", line 324, in ssl_wrap_socket\n",
      "    return context.wrap_socket(sock, server_hostname=server_hostname)\n",
      "  File \"/home/ubuntu/.pyenv/versions/3.6.1/lib/python3.6/site-packages/requests/packages/urllib3/contrib/pyopenssl.py\", line 443, in wrap_socket\n",
      "    raise ssl.SSLError('bad handshake: %r' % e)\n",
      "ssl.SSLError: (\"bad handshake: SysCallError(-1, 'Unexpected EOF')\",)\n",
      "\n",
      "During handling of the above exception, another exception occurred:\n",
      "\n",
      "Traceback (most recent call last):\n",
      "  File \"/home/ubuntu/.pyenv/versions/3.6.1/lib/python3.6/site-packages/requests/adapters.py\", line 423, in send\n",
      "    timeout=timeout\n",
      "  File \"/home/ubuntu/.pyenv/versions/3.6.1/lib/python3.6/site-packages/requests/packages/urllib3/connectionpool.py\", line 630, in urlopen\n",
      "    raise SSLError(e)\n",
      "requests.packages.urllib3.exceptions.SSLError: (\"bad handshake: SysCallError(-1, 'Unexpected EOF')\",)\n",
      "\n",
      "During handling of the above exception, another exception occurred:\n",
      "\n",
      "Traceback (most recent call last):\n",
      "  File \"/home/ubuntu/.pyenv/versions/3.6.1/lib/python3.6/threading.py\", line 916, in _bootstrap_inner\n",
      "    self.run()\n",
      "  File \"<ipython-input-18-c76fc6bf8299>\", line 6, in run\n",
      "    pageURL('https://www.518.com.tw/job-index-P-'+str(self.number)+'.html?i=1&am=1&ab=2032001,2032002,')\n",
      "  File \"<ipython-input-17-696307882546>\", line 6, in pageURL\n",
      "    innerURL(str(link['href']))  #throw in innerURL function\n",
      "  File \"<ipython-input-16-1d4840fd97cd>\", line 3, in innerURL\n",
      "    inner = requests.get(url)  #用get連到網頁\n",
      "  File \"/home/ubuntu/.pyenv/versions/3.6.1/lib/python3.6/site-packages/requests/api.py\", line 70, in get\n",
      "    return request('get', url, params=params, **kwargs)\n",
      "  File \"/home/ubuntu/.pyenv/versions/3.6.1/lib/python3.6/site-packages/requests/api.py\", line 56, in request\n",
      "    return session.request(method=method, url=url, **kwargs)\n",
      "  File \"/home/ubuntu/.pyenv/versions/3.6.1/lib/python3.6/site-packages/requests/sessions.py\", line 488, in request\n",
      "    resp = self.send(prep, **send_kwargs)\n",
      "  File \"/home/ubuntu/.pyenv/versions/3.6.1/lib/python3.6/site-packages/requests/sessions.py\", line 630, in send\n",
      "    history = [resp for resp in gen] if allow_redirects else []\n",
      "  File \"/home/ubuntu/.pyenv/versions/3.6.1/lib/python3.6/site-packages/requests/sessions.py\", line 630, in <listcomp>\n",
      "    history = [resp for resp in gen] if allow_redirects else []\n",
      "  File \"/home/ubuntu/.pyenv/versions/3.6.1/lib/python3.6/site-packages/requests/sessions.py\", line 190, in resolve_redirects\n",
      "    **adapter_kwargs\n",
      "  File \"/home/ubuntu/.pyenv/versions/3.6.1/lib/python3.6/site-packages/requests/sessions.py\", line 609, in send\n",
      "    r = adapter.send(request, **kwargs)\n",
      "  File \"/home/ubuntu/.pyenv/versions/3.6.1/lib/python3.6/site-packages/requests/adapters.py\", line 497, in send\n",
      "    raise SSLError(e, request=request)\n",
      "requests.exceptions.SSLError: (\"bad handshake: SysCallError(-1, 'Unexpected EOF')\",)\n",
      "\n"
     ]
    },
    {
     "name": "stdout",
     "output_type": "stream",
     "text": [
      "[Debug] Page 40 is finished\n",
      "[Debug] Page 50 is finished\n",
      "[Debug] Page 2 is finished\n",
      "[Debug] Page 5 is finished\n",
      "[Debug] Page 20 is finished\n",
      "[Debug] Page 38 is finished\n",
      "[Debug] Page 10 is finished\n",
      "[Debug] Page 27 is finished\n"
     ]
    },
    {
     "name": "stderr",
     "output_type": "stream",
     "text": [
      "Exception in thread Thread-24:\n",
      "Traceback (most recent call last):\n",
      "  File \"/home/ubuntu/.pyenv/versions/3.6.1/lib/python3.6/site-packages/requests/packages/urllib3/connection.py\", line 141, in _new_conn\n",
      "    (self.host, self.port), self.timeout, **extra_kw)\n",
      "  File \"/home/ubuntu/.pyenv/versions/3.6.1/lib/python3.6/site-packages/requests/packages/urllib3/util/connection.py\", line 83, in create_connection\n",
      "    raise err\n",
      "  File \"/home/ubuntu/.pyenv/versions/3.6.1/lib/python3.6/site-packages/requests/packages/urllib3/util/connection.py\", line 73, in create_connection\n",
      "    sock.connect(sa)\n",
      "TimeoutError: [Errno 110] Connection timed out\n",
      "\n",
      "During handling of the above exception, another exception occurred:\n",
      "\n",
      "Traceback (most recent call last):\n",
      "  File \"/home/ubuntu/.pyenv/versions/3.6.1/lib/python3.6/site-packages/requests/packages/urllib3/connectionpool.py\", line 600, in urlopen\n",
      "    chunked=chunked)\n",
      "  File \"/home/ubuntu/.pyenv/versions/3.6.1/lib/python3.6/site-packages/requests/packages/urllib3/connectionpool.py\", line 356, in _make_request\n",
      "    conn.request(method, url, **httplib_request_kw)\n",
      "  File \"/home/ubuntu/.pyenv/versions/3.6.1/lib/python3.6/http/client.py\", line 1239, in request\n",
      "    self._send_request(method, url, body, headers, encode_chunked)\n",
      "  File \"/home/ubuntu/.pyenv/versions/3.6.1/lib/python3.6/http/client.py\", line 1285, in _send_request\n",
      "    self.endheaders(body, encode_chunked=encode_chunked)\n",
      "  File \"/home/ubuntu/.pyenv/versions/3.6.1/lib/python3.6/http/client.py\", line 1234, in endheaders\n",
      "    self._send_output(message_body, encode_chunked=encode_chunked)\n",
      "  File \"/home/ubuntu/.pyenv/versions/3.6.1/lib/python3.6/http/client.py\", line 1026, in _send_output\n",
      "    self.send(msg)\n",
      "  File \"/home/ubuntu/.pyenv/versions/3.6.1/lib/python3.6/http/client.py\", line 964, in send\n",
      "    self.connect()\n",
      "  File \"/home/ubuntu/.pyenv/versions/3.6.1/lib/python3.6/site-packages/requests/packages/urllib3/connection.py\", line 166, in connect\n",
      "    conn = self._new_conn()\n",
      "  File \"/home/ubuntu/.pyenv/versions/3.6.1/lib/python3.6/site-packages/requests/packages/urllib3/connection.py\", line 150, in _new_conn\n",
      "    self, \"Failed to establish a new connection: %s\" % e)\n",
      "requests.packages.urllib3.exceptions.NewConnectionError: <requests.packages.urllib3.connection.HTTPConnection object at 0x7f245a2d0da0>: Failed to establish a new connection: [Errno 110] Connection timed out\n",
      "\n",
      "During handling of the above exception, another exception occurred:\n",
      "\n",
      "Traceback (most recent call last):\n",
      "  File \"/home/ubuntu/.pyenv/versions/3.6.1/lib/python3.6/site-packages/requests/adapters.py\", line 423, in send\n",
      "    timeout=timeout\n",
      "  File \"/home/ubuntu/.pyenv/versions/3.6.1/lib/python3.6/site-packages/requests/packages/urllib3/connectionpool.py\", line 649, in urlopen\n",
      "    _stacktrace=sys.exc_info()[2])\n",
      "  File \"/home/ubuntu/.pyenv/versions/3.6.1/lib/python3.6/site-packages/requests/packages/urllib3/util/retry.py\", line 376, in increment\n",
      "    raise MaxRetryError(_pool, url, error or ResponseError(cause))\n",
      "requests.packages.urllib3.exceptions.MaxRetryError: HTTPConnectionPool(host='case.518.com.tw', port=80): Max retries exceeded with url: /casepage-detail-124165.html?from=518&a_id=2183 (Caused by NewConnectionError('<requests.packages.urllib3.connection.HTTPConnection object at 0x7f245a2d0da0>: Failed to establish a new connection: [Errno 110] Connection timed out',))\n",
      "\n",
      "During handling of the above exception, another exception occurred:\n",
      "\n",
      "Traceback (most recent call last):\n",
      "  File \"/home/ubuntu/.pyenv/versions/3.6.1/lib/python3.6/threading.py\", line 916, in _bootstrap_inner\n",
      "    self.run()\n",
      "  File \"<ipython-input-18-c76fc6bf8299>\", line 6, in run\n",
      "    pageURL('https://www.518.com.tw/job-index-P-'+str(self.number)+'.html?i=1&am=1&ab=2032001,2032002,')\n",
      "  File \"<ipython-input-17-696307882546>\", line 6, in pageURL\n",
      "    innerURL(str(link['href']))  #throw in innerURL function\n",
      "  File \"<ipython-input-16-1d4840fd97cd>\", line 3, in innerURL\n",
      "    inner = requests.get(url)  #用get連到網頁\n",
      "  File \"/home/ubuntu/.pyenv/versions/3.6.1/lib/python3.6/site-packages/requests/api.py\", line 70, in get\n",
      "    return request('get', url, params=params, **kwargs)\n",
      "  File \"/home/ubuntu/.pyenv/versions/3.6.1/lib/python3.6/site-packages/requests/api.py\", line 56, in request\n",
      "    return session.request(method=method, url=url, **kwargs)\n",
      "  File \"/home/ubuntu/.pyenv/versions/3.6.1/lib/python3.6/site-packages/requests/sessions.py\", line 488, in request\n",
      "    resp = self.send(prep, **send_kwargs)\n",
      "  File \"/home/ubuntu/.pyenv/versions/3.6.1/lib/python3.6/site-packages/requests/sessions.py\", line 609, in send\n",
      "    r = adapter.send(request, **kwargs)\n",
      "  File \"/home/ubuntu/.pyenv/versions/3.6.1/lib/python3.6/site-packages/requests/adapters.py\", line 487, in send\n",
      "    raise ConnectionError(e, request=request)\n",
      "requests.exceptions.ConnectionError: HTTPConnectionPool(host='case.518.com.tw', port=80): Max retries exceeded with url: /casepage-detail-124165.html?from=518&a_id=2183 (Caused by NewConnectionError('<requests.packages.urllib3.connection.HTTPConnection object at 0x7f245a2d0da0>: Failed to establish a new connection: [Errno 110] Connection timed out',))\n",
      "\n"
     ]
    },
    {
     "ename": "KeyboardInterrupt",
     "evalue": "",
     "output_type": "error",
     "traceback": [
      "\u001b[0;31m---------------------------------------------------------------------------\u001b[0m",
      "\u001b[0;31mKeyboardInterrupt\u001b[0m                         Traceback (most recent call last)",
      "\u001b[0;32m<ipython-input-19-ef6fdb1e4b56>\u001b[0m in \u001b[0;36m<module>\u001b[0;34m()\u001b[0m\n\u001b[1;32m      7\u001b[0m     \u001b[0mthread\u001b[0m\u001b[0;34m.\u001b[0m\u001b[0mstart\u001b[0m\u001b[0;34m(\u001b[0m\u001b[0;34m)\u001b[0m\u001b[0;34m\u001b[0m\u001b[0m\n\u001b[1;32m      8\u001b[0m \u001b[0;32mfor\u001b[0m \u001b[0mthread\u001b[0m \u001b[0;32min\u001b[0m \u001b[0mthreads\u001b[0m\u001b[0;34m:\u001b[0m\u001b[0;34m\u001b[0m\u001b[0m\n\u001b[0;32m----> 9\u001b[0;31m     \u001b[0mthread\u001b[0m\u001b[0;34m.\u001b[0m\u001b[0mjoin\u001b[0m\u001b[0;34m(\u001b[0m\u001b[0;34m)\u001b[0m\u001b[0;34m\u001b[0m\u001b[0m\n\u001b[0m",
      "\u001b[0;32m/home/ubuntu/.pyenv/versions/3.6.1/lib/python3.6/threading.py\u001b[0m in \u001b[0;36mjoin\u001b[0;34m(self, timeout)\u001b[0m\n\u001b[1;32m   1054\u001b[0m \u001b[0;34m\u001b[0m\u001b[0m\n\u001b[1;32m   1055\u001b[0m         \u001b[0;32mif\u001b[0m \u001b[0mtimeout\u001b[0m \u001b[0;32mis\u001b[0m \u001b[0;32mNone\u001b[0m\u001b[0;34m:\u001b[0m\u001b[0;34m\u001b[0m\u001b[0m\n\u001b[0;32m-> 1056\u001b[0;31m             \u001b[0mself\u001b[0m\u001b[0;34m.\u001b[0m\u001b[0m_wait_for_tstate_lock\u001b[0m\u001b[0;34m(\u001b[0m\u001b[0;34m)\u001b[0m\u001b[0;34m\u001b[0m\u001b[0m\n\u001b[0m\u001b[1;32m   1057\u001b[0m         \u001b[0;32melse\u001b[0m\u001b[0;34m:\u001b[0m\u001b[0;34m\u001b[0m\u001b[0m\n\u001b[1;32m   1058\u001b[0m             \u001b[0;31m# the behavior of a negative timeout isn't documented, but\u001b[0m\u001b[0;34m\u001b[0m\u001b[0;34m\u001b[0m\u001b[0m\n",
      "\u001b[0;32m/home/ubuntu/.pyenv/versions/3.6.1/lib/python3.6/threading.py\u001b[0m in \u001b[0;36m_wait_for_tstate_lock\u001b[0;34m(self, block, timeout)\u001b[0m\n\u001b[1;32m   1070\u001b[0m         \u001b[0;32mif\u001b[0m \u001b[0mlock\u001b[0m \u001b[0;32mis\u001b[0m \u001b[0;32mNone\u001b[0m\u001b[0;34m:\u001b[0m  \u001b[0;31m# already determined that the C code is done\u001b[0m\u001b[0;34m\u001b[0m\u001b[0m\n\u001b[1;32m   1071\u001b[0m             \u001b[0;32massert\u001b[0m \u001b[0mself\u001b[0m\u001b[0;34m.\u001b[0m\u001b[0m_is_stopped\u001b[0m\u001b[0;34m\u001b[0m\u001b[0m\n\u001b[0;32m-> 1072\u001b[0;31m         \u001b[0;32melif\u001b[0m \u001b[0mlock\u001b[0m\u001b[0;34m.\u001b[0m\u001b[0macquire\u001b[0m\u001b[0;34m(\u001b[0m\u001b[0mblock\u001b[0m\u001b[0;34m,\u001b[0m \u001b[0mtimeout\u001b[0m\u001b[0;34m)\u001b[0m\u001b[0;34m:\u001b[0m\u001b[0;34m\u001b[0m\u001b[0m\n\u001b[0m\u001b[1;32m   1073\u001b[0m             \u001b[0mlock\u001b[0m\u001b[0;34m.\u001b[0m\u001b[0mrelease\u001b[0m\u001b[0;34m(\u001b[0m\u001b[0;34m)\u001b[0m\u001b[0;34m\u001b[0m\u001b[0m\n\u001b[1;32m   1074\u001b[0m             \u001b[0mself\u001b[0m\u001b[0;34m.\u001b[0m\u001b[0m_stop\u001b[0m\u001b[0;34m(\u001b[0m\u001b[0;34m)\u001b[0m\u001b[0;34m\u001b[0m\u001b[0m\n",
      "\u001b[0;31mKeyboardInterrupt\u001b[0m: "
     ]
    }
   ],
   "source": [
    "threads=[]\n",
    "# wordCoun = Counter()\n",
    "for i in range(1,55,1): \n",
    "    Thread=MyThread(i)\n",
    "    threads.append(Thread)\n",
    "for thread in threads:\n",
    "    thread.start()\n",
    "for thread in threads:\n",
    "    thread.join()"
   ]
  },
  {
   "cell_type": "code",
   "execution_count": null,
   "metadata": {
    "collapsed": true,
    "scrolled": true
   },
   "outputs": [],
   "source": [
    "static\n",
    "#結果"
   ]
  },
  {
   "cell_type": "code",
   "execution_count": null,
   "metadata": {
    "collapsed": true,
    "scrolled": true
   },
   "outputs": [],
   "source": [
    "dict2=sorted(static.items(), key=lambda d:d[1], reverse = True)\n",
    "dict2[:10]"
   ]
  },
  {
   "cell_type": "code",
   "execution_count": null,
   "metadata": {
    "collapsed": true,
    "scrolled": true
   },
   "outputs": [],
   "source": [
    "dict2"
   ]
  },
  {
   "cell_type": "code",
   "execution_count": null,
   "metadata": {
    "collapsed": true
   },
   "outputs": [],
   "source": [
    "len(dict2)"
   ]
  },
  {
   "cell_type": "code",
   "execution_count": null,
   "metadata": {
    "collapsed": true,
    "scrolled": true
   },
   "outputs": [],
   "source": [
    "# with open('518.csv','w') as f:   #tuple  in  list\n",
    "#     for k,v in dict2:\n",
    "#         f.write( '{},{}\\n'.format(k,v)) "
   ]
  },
  {
   "cell_type": "code",
   "execution_count": null,
   "metadata": {
    "collapsed": true
   },
   "outputs": [],
   "source": []
  }
 ],
 "metadata": {
  "kernelspec": {
   "display_name": "Python 3",
   "language": "python",
   "name": "python3"
  },
  "language_info": {
   "codemirror_mode": {
    "name": "ipython",
    "version": 3
   },
   "file_extension": ".py",
   "mimetype": "text/x-python",
   "name": "python",
   "nbconvert_exporter": "python",
   "pygments_lexer": "ipython3",
   "version": "3.6.1"
  }
 },
 "nbformat": 4,
 "nbformat_minor": 2
}
