{
 "cells": [
  {
   "cell_type": "code",
   "execution_count": 1,
   "metadata": {
    "collapsed": true
   },
   "outputs": [],
   "source": [
    "def get_innerlinks(url, lock, i, link_path):  #找所有連結\n",
    "    #call global var\n",
    "    global HEADER\n",
    "    global alinks\n",
    "    global page_links\n",
    "    count = 5             # retry 5 times\n",
    "    \n",
    "    while count:\n",
    "        try:\n",
    "            res = requests.get(url, headers=HEADER)\n",
    "            soup = BeautifulSoup(res.text, 'lxml')\n",
    "            links = soup.select('div.jbInfo > div > h3 > a')\n",
    "            if res.status_code == 200 and len(links) != 0:\n",
    "                for link in links:  \n",
    "                    page_links.append('https:' + str(link['href'])) #href put in innerURL function           \n",
    "                print('Get {} links from page {}'.format(len(page_links), i))              \n",
    "                with lock:\n",
    "                    with open(link_path, 'a') as fw:\n",
    "                        alinks += page_links\n",
    "                        fw.write('\\n'.join(page_links))\n",
    "                        fw.write('\\n')\n",
    "                break\n",
    "            else:\n",
    "                print ('Cannot retrieve links from page {} Retry: {} '.format(i, 6 - count))\n",
    "                count -= 1\n",
    "                time.sleep(1)\n",
    "        except Exception as e:\n",
    "            print ('Cannot retrieve links from page {} Retry: {} Error: {}'.format(i, 6 - count, e))\n",
    "            count -= 1\n",
    "            time.sleep(1)\n",
    "            \n",
    "    if count == 0:\n",
    "        print('[Error] Page {:2} failed'.format(i))"
   ]
  },
  {
   "cell_type": "code",
   "execution_count": 2,
   "metadata": {
    "collapsed": true
   },
   "outputs": [],
   "source": [
    "def grab_content(url,lock,idx): #一個用來分析內頁的function\n",
    "    \n",
    "    global page_links\n",
    "    global HEADER\n",
    "    global wc\n",
    "\n",
    "    count = 5\n",
    "    while count:\n",
    "        try:\n",
    "            res2 = requests.get(url, headers=HEADER)\n",
    "            if res2.status_code == 200:\n",
    "                soup = BeautifulSoup(res2.text, 'lxml')\n",
    "                dds = soup.select('dl.dataList > dd')\n",
    "                text = ''\n",
    "                for dd in dds:\n",
    "                    for a in dd.find_all('a'):\n",
    "                        a.decompose()\n",
    "                    for img in dd.find_all('img'):\n",
    "                        img.decompose()\n",
    "                    text += dd.text\n",
    "                words = list(set(re.findall('object c|visual basic|[A-Za-z.+#]+', text, re.IGNORECASE)))\n",
    "                with lock:      \n",
    "                    for lan in words: \n",
    "                        if lan in wc:  \n",
    "                            wc[lan] += 1\n",
    "                        else:\n",
    "                            wc[lan] = 1\n",
    "                if idx % 200 == 0:\n",
    "                    print('{} have been completed'.format(idx))\n",
    "                break\n",
    "            else:\n",
    "                print ('Cannot retrieve contentfrom page {} Retry: {} '.format(idx, 6 - count))\n",
    "                count -= 1\n",
    "                time.sleep(0.5)\n",
    "        except Exception as e:\n",
    "            print ('Cannot retrieve contentfrom page {} Retry: {} Error; {} '.format(idx, 6 - count), e)\n",
    "            count -= 1\n",
    "            time.sleep(0.5)\n",
    "    if count == 0:\n",
    "        print('Retrieve contetn failed page {} '.format(idx))"
   ]
  },
  {
   "cell_type": "code",
   "execution_count": 3,
   "metadata": {
    "collapsed": true
   },
   "outputs": [],
   "source": [
    "import requests\n",
    "from bs4 import BeautifulSoup\n",
    "from collections import Counter\n",
    "import time\n",
    "import threading\n",
    "from concurrent.futures import ThreadPoolExecutor\n",
    "from concurrent.futures import as_completed\n",
    "import re"
   ]
  },
  {
   "cell_type": "code",
   "execution_count": null,
   "metadata": {
    "collapsed": true
   },
   "outputs": [
    {
     "name": "stdout",
     "output_type": "stream",
     "text": [
      "[Error] Page  4 failed\n",
      "Cannot retrieve links from page 5 Retry: 5 Error: name 'page_links' is not defined\n",
      "Get 100 links from page 16\n",
      "Get 200 links from page 27\n",
      "Get 300 links from page 28\n",
      "[Error] Page  5 failed\n",
      "Get 400 links from page 13\n",
      "Get 500 links from page 19\n",
      "Get 600 links from page 18\n",
      "Get 700 links from page 20\n",
      "Get 800 links from page 9\n",
      "Get 900 links from page 17\n",
      "Get 1000 links from page 21\n",
      "Get 1100 links from page 10\n",
      "Get 1200 links from page 11\n",
      "Get 1305 links from page 1\n",
      "Get 1405 links from page 22\n",
      "Get 1505 links from page 7\n",
      "Get 1605 links from page 23\n",
      "Get 1705 links from page 12\n",
      "Get 1805 links from page 14\n",
      "Get 1905 links from page 29\n",
      "Get 2005 links from page 24\n",
      "Get 2105 links from page 6\n",
      "Get 2205 links from page 25\n",
      "Get 2305 links from page 15\n",
      "Get 2405 links from page 26\n",
      "Get 2505 links from page 8\n",
      "Get 2605 links from page 30\n",
      "Get 2710 links from page 2\n",
      "Get 2815 links from page 1\n",
      "Get 2920 links from page 2\n",
      "Get 3020 links from page 3\n",
      "Get 3120 links from page 4\n",
      "Get 3220 links from page 5\n",
      "Get 3320 links from page 6\n",
      "Get 3420 links from page 7\n",
      "Get 3520 links from page 8\n",
      "Get 3620 links from page 9\n",
      "Get 3720 links from page 10\n",
      "Get 3820 links from page 11\n",
      "Get 3920 links from page 12\n",
      "Get 4020 links from page 13\n",
      "Get 4120 links from page 14\n",
      "Get 4220 links from page 15\n",
      "Get 4320 links from page 16\n",
      "Get 4420 links from page 17\n",
      "Get 4520 links from page 18\n",
      "Get 4620 links from page 19\n",
      "Get 4720 links from page 20\n",
      "Get 4820 links from page 21\n",
      "Get 4920 links from page 22\n",
      "Get 5020 links from page 23\n",
      "Get 5120 links from page 24\n",
      "Get 5220 links from page 25\n",
      "Get 5320 links from page 26\n",
      "Get 5420 links from page 27\n",
      "Get 5520 links from page 28\n",
      "Get 5620 links from page 29\n",
      "Get 5720 links from page 30\n",
      "Get 5820 links from page 32\n",
      "Get 5920 links from page 31\n",
      "Get 6020 links from page 33\n",
      "Get 6120 links from page 34\n",
      "Get 6220 links from page 36\n",
      "Get 6320 links from page 37\n",
      "Get 6420 links from page 38\n",
      "Get 6520 links from page 39\n",
      "Get 6620 links from page 40\n",
      "Get 6720 links from page 35\n",
      "Get 6820 links from page 41\n",
      "Get 6920 links from page 42\n",
      "Get 7020 links from page 43\n",
      "Get 7120 links from page 44\n",
      "Get 7220 links from page 45\n",
      "Get 7320 links from page 46\n",
      "Get 7420 links from page 47\n",
      "Get 7520 links from page 48\n",
      "Get 7620 links from page 49\n",
      "Get 7720 links from page 50\n",
      "Get 7820 links from page 51\n",
      "Get 7920 links from page 52\n",
      "Get 8020 links from page 53\n",
      "Get 8120 links from page 54\n",
      "Get 8220 links from page 55\n",
      "Get 8320 links from page 56\n",
      "Get 8420 links from page 57\n",
      "Get 8520 links from page 58\n",
      "Get 8620 links from page 60\n",
      "Get 8720 links from page 59\n",
      "Get 8820 links from page 61\n",
      "Get 8920 links from page 62\n",
      "Get 9020 links from page 63\n",
      "Get 9120 links from page 64\n",
      "Get 9220 links from page 65\n",
      "Get 9320 links from page 66\n",
      "[Debug] All threads are started\n",
      "Get 9420 links from page 67\n",
      "Get 9467 links from page 70\n",
      "Get 9567 links from page 68\n",
      "Get 9667 links from page 69\n",
      "0 have been completed\n"
     ]
    },
    {
     "name": "stderr",
     "output_type": "stream",
     "text": [
      "Exception in thread Thread-309:\n",
      "Traceback (most recent call last):\n",
      "  File \"/home/ubuntu/.pyenv/versions/3.6.1/lib/python3.6/site-packages/requests/packages/urllib3/connection.py\", line 141, in _new_conn\n",
      "    (self.host, self.port), self.timeout, **extra_kw)\n",
      "  File \"/home/ubuntu/.pyenv/versions/3.6.1/lib/python3.6/site-packages/requests/packages/urllib3/util/connection.py\", line 60, in create_connection\n",
      "    for res in socket.getaddrinfo(host, port, family, socket.SOCK_STREAM):\n",
      "  File \"/home/ubuntu/.pyenv/versions/3.6.1/lib/python3.6/socket.py\", line 743, in getaddrinfo\n",
      "    for res in _socket.getaddrinfo(host, port, family, type, proto, flags):\n",
      "socket.gaierror: [Errno -3] Temporary failure in name resolution\n",
      "\n",
      "During handling of the above exception, another exception occurred:\n",
      "\n",
      "Traceback (most recent call last):\n",
      "  File \"/home/ubuntu/.pyenv/versions/3.6.1/lib/python3.6/site-packages/requests/packages/urllib3/connectionpool.py\", line 600, in urlopen\n",
      "    chunked=chunked)\n",
      "  File \"/home/ubuntu/.pyenv/versions/3.6.1/lib/python3.6/site-packages/requests/packages/urllib3/connectionpool.py\", line 345, in _make_request\n",
      "    self._validate_conn(conn)\n",
      "  File \"/home/ubuntu/.pyenv/versions/3.6.1/lib/python3.6/site-packages/requests/packages/urllib3/connectionpool.py\", line 844, in _validate_conn\n",
      "    conn.connect()\n",
      "  File \"/home/ubuntu/.pyenv/versions/3.6.1/lib/python3.6/site-packages/requests/packages/urllib3/connection.py\", line 284, in connect\n",
      "    conn = self._new_conn()\n",
      "  File \"/home/ubuntu/.pyenv/versions/3.6.1/lib/python3.6/site-packages/requests/packages/urllib3/connection.py\", line 150, in _new_conn\n",
      "    self, \"Failed to establish a new connection: %s\" % e)\n",
      "requests.packages.urllib3.exceptions.NewConnectionError: <requests.packages.urllib3.connection.VerifiedHTTPSConnection object at 0x7f24c80d7278>: Failed to establish a new connection: [Errno -3] Temporary failure in name resolution\n",
      "\n",
      "During handling of the above exception, another exception occurred:\n",
      "\n",
      "Traceback (most recent call last):\n",
      "  File \"/home/ubuntu/.pyenv/versions/3.6.1/lib/python3.6/site-packages/requests/adapters.py\", line 423, in send\n",
      "    timeout=timeout\n",
      "  File \"/home/ubuntu/.pyenv/versions/3.6.1/lib/python3.6/site-packages/requests/packages/urllib3/connectionpool.py\", line 649, in urlopen\n",
      "    _stacktrace=sys.exc_info()[2])\n",
      "  File \"/home/ubuntu/.pyenv/versions/3.6.1/lib/python3.6/site-packages/requests/packages/urllib3/util/retry.py\", line 376, in increment\n",
      "    raise MaxRetryError(_pool, url, error or ResponseError(cause))\n",
      "requests.packages.urllib3.exceptions.MaxRetryError: HTTPSConnectionPool(host='www.1111.com.tw', port=443): Max retries exceeded with url: /job/79814254/ (Caused by NewConnectionError('<requests.packages.urllib3.connection.VerifiedHTTPSConnection object at 0x7f24c80d7278>: Failed to establish a new connection: [Errno -3] Temporary failure in name resolution',))\n",
      "\n",
      "During handling of the above exception, another exception occurred:\n",
      "\n",
      "Traceback (most recent call last):\n",
      "  File \"<ipython-input-2-564dd7be0a3d>\", line 10, in grab_content\n",
      "    res2 = requests.get(url, headers=HEADER)\n",
      "  File \"/home/ubuntu/.pyenv/versions/3.6.1/lib/python3.6/site-packages/requests/api.py\", line 70, in get\n",
      "    return request('get', url, params=params, **kwargs)\n",
      "  File \"/home/ubuntu/.pyenv/versions/3.6.1/lib/python3.6/site-packages/requests/api.py\", line 56, in request\n",
      "    return session.request(method=method, url=url, **kwargs)\n",
      "  File \"/home/ubuntu/.pyenv/versions/3.6.1/lib/python3.6/site-packages/requests/sessions.py\", line 488, in request\n",
      "    resp = self.send(prep, **send_kwargs)\n",
      "  File \"/home/ubuntu/.pyenv/versions/3.6.1/lib/python3.6/site-packages/requests/sessions.py\", line 609, in send\n",
      "    r = adapter.send(request, **kwargs)\n",
      "  File \"/home/ubuntu/.pyenv/versions/3.6.1/lib/python3.6/site-packages/requests/adapters.py\", line 487, in send\n",
      "    raise ConnectionError(e, request=request)\n",
      "requests.exceptions.ConnectionError: HTTPSConnectionPool(host='www.1111.com.tw', port=443): Max retries exceeded with url: /job/79814254/ (Caused by NewConnectionError('<requests.packages.urllib3.connection.VerifiedHTTPSConnection object at 0x7f24c80d7278>: Failed to establish a new connection: [Errno -3] Temporary failure in name resolution',))\n",
      "\n",
      "During handling of the above exception, another exception occurred:\n",
      "\n",
      "Traceback (most recent call last):\n",
      "  File \"/home/ubuntu/.pyenv/versions/3.6.1/lib/python3.6/threading.py\", line 916, in _bootstrap_inner\n",
      "    self.run()\n",
      "  File \"/home/ubuntu/.pyenv/versions/3.6.1/lib/python3.6/threading.py\", line 864, in run\n",
      "    self._target(*self._args, **self._kwargs)\n",
      "  File \"<ipython-input-2-564dd7be0a3d>\", line 36, in grab_content\n",
      "    print ('Cannot retrieve contentfrom page {} Retry: {} Error; {} '.format(idx, 6 - count), e)\n",
      "IndexError: tuple index out of range\n",
      "\n"
     ]
    },
    {
     "name": "stdout",
     "output_type": "stream",
     "text": [
      "400 have been completed\n"
     ]
    },
    {
     "name": "stderr",
     "output_type": "stream",
     "text": [
      "Exception in thread Thread-722:\n",
      "Traceback (most recent call last):\n",
      "  File \"/home/ubuntu/.pyenv/versions/3.6.1/lib/python3.6/site-packages/requests/packages/urllib3/connection.py\", line 141, in _new_conn\n",
      "    (self.host, self.port), self.timeout, **extra_kw)\n",
      "  File \"/home/ubuntu/.pyenv/versions/3.6.1/lib/python3.6/site-packages/requests/packages/urllib3/util/connection.py\", line 60, in create_connection\n",
      "    for res in socket.getaddrinfo(host, port, family, socket.SOCK_STREAM):\n",
      "  File \"/home/ubuntu/.pyenv/versions/3.6.1/lib/python3.6/socket.py\", line 743, in getaddrinfo\n",
      "    for res in _socket.getaddrinfo(host, port, family, type, proto, flags):\n",
      "socket.gaierror: [Errno -3] Temporary failure in name resolution\n",
      "\n",
      "During handling of the above exception, another exception occurred:\n",
      "\n",
      "Traceback (most recent call last):\n",
      "  File \"/home/ubuntu/.pyenv/versions/3.6.1/lib/python3.6/site-packages/requests/packages/urllib3/connectionpool.py\", line 600, in urlopen\n",
      "    chunked=chunked)\n",
      "  File \"/home/ubuntu/.pyenv/versions/3.6.1/lib/python3.6/site-packages/requests/packages/urllib3/connectionpool.py\", line 345, in _make_request\n",
      "    self._validate_conn(conn)\n",
      "  File \"/home/ubuntu/.pyenv/versions/3.6.1/lib/python3.6/site-packages/requests/packages/urllib3/connectionpool.py\", line 844, in _validate_conn\n",
      "    conn.connect()\n",
      "  File \"/home/ubuntu/.pyenv/versions/3.6.1/lib/python3.6/site-packages/requests/packages/urllib3/connection.py\", line 284, in connect\n",
      "    conn = self._new_conn()\n",
      "  File \"/home/ubuntu/.pyenv/versions/3.6.1/lib/python3.6/site-packages/requests/packages/urllib3/connection.py\", line 150, in _new_conn\n",
      "    self, \"Failed to establish a new connection: %s\" % e)\n",
      "requests.packages.urllib3.exceptions.NewConnectionError: <requests.packages.urllib3.connection.VerifiedHTTPSConnection object at 0x7f24c80d74a8>: Failed to establish a new connection: [Errno -3] Temporary failure in name resolution\n",
      "\n",
      "During handling of the above exception, another exception occurred:\n",
      "\n",
      "Traceback (most recent call last):\n",
      "  File \"/home/ubuntu/.pyenv/versions/3.6.1/lib/python3.6/site-packages/requests/adapters.py\", line 423, in send\n",
      "    timeout=timeout\n",
      "  File \"/home/ubuntu/.pyenv/versions/3.6.1/lib/python3.6/site-packages/requests/packages/urllib3/connectionpool.py\", line 649, in urlopen\n",
      "    _stacktrace=sys.exc_info()[2])\n",
      "  File \"/home/ubuntu/.pyenv/versions/3.6.1/lib/python3.6/site-packages/requests/packages/urllib3/util/retry.py\", line 376, in increment\n",
      "    raise MaxRetryError(_pool, url, error or ResponseError(cause))\n",
      "requests.packages.urllib3.exceptions.MaxRetryError: HTTPSConnectionPool(host='www.1111.com.tw', port=443): Max retries exceeded with url: /job/79041117/ (Caused by NewConnectionError('<requests.packages.urllib3.connection.VerifiedHTTPSConnection object at 0x7f24c80d74a8>: Failed to establish a new connection: [Errno -3] Temporary failure in name resolution',))\n",
      "\n",
      "During handling of the above exception, another exception occurred:\n",
      "\n",
      "Traceback (most recent call last):\n",
      "  File \"<ipython-input-2-564dd7be0a3d>\", line 10, in grab_content\n",
      "    res2 = requests.get(url, headers=HEADER)\n",
      "  File \"/home/ubuntu/.pyenv/versions/3.6.1/lib/python3.6/site-packages/requests/api.py\", line 70, in get\n",
      "    return request('get', url, params=params, **kwargs)\n",
      "  File \"/home/ubuntu/.pyenv/versions/3.6.1/lib/python3.6/site-packages/requests/api.py\", line 56, in request\n",
      "    return session.request(method=method, url=url, **kwargs)\n",
      "  File \"/home/ubuntu/.pyenv/versions/3.6.1/lib/python3.6/site-packages/requests/sessions.py\", line 488, in request\n",
      "    resp = self.send(prep, **send_kwargs)\n",
      "  File \"/home/ubuntu/.pyenv/versions/3.6.1/lib/python3.6/site-packages/requests/sessions.py\", line 609, in send\n",
      "    r = adapter.send(request, **kwargs)\n",
      "  File \"/home/ubuntu/.pyenv/versions/3.6.1/lib/python3.6/site-packages/requests/adapters.py\", line 487, in send\n",
      "    raise ConnectionError(e, request=request)\n",
      "requests.exceptions.ConnectionError: HTTPSConnectionPool(host='www.1111.com.tw', port=443): Max retries exceeded with url: /job/79041117/ (Caused by NewConnectionError('<requests.packages.urllib3.connection.VerifiedHTTPSConnection object at 0x7f24c80d74a8>: Failed to establish a new connection: [Errno -3] Temporary failure in name resolution',))\n",
      "\n",
      "During handling of the above exception, another exception occurred:\n",
      "\n",
      "Traceback (most recent call last):\n",
      "  File \"/home/ubuntu/.pyenv/versions/3.6.1/lib/python3.6/threading.py\", line 916, in _bootstrap_inner\n",
      "    self.run()\n",
      "  File \"/home/ubuntu/.pyenv/versions/3.6.1/lib/python3.6/threading.py\", line 864, in run\n",
      "    self._target(*self._args, **self._kwargs)\n",
      "  File \"<ipython-input-2-564dd7be0a3d>\", line 36, in grab_content\n",
      "    print ('Cannot retrieve contentfrom page {} Retry: {} Error; {} '.format(idx, 6 - count), e)\n",
      "IndexError: tuple index out of range\n",
      "\n",
      "Exception in thread Thread-746:\n",
      "Traceback (most recent call last):\n",
      "  File \"/home/ubuntu/.pyenv/versions/3.6.1/lib/python3.6/site-packages/requests/packages/urllib3/connection.py\", line 141, in _new_conn\n",
      "    (self.host, self.port), self.timeout, **extra_kw)\n",
      "  File \"/home/ubuntu/.pyenv/versions/3.6.1/lib/python3.6/site-packages/requests/packages/urllib3/util/connection.py\", line 60, in create_connection\n",
      "    for res in socket.getaddrinfo(host, port, family, socket.SOCK_STREAM):\n",
      "  File \"/home/ubuntu/.pyenv/versions/3.6.1/lib/python3.6/socket.py\", line 743, in getaddrinfo\n",
      "    for res in _socket.getaddrinfo(host, port, family, type, proto, flags):\n",
      "socket.gaierror: [Errno -3] Temporary failure in name resolution\n",
      "\n",
      "During handling of the above exception, another exception occurred:\n",
      "\n",
      "Traceback (most recent call last):\n",
      "  File \"/home/ubuntu/.pyenv/versions/3.6.1/lib/python3.6/site-packages/requests/packages/urllib3/connectionpool.py\", line 600, in urlopen\n",
      "    chunked=chunked)\n",
      "  File \"/home/ubuntu/.pyenv/versions/3.6.1/lib/python3.6/site-packages/requests/packages/urllib3/connectionpool.py\", line 345, in _make_request\n",
      "    self._validate_conn(conn)\n",
      "  File \"/home/ubuntu/.pyenv/versions/3.6.1/lib/python3.6/site-packages/requests/packages/urllib3/connectionpool.py\", line 844, in _validate_conn\n",
      "    conn.connect()\n",
      "  File \"/home/ubuntu/.pyenv/versions/3.6.1/lib/python3.6/site-packages/requests/packages/urllib3/connection.py\", line 284, in connect\n",
      "    conn = self._new_conn()\n",
      "  File \"/home/ubuntu/.pyenv/versions/3.6.1/lib/python3.6/site-packages/requests/packages/urllib3/connection.py\", line 150, in _new_conn\n",
      "    self, \"Failed to establish a new connection: %s\" % e)\n",
      "requests.packages.urllib3.exceptions.NewConnectionError: <requests.packages.urllib3.connection.VerifiedHTTPSConnection object at 0x7f24b8a27d30>: Failed to establish a new connection: [Errno -3] Temporary failure in name resolution\n",
      "\n",
      "During handling of the above exception, another exception occurred:\n",
      "\n",
      "Traceback (most recent call last):\n",
      "  File \"/home/ubuntu/.pyenv/versions/3.6.1/lib/python3.6/site-packages/requests/adapters.py\", line 423, in send\n",
      "    timeout=timeout\n",
      "  File \"/home/ubuntu/.pyenv/versions/3.6.1/lib/python3.6/site-packages/requests/packages/urllib3/connectionpool.py\", line 649, in urlopen\n",
      "    _stacktrace=sys.exc_info()[2])\n",
      "  File \"/home/ubuntu/.pyenv/versions/3.6.1/lib/python3.6/site-packages/requests/packages/urllib3/util/retry.py\", line 376, in increment\n",
      "    raise MaxRetryError(_pool, url, error or ResponseError(cause))\n",
      "requests.packages.urllib3.exceptions.MaxRetryError: HTTPSConnectionPool(host='www.1111.com.tw', port=443): Max retries exceeded with url: /job/78597309/ (Caused by NewConnectionError('<requests.packages.urllib3.connection.VerifiedHTTPSConnection object at 0x7f24b8a27d30>: Failed to establish a new connection: [Errno -3] Temporary failure in name resolution',))\n",
      "\n",
      "During handling of the above exception, another exception occurred:\n",
      "\n",
      "Traceback (most recent call last):\n",
      "  File \"<ipython-input-2-564dd7be0a3d>\", line 10, in grab_content\n",
      "    res2 = requests.get(url, headers=HEADER)\n",
      "  File \"/home/ubuntu/.pyenv/versions/3.6.1/lib/python3.6/site-packages/requests/api.py\", line 70, in get\n",
      "    return request('get', url, params=params, **kwargs)\n",
      "  File \"/home/ubuntu/.pyenv/versions/3.6.1/lib/python3.6/site-packages/requests/api.py\", line 56, in request\n",
      "    return session.request(method=method, url=url, **kwargs)\n",
      "  File \"/home/ubuntu/.pyenv/versions/3.6.1/lib/python3.6/site-packages/requests/sessions.py\", line 488, in request\n",
      "    resp = self.send(prep, **send_kwargs)\n",
      "  File \"/home/ubuntu/.pyenv/versions/3.6.1/lib/python3.6/site-packages/requests/sessions.py\", line 609, in send\n",
      "    r = adapter.send(request, **kwargs)\n",
      "  File \"/home/ubuntu/.pyenv/versions/3.6.1/lib/python3.6/site-packages/requests/adapters.py\", line 487, in send\n",
      "    raise ConnectionError(e, request=request)\n",
      "requests.exceptions.ConnectionError: HTTPSConnectionPool(host='www.1111.com.tw', port=443): Max retries exceeded with url: /job/78597309/ (Caused by NewConnectionError('<requests.packages.urllib3.connection.VerifiedHTTPSConnection object at 0x7f24b8a27d30>: Failed to establish a new connection: [Errno -3] Temporary failure in name resolution',))\n",
      "\n",
      "During handling of the above exception, another exception occurred:\n",
      "\n",
      "Traceback (most recent call last):\n",
      "  File \"/home/ubuntu/.pyenv/versions/3.6.1/lib/python3.6/threading.py\", line 916, in _bootstrap_inner\n",
      "    self.run()\n",
      "  File \"/home/ubuntu/.pyenv/versions/3.6.1/lib/python3.6/threading.py\", line 864, in run\n",
      "    self._target(*self._args, **self._kwargs)\n",
      "  File \"<ipython-input-2-564dd7be0a3d>\", line 36, in grab_content\n",
      "    print ('Cannot retrieve contentfrom page {} Retry: {} Error; {} '.format(idx, 6 - count), e)\n",
      "IndexError: tuple index out of range\n",
      "\n",
      "Exception in thread Thread-295:\n",
      "Traceback (most recent call last):\n",
      "  File \"/home/ubuntu/.pyenv/versions/3.6.1/lib/python3.6/site-packages/requests/packages/urllib3/connectionpool.py\", line 600, in urlopen\n",
      "    chunked=chunked)\n",
      "  File \"/home/ubuntu/.pyenv/versions/3.6.1/lib/python3.6/site-packages/requests/packages/urllib3/connectionpool.py\", line 386, in _make_request\n",
      "    six.raise_from(e, None)\n",
      "  File \"<string>\", line 2, in raise_from\n",
      "  File \"/home/ubuntu/.pyenv/versions/3.6.1/lib/python3.6/site-packages/requests/packages/urllib3/connectionpool.py\", line 382, in _make_request\n",
      "    httplib_response = conn.getresponse()\n",
      "  File \"/home/ubuntu/.pyenv/versions/3.6.1/lib/python3.6/http/client.py\", line 1331, in getresponse\n",
      "    response.begin()\n",
      "  File \"/home/ubuntu/.pyenv/versions/3.6.1/lib/python3.6/http/client.py\", line 297, in begin\n",
      "    version, status, reason = self._read_status()\n",
      "  File \"/home/ubuntu/.pyenv/versions/3.6.1/lib/python3.6/http/client.py\", line 266, in _read_status\n",
      "    raise RemoteDisconnected(\"Remote end closed connection without\"\n",
      "http.client.RemoteDisconnected: Remote end closed connection without response\n",
      "\n",
      "During handling of the above exception, another exception occurred:\n",
      "\n",
      "Traceback (most recent call last):\n",
      "  File \"/home/ubuntu/.pyenv/versions/3.6.1/lib/python3.6/site-packages/requests/adapters.py\", line 423, in send\n",
      "    timeout=timeout\n",
      "  File \"/home/ubuntu/.pyenv/versions/3.6.1/lib/python3.6/site-packages/requests/packages/urllib3/connectionpool.py\", line 649, in urlopen\n",
      "    _stacktrace=sys.exc_info()[2])\n",
      "  File \"/home/ubuntu/.pyenv/versions/3.6.1/lib/python3.6/site-packages/requests/packages/urllib3/util/retry.py\", line 347, in increment\n",
      "    raise six.reraise(type(error), error, _stacktrace)\n",
      "  File \"/home/ubuntu/.pyenv/versions/3.6.1/lib/python3.6/site-packages/requests/packages/urllib3/packages/six.py\", line 685, in reraise\n",
      "    raise value.with_traceback(tb)\n",
      "  File \"/home/ubuntu/.pyenv/versions/3.6.1/lib/python3.6/site-packages/requests/packages/urllib3/connectionpool.py\", line 600, in urlopen\n",
      "    chunked=chunked)\n",
      "  File \"/home/ubuntu/.pyenv/versions/3.6.1/lib/python3.6/site-packages/requests/packages/urllib3/connectionpool.py\", line 386, in _make_request\n",
      "    six.raise_from(e, None)\n",
      "  File \"<string>\", line 2, in raise_from\n",
      "  File \"/home/ubuntu/.pyenv/versions/3.6.1/lib/python3.6/site-packages/requests/packages/urllib3/connectionpool.py\", line 382, in _make_request\n",
      "    httplib_response = conn.getresponse()\n",
      "  File \"/home/ubuntu/.pyenv/versions/3.6.1/lib/python3.6/http/client.py\", line 1331, in getresponse\n",
      "    response.begin()\n",
      "  File \"/home/ubuntu/.pyenv/versions/3.6.1/lib/python3.6/http/client.py\", line 297, in begin\n",
      "    version, status, reason = self._read_status()\n",
      "  File \"/home/ubuntu/.pyenv/versions/3.6.1/lib/python3.6/http/client.py\", line 266, in _read_status\n",
      "    raise RemoteDisconnected(\"Remote end closed connection without\"\n",
      "requests.packages.urllib3.exceptions.ProtocolError: ('Connection aborted.', RemoteDisconnected('Remote end closed connection without response',))\n",
      "\n",
      "During handling of the above exception, another exception occurred:\n",
      "\n",
      "Traceback (most recent call last):\n",
      "  File \"<ipython-input-2-564dd7be0a3d>\", line 10, in grab_content\n",
      "    res2 = requests.get(url, headers=HEADER)\n",
      "  File \"/home/ubuntu/.pyenv/versions/3.6.1/lib/python3.6/site-packages/requests/api.py\", line 70, in get\n",
      "    return request('get', url, params=params, **kwargs)\n",
      "  File \"/home/ubuntu/.pyenv/versions/3.6.1/lib/python3.6/site-packages/requests/api.py\", line 56, in request\n",
      "    return session.request(method=method, url=url, **kwargs)\n",
      "  File \"/home/ubuntu/.pyenv/versions/3.6.1/lib/python3.6/site-packages/requests/sessions.py\", line 488, in request\n",
      "    resp = self.send(prep, **send_kwargs)\n",
      "  File \"/home/ubuntu/.pyenv/versions/3.6.1/lib/python3.6/site-packages/requests/sessions.py\", line 609, in send\n",
      "    r = adapter.send(request, **kwargs)\n",
      "  File \"/home/ubuntu/.pyenv/versions/3.6.1/lib/python3.6/site-packages/requests/adapters.py\", line 473, in send\n",
      "    raise ConnectionError(err, request=request)\n",
      "requests.exceptions.ConnectionError: ('Connection aborted.', RemoteDisconnected('Remote end closed connection without response',))\n",
      "\n",
      "During handling of the above exception, another exception occurred:\n",
      "\n",
      "Traceback (most recent call last):\n",
      "  File \"/home/ubuntu/.pyenv/versions/3.6.1/lib/python3.6/threading.py\", line 916, in _bootstrap_inner\n",
      "    self.run()\n",
      "  File \"/home/ubuntu/.pyenv/versions/3.6.1/lib/python3.6/threading.py\", line 864, in run\n",
      "    self._target(*self._args, **self._kwargs)\n",
      "  File \"<ipython-input-2-564dd7be0a3d>\", line 36, in grab_content\n",
      "    print ('Cannot retrieve contentfrom page {} Retry: {} Error; {} '.format(idx, 6 - count), e)\n",
      "IndexError: tuple index out of range\n",
      "\n",
      "Exception in thread Thread-875:\n",
      "Traceback (most recent call last):\n",
      "  File \"/home/ubuntu/.pyenv/versions/3.6.1/lib/python3.6/site-packages/requests/packages/urllib3/connection.py\", line 141, in _new_conn\n",
      "    (self.host, self.port), self.timeout, **extra_kw)\n",
      "  File \"/home/ubuntu/.pyenv/versions/3.6.1/lib/python3.6/site-packages/requests/packages/urllib3/util/connection.py\", line 60, in create_connection\n",
      "    for res in socket.getaddrinfo(host, port, family, socket.SOCK_STREAM):\n",
      "  File \"/home/ubuntu/.pyenv/versions/3.6.1/lib/python3.6/socket.py\", line 743, in getaddrinfo\n",
      "    for res in _socket.getaddrinfo(host, port, family, type, proto, flags):\n",
      "socket.gaierror: [Errno -3] Temporary failure in name resolution\n",
      "\n",
      "During handling of the above exception, another exception occurred:\n",
      "\n",
      "Traceback (most recent call last):\n",
      "  File \"/home/ubuntu/.pyenv/versions/3.6.1/lib/python3.6/site-packages/requests/packages/urllib3/connectionpool.py\", line 600, in urlopen\n",
      "    chunked=chunked)\n",
      "  File \"/home/ubuntu/.pyenv/versions/3.6.1/lib/python3.6/site-packages/requests/packages/urllib3/connectionpool.py\", line 345, in _make_request\n",
      "    self._validate_conn(conn)\n",
      "  File \"/home/ubuntu/.pyenv/versions/3.6.1/lib/python3.6/site-packages/requests/packages/urllib3/connectionpool.py\", line 844, in _validate_conn\n",
      "    conn.connect()\n",
      "  File \"/home/ubuntu/.pyenv/versions/3.6.1/lib/python3.6/site-packages/requests/packages/urllib3/connection.py\", line 284, in connect\n",
      "    conn = self._new_conn()\n",
      "  File \"/home/ubuntu/.pyenv/versions/3.6.1/lib/python3.6/site-packages/requests/packages/urllib3/connection.py\", line 150, in _new_conn\n",
      "    self, \"Failed to establish a new connection: %s\" % e)\n",
      "requests.packages.urllib3.exceptions.NewConnectionError: <requests.packages.urllib3.connection.VerifiedHTTPSConnection object at 0x7f24b8852cf8>: Failed to establish a new connection: [Errno -3] Temporary failure in name resolution\n",
      "\n",
      "During handling of the above exception, another exception occurred:\n",
      "\n",
      "Traceback (most recent call last):\n",
      "  File \"/home/ubuntu/.pyenv/versions/3.6.1/lib/python3.6/site-packages/requests/adapters.py\", line 423, in send\n",
      "    timeout=timeout\n",
      "  File \"/home/ubuntu/.pyenv/versions/3.6.1/lib/python3.6/site-packages/requests/packages/urllib3/connectionpool.py\", line 649, in urlopen\n",
      "    _stacktrace=sys.exc_info()[2])\n",
      "  File \"/home/ubuntu/.pyenv/versions/3.6.1/lib/python3.6/site-packages/requests/packages/urllib3/util/retry.py\", line 376, in increment\n",
      "    raise MaxRetryError(_pool, url, error or ResponseError(cause))\n",
      "requests.packages.urllib3.exceptions.MaxRetryError: HTTPSConnectionPool(host='www.1111.com.tw', port=443): Max retries exceeded with url: /job/79797346/ (Caused by NewConnectionError('<requests.packages.urllib3.connection.VerifiedHTTPSConnection object at 0x7f24b8852cf8>: Failed to establish a new connection: [Errno -3] Temporary failure in name resolution',))\n",
      "\n",
      "During handling of the above exception, another exception occurred:\n",
      "\n",
      "Traceback (most recent call last):\n",
      "  File \"<ipython-input-2-564dd7be0a3d>\", line 10, in grab_content\n",
      "    res2 = requests.get(url, headers=HEADER)\n",
      "  File \"/home/ubuntu/.pyenv/versions/3.6.1/lib/python3.6/site-packages/requests/api.py\", line 70, in get\n",
      "    return request('get', url, params=params, **kwargs)\n",
      "  File \"/home/ubuntu/.pyenv/versions/3.6.1/lib/python3.6/site-packages/requests/api.py\", line 56, in request\n",
      "    return session.request(method=method, url=url, **kwargs)\n",
      "  File \"/home/ubuntu/.pyenv/versions/3.6.1/lib/python3.6/site-packages/requests/sessions.py\", line 488, in request\n",
      "    resp = self.send(prep, **send_kwargs)\n",
      "  File \"/home/ubuntu/.pyenv/versions/3.6.1/lib/python3.6/site-packages/requests/sessions.py\", line 609, in send\n",
      "    r = adapter.send(request, **kwargs)\n",
      "  File \"/home/ubuntu/.pyenv/versions/3.6.1/lib/python3.6/site-packages/requests/adapters.py\", line 487, in send\n",
      "    raise ConnectionError(e, request=request)\n",
      "requests.exceptions.ConnectionError: HTTPSConnectionPool(host='www.1111.com.tw', port=443): Max retries exceeded with url: /job/79797346/ (Caused by NewConnectionError('<requests.packages.urllib3.connection.VerifiedHTTPSConnection object at 0x7f24b8852cf8>: Failed to establish a new connection: [Errno -3] Temporary failure in name resolution',))\n",
      "\n",
      "During handling of the above exception, another exception occurred:\n",
      "\n",
      "Traceback (most recent call last):\n",
      "  File \"/home/ubuntu/.pyenv/versions/3.6.1/lib/python3.6/threading.py\", line 916, in _bootstrap_inner\n",
      "    self.run()\n",
      "  File \"/home/ubuntu/.pyenv/versions/3.6.1/lib/python3.6/threading.py\", line 864, in run\n",
      "    self._target(*self._args, **self._kwargs)\n",
      "  File \"<ipython-input-2-564dd7be0a3d>\", line 36, in grab_content\n",
      "    print ('Cannot retrieve contentfrom page {} Retry: {} Error; {} '.format(idx, 6 - count), e)\n",
      "IndexError: tuple index out of range\n",
      "\n",
      "Exception in thread Thread-340:\n",
      "Traceback (most recent call last):\n",
      "  File \"/home/ubuntu/.pyenv/versions/3.6.1/lib/python3.6/site-packages/requests/packages/urllib3/connection.py\", line 141, in _new_conn\n",
      "    (self.host, self.port), self.timeout, **extra_kw)\n",
      "  File \"/home/ubuntu/.pyenv/versions/3.6.1/lib/python3.6/site-packages/requests/packages/urllib3/util/connection.py\", line 83, in create_connection\n",
      "    raise err\n",
      "  File \"/home/ubuntu/.pyenv/versions/3.6.1/lib/python3.6/site-packages/requests/packages/urllib3/util/connection.py\", line 73, in create_connection\n",
      "    sock.connect(sa)\n",
      "TimeoutError: [Errno 110] Connection timed out\n",
      "\n",
      "During handling of the above exception, another exception occurred:\n",
      "\n",
      "Traceback (most recent call last):\n",
      "  File \"/home/ubuntu/.pyenv/versions/3.6.1/lib/python3.6/site-packages/requests/packages/urllib3/connectionpool.py\", line 600, in urlopen\n",
      "    chunked=chunked)\n",
      "  File \"/home/ubuntu/.pyenv/versions/3.6.1/lib/python3.6/site-packages/requests/packages/urllib3/connectionpool.py\", line 345, in _make_request\n",
      "    self._validate_conn(conn)\n",
      "  File \"/home/ubuntu/.pyenv/versions/3.6.1/lib/python3.6/site-packages/requests/packages/urllib3/connectionpool.py\", line 844, in _validate_conn\n",
      "    conn.connect()\n",
      "  File \"/home/ubuntu/.pyenv/versions/3.6.1/lib/python3.6/site-packages/requests/packages/urllib3/connection.py\", line 284, in connect\n",
      "    conn = self._new_conn()\n",
      "  File \"/home/ubuntu/.pyenv/versions/3.6.1/lib/python3.6/site-packages/requests/packages/urllib3/connection.py\", line 150, in _new_conn\n",
      "    self, \"Failed to establish a new connection: %s\" % e)\n",
      "requests.packages.urllib3.exceptions.NewConnectionError: <requests.packages.urllib3.connection.VerifiedHTTPSConnection object at 0x7f24b3b739e8>: Failed to establish a new connection: [Errno 110] Connection timed out\n",
      "\n",
      "During handling of the above exception, another exception occurred:\n",
      "\n",
      "Traceback (most recent call last):\n",
      "  File \"/home/ubuntu/.pyenv/versions/3.6.1/lib/python3.6/site-packages/requests/adapters.py\", line 423, in send\n",
      "    timeout=timeout\n",
      "  File \"/home/ubuntu/.pyenv/versions/3.6.1/lib/python3.6/site-packages/requests/packages/urllib3/connectionpool.py\", line 649, in urlopen\n",
      "    _stacktrace=sys.exc_info()[2])\n",
      "  File \"/home/ubuntu/.pyenv/versions/3.6.1/lib/python3.6/site-packages/requests/packages/urllib3/util/retry.py\", line 376, in increment\n",
      "    raise MaxRetryError(_pool, url, error or ResponseError(cause))\n",
      "requests.packages.urllib3.exceptions.MaxRetryError: HTTPSConnectionPool(host='www.1111.com.tw', port=443): Max retries exceeded with url: /job/79808968/ (Caused by NewConnectionError('<requests.packages.urllib3.connection.VerifiedHTTPSConnection object at 0x7f24b3b739e8>: Failed to establish a new connection: [Errno 110] Connection timed out',))\n",
      "\n",
      "During handling of the above exception, another exception occurred:\n",
      "\n",
      "Traceback (most recent call last):\n",
      "  File \"<ipython-input-2-564dd7be0a3d>\", line 10, in grab_content\n",
      "    res2 = requests.get(url, headers=HEADER)\n",
      "  File \"/home/ubuntu/.pyenv/versions/3.6.1/lib/python3.6/site-packages/requests/api.py\", line 70, in get\n",
      "    return request('get', url, params=params, **kwargs)\n",
      "  File \"/home/ubuntu/.pyenv/versions/3.6.1/lib/python3.6/site-packages/requests/api.py\", line 56, in request\n",
      "    return session.request(method=method, url=url, **kwargs)\n",
      "  File \"/home/ubuntu/.pyenv/versions/3.6.1/lib/python3.6/site-packages/requests/sessions.py\", line 488, in request\n",
      "    resp = self.send(prep, **send_kwargs)\n",
      "  File \"/home/ubuntu/.pyenv/versions/3.6.1/lib/python3.6/site-packages/requests/sessions.py\", line 609, in send\n",
      "    r = adapter.send(request, **kwargs)\n",
      "  File \"/home/ubuntu/.pyenv/versions/3.6.1/lib/python3.6/site-packages/requests/adapters.py\", line 487, in send\n",
      "    raise ConnectionError(e, request=request)\n",
      "requests.exceptions.ConnectionError: HTTPSConnectionPool(host='www.1111.com.tw', port=443): Max retries exceeded with url: /job/79808968/ (Caused by NewConnectionError('<requests.packages.urllib3.connection.VerifiedHTTPSConnection object at 0x7f24b3b739e8>: Failed to establish a new connection: [Errno 110] Connection timed out',))\n",
      "\n",
      "During handling of the above exception, another exception occurred:\n",
      "\n",
      "Traceback (most recent call last):\n",
      "  File \"/home/ubuntu/.pyenv/versions/3.6.1/lib/python3.6/threading.py\", line 916, in _bootstrap_inner\n",
      "    self.run()\n",
      "  File \"/home/ubuntu/.pyenv/versions/3.6.1/lib/python3.6/threading.py\", line 864, in run\n",
      "    self._target(*self._args, **self._kwargs)\n",
      "  File \"<ipython-input-2-564dd7be0a3d>\", line 36, in grab_content\n",
      "    print ('Cannot retrieve contentfrom page {} Retry: {} Error; {} '.format(idx, 6 - count), e)\n",
      "IndexError: tuple index out of range\n",
      "\n",
      "Exception in thread Thread-387:\n",
      "Traceback (most recent call last):\n",
      "  File \"/home/ubuntu/.pyenv/versions/3.6.1/lib/python3.6/site-packages/requests/packages/urllib3/connectionpool.py\", line 600, in urlopen\n",
      "    chunked=chunked)\n",
      "  File \"/home/ubuntu/.pyenv/versions/3.6.1/lib/python3.6/site-packages/requests/packages/urllib3/connectionpool.py\", line 386, in _make_request\n",
      "    six.raise_from(e, None)\n",
      "  File \"<string>\", line 2, in raise_from\n",
      "  File \"/home/ubuntu/.pyenv/versions/3.6.1/lib/python3.6/site-packages/requests/packages/urllib3/connectionpool.py\", line 382, in _make_request\n",
      "    httplib_response = conn.getresponse()\n",
      "  File \"/home/ubuntu/.pyenv/versions/3.6.1/lib/python3.6/http/client.py\", line 1331, in getresponse\n",
      "    response.begin()\n",
      "  File \"/home/ubuntu/.pyenv/versions/3.6.1/lib/python3.6/http/client.py\", line 297, in begin\n",
      "    version, status, reason = self._read_status()\n",
      "  File \"/home/ubuntu/.pyenv/versions/3.6.1/lib/python3.6/http/client.py\", line 266, in _read_status\n",
      "    raise RemoteDisconnected(\"Remote end closed connection without\"\n",
      "http.client.RemoteDisconnected: Remote end closed connection without response\n",
      "\n",
      "During handling of the above exception, another exception occurred:\n",
      "\n",
      "Traceback (most recent call last):\n",
      "  File \"/home/ubuntu/.pyenv/versions/3.6.1/lib/python3.6/site-packages/requests/adapters.py\", line 423, in send\n",
      "    timeout=timeout\n",
      "  File \"/home/ubuntu/.pyenv/versions/3.6.1/lib/python3.6/site-packages/requests/packages/urllib3/connectionpool.py\", line 649, in urlopen\n",
      "    _stacktrace=sys.exc_info()[2])\n",
      "  File \"/home/ubuntu/.pyenv/versions/3.6.1/lib/python3.6/site-packages/requests/packages/urllib3/util/retry.py\", line 347, in increment\n",
      "    raise six.reraise(type(error), error, _stacktrace)\n",
      "  File \"/home/ubuntu/.pyenv/versions/3.6.1/lib/python3.6/site-packages/requests/packages/urllib3/packages/six.py\", line 685, in reraise\n",
      "    raise value.with_traceback(tb)\n",
      "  File \"/home/ubuntu/.pyenv/versions/3.6.1/lib/python3.6/site-packages/requests/packages/urllib3/connectionpool.py\", line 600, in urlopen\n",
      "    chunked=chunked)\n",
      "  File \"/home/ubuntu/.pyenv/versions/3.6.1/lib/python3.6/site-packages/requests/packages/urllib3/connectionpool.py\", line 386, in _make_request\n",
      "    six.raise_from(e, None)\n",
      "  File \"<string>\", line 2, in raise_from\n",
      "  File \"/home/ubuntu/.pyenv/versions/3.6.1/lib/python3.6/site-packages/requests/packages/urllib3/connectionpool.py\", line 382, in _make_request\n",
      "    httplib_response = conn.getresponse()\n",
      "  File \"/home/ubuntu/.pyenv/versions/3.6.1/lib/python3.6/http/client.py\", line 1331, in getresponse\n",
      "    response.begin()\n",
      "  File \"/home/ubuntu/.pyenv/versions/3.6.1/lib/python3.6/http/client.py\", line 297, in begin\n",
      "    version, status, reason = self._read_status()\n",
      "  File \"/home/ubuntu/.pyenv/versions/3.6.1/lib/python3.6/http/client.py\", line 266, in _read_status\n",
      "    raise RemoteDisconnected(\"Remote end closed connection without\"\n",
      "requests.packages.urllib3.exceptions.ProtocolError: ('Connection aborted.', RemoteDisconnected('Remote end closed connection without response',))\n",
      "\n",
      "During handling of the above exception, another exception occurred:\n",
      "\n",
      "Traceback (most recent call last):\n",
      "  File \"<ipython-input-2-564dd7be0a3d>\", line 10, in grab_content\n",
      "    res2 = requests.get(url, headers=HEADER)\n",
      "  File \"/home/ubuntu/.pyenv/versions/3.6.1/lib/python3.6/site-packages/requests/api.py\", line 70, in get\n",
      "    return request('get', url, params=params, **kwargs)\n",
      "  File \"/home/ubuntu/.pyenv/versions/3.6.1/lib/python3.6/site-packages/requests/api.py\", line 56, in request\n",
      "    return session.request(method=method, url=url, **kwargs)\n",
      "  File \"/home/ubuntu/.pyenv/versions/3.6.1/lib/python3.6/site-packages/requests/sessions.py\", line 488, in request\n",
      "    resp = self.send(prep, **send_kwargs)\n",
      "  File \"/home/ubuntu/.pyenv/versions/3.6.1/lib/python3.6/site-packages/requests/sessions.py\", line 609, in send\n",
      "    r = adapter.send(request, **kwargs)\n",
      "  File \"/home/ubuntu/.pyenv/versions/3.6.1/lib/python3.6/site-packages/requests/adapters.py\", line 473, in send\n",
      "    raise ConnectionError(err, request=request)\n",
      "requests.exceptions.ConnectionError: ('Connection aborted.', RemoteDisconnected('Remote end closed connection without response',))\n",
      "\n",
      "During handling of the above exception, another exception occurred:\n",
      "\n",
      "Traceback (most recent call last):\n",
      "  File \"/home/ubuntu/.pyenv/versions/3.6.1/lib/python3.6/threading.py\", line 916, in _bootstrap_inner\n",
      "    self.run()\n",
      "  File \"/home/ubuntu/.pyenv/versions/3.6.1/lib/python3.6/threading.py\", line 864, in run\n",
      "    self._target(*self._args, **self._kwargs)\n",
      "  File \"<ipython-input-2-564dd7be0a3d>\", line 36, in grab_content\n",
      "    print ('Cannot retrieve contentfrom page {} Retry: {} Error; {} '.format(idx, 6 - count), e)\n",
      "IndexError: tuple index out of range\n",
      "\n",
      "Exception in thread Thread-362:\n",
      "Traceback (most recent call last):\n",
      "  File \"/home/ubuntu/.pyenv/versions/3.6.1/lib/python3.6/site-packages/requests/packages/urllib3/connectionpool.py\", line 600, in urlopen\n",
      "    chunked=chunked)\n",
      "  File \"/home/ubuntu/.pyenv/versions/3.6.1/lib/python3.6/site-packages/requests/packages/urllib3/connectionpool.py\", line 386, in _make_request\n",
      "    six.raise_from(e, None)\n",
      "  File \"<string>\", line 2, in raise_from\n",
      "  File \"/home/ubuntu/.pyenv/versions/3.6.1/lib/python3.6/site-packages/requests/packages/urllib3/connectionpool.py\", line 382, in _make_request\n",
      "    httplib_response = conn.getresponse()\n",
      "  File \"/home/ubuntu/.pyenv/versions/3.6.1/lib/python3.6/http/client.py\", line 1331, in getresponse\n",
      "    response.begin()\n",
      "  File \"/home/ubuntu/.pyenv/versions/3.6.1/lib/python3.6/http/client.py\", line 297, in begin\n",
      "    version, status, reason = self._read_status()\n",
      "  File \"/home/ubuntu/.pyenv/versions/3.6.1/lib/python3.6/http/client.py\", line 266, in _read_status\n",
      "    raise RemoteDisconnected(\"Remote end closed connection without\"\n",
      "http.client.RemoteDisconnected: Remote end closed connection without response\n",
      "\n",
      "During handling of the above exception, another exception occurred:\n",
      "\n",
      "Traceback (most recent call last):\n",
      "  File \"/home/ubuntu/.pyenv/versions/3.6.1/lib/python3.6/site-packages/requests/adapters.py\", line 423, in send\n",
      "    timeout=timeout\n",
      "  File \"/home/ubuntu/.pyenv/versions/3.6.1/lib/python3.6/site-packages/requests/packages/urllib3/connectionpool.py\", line 649, in urlopen\n",
      "    _stacktrace=sys.exc_info()[2])\n",
      "  File \"/home/ubuntu/.pyenv/versions/3.6.1/lib/python3.6/site-packages/requests/packages/urllib3/util/retry.py\", line 347, in increment\n",
      "    raise six.reraise(type(error), error, _stacktrace)\n",
      "  File \"/home/ubuntu/.pyenv/versions/3.6.1/lib/python3.6/site-packages/requests/packages/urllib3/packages/six.py\", line 685, in reraise\n",
      "    raise value.with_traceback(tb)\n",
      "  File \"/home/ubuntu/.pyenv/versions/3.6.1/lib/python3.6/site-packages/requests/packages/urllib3/connectionpool.py\", line 600, in urlopen\n",
      "    chunked=chunked)\n",
      "  File \"/home/ubuntu/.pyenv/versions/3.6.1/lib/python3.6/site-packages/requests/packages/urllib3/connectionpool.py\", line 386, in _make_request\n",
      "    six.raise_from(e, None)\n",
      "  File \"<string>\", line 2, in raise_from\n",
      "  File \"/home/ubuntu/.pyenv/versions/3.6.1/lib/python3.6/site-packages/requests/packages/urllib3/connectionpool.py\", line 382, in _make_request\n",
      "    httplib_response = conn.getresponse()\n",
      "  File \"/home/ubuntu/.pyenv/versions/3.6.1/lib/python3.6/http/client.py\", line 1331, in getresponse\n",
      "    response.begin()\n",
      "  File \"/home/ubuntu/.pyenv/versions/3.6.1/lib/python3.6/http/client.py\", line 297, in begin\n",
      "    version, status, reason = self._read_status()\n",
      "  File \"/home/ubuntu/.pyenv/versions/3.6.1/lib/python3.6/http/client.py\", line 266, in _read_status\n",
      "    raise RemoteDisconnected(\"Remote end closed connection without\"\n",
      "requests.packages.urllib3.exceptions.ProtocolError: ('Connection aborted.', RemoteDisconnected('Remote end closed connection without response',))\n",
      "\n",
      "During handling of the above exception, another exception occurred:\n",
      "\n",
      "Traceback (most recent call last):\n",
      "  File \"<ipython-input-2-564dd7be0a3d>\", line 10, in grab_content\n",
      "    res2 = requests.get(url, headers=HEADER)\n",
      "  File \"/home/ubuntu/.pyenv/versions/3.6.1/lib/python3.6/site-packages/requests/api.py\", line 70, in get\n",
      "    return request('get', url, params=params, **kwargs)\n",
      "  File \"/home/ubuntu/.pyenv/versions/3.6.1/lib/python3.6/site-packages/requests/api.py\", line 56, in request\n",
      "    return session.request(method=method, url=url, **kwargs)\n",
      "  File \"/home/ubuntu/.pyenv/versions/3.6.1/lib/python3.6/site-packages/requests/sessions.py\", line 488, in request\n",
      "    resp = self.send(prep, **send_kwargs)\n",
      "  File \"/home/ubuntu/.pyenv/versions/3.6.1/lib/python3.6/site-packages/requests/sessions.py\", line 609, in send\n",
      "    r = adapter.send(request, **kwargs)\n",
      "  File \"/home/ubuntu/.pyenv/versions/3.6.1/lib/python3.6/site-packages/requests/adapters.py\", line 473, in send\n",
      "    raise ConnectionError(err, request=request)\n",
      "requests.exceptions.ConnectionError: ('Connection aborted.', RemoteDisconnected('Remote end closed connection without response',))\n",
      "\n",
      "During handling of the above exception, another exception occurred:\n",
      "\n",
      "Traceback (most recent call last):\n",
      "  File \"/home/ubuntu/.pyenv/versions/3.6.1/lib/python3.6/threading.py\", line 916, in _bootstrap_inner\n",
      "    self.run()\n",
      "  File \"/home/ubuntu/.pyenv/versions/3.6.1/lib/python3.6/threading.py\", line 864, in run\n",
      "    self._target(*self._args, **self._kwargs)\n",
      "  File \"<ipython-input-2-564dd7be0a3d>\", line 36, in grab_content\n",
      "    print ('Cannot retrieve contentfrom page {} Retry: {} Error; {} '.format(idx, 6 - count), e)\n",
      "IndexError: tuple index out of range\n",
      "Exception in thread Thread-333:\n",
      "Traceback (most recent call last):\n",
      "  File \"/home/ubuntu/.pyenv/versions/3.6.1/lib/python3.6/site-packages/requests/packages/urllib3/connectionpool.py\", line 600, in urlopen\n",
      "    chunked=chunked)\n",
      "  File \"/home/ubuntu/.pyenv/versions/3.6.1/lib/python3.6/site-packages/requests/packages/urllib3/connectionpool.py\", line 386, in _make_request\n",
      "    six.raise_from(e, None)\n",
      "  File \"<string>\", line 2, in raise_from\n",
      "  File \"/home/ubuntu/.pyenv/versions/3.6.1/lib/python3.6/site-packages/requests/packages/urllib3/connectionpool.py\", line 382, in _make_request\n",
      "    httplib_response = conn.getresponse()\n",
      "  File \"/home/ubuntu/.pyenv/versions/3.6.1/lib/python3.6/http/client.py\", line 1331, in getresponse\n",
      "    response.begin()\n",
      "  File \"/home/ubuntu/.pyenv/versions/3.6.1/lib/python3.6/http/client.py\", line 297, in begin\n",
      "    version, status, reason = self._read_status()\n",
      "  File \"/home/ubuntu/.pyenv/versions/3.6.1/lib/python3.6/http/client.py\", line 266, in _read_status\n",
      "    raise RemoteDisconnected(\"Remote end closed connection without\"\n",
      "http.client.RemoteDisconnected: Remote end closed connection without response\n",
      "\n",
      "During handling of the above exception, another exception occurred:\n",
      "\n",
      "Traceback (most recent call last):\n",
      "  File \"/home/ubuntu/.pyenv/versions/3.6.1/lib/python3.6/site-packages/requests/adapters.py\", line 423, in send\n",
      "    timeout=timeout\n",
      "  File \"/home/ubuntu/.pyenv/versions/3.6.1/lib/python3.6/site-packages/requests/packages/urllib3/connectionpool.py\", line 649, in urlopen\n",
      "    _stacktrace=sys.exc_info()[2])\n",
      "  File \"/home/ubuntu/.pyenv/versions/3.6.1/lib/python3.6/site-packages/requests/packages/urllib3/util/retry.py\", line 347, in increment\n",
      "    raise six.reraise(type(error), error, _stacktrace)\n",
      "  File \"/home/ubuntu/.pyenv/versions/3.6.1/lib/python3.6/site-packages/requests/packages/urllib3/packages/six.py\", line 685, in reraise\n",
      "    raise value.with_traceback(tb)\n",
      "  File \"/home/ubuntu/.pyenv/versions/3.6.1/lib/python3.6/site-packages/requests/packages/urllib3/connectionpool.py\", line 600, in urlopen\n",
      "    chunked=chunked)\n",
      "  File \"/home/ubuntu/.pyenv/versions/3.6.1/lib/python3.6/site-packages/requests/packages/urllib3/connectionpool.py\", line 386, in _make_request\n",
      "    six.raise_from(e, None)\n",
      "  File \"<string>\", line 2, in raise_from\n",
      "  File \"/home/ubuntu/.pyenv/versions/3.6.1/lib/python3.6/site-packages/requests/packages/urllib3/connectionpool.py\", line 382, in _make_request\n",
      "    httplib_response = conn.getresponse()\n",
      "  File \"/home/ubuntu/.pyenv/versions/3.6.1/lib/python3.6/http/client.py\", line 1331, in getresponse\n",
      "    response.begin()\n",
      "  File \"/home/ubuntu/.pyenv/versions/3.6.1/lib/python3.6/http/client.py\", line 297, in begin\n",
      "    version, status, reason = self._read_status()\n",
      "  File \"/home/ubuntu/.pyenv/versions/3.6.1/lib/python3.6/http/client.py\", line 266, in _read_status\n",
      "    raise RemoteDisconnected(\"Remote end closed connection without\"\n",
      "requests.packages.urllib3.exceptions.ProtocolError: ('Connection aborted.', RemoteDisconnected('Remote end closed connection without response',))\n",
      "\n",
      "During handling of the above exception, another exception occurred:\n",
      "\n",
      "Traceback (most recent call last):\n",
      "  File \"<ipython-input-2-564dd7be0a3d>\", line 10, in grab_content\n",
      "    res2 = requests.get(url, headers=HEADER)\n",
      "  File \"/home/ubuntu/.pyenv/versions/3.6.1/lib/python3.6/site-packages/requests/api.py\", line 70, in get\n",
      "    return request('get', url, params=params, **kwargs)\n",
      "  File \"/home/ubuntu/.pyenv/versions/3.6.1/lib/python3.6/site-packages/requests/api.py\", line 56, in request\n",
      "    return session.request(method=method, url=url, **kwargs)\n",
      "  File \"/home/ubuntu/.pyenv/versions/3.6.1/lib/python3.6/site-packages/requests/sessions.py\", line 488, in request\n",
      "    resp = self.send(prep, **send_kwargs)\n",
      "  File \"/home/ubuntu/.pyenv/versions/3.6.1/lib/python3.6/site-packages/requests/sessions.py\", line 609, in send\n",
      "    r = adapter.send(request, **kwargs)\n",
      "  File \"/home/ubuntu/.pyenv/versions/3.6.1/lib/python3.6/site-packages/requests/adapters.py\", line 473, in send\n",
      "    raise ConnectionError(err, request=request)\n",
      "requests.exceptions.ConnectionError: ('Connection aborted.', RemoteDisconnected('Remote end closed connection without response',))\n",
      "\n",
      "During handling of the above exception, another exception occurred:\n",
      "\n",
      "Traceback (most recent call last):\n",
      "  File \"/home/ubuntu/.pyenv/versions/3.6.1/lib/python3.6/threading.py\", line 916, in _bootstrap_inner\n",
      "    self.run()\n",
      "  File \"/home/ubuntu/.pyenv/versions/3.6.1/lib/python3.6/threading.py\", line 864, in run\n",
      "    self._target(*self._args, **self._kwargs)\n",
      "  File \"<ipython-input-2-564dd7be0a3d>\", line 36, in grab_content\n",
      "    print ('Cannot retrieve contentfrom page {} Retry: {} Error; {} '.format(idx, 6 - count), e)\n",
      "IndexError: tuple index out of range\n",
      "\n",
      "Exception in thread Thread-366:\n",
      "Traceback (most recent call last):\n",
      "  File \"/home/ubuntu/.pyenv/versions/3.6.1/lib/python3.6/site-packages/requests/packages/urllib3/contrib/pyopenssl.py\", line 436, in wrap_socket\n",
      "    cnx.do_handshake()\n",
      "  File \"/home/ubuntu/.pyenv/versions/3.6.1/lib/python3.6/site-packages/OpenSSL/SSL.py\", line 1638, in do_handshake\n",
      "    self._raise_ssl_error(self._ssl, result)\n",
      "  File \"/home/ubuntu/.pyenv/versions/3.6.1/lib/python3.6/site-packages/OpenSSL/SSL.py\", line 1371, in _raise_ssl_error\n",
      "    raise SysCallError(-1, \"Unexpected EOF\")\n",
      "OpenSSL.SSL.SysCallError: (-1, 'Unexpected EOF')\n",
      "\n",
      "During handling of the above exception, another exception occurred:\n",
      "\n",
      "Traceback (most recent call last):\n",
      "  File \"/home/ubuntu/.pyenv/versions/3.6.1/lib/python3.6/site-packages/requests/packages/urllib3/connectionpool.py\", line 600, in urlopen\n",
      "    chunked=chunked)\n",
      "  File \"/home/ubuntu/.pyenv/versions/3.6.1/lib/python3.6/site-packages/requests/packages/urllib3/connectionpool.py\", line 345, in _make_request\n",
      "    self._validate_conn(conn)\n",
      "  File \"/home/ubuntu/.pyenv/versions/3.6.1/lib/python3.6/site-packages/requests/packages/urllib3/connectionpool.py\", line 844, in _validate_conn\n",
      "    conn.connect()\n",
      "  File \"/home/ubuntu/.pyenv/versions/3.6.1/lib/python3.6/site-packages/requests/packages/urllib3/connection.py\", line 326, in connect\n",
      "    ssl_context=context)\n",
      "  File \"/home/ubuntu/.pyenv/versions/3.6.1/lib/python3.6/site-packages/requests/packages/urllib3/util/ssl_.py\", line 324, in ssl_wrap_socket\n",
      "    return context.wrap_socket(sock, server_hostname=server_hostname)\n",
      "  File \"/home/ubuntu/.pyenv/versions/3.6.1/lib/python3.6/site-packages/requests/packages/urllib3/contrib/pyopenssl.py\", line 443, in wrap_socket\n",
      "    raise ssl.SSLError('bad handshake: %r' % e)\n",
      "ssl.SSLError: (\"bad handshake: SysCallError(-1, 'Unexpected EOF')\",)\n",
      "\n",
      "During handling of the above exception, another exception occurred:\n",
      "\n",
      "Traceback (most recent call last):\n",
      "  File \"/home/ubuntu/.pyenv/versions/3.6.1/lib/python3.6/site-packages/requests/adapters.py\", line 423, in send\n",
      "    timeout=timeout\n",
      "  File \"/home/ubuntu/.pyenv/versions/3.6.1/lib/python3.6/site-packages/requests/packages/urllib3/connectionpool.py\", line 630, in urlopen\n",
      "    raise SSLError(e)\n",
      "requests.packages.urllib3.exceptions.SSLError: (\"bad handshake: SysCallError(-1, 'Unexpected EOF')\",)\n",
      "\n",
      "During handling of the above exception, another exception occurred:\n",
      "\n",
      "Traceback (most recent call last):\n",
      "  File \"<ipython-input-2-564dd7be0a3d>\", line 10, in grab_content\n",
      "    res2 = requests.get(url, headers=HEADER)\n",
      "  File \"/home/ubuntu/.pyenv/versions/3.6.1/lib/python3.6/site-packages/requests/api.py\", line 70, in get\n",
      "    return request('get', url, params=params, **kwargs)\n",
      "  File \"/home/ubuntu/.pyenv/versions/3.6.1/lib/python3.6/site-packages/requests/api.py\", line 56, in request\n",
      "    return session.request(method=method, url=url, **kwargs)\n",
      "  File \"/home/ubuntu/.pyenv/versions/3.6.1/lib/python3.6/site-packages/requests/sessions.py\", line 488, in request\n",
      "    resp = self.send(prep, **send_kwargs)\n",
      "  File \"/home/ubuntu/.pyenv/versions/3.6.1/lib/python3.6/site-packages/requests/sessions.py\", line 609, in send\n",
      "    r = adapter.send(request, **kwargs)\n",
      "  File \"/home/ubuntu/.pyenv/versions/3.6.1/lib/python3.6/site-packages/requests/adapters.py\", line 497, in send\n",
      "    raise SSLError(e, request=request)\n",
      "requests.exceptions.SSLError: (\"bad handshake: SysCallError(-1, 'Unexpected EOF')\",)\n",
      "\n",
      "During handling of the above exception, another exception occurred:\n",
      "\n",
      "Traceback (most recent call last):\n",
      "  File \"/home/ubuntu/.pyenv/versions/3.6.1/lib/python3.6/threading.py\", line 916, in _bootstrap_inner\n",
      "    self.run()\n",
      "  File \"/home/ubuntu/.pyenv/versions/3.6.1/lib/python3.6/threading.py\", line 864, in run\n",
      "    self._target(*self._args, **self._kwargs)\n",
      "  File \"<ipython-input-2-564dd7be0a3d>\", line 36, in grab_content\n",
      "    print ('Cannot retrieve contentfrom page {} Retry: {} Error; {} '.format(idx, 6 - count), e)\n",
      "IndexError: tuple index out of range\n",
      "\n",
      "\n",
      "Exception in thread Thread-354:\n",
      "Traceback (most recent call last):\n",
      "  File \"/home/ubuntu/.pyenv/versions/3.6.1/lib/python3.6/site-packages/requests/packages/urllib3/connection.py\", line 141, in _new_conn\n",
      "    (self.host, self.port), self.timeout, **extra_kw)\n",
      "  File \"/home/ubuntu/.pyenv/versions/3.6.1/lib/python3.6/site-packages/requests/packages/urllib3/util/connection.py\", line 83, in create_connection\n",
      "    raise err\n",
      "  File \"/home/ubuntu/.pyenv/versions/3.6.1/lib/python3.6/site-packages/requests/packages/urllib3/util/connection.py\", line 73, in create_connection\n",
      "    sock.connect(sa)\n",
      "TimeoutError: [Errno 110] Connection timed out\n",
      "\n",
      "During handling of the above exception, another exception occurred:\n",
      "\n",
      "Traceback (most recent call last):\n",
      "  File \"/home/ubuntu/.pyenv/versions/3.6.1/lib/python3.6/site-packages/requests/packages/urllib3/connectionpool.py\", line 600, in urlopen\n",
      "    chunked=chunked)\n",
      "  File \"/home/ubuntu/.pyenv/versions/3.6.1/lib/python3.6/site-packages/requests/packages/urllib3/connectionpool.py\", line 345, in _make_request\n",
      "    self._validate_conn(conn)\n",
      "  File \"/home/ubuntu/.pyenv/versions/3.6.1/lib/python3.6/site-packages/requests/packages/urllib3/connectionpool.py\", line 844, in _validate_conn\n",
      "    conn.connect()\n",
      "  File \"/home/ubuntu/.pyenv/versions/3.6.1/lib/python3.6/site-packages/requests/packages/urllib3/connection.py\", line 284, in connect\n",
      "    conn = self._new_conn()\n",
      "  File \"/home/ubuntu/.pyenv/versions/3.6.1/lib/python3.6/site-packages/requests/packages/urllib3/connection.py\", line 150, in _new_conn\n",
      "    self, \"Failed to establish a new connection: %s\" % e)\n",
      "requests.packages.urllib3.exceptions.NewConnectionError: <requests.packages.urllib3.connection.VerifiedHTTPSConnection object at 0x7f24b2c6c4e0>: Failed to establish a new connection: [Errno 110] Connection timed out\n",
      "\n",
      "During handling of the above exception, another exception occurred:\n",
      "\n",
      "Traceback (most recent call last):\n",
      "  File \"/home/ubuntu/.pyenv/versions/3.6.1/lib/python3.6/site-packages/requests/adapters.py\", line 423, in send\n",
      "    timeout=timeout\n",
      "  File \"/home/ubuntu/.pyenv/versions/3.6.1/lib/python3.6/site-packages/requests/packages/urllib3/connectionpool.py\", line 649, in urlopen\n",
      "    _stacktrace=sys.exc_info()[2])\n",
      "  File \"/home/ubuntu/.pyenv/versions/3.6.1/lib/python3.6/site-packages/requests/packages/urllib3/util/retry.py\", line 376, in increment\n",
      "    raise MaxRetryError(_pool, url, error or ResponseError(cause))\n",
      "requests.packages.urllib3.exceptions.MaxRetryError: HTTPSConnectionPool(host='www.1111.com.tw', port=443): Max retries exceeded with url: /job/79803248/ (Caused by NewConnectionError('<requests.packages.urllib3.connection.VerifiedHTTPSConnection object at 0x7f24b2c6c4e0>: Failed to establish a new connection: [Errno 110] Connection timed out',))\n",
      "\n",
      "During handling of the above exception, another exception occurred:\n",
      "\n",
      "Traceback (most recent call last):\n",
      "  File \"<ipython-input-2-564dd7be0a3d>\", line 10, in grab_content\n",
      "    res2 = requests.get(url, headers=HEADER)\n",
      "  File \"/home/ubuntu/.pyenv/versions/3.6.1/lib/python3.6/site-packages/requests/api.py\", line 70, in get\n",
      "    return request('get', url, params=params, **kwargs)\n",
      "  File \"/home/ubuntu/.pyenv/versions/3.6.1/lib/python3.6/site-packages/requests/api.py\", line 56, in request\n",
      "    return session.request(method=method, url=url, **kwargs)\n",
      "  File \"/home/ubuntu/.pyenv/versions/3.6.1/lib/python3.6/site-packages/requests/sessions.py\", line 488, in request\n",
      "    resp = self.send(prep, **send_kwargs)\n",
      "  File \"/home/ubuntu/.pyenv/versions/3.6.1/lib/python3.6/site-packages/requests/sessions.py\", line 609, in send\n",
      "    r = adapter.send(request, **kwargs)\n",
      "  File \"/home/ubuntu/.pyenv/versions/3.6.1/lib/python3.6/site-packages/requests/adapters.py\", line 487, in send\n",
      "    raise ConnectionError(e, request=request)\n",
      "requests.exceptions.ConnectionError: HTTPSConnectionPool(host='www.1111.com.tw', port=443): Max retries exceeded with url: /job/79803248/ (Caused by NewConnectionError('<requests.packages.urllib3.connection.VerifiedHTTPSConnection object at 0x7f24b2c6c4e0>: Failed to establish a new connection: [Errno 110] Connection timed out',))\n",
      "\n",
      "During handling of the above exception, another exception occurred:\n",
      "\n",
      "Traceback (most recent call last):\n",
      "  File \"/home/ubuntu/.pyenv/versions/3.6.1/lib/python3.6/threading.py\", line 916, in _bootstrap_inner\n",
      "    self.run()\n",
      "  File \"/home/ubuntu/.pyenv/versions/3.6.1/lib/python3.6/threading.py\", line 864, in run\n",
      "    self._target(*self._args, **self._kwargs)\n",
      "  File \"<ipython-input-2-564dd7be0a3d>\", line 36, in grab_content\n",
      "    print ('Cannot retrieve contentfrom page {} Retry: {} Error; {} '.format(idx, 6 - count), e)\n",
      "IndexError: tuple index out of range\n",
      "Exception in thread Thread-379:\n",
      "Traceback (most recent call last):\n",
      "  File \"/home/ubuntu/.pyenv/versions/3.6.1/lib/python3.6/site-packages/requests/packages/urllib3/connection.py\", line 141, in _new_conn\n",
      "    (self.host, self.port), self.timeout, **extra_kw)\n",
      "  File \"/home/ubuntu/.pyenv/versions/3.6.1/lib/python3.6/site-packages/requests/packages/urllib3/util/connection.py\", line 83, in create_connection\n",
      "    raise err\n",
      "  File \"/home/ubuntu/.pyenv/versions/3.6.1/lib/python3.6/site-packages/requests/packages/urllib3/util/connection.py\", line 73, in create_connection\n",
      "    sock.connect(sa)\n",
      "TimeoutError: [Errno 110] Connection timed out\n",
      "\n",
      "During handling of the above exception, another exception occurred:\n",
      "\n",
      "Traceback (most recent call last):\n",
      "  File \"/home/ubuntu/.pyenv/versions/3.6.1/lib/python3.6/site-packages/requests/packages/urllib3/connectionpool.py\", line 600, in urlopen\n",
      "    chunked=chunked)\n",
      "  File \"/home/ubuntu/.pyenv/versions/3.6.1/lib/python3.6/site-packages/requests/packages/urllib3/connectionpool.py\", line 345, in _make_request\n",
      "    self._validate_conn(conn)\n",
      "  File \"/home/ubuntu/.pyenv/versions/3.6.1/lib/python3.6/site-packages/requests/packages/urllib3/connectionpool.py\", line 844, in _validate_conn\n",
      "    conn.connect()\n",
      "  File \"/home/ubuntu/.pyenv/versions/3.6.1/lib/python3.6/site-packages/requests/packages/urllib3/connection.py\", line 284, in connect\n",
      "    conn = self._new_conn()\n",
      "  File \"/home/ubuntu/.pyenv/versions/3.6.1/lib/python3.6/site-packages/requests/packages/urllib3/connection.py\", line 150, in _new_conn\n",
      "    self, \"Failed to establish a new connection: %s\" % e)\n",
      "requests.packages.urllib3.exceptions.NewConnectionError: <requests.packages.urllib3.connection.VerifiedHTTPSConnection object at 0x7f24badce048>: Failed to establish a new connection: [Errno 110] Connection timed out\n",
      "\n",
      "During handling of the above exception, another exception occurred:\n",
      "\n",
      "Traceback (most recent call last):\n",
      "  File \"/home/ubuntu/.pyenv/versions/3.6.1/lib/python3.6/site-packages/requests/adapters.py\", line 423, in send\n",
      "    timeout=timeout\n",
      "  File \"/home/ubuntu/.pyenv/versions/3.6.1/lib/python3.6/site-packages/requests/packages/urllib3/connectionpool.py\", line 649, in urlopen\n",
      "    _stacktrace=sys.exc_info()[2])\n",
      "  File \"/home/ubuntu/.pyenv/versions/3.6.1/lib/python3.6/site-packages/requests/packages/urllib3/util/retry.py\", line 376, in increment\n",
      "    raise MaxRetryError(_pool, url, error or ResponseError(cause))\n",
      "requests.packages.urllib3.exceptions.MaxRetryError: HTTPSConnectionPool(host='www.1111.com.tw', port=443): Max retries exceeded with url: /job/79796999/ (Caused by NewConnectionError('<requests.packages.urllib3.connection.VerifiedHTTPSConnection object at 0x7f24badce048>: Failed to establish a new connection: [Errno 110] Connection timed out',))\n",
      "\n",
      "During handling of the above exception, another exception occurred:\n",
      "\n",
      "Traceback (most recent call last):\n",
      "  File \"<ipython-input-2-564dd7be0a3d>\", line 10, in grab_content\n",
      "    res2 = requests.get(url, headers=HEADER)\n",
      "  File \"/home/ubuntu/.pyenv/versions/3.6.1/lib/python3.6/site-packages/requests/api.py\", line 70, in get\n",
      "    return request('get', url, params=params, **kwargs)\n",
      "  File \"/home/ubuntu/.pyenv/versions/3.6.1/lib/python3.6/site-packages/requests/api.py\", line 56, in request\n",
      "    return session.request(method=method, url=url, **kwargs)\n",
      "  File \"/home/ubuntu/.pyenv/versions/3.6.1/lib/python3.6/site-packages/requests/sessions.py\", line 488, in request\n",
      "    resp = self.send(prep, **send_kwargs)\n",
      "  File \"/home/ubuntu/.pyenv/versions/3.6.1/lib/python3.6/site-packages/requests/sessions.py\", line 609, in send\n",
      "    r = adapter.send(request, **kwargs)\n",
      "  File \"/home/ubuntu/.pyenv/versions/3.6.1/lib/python3.6/site-packages/requests/adapters.py\", line 487, in send\n",
      "    raise ConnectionError(e, request=request)\n",
      "requests.exceptions.ConnectionError: HTTPSConnectionPool(host='www.1111.com.tw', port=443): Max retries exceeded with url: /job/79796999/ (Caused by NewConnectionError('<requests.packages.urllib3.connection.VerifiedHTTPSConnection object at 0x7f24badce048>: Failed to establish a new connection: [Errno 110] Connection timed out',))\n",
      "\n",
      "During handling of the above exception, another exception occurred:\n",
      "\n",
      "Traceback (most recent call last):\n",
      "  File \"/home/ubuntu/.pyenv/versions/3.6.1/lib/python3.6/threading.py\", line 916, in _bootstrap_inner\n",
      "    self.run()\n",
      "  File \"/home/ubuntu/.pyenv/versions/3.6.1/lib/python3.6/threading.py\", line 864, in run\n",
      "    self._target(*self._args, **self._kwargs)\n",
      "  File \"<ipython-input-2-564dd7be0a3d>\", line 36, in grab_content\n",
      "    print ('Cannot retrieve contentfrom page {} Retry: {} Error; {} '.format(idx, 6 - count), e)\n",
      "IndexError: tuple index out of range\n",
      "\n",
      "\n",
      "Exception in thread Thread-395:\n",
      "Traceback (most recent call last):\n",
      "  File \"/home/ubuntu/.pyenv/versions/3.6.1/lib/python3.6/site-packages/requests/packages/urllib3/connection.py\", line 141, in _new_conn\n",
      "    (self.host, self.port), self.timeout, **extra_kw)\n",
      "  File \"/home/ubuntu/.pyenv/versions/3.6.1/lib/python3.6/site-packages/requests/packages/urllib3/util/connection.py\", line 83, in create_connection\n",
      "    raise err\n",
      "  File \"/home/ubuntu/.pyenv/versions/3.6.1/lib/python3.6/site-packages/requests/packages/urllib3/util/connection.py\", line 73, in create_connection\n",
      "    sock.connect(sa)\n",
      "TimeoutError: [Errno 110] Connection timed out\n",
      "\n",
      "During handling of the above exception, another exception occurred:\n",
      "\n",
      "Traceback (most recent call last):\n",
      "  File \"/home/ubuntu/.pyenv/versions/3.6.1/lib/python3.6/site-packages/requests/packages/urllib3/connectionpool.py\", line 600, in urlopen\n",
      "    chunked=chunked)\n",
      "  File \"/home/ubuntu/.pyenv/versions/3.6.1/lib/python3.6/site-packages/requests/packages/urllib3/connectionpool.py\", line 345, in _make_request\n",
      "    self._validate_conn(conn)\n",
      "  File \"/home/ubuntu/.pyenv/versions/3.6.1/lib/python3.6/site-packages/requests/packages/urllib3/connectionpool.py\", line 844, in _validate_conn\n",
      "    conn.connect()\n",
      "  File \"/home/ubuntu/.pyenv/versions/3.6.1/lib/python3.6/site-packages/requests/packages/urllib3/connection.py\", line 284, in connect\n",
      "    conn = self._new_conn()\n",
      "  File \"/home/ubuntu/.pyenv/versions/3.6.1/lib/python3.6/site-packages/requests/packages/urllib3/connection.py\", line 150, in _new_conn\n",
      "    self, \"Failed to establish a new connection: %s\" % e)\n",
      "requests.packages.urllib3.exceptions.NewConnectionError: <requests.packages.urllib3.connection.VerifiedHTTPSConnection object at 0x7f24b0c33a20>: Failed to establish a new connection: [Errno 110] Connection timed out\n",
      "\n",
      "During handling of the above exception, another exception occurred:\n",
      "\n",
      "Traceback (most recent call last):\n",
      "  File \"/home/ubuntu/.pyenv/versions/3.6.1/lib/python3.6/site-packages/requests/adapters.py\", line 423, in send\n",
      "    timeout=timeout\n",
      "  File \"/home/ubuntu/.pyenv/versions/3.6.1/lib/python3.6/site-packages/requests/packages/urllib3/connectionpool.py\", line 649, in urlopen\n",
      "    _stacktrace=sys.exc_info()[2])\n",
      "  File \"/home/ubuntu/.pyenv/versions/3.6.1/lib/python3.6/site-packages/requests/packages/urllib3/util/retry.py\", line 376, in increment\n",
      "    raise MaxRetryError(_pool, url, error or ResponseError(cause))\n",
      "requests.packages.urllib3.exceptions.MaxRetryError: HTTPSConnectionPool(host='www.1111.com.tw', port=443): Max retries exceeded with url: /job/79792958/ (Caused by NewConnectionError('<requests.packages.urllib3.connection.VerifiedHTTPSConnection object at 0x7f24b0c33a20>: Failed to establish a new connection: [Errno 110] Connection timed out',))\n",
      "\n",
      "During handling of the above exception, another exception occurred:\n",
      "\n",
      "Traceback (most recent call last):\n",
      "  File \"<ipython-input-2-564dd7be0a3d>\", line 10, in grab_content\n",
      "    res2 = requests.get(url, headers=HEADER)\n",
      "  File \"/home/ubuntu/.pyenv/versions/3.6.1/lib/python3.6/site-packages/requests/api.py\", line 70, in get\n",
      "    return request('get', url, params=params, **kwargs)\n",
      "  File \"/home/ubuntu/.pyenv/versions/3.6.1/lib/python3.6/site-packages/requests/api.py\", line 56, in request\n",
      "    return session.request(method=method, url=url, **kwargs)\n",
      "  File \"/home/ubuntu/.pyenv/versions/3.6.1/lib/python3.6/site-packages/requests/sessions.py\", line 488, in request\n",
      "    resp = self.send(prep, **send_kwargs)\n",
      "  File \"/home/ubuntu/.pyenv/versions/3.6.1/lib/python3.6/site-packages/requests/sessions.py\", line 609, in send\n",
      "    r = adapter.send(request, **kwargs)\n",
      "  File \"/home/ubuntu/.pyenv/versions/3.6.1/lib/python3.6/site-packages/requests/adapters.py\", line 487, in send\n",
      "    raise ConnectionError(e, request=request)\n",
      "requests.exceptions.ConnectionError: HTTPSConnectionPool(host='www.1111.com.tw', port=443): Max retries exceeded with url: /job/79792958/ (Caused by NewConnectionError('<requests.packages.urllib3.connection.VerifiedHTTPSConnection object at 0x7f24b0c33a20>: Failed to establish a new connection: [Errno 110] Connection timed out',))\n",
      "\n",
      "During handling of the above exception, another exception occurred:\n",
      "\n",
      "Traceback (most recent call last):\n",
      "  File \"/home/ubuntu/.pyenv/versions/3.6.1/lib/python3.6/threading.py\", line 916, in _bootstrap_inner\n",
      "    self.run()\n",
      "  File \"/home/ubuntu/.pyenv/versions/3.6.1/lib/python3.6/threading.py\", line 864, in run\n",
      "    self._target(*self._args, **self._kwargs)\n",
      "  File \"<ipython-input-2-564dd7be0a3d>\", line 36, in grab_content\n",
      "    print ('Cannot retrieve contentfrom page {} Retry: {} Error; {} '.format(idx, 6 - count), e)\n",
      "IndexError: tuple index out of range\n",
      "\n",
      "Exception in thread Thread-391:\n",
      "Traceback (most recent call last):\n",
      "  File \"/home/ubuntu/.pyenv/versions/3.6.1/lib/python3.6/site-packages/requests/packages/urllib3/connectionpool.py\", line 600, in urlopen\n",
      "    chunked=chunked)\n",
      "  File \"/home/ubuntu/.pyenv/versions/3.6.1/lib/python3.6/site-packages/requests/packages/urllib3/connectionpool.py\", line 386, in _make_request\n",
      "    six.raise_from(e, None)\n",
      "  File \"<string>\", line 2, in raise_from\n",
      "  File \"/home/ubuntu/.pyenv/versions/3.6.1/lib/python3.6/site-packages/requests/packages/urllib3/connectionpool.py\", line 382, in _make_request\n",
      "    httplib_response = conn.getresponse()\n",
      "  File \"/home/ubuntu/.pyenv/versions/3.6.1/lib/python3.6/http/client.py\", line 1331, in getresponse\n",
      "    response.begin()\n",
      "  File \"/home/ubuntu/.pyenv/versions/3.6.1/lib/python3.6/http/client.py\", line 297, in begin\n",
      "    version, status, reason = self._read_status()\n",
      "  File \"/home/ubuntu/.pyenv/versions/3.6.1/lib/python3.6/http/client.py\", line 266, in _read_status\n",
      "    raise RemoteDisconnected(\"Remote end closed connection without\"\n",
      "http.client.RemoteDisconnected: Remote end closed connection without response\n",
      "\n",
      "During handling of the above exception, another exception occurred:\n",
      "\n",
      "Traceback (most recent call last):\n",
      "  File \"/home/ubuntu/.pyenv/versions/3.6.1/lib/python3.6/site-packages/requests/adapters.py\", line 423, in send\n",
      "    timeout=timeout\n",
      "  File \"/home/ubuntu/.pyenv/versions/3.6.1/lib/python3.6/site-packages/requests/packages/urllib3/connectionpool.py\", line 649, in urlopen\n",
      "    _stacktrace=sys.exc_info()[2])\n",
      "  File \"/home/ubuntu/.pyenv/versions/3.6.1/lib/python3.6/site-packages/requests/packages/urllib3/util/retry.py\", line 347, in increment\n",
      "    raise six.reraise(type(error), error, _stacktrace)\n",
      "  File \"/home/ubuntu/.pyenv/versions/3.6.1/lib/python3.6/site-packages/requests/packages/urllib3/packages/six.py\", line 685, in reraise\n",
      "    raise value.with_traceback(tb)\n",
      "  File \"/home/ubuntu/.pyenv/versions/3.6.1/lib/python3.6/site-packages/requests/packages/urllib3/connectionpool.py\", line 600, in urlopen\n",
      "    chunked=chunked)\n",
      "  File \"/home/ubuntu/.pyenv/versions/3.6.1/lib/python3.6/site-packages/requests/packages/urllib3/connectionpool.py\", line 386, in _make_request\n",
      "    six.raise_from(e, None)\n",
      "  File \"<string>\", line 2, in raise_from\n",
      "  File \"/home/ubuntu/.pyenv/versions/3.6.1/lib/python3.6/site-packages/requests/packages/urllib3/connectionpool.py\", line 382, in _make_request\n",
      "    httplib_response = conn.getresponse()\n",
      "  File \"/home/ubuntu/.pyenv/versions/3.6.1/lib/python3.6/http/client.py\", line 1331, in getresponse\n",
      "    response.begin()\n",
      "  File \"/home/ubuntu/.pyenv/versions/3.6.1/lib/python3.6/http/client.py\", line 297, in begin\n",
      "    version, status, reason = self._read_status()\n",
      "  File \"/home/ubuntu/.pyenv/versions/3.6.1/lib/python3.6/http/client.py\", line 266, in _read_status\n",
      "    raise RemoteDisconnected(\"Remote end closed connection without\"\n",
      "requests.packages.urllib3.exceptions.ProtocolError: ('Connection aborted.', RemoteDisconnected('Remote end closed connection without response',))\n",
      "\n",
      "During handling of the above exception, another exception occurred:\n",
      "\n",
      "Traceback (most recent call last):\n",
      "  File \"<ipython-input-2-564dd7be0a3d>\", line 10, in grab_content\n",
      "    res2 = requests.get(url, headers=HEADER)\n",
      "  File \"/home/ubuntu/.pyenv/versions/3.6.1/lib/python3.6/site-packages/requests/api.py\", line 70, in get\n",
      "    return request('get', url, params=params, **kwargs)\n",
      "  File \"/home/ubuntu/.pyenv/versions/3.6.1/lib/python3.6/site-packages/requests/api.py\", line 56, in request\n",
      "    return session.request(method=method, url=url, **kwargs)\n",
      "  File \"/home/ubuntu/.pyenv/versions/3.6.1/lib/python3.6/site-packages/requests/sessions.py\", line 488, in request\n",
      "    resp = self.send(prep, **send_kwargs)\n",
      "  File \"/home/ubuntu/.pyenv/versions/3.6.1/lib/python3.6/site-packages/requests/sessions.py\", line 609, in send\n",
      "    r = adapter.send(request, **kwargs)\n",
      "  File \"/home/ubuntu/.pyenv/versions/3.6.1/lib/python3.6/site-packages/requests/adapters.py\", line 473, in send\n",
      "    raise ConnectionError(err, request=request)\n",
      "requests.exceptions.ConnectionError: ('Connection aborted.', RemoteDisconnected('Remote end closed connection without response',))\n",
      "\n",
      "During handling of the above exception, another exception occurred:\n",
      "\n",
      "Traceback (most recent call last):\n",
      "  File \"/home/ubuntu/.pyenv/versions/3.6.1/lib/python3.6/threading.py\", line 916, in _bootstrap_inner\n",
      "    self.run()\n",
      "  File \"/home/ubuntu/.pyenv/versions/3.6.1/lib/python3.6/threading.py\", line 864, in run\n",
      "    self._target(*self._args, **self._kwargs)\n",
      "  File \"<ipython-input-2-564dd7be0a3d>\", line 36, in grab_content\n",
      "    print ('Cannot retrieve contentfrom page {} Retry: {} Error; {} '.format(idx, 6 - count), e)\n",
      "IndexError: tuple index out of range\n",
      "\n",
      "Exception in thread Thread-390:\n",
      "Traceback (most recent call last):\n",
      "  File \"/home/ubuntu/.pyenv/versions/3.6.1/lib/python3.6/site-packages/requests/packages/urllib3/connectionpool.py\", line 600, in urlopen\n",
      "    chunked=chunked)\n",
      "  File \"/home/ubuntu/.pyenv/versions/3.6.1/lib/python3.6/site-packages/requests/packages/urllib3/connectionpool.py\", line 386, in _make_request\n",
      "    six.raise_from(e, None)\n",
      "  File \"<string>\", line 2, in raise_from\n",
      "  File \"/home/ubuntu/.pyenv/versions/3.6.1/lib/python3.6/site-packages/requests/packages/urllib3/connectionpool.py\", line 382, in _make_request\n",
      "    httplib_response = conn.getresponse()\n",
      "  File \"/home/ubuntu/.pyenv/versions/3.6.1/lib/python3.6/http/client.py\", line 1331, in getresponse\n",
      "    response.begin()\n",
      "  File \"/home/ubuntu/.pyenv/versions/3.6.1/lib/python3.6/http/client.py\", line 297, in begin\n",
      "    version, status, reason = self._read_status()\n",
      "  File \"/home/ubuntu/.pyenv/versions/3.6.1/lib/python3.6/http/client.py\", line 266, in _read_status\n",
      "    raise RemoteDisconnected(\"Remote end closed connection without\"\n",
      "http.client.RemoteDisconnected: Remote end closed connection without response\n",
      "\n",
      "During handling of the above exception, another exception occurred:\n",
      "\n",
      "Traceback (most recent call last):\n",
      "  File \"/home/ubuntu/.pyenv/versions/3.6.1/lib/python3.6/site-packages/requests/adapters.py\", line 423, in send\n",
      "    timeout=timeout\n",
      "  File \"/home/ubuntu/.pyenv/versions/3.6.1/lib/python3.6/site-packages/requests/packages/urllib3/connectionpool.py\", line 649, in urlopen\n",
      "    _stacktrace=sys.exc_info()[2])\n",
      "  File \"/home/ubuntu/.pyenv/versions/3.6.1/lib/python3.6/site-packages/requests/packages/urllib3/util/retry.py\", line 347, in increment\n",
      "    raise six.reraise(type(error), error, _stacktrace)\n",
      "  File \"/home/ubuntu/.pyenv/versions/3.6.1/lib/python3.6/site-packages/requests/packages/urllib3/packages/six.py\", line 685, in reraise\n",
      "    raise value.with_traceback(tb)\n",
      "  File \"/home/ubuntu/.pyenv/versions/3.6.1/lib/python3.6/site-packages/requests/packages/urllib3/connectionpool.py\", line 600, in urlopen\n",
      "    chunked=chunked)\n",
      "  File \"/home/ubuntu/.pyenv/versions/3.6.1/lib/python3.6/site-packages/requests/packages/urllib3/connectionpool.py\", line 386, in _make_request\n",
      "    six.raise_from(e, None)\n",
      "  File \"<string>\", line 2, in raise_from\n",
      "  File \"/home/ubuntu/.pyenv/versions/3.6.1/lib/python3.6/site-packages/requests/packages/urllib3/connectionpool.py\", line 382, in _make_request\n",
      "    httplib_response = conn.getresponse()\n",
      "  File \"/home/ubuntu/.pyenv/versions/3.6.1/lib/python3.6/http/client.py\", line 1331, in getresponse\n",
      "    response.begin()\n",
      "  File \"/home/ubuntu/.pyenv/versions/3.6.1/lib/python3.6/http/client.py\", line 297, in begin\n",
      "    version, status, reason = self._read_status()\n",
      "  File \"/home/ubuntu/.pyenv/versions/3.6.1/lib/python3.6/http/client.py\", line 266, in _read_status\n",
      "    raise RemoteDisconnected(\"Remote end closed connection without\"\n",
      "requests.packages.urllib3.exceptions.ProtocolError: ('Connection aborted.', RemoteDisconnected('Remote end closed connection without response',))\n",
      "\n",
      "During handling of the above exception, another exception occurred:\n",
      "\n",
      "Traceback (most recent call last):\n",
      "  File \"<ipython-input-2-564dd7be0a3d>\", line 10, in grab_content\n",
      "    res2 = requests.get(url, headers=HEADER)\n",
      "  File \"/home/ubuntu/.pyenv/versions/3.6.1/lib/python3.6/site-packages/requests/api.py\", line 70, in get\n",
      "    return request('get', url, params=params, **kwargs)\n",
      "  File \"/home/ubuntu/.pyenv/versions/3.6.1/lib/python3.6/site-packages/requests/api.py\", line 56, in request\n",
      "    return session.request(method=method, url=url, **kwargs)\n",
      "  File \"/home/ubuntu/.pyenv/versions/3.6.1/lib/python3.6/site-packages/requests/sessions.py\", line 488, in request\n",
      "    resp = self.send(prep, **send_kwargs)\n",
      "  File \"/home/ubuntu/.pyenv/versions/3.6.1/lib/python3.6/site-packages/requests/sessions.py\", line 609, in send\n",
      "    r = adapter.send(request, **kwargs)\n",
      "  File \"/home/ubuntu/.pyenv/versions/3.6.1/lib/python3.6/site-packages/requests/adapters.py\", line 473, in send\n",
      "    raise ConnectionError(err, request=request)\n",
      "requests.exceptions.ConnectionError: ('Connection aborted.', RemoteDisconnected('Remote end closed connection without response',))\n",
      "\n",
      "During handling of the above exception, another exception occurred:\n",
      "\n",
      "Traceback (most recent call last):\n",
      "  File \"/home/ubuntu/.pyenv/versions/3.6.1/lib/python3.6/threading.py\", line 916, in _bootstrap_inner\n",
      "    self.run()\n",
      "  File \"/home/ubuntu/.pyenv/versions/3.6.1/lib/python3.6/threading.py\", line 864, in run\n",
      "    self._target(*self._args, **self._kwargs)\n",
      "  File \"<ipython-input-2-564dd7be0a3d>\", line 36, in grab_content\n",
      "    print ('Cannot retrieve contentfrom page {} Retry: {} Error; {} '.format(idx, 6 - count), e)\n",
      "IndexError: tuple index out of range\n",
      "\n",
      "Exception in thread Thread-358:\n",
      "Traceback (most recent call last):\n",
      "  File \"/home/ubuntu/.pyenv/versions/3.6.1/lib/python3.6/site-packages/requests/packages/urllib3/connectionpool.py\", line 600, in urlopen\n",
      "    chunked=chunked)\n",
      "  File \"/home/ubuntu/.pyenv/versions/3.6.1/lib/python3.6/site-packages/requests/packages/urllib3/connectionpool.py\", line 386, in _make_request\n",
      "    six.raise_from(e, None)\n",
      "  File \"<string>\", line 2, in raise_from\n",
      "  File \"/home/ubuntu/.pyenv/versions/3.6.1/lib/python3.6/site-packages/requests/packages/urllib3/connectionpool.py\", line 382, in _make_request\n",
      "    httplib_response = conn.getresponse()\n",
      "  File \"/home/ubuntu/.pyenv/versions/3.6.1/lib/python3.6/http/client.py\", line 1331, in getresponse\n",
      "    response.begin()\n",
      "  File \"/home/ubuntu/.pyenv/versions/3.6.1/lib/python3.6/http/client.py\", line 297, in begin\n",
      "    version, status, reason = self._read_status()\n",
      "  File \"/home/ubuntu/.pyenv/versions/3.6.1/lib/python3.6/http/client.py\", line 266, in _read_status\n",
      "    raise RemoteDisconnected(\"Remote end closed connection without\"\n",
      "http.client.RemoteDisconnected: Remote end closed connection without response\n",
      "\n",
      "During handling of the above exception, another exception occurred:\n",
      "\n",
      "Traceback (most recent call last):\n",
      "  File \"/home/ubuntu/.pyenv/versions/3.6.1/lib/python3.6/site-packages/requests/adapters.py\", line 423, in send\n",
      "    timeout=timeout\n",
      "  File \"/home/ubuntu/.pyenv/versions/3.6.1/lib/python3.6/site-packages/requests/packages/urllib3/connectionpool.py\", line 649, in urlopen\n",
      "    _stacktrace=sys.exc_info()[2])\n",
      "  File \"/home/ubuntu/.pyenv/versions/3.6.1/lib/python3.6/site-packages/requests/packages/urllib3/util/retry.py\", line 347, in increment\n",
      "    raise six.reraise(type(error), error, _stacktrace)\n",
      "  File \"/home/ubuntu/.pyenv/versions/3.6.1/lib/python3.6/site-packages/requests/packages/urllib3/packages/six.py\", line 685, in reraise\n",
      "    raise value.with_traceback(tb)\n",
      "  File \"/home/ubuntu/.pyenv/versions/3.6.1/lib/python3.6/site-packages/requests/packages/urllib3/connectionpool.py\", line 600, in urlopen\n",
      "    chunked=chunked)\n",
      "  File \"/home/ubuntu/.pyenv/versions/3.6.1/lib/python3.6/site-packages/requests/packages/urllib3/connectionpool.py\", line 386, in _make_request\n",
      "    six.raise_from(e, None)\n",
      "  File \"<string>\", line 2, in raise_from\n",
      "  File \"/home/ubuntu/.pyenv/versions/3.6.1/lib/python3.6/site-packages/requests/packages/urllib3/connectionpool.py\", line 382, in _make_request\n",
      "    httplib_response = conn.getresponse()\n",
      "  File \"/home/ubuntu/.pyenv/versions/3.6.1/lib/python3.6/http/client.py\", line 1331, in getresponse\n",
      "    response.begin()\n",
      "  File \"/home/ubuntu/.pyenv/versions/3.6.1/lib/python3.6/http/client.py\", line 297, in begin\n",
      "    version, status, reason = self._read_status()\n",
      "  File \"/home/ubuntu/.pyenv/versions/3.6.1/lib/python3.6/http/client.py\", line 266, in _read_status\n",
      "    raise RemoteDisconnected(\"Remote end closed connection without\"\n",
      "requests.packages.urllib3.exceptions.ProtocolError: ('Connection aborted.', RemoteDisconnected('Remote end closed connection without response',))\n",
      "\n",
      "During handling of the above exception, another exception occurred:\n",
      "\n",
      "Traceback (most recent call last):\n",
      "  File \"<ipython-input-2-564dd7be0a3d>\", line 10, in grab_content\n",
      "    res2 = requests.get(url, headers=HEADER)\n",
      "  File \"/home/ubuntu/.pyenv/versions/3.6.1/lib/python3.6/site-packages/requests/api.py\", line 70, in get\n",
      "    return request('get', url, params=params, **kwargs)\n",
      "  File \"/home/ubuntu/.pyenv/versions/3.6.1/lib/python3.6/site-packages/requests/api.py\", line 56, in request\n",
      "    return session.request(method=method, url=url, **kwargs)\n",
      "  File \"/home/ubuntu/.pyenv/versions/3.6.1/lib/python3.6/site-packages/requests/sessions.py\", line 488, in request\n",
      "    resp = self.send(prep, **send_kwargs)\n",
      "  File \"/home/ubuntu/.pyenv/versions/3.6.1/lib/python3.6/site-packages/requests/sessions.py\", line 609, in send\n",
      "    r = adapter.send(request, **kwargs)\n",
      "  File \"/home/ubuntu/.pyenv/versions/3.6.1/lib/python3.6/site-packages/requests/adapters.py\", line 473, in send\n",
      "    raise ConnectionError(err, request=request)\n",
      "requests.exceptions.ConnectionError: ('Connection aborted.', RemoteDisconnected('Remote end closed connection without response',))\n",
      "\n",
      "During handling of the above exception, another exception occurred:\n",
      "\n",
      "Traceback (most recent call last):\n",
      "  File \"/home/ubuntu/.pyenv/versions/3.6.1/lib/python3.6/threading.py\", line 916, in _bootstrap_inner\n",
      "    self.run()\n",
      "  File \"/home/ubuntu/.pyenv/versions/3.6.1/lib/python3.6/threading.py\", line 864, in run\n",
      "    self._target(*self._args, **self._kwargs)\n",
      "  File \"<ipython-input-2-564dd7be0a3d>\", line 36, in grab_content\n",
      "    print ('Cannot retrieve contentfrom page {} Retry: {} Error; {} '.format(idx, 6 - count), e)\n",
      "IndexError: tuple index out of range\n",
      "\n",
      "Exception in thread Thread-370:\n",
      "Traceback (most recent call last):\n",
      "  File \"/home/ubuntu/.pyenv/versions/3.6.1/lib/python3.6/site-packages/requests/packages/urllib3/contrib/pyopenssl.py\", line 436, in wrap_socket\n",
      "    cnx.do_handshake()\n",
      "  File \"/home/ubuntu/.pyenv/versions/3.6.1/lib/python3.6/site-packages/OpenSSL/SSL.py\", line 1638, in do_handshake\n",
      "    self._raise_ssl_error(self._ssl, result)\n",
      "  File \"/home/ubuntu/.pyenv/versions/3.6.1/lib/python3.6/site-packages/OpenSSL/SSL.py\", line 1371, in _raise_ssl_error\n",
      "    raise SysCallError(-1, \"Unexpected EOF\")\n",
      "OpenSSL.SSL.SysCallError: (-1, 'Unexpected EOF')\n",
      "\n",
      "During handling of the above exception, another exception occurred:\n",
      "\n",
      "Traceback (most recent call last):\n",
      "  File \"/home/ubuntu/.pyenv/versions/3.6.1/lib/python3.6/site-packages/requests/packages/urllib3/connectionpool.py\", line 600, in urlopen\n",
      "    chunked=chunked)\n",
      "  File \"/home/ubuntu/.pyenv/versions/3.6.1/lib/python3.6/site-packages/requests/packages/urllib3/connectionpool.py\", line 345, in _make_request\n",
      "    self._validate_conn(conn)\n",
      "  File \"/home/ubuntu/.pyenv/versions/3.6.1/lib/python3.6/site-packages/requests/packages/urllib3/connectionpool.py\", line 844, in _validate_conn\n",
      "    conn.connect()\n",
      "  File \"/home/ubuntu/.pyenv/versions/3.6.1/lib/python3.6/site-packages/requests/packages/urllib3/connection.py\", line 326, in connect\n",
      "    ssl_context=context)\n",
      "  File \"/home/ubuntu/.pyenv/versions/3.6.1/lib/python3.6/site-packages/requests/packages/urllib3/util/ssl_.py\", line 324, in ssl_wrap_socket\n",
      "    return context.wrap_socket(sock, server_hostname=server_hostname)\n",
      "  File \"/home/ubuntu/.pyenv/versions/3.6.1/lib/python3.6/site-packages/requests/packages/urllib3/contrib/pyopenssl.py\", line 443, in wrap_socket\n",
      "    raise ssl.SSLError('bad handshake: %r' % e)\n",
      "ssl.SSLError: (\"bad handshake: SysCallError(-1, 'Unexpected EOF')\",)\n",
      "\n",
      "During handling of the above exception, another exception occurred:\n",
      "\n",
      "Traceback (most recent call last):\n",
      "  File \"/home/ubuntu/.pyenv/versions/3.6.1/lib/python3.6/site-packages/requests/adapters.py\", line 423, in send\n",
      "    timeout=timeout\n",
      "  File \"/home/ubuntu/.pyenv/versions/3.6.1/lib/python3.6/site-packages/requests/packages/urllib3/connectionpool.py\", line 630, in urlopen\n",
      "    raise SSLError(e)\n",
      "requests.packages.urllib3.exceptions.SSLError: (\"bad handshake: SysCallError(-1, 'Unexpected EOF')\",)\n",
      "\n",
      "During handling of the above exception, another exception occurred:\n",
      "\n",
      "Traceback (most recent call last):\n",
      "  File \"<ipython-input-2-564dd7be0a3d>\", line 10, in grab_content\n",
      "    res2 = requests.get(url, headers=HEADER)\n",
      "  File \"/home/ubuntu/.pyenv/versions/3.6.1/lib/python3.6/site-packages/requests/api.py\", line 70, in get\n",
      "    return request('get', url, params=params, **kwargs)\n",
      "  File \"/home/ubuntu/.pyenv/versions/3.6.1/lib/python3.6/site-packages/requests/api.py\", line 56, in request\n",
      "    return session.request(method=method, url=url, **kwargs)\n",
      "  File \"/home/ubuntu/.pyenv/versions/3.6.1/lib/python3.6/site-packages/requests/sessions.py\", line 488, in request\n",
      "    resp = self.send(prep, **send_kwargs)\n",
      "  File \"/home/ubuntu/.pyenv/versions/3.6.1/lib/python3.6/site-packages/requests/sessions.py\", line 609, in send\n",
      "    r = adapter.send(request, **kwargs)\n",
      "  File \"/home/ubuntu/.pyenv/versions/3.6.1/lib/python3.6/site-packages/requests/adapters.py\", line 497, in send\n",
      "    raise SSLError(e, request=request)\n",
      "requests.exceptions.SSLError: (\"bad handshake: SysCallError(-1, 'Unexpected EOF')\",)\n",
      "\n",
      "During handling of the above exception, another exception occurred:\n",
      "\n",
      "Traceback (most recent call last):\n",
      "  File \"/home/ubuntu/.pyenv/versions/3.6.1/lib/python3.6/threading.py\", line 916, in _bootstrap_inner\n",
      "    self.run()\n",
      "  File \"/home/ubuntu/.pyenv/versions/3.6.1/lib/python3.6/threading.py\", line 864, in run\n",
      "    self._target(*self._args, **self._kwargs)\n",
      "  File \"<ipython-input-2-564dd7be0a3d>\", line 36, in grab_content\n",
      "    print ('Cannot retrieve contentfrom page {} Retry: {} Error; {} '.format(idx, 6 - count), e)\n",
      "IndexError: tuple index out of range\n",
      "\n",
      "Exception in thread Thread-407:\n",
      "Traceback (most recent call last):\n",
      "  File \"/home/ubuntu/.pyenv/versions/3.6.1/lib/python3.6/site-packages/requests/packages/urllib3/connection.py\", line 141, in _new_conn\n",
      "    (self.host, self.port), self.timeout, **extra_kw)\n",
      "  File \"/home/ubuntu/.pyenv/versions/3.6.1/lib/python3.6/site-packages/requests/packages/urllib3/util/connection.py\", line 83, in create_connection\n",
      "    raise err\n",
      "  File \"/home/ubuntu/.pyenv/versions/3.6.1/lib/python3.6/site-packages/requests/packages/urllib3/util/connection.py\", line 73, in create_connection\n",
      "    sock.connect(sa)\n",
      "TimeoutError: [Errno 110] Connection timed out\n",
      "\n",
      "During handling of the above exception, another exception occurred:\n",
      "\n",
      "Traceback (most recent call last):\n",
      "  File \"/home/ubuntu/.pyenv/versions/3.6.1/lib/python3.6/site-packages/requests/packages/urllib3/connectionpool.py\", line 600, in urlopen\n",
      "    chunked=chunked)\n",
      "  File \"/home/ubuntu/.pyenv/versions/3.6.1/lib/python3.6/site-packages/requests/packages/urllib3/connectionpool.py\", line 345, in _make_request\n",
      "    self._validate_conn(conn)\n",
      "  File \"/home/ubuntu/.pyenv/versions/3.6.1/lib/python3.6/site-packages/requests/packages/urllib3/connectionpool.py\", line 844, in _validate_conn\n",
      "    conn.connect()\n",
      "  File \"/home/ubuntu/.pyenv/versions/3.6.1/lib/python3.6/site-packages/requests/packages/urllib3/connection.py\", line 284, in connect\n",
      "    conn = self._new_conn()\n",
      "  File \"/home/ubuntu/.pyenv/versions/3.6.1/lib/python3.6/site-packages/requests/packages/urllib3/connection.py\", line 150, in _new_conn\n",
      "    self, \"Failed to establish a new connection: %s\" % e)\n",
      "requests.packages.urllib3.exceptions.NewConnectionError: <requests.packages.urllib3.connection.VerifiedHTTPSConnection object at 0x7f24b3378ba8>: Failed to establish a new connection: [Errno 110] Connection timed out\n",
      "\n",
      "During handling of the above exception, another exception occurred:\n",
      "\n",
      "Traceback (most recent call last):\n",
      "  File \"/home/ubuntu/.pyenv/versions/3.6.1/lib/python3.6/site-packages/requests/adapters.py\", line 423, in send\n",
      "    timeout=timeout\n",
      "  File \"/home/ubuntu/.pyenv/versions/3.6.1/lib/python3.6/site-packages/requests/packages/urllib3/connectionpool.py\", line 649, in urlopen\n",
      "    _stacktrace=sys.exc_info()[2])\n",
      "  File \"/home/ubuntu/.pyenv/versions/3.6.1/lib/python3.6/site-packages/requests/packages/urllib3/util/retry.py\", line 376, in increment\n",
      "    raise MaxRetryError(_pool, url, error or ResponseError(cause))\n",
      "requests.packages.urllib3.exceptions.MaxRetryError: HTTPSConnectionPool(host='www.1111.com.tw', port=443): Max retries exceeded with url: /job/79108697/ (Caused by NewConnectionError('<requests.packages.urllib3.connection.VerifiedHTTPSConnection object at 0x7f24b3378ba8>: Failed to establish a new connection: [Errno 110] Connection timed out',))\n",
      "\n",
      "During handling of the above exception, another exception occurred:\n",
      "\n",
      "Traceback (most recent call last):\n",
      "  File \"<ipython-input-2-564dd7be0a3d>\", line 10, in grab_content\n",
      "    res2 = requests.get(url, headers=HEADER)\n",
      "  File \"/home/ubuntu/.pyenv/versions/3.6.1/lib/python3.6/site-packages/requests/api.py\", line 70, in get\n",
      "    return request('get', url, params=params, **kwargs)\n",
      "  File \"/home/ubuntu/.pyenv/versions/3.6.1/lib/python3.6/site-packages/requests/api.py\", line 56, in request\n",
      "    return session.request(method=method, url=url, **kwargs)\n",
      "  File \"/home/ubuntu/.pyenv/versions/3.6.1/lib/python3.6/site-packages/requests/sessions.py\", line 488, in request\n",
      "    resp = self.send(prep, **send_kwargs)\n",
      "  File \"/home/ubuntu/.pyenv/versions/3.6.1/lib/python3.6/site-packages/requests/sessions.py\", line 609, in send\n",
      "    r = adapter.send(request, **kwargs)\n",
      "  File \"/home/ubuntu/.pyenv/versions/3.6.1/lib/python3.6/site-packages/requests/adapters.py\", line 487, in send\n",
      "    raise ConnectionError(e, request=request)\n",
      "requests.exceptions.ConnectionError: HTTPSConnectionPool(host='www.1111.com.tw', port=443): Max retries exceeded with url: /job/79108697/ (Caused by NewConnectionError('<requests.packages.urllib3.connection.VerifiedHTTPSConnection object at 0x7f24b3378ba8>: Failed to establish a new connection: [Errno 110] Connection timed out',))\n",
      "\n",
      "During handling of the above exception, another exception occurred:\n",
      "\n",
      "Traceback (most recent call last):\n",
      "  File \"/home/ubuntu/.pyenv/versions/3.6.1/lib/python3.6/threading.py\", line 916, in _bootstrap_inner\n",
      "    self.run()\n",
      "  File \"/home/ubuntu/.pyenv/versions/3.6.1/lib/python3.6/threading.py\", line 864, in run\n",
      "    self._target(*self._args, **self._kwargs)\n",
      "  File \"<ipython-input-2-564dd7be0a3d>\", line 36, in grab_content\n",
      "    print ('Cannot retrieve contentfrom page {} Retry: {} Error; {} '.format(idx, 6 - count), e)\n",
      "IndexError: tuple index out of range\n",
      "\n",
      "Exception in thread Thread-422:\n",
      "Traceback (most recent call last):\n",
      "  File \"/home/ubuntu/.pyenv/versions/3.6.1/lib/python3.6/site-packages/requests/packages/urllib3/connectionpool.py\", line 600, in urlopen\n",
      "    chunked=chunked)\n",
      "  File \"/home/ubuntu/.pyenv/versions/3.6.1/lib/python3.6/site-packages/requests/packages/urllib3/connectionpool.py\", line 386, in _make_request\n",
      "    six.raise_from(e, None)\n",
      "  File \"<string>\", line 2, in raise_from\n",
      "  File \"/home/ubuntu/.pyenv/versions/3.6.1/lib/python3.6/site-packages/requests/packages/urllib3/connectionpool.py\", line 382, in _make_request\n",
      "    httplib_response = conn.getresponse()\n",
      "  File \"/home/ubuntu/.pyenv/versions/3.6.1/lib/python3.6/http/client.py\", line 1331, in getresponse\n",
      "    response.begin()\n",
      "  File \"/home/ubuntu/.pyenv/versions/3.6.1/lib/python3.6/http/client.py\", line 297, in begin\n",
      "    version, status, reason = self._read_status()\n",
      "  File \"/home/ubuntu/.pyenv/versions/3.6.1/lib/python3.6/http/client.py\", line 266, in _read_status\n",
      "    raise RemoteDisconnected(\"Remote end closed connection without\"\n",
      "http.client.RemoteDisconnected: Remote end closed connection without response\n",
      "\n",
      "During handling of the above exception, another exception occurred:\n",
      "\n",
      "Traceback (most recent call last):\n",
      "  File \"/home/ubuntu/.pyenv/versions/3.6.1/lib/python3.6/site-packages/requests/adapters.py\", line 423, in send\n",
      "    timeout=timeout\n",
      "  File \"/home/ubuntu/.pyenv/versions/3.6.1/lib/python3.6/site-packages/requests/packages/urllib3/connectionpool.py\", line 649, in urlopen\n",
      "    _stacktrace=sys.exc_info()[2])\n",
      "  File \"/home/ubuntu/.pyenv/versions/3.6.1/lib/python3.6/site-packages/requests/packages/urllib3/util/retry.py\", line 347, in increment\n",
      "    raise six.reraise(type(error), error, _stacktrace)\n",
      "  File \"/home/ubuntu/.pyenv/versions/3.6.1/lib/python3.6/site-packages/requests/packages/urllib3/packages/six.py\", line 685, in reraise\n",
      "    raise value.with_traceback(tb)\n",
      "  File \"/home/ubuntu/.pyenv/versions/3.6.1/lib/python3.6/site-packages/requests/packages/urllib3/connectionpool.py\", line 600, in urlopen\n",
      "    chunked=chunked)\n",
      "  File \"/home/ubuntu/.pyenv/versions/3.6.1/lib/python3.6/site-packages/requests/packages/urllib3/connectionpool.py\", line 386, in _make_request\n",
      "    six.raise_from(e, None)\n",
      "  File \"<string>\", line 2, in raise_from\n",
      "  File \"/home/ubuntu/.pyenv/versions/3.6.1/lib/python3.6/site-packages/requests/packages/urllib3/connectionpool.py\", line 382, in _make_request\n",
      "    httplib_response = conn.getresponse()\n",
      "  File \"/home/ubuntu/.pyenv/versions/3.6.1/lib/python3.6/http/client.py\", line 1331, in getresponse\n",
      "    response.begin()\n",
      "  File \"/home/ubuntu/.pyenv/versions/3.6.1/lib/python3.6/http/client.py\", line 297, in begin\n",
      "    version, status, reason = self._read_status()\n",
      "  File \"/home/ubuntu/.pyenv/versions/3.6.1/lib/python3.6/http/client.py\", line 266, in _read_status\n",
      "    raise RemoteDisconnected(\"Remote end closed connection without\"\n",
      "requests.packages.urllib3.exceptions.ProtocolError: ('Connection aborted.', RemoteDisconnected('Remote end closed connection without response',))\n",
      "\n",
      "During handling of the above exception, another exception occurred:\n",
      "\n",
      "Traceback (most recent call last):\n",
      "  File \"<ipython-input-2-564dd7be0a3d>\", line 10, in grab_content\n",
      "    res2 = requests.get(url, headers=HEADER)\n",
      "  File \"/home/ubuntu/.pyenv/versions/3.6.1/lib/python3.6/site-packages/requests/api.py\", line 70, in get\n",
      "    return request('get', url, params=params, **kwargs)\n",
      "  File \"/home/ubuntu/.pyenv/versions/3.6.1/lib/python3.6/site-packages/requests/api.py\", line 56, in request\n",
      "    return session.request(method=method, url=url, **kwargs)\n",
      "  File \"/home/ubuntu/.pyenv/versions/3.6.1/lib/python3.6/site-packages/requests/sessions.py\", line 488, in request\n",
      "    resp = self.send(prep, **send_kwargs)\n",
      "  File \"/home/ubuntu/.pyenv/versions/3.6.1/lib/python3.6/site-packages/requests/sessions.py\", line 609, in send\n",
      "    r = adapter.send(request, **kwargs)\n",
      "  File \"/home/ubuntu/.pyenv/versions/3.6.1/lib/python3.6/site-packages/requests/adapters.py\", line 473, in send\n",
      "    raise ConnectionError(err, request=request)\n",
      "requests.exceptions.ConnectionError: ('Connection aborted.', RemoteDisconnected('Remote end closed connection without response',))\n",
      "\n",
      "During handling of the above exception, another exception occurred:\n",
      "\n",
      "Traceback (most recent call last):\n",
      "  File \"/home/ubuntu/.pyenv/versions/3.6.1/lib/python3.6/threading.py\", line 916, in _bootstrap_inner\n",
      "    self.run()\n",
      "  File \"/home/ubuntu/.pyenv/versions/3.6.1/lib/python3.6/threading.py\", line 864, in run\n",
      "    self._target(*self._args, **self._kwargs)\n",
      "  File \"<ipython-input-2-564dd7be0a3d>\", line 36, in grab_content\n",
      "    print ('Cannot retrieve contentfrom page {} Retry: {} Error; {} '.format(idx, 6 - count), e)\n",
      "IndexError: tuple index out of range\n",
      "\n",
      "Exception in thread Thread-396:\n",
      "Traceback (most recent call last):\n",
      "  File \"/home/ubuntu/.pyenv/versions/3.6.1/lib/python3.6/site-packages/requests/packages/urllib3/contrib/pyopenssl.py\", line 436, in wrap_socket\n",
      "    cnx.do_handshake()\n",
      "  File \"/home/ubuntu/.pyenv/versions/3.6.1/lib/python3.6/site-packages/OpenSSL/SSL.py\", line 1638, in do_handshake\n",
      "    self._raise_ssl_error(self._ssl, result)\n",
      "  File \"/home/ubuntu/.pyenv/versions/3.6.1/lib/python3.6/site-packages/OpenSSL/SSL.py\", line 1371, in _raise_ssl_error\n",
      "    raise SysCallError(-1, \"Unexpected EOF\")\n",
      "OpenSSL.SSL.SysCallError: (-1, 'Unexpected EOF')\n",
      "\n",
      "During handling of the above exception, another exception occurred:\n",
      "\n",
      "Traceback (most recent call last):\n",
      "  File \"/home/ubuntu/.pyenv/versions/3.6.1/lib/python3.6/site-packages/requests/packages/urllib3/connectionpool.py\", line 600, in urlopen\n",
      "    chunked=chunked)\n",
      "  File \"/home/ubuntu/.pyenv/versions/3.6.1/lib/python3.6/site-packages/requests/packages/urllib3/connectionpool.py\", line 345, in _make_request\n",
      "    self._validate_conn(conn)\n",
      "  File \"/home/ubuntu/.pyenv/versions/3.6.1/lib/python3.6/site-packages/requests/packages/urllib3/connectionpool.py\", line 844, in _validate_conn\n",
      "    conn.connect()\n",
      "  File \"/home/ubuntu/.pyenv/versions/3.6.1/lib/python3.6/site-packages/requests/packages/urllib3/connection.py\", line 326, in connect\n",
      "    ssl_context=context)\n",
      "  File \"/home/ubuntu/.pyenv/versions/3.6.1/lib/python3.6/site-packages/requests/packages/urllib3/util/ssl_.py\", line 324, in ssl_wrap_socket\n",
      "    return context.wrap_socket(sock, server_hostname=server_hostname)\n",
      "  File \"/home/ubuntu/.pyenv/versions/3.6.1/lib/python3.6/site-packages/requests/packages/urllib3/contrib/pyopenssl.py\", line 443, in wrap_socket\n",
      "    raise ssl.SSLError('bad handshake: %r' % e)\n",
      "ssl.SSLError: (\"bad handshake: SysCallError(-1, 'Unexpected EOF')\",)\n",
      "\n",
      "During handling of the above exception, another exception occurred:\n",
      "\n",
      "Traceback (most recent call last):\n",
      "  File \"/home/ubuntu/.pyenv/versions/3.6.1/lib/python3.6/site-packages/requests/adapters.py\", line 423, in send\n",
      "    timeout=timeout\n",
      "  File \"/home/ubuntu/.pyenv/versions/3.6.1/lib/python3.6/site-packages/requests/packages/urllib3/connectionpool.py\", line 630, in urlopen\n",
      "    raise SSLError(e)\n",
      "requests.packages.urllib3.exceptions.SSLError: (\"bad handshake: SysCallError(-1, 'Unexpected EOF')\",)\n",
      "\n",
      "During handling of the above exception, another exception occurred:\n",
      "\n",
      "Traceback (most recent call last):\n",
      "  File \"<ipython-input-2-564dd7be0a3d>\", line 10, in grab_content\n",
      "    res2 = requests.get(url, headers=HEADER)\n",
      "  File \"/home/ubuntu/.pyenv/versions/3.6.1/lib/python3.6/site-packages/requests/api.py\", line 70, in get\n",
      "    return request('get', url, params=params, **kwargs)\n",
      "  File \"/home/ubuntu/.pyenv/versions/3.6.1/lib/python3.6/site-packages/requests/api.py\", line 56, in request\n",
      "    return session.request(method=method, url=url, **kwargs)\n",
      "  File \"/home/ubuntu/.pyenv/versions/3.6.1/lib/python3.6/site-packages/requests/sessions.py\", line 488, in request\n",
      "    resp = self.send(prep, **send_kwargs)\n",
      "  File \"/home/ubuntu/.pyenv/versions/3.6.1/lib/python3.6/site-packages/requests/sessions.py\", line 609, in send\n",
      "    r = adapter.send(request, **kwargs)\n",
      "  File \"/home/ubuntu/.pyenv/versions/3.6.1/lib/python3.6/site-packages/requests/adapters.py\", line 497, in send\n",
      "    raise SSLError(e, request=request)\n",
      "requests.exceptions.SSLError: (\"bad handshake: SysCallError(-1, 'Unexpected EOF')\",)\n",
      "\n",
      "During handling of the above exception, another exception occurred:\n",
      "\n",
      "Traceback (most recent call last):\n",
      "  File \"/home/ubuntu/.pyenv/versions/3.6.1/lib/python3.6/threading.py\", line 916, in _bootstrap_inner\n",
      "    self.run()\n",
      "  File \"/home/ubuntu/.pyenv/versions/3.6.1/lib/python3.6/threading.py\", line 864, in run\n",
      "    self._target(*self._args, **self._kwargs)\n",
      "  File \"<ipython-input-2-564dd7be0a3d>\", line 36, in grab_content\n",
      "    print ('Cannot retrieve contentfrom page {} Retry: {} Error; {} '.format(idx, 6 - count), e)\n",
      "IndexError: tuple index out of range\n",
      "\n"
     ]
    },
    {
     "name": "stdout",
     "output_type": "stream",
     "text": [
      "800 have been completed\n"
     ]
    },
    {
     "name": "stderr",
     "output_type": "stream",
     "text": [
      "Exception in thread Thread-436:\n",
      "Traceback (most recent call last):\n",
      "  File \"/home/ubuntu/.pyenv/versions/3.6.1/lib/python3.6/site-packages/requests/packages/urllib3/connection.py\", line 141, in _new_conn\n",
      "    (self.host, self.port), self.timeout, **extra_kw)\n",
      "  File \"/home/ubuntu/.pyenv/versions/3.6.1/lib/python3.6/site-packages/requests/packages/urllib3/util/connection.py\", line 83, in create_connection\n",
      "    raise err\n",
      "  File \"/home/ubuntu/.pyenv/versions/3.6.1/lib/python3.6/site-packages/requests/packages/urllib3/util/connection.py\", line 73, in create_connection\n",
      "    sock.connect(sa)\n",
      "TimeoutError: [Errno 110] Connection timed out\n",
      "\n",
      "During handling of the above exception, another exception occurred:\n",
      "\n",
      "Traceback (most recent call last):\n",
      "  File \"/home/ubuntu/.pyenv/versions/3.6.1/lib/python3.6/site-packages/requests/packages/urllib3/connectionpool.py\", line 600, in urlopen\n",
      "    chunked=chunked)\n",
      "  File \"/home/ubuntu/.pyenv/versions/3.6.1/lib/python3.6/site-packages/requests/packages/urllib3/connectionpool.py\", line 345, in _make_request\n",
      "    self._validate_conn(conn)\n",
      "  File \"/home/ubuntu/.pyenv/versions/3.6.1/lib/python3.6/site-packages/requests/packages/urllib3/connectionpool.py\", line 844, in _validate_conn\n",
      "    conn.connect()\n",
      "  File \"/home/ubuntu/.pyenv/versions/3.6.1/lib/python3.6/site-packages/requests/packages/urllib3/connection.py\", line 284, in connect\n",
      "    conn = self._new_conn()\n",
      "  File \"/home/ubuntu/.pyenv/versions/3.6.1/lib/python3.6/site-packages/requests/packages/urllib3/connection.py\", line 150, in _new_conn\n",
      "    self, \"Failed to establish a new connection: %s\" % e)\n",
      "requests.packages.urllib3.exceptions.NewConnectionError: <requests.packages.urllib3.connection.VerifiedHTTPSConnection object at 0x7f24b8a232b0>: Failed to establish a new connection: [Errno 110] Connection timed out\n",
      "\n",
      "During handling of the above exception, another exception occurred:\n",
      "\n",
      "Traceback (most recent call last):\n",
      "  File \"/home/ubuntu/.pyenv/versions/3.6.1/lib/python3.6/site-packages/requests/adapters.py\", line 423, in send\n",
      "    timeout=timeout\n",
      "  File \"/home/ubuntu/.pyenv/versions/3.6.1/lib/python3.6/site-packages/requests/packages/urllib3/connectionpool.py\", line 649, in urlopen\n",
      "    _stacktrace=sys.exc_info()[2])\n",
      "  File \"/home/ubuntu/.pyenv/versions/3.6.1/lib/python3.6/site-packages/requests/packages/urllib3/util/retry.py\", line 376, in increment\n",
      "    raise MaxRetryError(_pool, url, error or ResponseError(cause))\n",
      "requests.packages.urllib3.exceptions.MaxRetryError: HTTPSConnectionPool(host='www.1111.com.tw', port=443): Max retries exceeded with url: /job/78612885/ (Caused by NewConnectionError('<requests.packages.urllib3.connection.VerifiedHTTPSConnection object at 0x7f24b8a232b0>: Failed to establish a new connection: [Errno 110] Connection timed out',))\n",
      "\n",
      "During handling of the above exception, another exception occurred:\n",
      "\n",
      "Traceback (most recent call last):\n",
      "  File \"<ipython-input-2-564dd7be0a3d>\", line 10, in grab_content\n",
      "    res2 = requests.get(url, headers=HEADER)\n",
      "  File \"/home/ubuntu/.pyenv/versions/3.6.1/lib/python3.6/site-packages/requests/api.py\", line 70, in get\n",
      "    return request('get', url, params=params, **kwargs)\n",
      "  File \"/home/ubuntu/.pyenv/versions/3.6.1/lib/python3.6/site-packages/requests/api.py\", line 56, in request\n",
      "    return session.request(method=method, url=url, **kwargs)\n",
      "  File \"/home/ubuntu/.pyenv/versions/3.6.1/lib/python3.6/site-packages/requests/sessions.py\", line 488, in request\n",
      "    resp = self.send(prep, **send_kwargs)\n",
      "  File \"/home/ubuntu/.pyenv/versions/3.6.1/lib/python3.6/site-packages/requests/sessions.py\", line 609, in send\n",
      "    r = adapter.send(request, **kwargs)\n",
      "  File \"/home/ubuntu/.pyenv/versions/3.6.1/lib/python3.6/site-packages/requests/adapters.py\", line 487, in send\n",
      "    raise ConnectionError(e, request=request)\n",
      "requests.exceptions.ConnectionError: HTTPSConnectionPool(host='www.1111.com.tw', port=443): Max retries exceeded with url: /job/78612885/ (Caused by NewConnectionError('<requests.packages.urllib3.connection.VerifiedHTTPSConnection object at 0x7f24b8a232b0>: Failed to establish a new connection: [Errno 110] Connection timed out',))\n",
      "\n",
      "During handling of the above exception, another exception occurred:\n",
      "\n",
      "Traceback (most recent call last):\n",
      "  File \"/home/ubuntu/.pyenv/versions/3.6.1/lib/python3.6/threading.py\", line 916, in _bootstrap_inner\n",
      "    self.run()\n",
      "  File \"/home/ubuntu/.pyenv/versions/3.6.1/lib/python3.6/threading.py\", line 864, in run\n",
      "    self._target(*self._args, **self._kwargs)\n",
      "  File \"<ipython-input-2-564dd7be0a3d>\", line 36, in grab_content\n",
      "    print ('Cannot retrieve contentfrom page {} Retry: {} Error; {} '.format(idx, 6 - count), e)\n",
      "IndexError: tuple index out of range\n",
      "\n",
      "Exception in thread Thread-434:\n",
      "Traceback (most recent call last):\n",
      "  File \"/home/ubuntu/.pyenv/versions/3.6.1/lib/python3.6/site-packages/requests/packages/urllib3/connectionpool.py\", line 600, in urlopen\n",
      "    chunked=chunked)\n",
      "  File \"/home/ubuntu/.pyenv/versions/3.6.1/lib/python3.6/site-packages/requests/packages/urllib3/connectionpool.py\", line 386, in _make_request\n",
      "    six.raise_from(e, None)\n",
      "  File \"<string>\", line 2, in raise_from\n",
      "  File \"/home/ubuntu/.pyenv/versions/3.6.1/lib/python3.6/site-packages/requests/packages/urllib3/connectionpool.py\", line 382, in _make_request\n",
      "    httplib_response = conn.getresponse()\n",
      "  File \"/home/ubuntu/.pyenv/versions/3.6.1/lib/python3.6/http/client.py\", line 1331, in getresponse\n",
      "    response.begin()\n",
      "  File \"/home/ubuntu/.pyenv/versions/3.6.1/lib/python3.6/http/client.py\", line 297, in begin\n",
      "    version, status, reason = self._read_status()\n",
      "  File \"/home/ubuntu/.pyenv/versions/3.6.1/lib/python3.6/http/client.py\", line 266, in _read_status\n",
      "    raise RemoteDisconnected(\"Remote end closed connection without\"\n",
      "http.client.RemoteDisconnected: Remote end closed connection without response\n",
      "\n",
      "During handling of the above exception, another exception occurred:\n",
      "\n",
      "Traceback (most recent call last):\n",
      "  File \"/home/ubuntu/.pyenv/versions/3.6.1/lib/python3.6/site-packages/requests/adapters.py\", line 423, in send\n",
      "    timeout=timeout\n",
      "  File \"/home/ubuntu/.pyenv/versions/3.6.1/lib/python3.6/site-packages/requests/packages/urllib3/connectionpool.py\", line 649, in urlopen\n",
      "    _stacktrace=sys.exc_info()[2])\n",
      "  File \"/home/ubuntu/.pyenv/versions/3.6.1/lib/python3.6/site-packages/requests/packages/urllib3/util/retry.py\", line 347, in increment\n",
      "    raise six.reraise(type(error), error, _stacktrace)\n",
      "  File \"/home/ubuntu/.pyenv/versions/3.6.1/lib/python3.6/site-packages/requests/packages/urllib3/packages/six.py\", line 685, in reraise\n",
      "    raise value.with_traceback(tb)\n",
      "  File \"/home/ubuntu/.pyenv/versions/3.6.1/lib/python3.6/site-packages/requests/packages/urllib3/connectionpool.py\", line 600, in urlopen\n",
      "    chunked=chunked)\n",
      "  File \"/home/ubuntu/.pyenv/versions/3.6.1/lib/python3.6/site-packages/requests/packages/urllib3/connectionpool.py\", line 386, in _make_request\n",
      "    six.raise_from(e, None)\n",
      "  File \"<string>\", line 2, in raise_from\n",
      "  File \"/home/ubuntu/.pyenv/versions/3.6.1/lib/python3.6/site-packages/requests/packages/urllib3/connectionpool.py\", line 382, in _make_request\n",
      "    httplib_response = conn.getresponse()\n",
      "  File \"/home/ubuntu/.pyenv/versions/3.6.1/lib/python3.6/http/client.py\", line 1331, in getresponse\n",
      "    response.begin()\n",
      "  File \"/home/ubuntu/.pyenv/versions/3.6.1/lib/python3.6/http/client.py\", line 297, in begin\n",
      "    version, status, reason = self._read_status()\n",
      "  File \"/home/ubuntu/.pyenv/versions/3.6.1/lib/python3.6/http/client.py\", line 266, in _read_status\n",
      "    raise RemoteDisconnected(\"Remote end closed connection without\"\n",
      "requests.packages.urllib3.exceptions.ProtocolError: ('Connection aborted.', RemoteDisconnected('Remote end closed connection without response',))\n",
      "\n",
      "During handling of the above exception, another exception occurred:\n",
      "\n",
      "Traceback (most recent call last):\n",
      "  File \"<ipython-input-2-564dd7be0a3d>\", line 10, in grab_content\n",
      "    res2 = requests.get(url, headers=HEADER)\n",
      "  File \"/home/ubuntu/.pyenv/versions/3.6.1/lib/python3.6/site-packages/requests/api.py\", line 70, in get\n",
      "    return request('get', url, params=params, **kwargs)\n",
      "  File \"/home/ubuntu/.pyenv/versions/3.6.1/lib/python3.6/site-packages/requests/api.py\", line 56, in request\n",
      "    return session.request(method=method, url=url, **kwargs)\n",
      "  File \"/home/ubuntu/.pyenv/versions/3.6.1/lib/python3.6/site-packages/requests/sessions.py\", line 488, in request\n",
      "    resp = self.send(prep, **send_kwargs)\n",
      "  File \"/home/ubuntu/.pyenv/versions/3.6.1/lib/python3.6/site-packages/requests/sessions.py\", line 609, in send\n",
      "    r = adapter.send(request, **kwargs)\n",
      "  File \"/home/ubuntu/.pyenv/versions/3.6.1/lib/python3.6/site-packages/requests/adapters.py\", line 473, in send\n",
      "    raise ConnectionError(err, request=request)\n",
      "requests.exceptions.ConnectionError: ('Connection aborted.', RemoteDisconnected('Remote end closed connection without response',))\n",
      "\n",
      "During handling of the above exception, another exception occurred:\n",
      "\n",
      "Traceback (most recent call last):\n",
      "  File \"/home/ubuntu/.pyenv/versions/3.6.1/lib/python3.6/threading.py\", line 916, in _bootstrap_inner\n",
      "    self.run()\n",
      "  File \"/home/ubuntu/.pyenv/versions/3.6.1/lib/python3.6/threading.py\", line 864, in run\n",
      "    self._target(*self._args, **self._kwargs)\n",
      "  File \"<ipython-input-2-564dd7be0a3d>\", line 36, in grab_content\n",
      "    print ('Cannot retrieve contentfrom page {} Retry: {} Error; {} '.format(idx, 6 - count), e)\n",
      "IndexError: tuple index out of range\n",
      "\n",
      "Exception in thread Thread-448:\n",
      "Traceback (most recent call last):\n",
      "  File \"/home/ubuntu/.pyenv/versions/3.6.1/lib/python3.6/site-packages/requests/packages/urllib3/contrib/pyopenssl.py\", line 436, in wrap_socket\n",
      "    cnx.do_handshake()\n",
      "  File \"/home/ubuntu/.pyenv/versions/3.6.1/lib/python3.6/site-packages/OpenSSL/SSL.py\", line 1638, in do_handshake\n",
      "    self._raise_ssl_error(self._ssl, result)\n",
      "  File \"/home/ubuntu/.pyenv/versions/3.6.1/lib/python3.6/site-packages/OpenSSL/SSL.py\", line 1371, in _raise_ssl_error\n",
      "    raise SysCallError(-1, \"Unexpected EOF\")\n",
      "OpenSSL.SSL.SysCallError: (-1, 'Unexpected EOF')\n",
      "\n",
      "During handling of the above exception, another exception occurred:\n",
      "\n",
      "Traceback (most recent call last):\n",
      "  File \"/home/ubuntu/.pyenv/versions/3.6.1/lib/python3.6/site-packages/requests/packages/urllib3/connectionpool.py\", line 600, in urlopen\n",
      "    chunked=chunked)\n",
      "  File \"/home/ubuntu/.pyenv/versions/3.6.1/lib/python3.6/site-packages/requests/packages/urllib3/connectionpool.py\", line 345, in _make_request\n",
      "    self._validate_conn(conn)\n",
      "  File \"/home/ubuntu/.pyenv/versions/3.6.1/lib/python3.6/site-packages/requests/packages/urllib3/connectionpool.py\", line 844, in _validate_conn\n",
      "    conn.connect()\n",
      "  File \"/home/ubuntu/.pyenv/versions/3.6.1/lib/python3.6/site-packages/requests/packages/urllib3/connection.py\", line 326, in connect\n",
      "    ssl_context=context)\n",
      "  File \"/home/ubuntu/.pyenv/versions/3.6.1/lib/python3.6/site-packages/requests/packages/urllib3/util/ssl_.py\", line 324, in ssl_wrap_socket\n",
      "    return context.wrap_socket(sock, server_hostname=server_hostname)\n",
      "  File \"/home/ubuntu/.pyenv/versions/3.6.1/lib/python3.6/site-packages/requests/packages/urllib3/contrib/pyopenssl.py\", line 443, in wrap_socket\n",
      "    raise ssl.SSLError('bad handshake: %r' % e)\n",
      "ssl.SSLError: (\"bad handshake: SysCallError(-1, 'Unexpected EOF')\",)\n",
      "\n",
      "During handling of the above exception, another exception occurred:\n",
      "\n",
      "Traceback (most recent call last):\n",
      "  File \"/home/ubuntu/.pyenv/versions/3.6.1/lib/python3.6/site-packages/requests/adapters.py\", line 423, in send\n",
      "    timeout=timeout\n",
      "  File \"/home/ubuntu/.pyenv/versions/3.6.1/lib/python3.6/site-packages/requests/packages/urllib3/connectionpool.py\", line 630, in urlopen\n",
      "    raise SSLError(e)\n",
      "requests.packages.urllib3.exceptions.SSLError: (\"bad handshake: SysCallError(-1, 'Unexpected EOF')\",)\n",
      "\n",
      "During handling of the above exception, another exception occurred:\n",
      "\n",
      "Traceback (most recent call last):\n",
      "  File \"<ipython-input-2-564dd7be0a3d>\", line 10, in grab_content\n",
      "    res2 = requests.get(url, headers=HEADER)\n",
      "  File \"/home/ubuntu/.pyenv/versions/3.6.1/lib/python3.6/site-packages/requests/api.py\", line 70, in get\n",
      "    return request('get', url, params=params, **kwargs)\n",
      "  File \"/home/ubuntu/.pyenv/versions/3.6.1/lib/python3.6/site-packages/requests/api.py\", line 56, in request\n",
      "    return session.request(method=method, url=url, **kwargs)\n",
      "  File \"/home/ubuntu/.pyenv/versions/3.6.1/lib/python3.6/site-packages/requests/sessions.py\", line 488, in request\n",
      "    resp = self.send(prep, **send_kwargs)\n",
      "  File \"/home/ubuntu/.pyenv/versions/3.6.1/lib/python3.6/site-packages/requests/sessions.py\", line 609, in send\n",
      "    r = adapter.send(request, **kwargs)\n",
      "  File \"/home/ubuntu/.pyenv/versions/3.6.1/lib/python3.6/site-packages/requests/adapters.py\", line 497, in send\n",
      "    raise SSLError(e, request=request)\n",
      "requests.exceptions.SSLError: (\"bad handshake: SysCallError(-1, 'Unexpected EOF')\",)\n",
      "\n",
      "During handling of the above exception, another exception occurred:\n",
      "\n",
      "Traceback (most recent call last):\n",
      "  File \"/home/ubuntu/.pyenv/versions/3.6.1/lib/python3.6/threading.py\", line 916, in _bootstrap_inner\n",
      "    self.run()\n",
      "  File \"/home/ubuntu/.pyenv/versions/3.6.1/lib/python3.6/threading.py\", line 864, in run\n",
      "    self._target(*self._args, **self._kwargs)\n",
      "  File \"<ipython-input-2-564dd7be0a3d>\", line 36, in grab_content\n",
      "    print ('Cannot retrieve contentfrom page {} Retry: {} Error; {} '.format(idx, 6 - count), e)\n",
      "IndexError: tuple index out of range\n",
      "\n",
      "Exception in thread Thread-416:\n",
      "Traceback (most recent call last):\n",
      "  File \"/home/ubuntu/.pyenv/versions/3.6.1/lib/python3.6/site-packages/requests/packages/urllib3/contrib/pyopenssl.py\", line 436, in wrap_socket\n",
      "    cnx.do_handshake()\n",
      "  File \"/home/ubuntu/.pyenv/versions/3.6.1/lib/python3.6/site-packages/OpenSSL/SSL.py\", line 1638, in do_handshake\n",
      "    self._raise_ssl_error(self._ssl, result)\n",
      "  File \"/home/ubuntu/.pyenv/versions/3.6.1/lib/python3.6/site-packages/OpenSSL/SSL.py\", line 1371, in _raise_ssl_error\n",
      "    raise SysCallError(-1, \"Unexpected EOF\")\n",
      "OpenSSL.SSL.SysCallError: (-1, 'Unexpected EOF')\n",
      "\n",
      "During handling of the above exception, another exception occurred:\n",
      "\n",
      "Traceback (most recent call last):\n",
      "  File \"/home/ubuntu/.pyenv/versions/3.6.1/lib/python3.6/site-packages/requests/packages/urllib3/connectionpool.py\", line 600, in urlopen\n",
      "    chunked=chunked)\n",
      "  File \"/home/ubuntu/.pyenv/versions/3.6.1/lib/python3.6/site-packages/requests/packages/urllib3/connectionpool.py\", line 345, in _make_request\n",
      "    self._validate_conn(conn)\n",
      "  File \"/home/ubuntu/.pyenv/versions/3.6.1/lib/python3.6/site-packages/requests/packages/urllib3/connectionpool.py\", line 844, in _validate_conn\n",
      "    conn.connect()\n",
      "  File \"/home/ubuntu/.pyenv/versions/3.6.1/lib/python3.6/site-packages/requests/packages/urllib3/connection.py\", line 326, in connect\n",
      "    ssl_context=context)\n",
      "  File \"/home/ubuntu/.pyenv/versions/3.6.1/lib/python3.6/site-packages/requests/packages/urllib3/util/ssl_.py\", line 324, in ssl_wrap_socket\n",
      "    return context.wrap_socket(sock, server_hostname=server_hostname)\n",
      "  File \"/home/ubuntu/.pyenv/versions/3.6.1/lib/python3.6/site-packages/requests/packages/urllib3/contrib/pyopenssl.py\", line 443, in wrap_socket\n",
      "    raise ssl.SSLError('bad handshake: %r' % e)\n",
      "ssl.SSLError: (\"bad handshake: SysCallError(-1, 'Unexpected EOF')\",)\n",
      "\n",
      "During handling of the above exception, another exception occurred:\n",
      "\n",
      "Traceback (most recent call last):\n",
      "  File \"/home/ubuntu/.pyenv/versions/3.6.1/lib/python3.6/site-packages/requests/adapters.py\", line 423, in send\n",
      "    timeout=timeout\n",
      "  File \"/home/ubuntu/.pyenv/versions/3.6.1/lib/python3.6/site-packages/requests/packages/urllib3/connectionpool.py\", line 630, in urlopen\n",
      "    raise SSLError(e)\n",
      "requests.packages.urllib3.exceptions.SSLError: (\"bad handshake: SysCallError(-1, 'Unexpected EOF')\",)\n",
      "\n",
      "During handling of the above exception, another exception occurred:\n",
      "\n",
      "Traceback (most recent call last):\n",
      "  File \"<ipython-input-2-564dd7be0a3d>\", line 10, in grab_content\n",
      "    res2 = requests.get(url, headers=HEADER)\n",
      "  File \"/home/ubuntu/.pyenv/versions/3.6.1/lib/python3.6/site-packages/requests/api.py\", line 70, in get\n",
      "    return request('get', url, params=params, **kwargs)\n",
      "  File \"/home/ubuntu/.pyenv/versions/3.6.1/lib/python3.6/site-packages/requests/api.py\", line 56, in request\n",
      "    return session.request(method=method, url=url, **kwargs)\n",
      "  File \"/home/ubuntu/.pyenv/versions/3.6.1/lib/python3.6/site-packages/requests/sessions.py\", line 488, in request\n",
      "    resp = self.send(prep, **send_kwargs)\n",
      "  File \"/home/ubuntu/.pyenv/versions/3.6.1/lib/python3.6/site-packages/requests/sessions.py\", line 609, in send\n",
      "    r = adapter.send(request, **kwargs)\n",
      "  File \"/home/ubuntu/.pyenv/versions/3.6.1/lib/python3.6/site-packages/requests/adapters.py\", line 497, in send\n",
      "    raise SSLError(e, request=request)\n",
      "requests.exceptions.SSLError: (\"bad handshake: SysCallError(-1, 'Unexpected EOF')\",)\n",
      "\n",
      "During handling of the above exception, another exception occurred:\n",
      "\n",
      "Traceback (most recent call last):\n",
      "  File \"/home/ubuntu/.pyenv/versions/3.6.1/lib/python3.6/threading.py\", line 916, in _bootstrap_inner\n",
      "    self.run()\n",
      "  File \"/home/ubuntu/.pyenv/versions/3.6.1/lib/python3.6/threading.py\", line 864, in run\n",
      "    self._target(*self._args, **self._kwargs)\n",
      "  File \"<ipython-input-2-564dd7be0a3d>\", line 36, in grab_content\n",
      "    print ('Cannot retrieve contentfrom page {} Retry: {} Error; {} '.format(idx, 6 - count), e)\n",
      "IndexError: tuple index out of range\n",
      "\n",
      "Exception in thread Thread-444:\n",
      "Traceback (most recent call last):\n",
      "  File \"/home/ubuntu/.pyenv/versions/3.6.1/lib/python3.6/site-packages/requests/packages/urllib3/connection.py\", line 141, in _new_conn\n",
      "    (self.host, self.port), self.timeout, **extra_kw)\n",
      "  File \"/home/ubuntu/.pyenv/versions/3.6.1/lib/python3.6/site-packages/requests/packages/urllib3/util/connection.py\", line 83, in create_connection\n",
      "    raise err\n",
      "  File \"/home/ubuntu/.pyenv/versions/3.6.1/lib/python3.6/site-packages/requests/packages/urllib3/util/connection.py\", line 73, in create_connection\n",
      "    sock.connect(sa)\n",
      "TimeoutError: [Errno 110] Connection timed out\n",
      "\n",
      "During handling of the above exception, another exception occurred:\n",
      "\n",
      "Traceback (most recent call last):\n",
      "  File \"/home/ubuntu/.pyenv/versions/3.6.1/lib/python3.6/site-packages/requests/packages/urllib3/connectionpool.py\", line 600, in urlopen\n",
      "    chunked=chunked)\n",
      "  File \"/home/ubuntu/.pyenv/versions/3.6.1/lib/python3.6/site-packages/requests/packages/urllib3/connectionpool.py\", line 345, in _make_request\n",
      "    self._validate_conn(conn)\n",
      "  File \"/home/ubuntu/.pyenv/versions/3.6.1/lib/python3.6/site-packages/requests/packages/urllib3/connectionpool.py\", line 844, in _validate_conn\n",
      "    conn.connect()\n",
      "  File \"/home/ubuntu/.pyenv/versions/3.6.1/lib/python3.6/site-packages/requests/packages/urllib3/connection.py\", line 284, in connect\n",
      "    conn = self._new_conn()\n",
      "  File \"/home/ubuntu/.pyenv/versions/3.6.1/lib/python3.6/site-packages/requests/packages/urllib3/connection.py\", line 150, in _new_conn\n",
      "    self, \"Failed to establish a new connection: %s\" % e)\n",
      "requests.packages.urllib3.exceptions.NewConnectionError: <requests.packages.urllib3.connection.VerifiedHTTPSConnection object at 0x7f24b24a0780>: Failed to establish a new connection: [Errno 110] Connection timed out\n",
      "\n",
      "During handling of the above exception, another exception occurred:\n",
      "\n",
      "Traceback (most recent call last):\n",
      "  File \"/home/ubuntu/.pyenv/versions/3.6.1/lib/python3.6/site-packages/requests/adapters.py\", line 423, in send\n",
      "    timeout=timeout\n",
      "  File \"/home/ubuntu/.pyenv/versions/3.6.1/lib/python3.6/site-packages/requests/packages/urllib3/connectionpool.py\", line 649, in urlopen\n",
      "    _stacktrace=sys.exc_info()[2])\n",
      "  File \"/home/ubuntu/.pyenv/versions/3.6.1/lib/python3.6/site-packages/requests/packages/urllib3/util/retry.py\", line 376, in increment\n",
      "    raise MaxRetryError(_pool, url, error or ResponseError(cause))\n",
      "requests.packages.urllib3.exceptions.MaxRetryError: HTTPSConnectionPool(host='www.1111.com.tw', port=443): Max retries exceeded with url: /job/78598560/ (Caused by NewConnectionError('<requests.packages.urllib3.connection.VerifiedHTTPSConnection object at 0x7f24b24a0780>: Failed to establish a new connection: [Errno 110] Connection timed out',))\n",
      "\n",
      "During handling of the above exception, another exception occurred:\n",
      "\n",
      "Traceback (most recent call last):\n",
      "  File \"<ipython-input-2-564dd7be0a3d>\", line 10, in grab_content\n",
      "    res2 = requests.get(url, headers=HEADER)\n",
      "  File \"/home/ubuntu/.pyenv/versions/3.6.1/lib/python3.6/site-packages/requests/api.py\", line 70, in get\n",
      "    return request('get', url, params=params, **kwargs)\n",
      "  File \"/home/ubuntu/.pyenv/versions/3.6.1/lib/python3.6/site-packages/requests/api.py\", line 56, in request\n",
      "    return session.request(method=method, url=url, **kwargs)\n",
      "  File \"/home/ubuntu/.pyenv/versions/3.6.1/lib/python3.6/site-packages/requests/sessions.py\", line 488, in request\n",
      "    resp = self.send(prep, **send_kwargs)\n",
      "  File \"/home/ubuntu/.pyenv/versions/3.6.1/lib/python3.6/site-packages/requests/sessions.py\", line 609, in send\n",
      "    r = adapter.send(request, **kwargs)\n",
      "  File \"/home/ubuntu/.pyenv/versions/3.6.1/lib/python3.6/site-packages/requests/adapters.py\", line 487, in send\n",
      "    raise ConnectionError(e, request=request)\n",
      "requests.exceptions.ConnectionError: HTTPSConnectionPool(host='www.1111.com.tw', port=443): Max retries exceeded with url: /job/78598560/ (Caused by NewConnectionError('<requests.packages.urllib3.connection.VerifiedHTTPSConnection object at 0x7f24b24a0780>: Failed to establish a new connection: [Errno 110] Connection timed out',))\n",
      "\n",
      "During handling of the above exception, another exception occurred:\n",
      "\n",
      "Traceback (most recent call last):\n",
      "  File \"/home/ubuntu/.pyenv/versions/3.6.1/lib/python3.6/threading.py\", line 916, in _bootstrap_inner\n",
      "    self.run()\n",
      "  File \"/home/ubuntu/.pyenv/versions/3.6.1/lib/python3.6/threading.py\", line 864, in run\n",
      "    self._target(*self._args, **self._kwargs)\n",
      "  File \"<ipython-input-2-564dd7be0a3d>\", line 36, in grab_content\n",
      "    print ('Cannot retrieve contentfrom page {} Retry: {} Error; {} '.format(idx, 6 - count), e)\n",
      "IndexError: tuple index out of range\n",
      "\n",
      "Exception in thread Thread-450:\n",
      "Traceback (most recent call last):\n",
      "  File \"/home/ubuntu/.pyenv/versions/3.6.1/lib/python3.6/site-packages/requests/packages/urllib3/connection.py\", line 141, in _new_conn\n",
      "    (self.host, self.port), self.timeout, **extra_kw)\n",
      "  File \"/home/ubuntu/.pyenv/versions/3.6.1/lib/python3.6/site-packages/requests/packages/urllib3/util/connection.py\", line 83, in create_connection\n",
      "    raise err\n",
      "  File \"/home/ubuntu/.pyenv/versions/3.6.1/lib/python3.6/site-packages/requests/packages/urllib3/util/connection.py\", line 73, in create_connection\n",
      "    sock.connect(sa)\n",
      "TimeoutError: [Errno 110] Connection timed out\n",
      "\n",
      "During handling of the above exception, another exception occurred:\n",
      "\n",
      "Traceback (most recent call last):\n",
      "  File \"/home/ubuntu/.pyenv/versions/3.6.1/lib/python3.6/site-packages/requests/packages/urllib3/connectionpool.py\", line 600, in urlopen\n",
      "    chunked=chunked)\n",
      "  File \"/home/ubuntu/.pyenv/versions/3.6.1/lib/python3.6/site-packages/requests/packages/urllib3/connectionpool.py\", line 345, in _make_request\n",
      "    self._validate_conn(conn)\n",
      "  File \"/home/ubuntu/.pyenv/versions/3.6.1/lib/python3.6/site-packages/requests/packages/urllib3/connectionpool.py\", line 844, in _validate_conn\n",
      "    conn.connect()\n",
      "  File \"/home/ubuntu/.pyenv/versions/3.6.1/lib/python3.6/site-packages/requests/packages/urllib3/connection.py\", line 284, in connect\n",
      "    conn = self._new_conn()\n",
      "  File \"/home/ubuntu/.pyenv/versions/3.6.1/lib/python3.6/site-packages/requests/packages/urllib3/connection.py\", line 150, in _new_conn\n",
      "    self, \"Failed to establish a new connection: %s\" % e)\n",
      "requests.packages.urllib3.exceptions.NewConnectionError: <requests.packages.urllib3.connection.VerifiedHTTPSConnection object at 0x7f24f8471748>: Failed to establish a new connection: [Errno 110] Connection timed out\n",
      "\n",
      "During handling of the above exception, another exception occurred:\n",
      "\n",
      "Traceback (most recent call last):\n",
      "  File \"/home/ubuntu/.pyenv/versions/3.6.1/lib/python3.6/site-packages/requests/adapters.py\", line 423, in send\n",
      "    timeout=timeout\n",
      "  File \"/home/ubuntu/.pyenv/versions/3.6.1/lib/python3.6/site-packages/requests/packages/urllib3/connectionpool.py\", line 649, in urlopen\n",
      "    _stacktrace=sys.exc_info()[2])\n",
      "  File \"/home/ubuntu/.pyenv/versions/3.6.1/lib/python3.6/site-packages/requests/packages/urllib3/util/retry.py\", line 376, in increment\n",
      "    raise MaxRetryError(_pool, url, error or ResponseError(cause))\n",
      "requests.packages.urllib3.exceptions.MaxRetryError: HTTPSConnectionPool(host='www.1111.com.tw', port=443): Max retries exceeded with url: /job/78585695/ (Caused by NewConnectionError('<requests.packages.urllib3.connection.VerifiedHTTPSConnection object at 0x7f24f8471748>: Failed to establish a new connection: [Errno 110] Connection timed out',))\n",
      "\n",
      "During handling of the above exception, another exception occurred:\n",
      "\n",
      "Traceback (most recent call last):\n",
      "  File \"<ipython-input-2-564dd7be0a3d>\", line 10, in grab_content\n",
      "    res2 = requests.get(url, headers=HEADER)\n",
      "  File \"/home/ubuntu/.pyenv/versions/3.6.1/lib/python3.6/site-packages/requests/api.py\", line 70, in get\n",
      "    return request('get', url, params=params, **kwargs)\n",
      "  File \"/home/ubuntu/.pyenv/versions/3.6.1/lib/python3.6/site-packages/requests/api.py\", line 56, in request\n",
      "    return session.request(method=method, url=url, **kwargs)\n",
      "  File \"/home/ubuntu/.pyenv/versions/3.6.1/lib/python3.6/site-packages/requests/sessions.py\", line 488, in request\n",
      "    resp = self.send(prep, **send_kwargs)\n",
      "  File \"/home/ubuntu/.pyenv/versions/3.6.1/lib/python3.6/site-packages/requests/sessions.py\", line 609, in send\n",
      "    r = adapter.send(request, **kwargs)\n",
      "  File \"/home/ubuntu/.pyenv/versions/3.6.1/lib/python3.6/site-packages/requests/adapters.py\", line 487, in send\n",
      "    raise ConnectionError(e, request=request)\n",
      "requests.exceptions.ConnectionError: HTTPSConnectionPool(host='www.1111.com.tw', port=443): Max retries exceeded with url: /job/78585695/ (Caused by NewConnectionError('<requests.packages.urllib3.connection.VerifiedHTTPSConnection object at 0x7f24f8471748>: Failed to establish a new connection: [Errno 110] Connection timed out',))\n",
      "\n",
      "During handling of the above exception, another exception occurred:\n",
      "\n",
      "Traceback (most recent call last):\n",
      "  File \"/home/ubuntu/.pyenv/versions/3.6.1/lib/python3.6/threading.py\", line 916, in _bootstrap_inner\n",
      "    self.run()\n",
      "  File \"/home/ubuntu/.pyenv/versions/3.6.1/lib/python3.6/threading.py\", line 864, in run\n",
      "    self._target(*self._args, **self._kwargs)\n",
      "  File \"<ipython-input-2-564dd7be0a3d>\", line 36, in grab_content\n",
      "    print ('Cannot retrieve contentfrom page {} Retry: {} Error; {} '.format(idx, 6 - count), e)\n",
      "IndexError: tuple index out of range\n",
      "\n",
      "Exception in thread Thread-443:\n",
      "Traceback (most recent call last):\n",
      "  File \"/home/ubuntu/.pyenv/versions/3.6.1/lib/python3.6/site-packages/requests/packages/urllib3/connection.py\", line 141, in _new_conn\n",
      "    (self.host, self.port), self.timeout, **extra_kw)\n",
      "  File \"/home/ubuntu/.pyenv/versions/3.6.1/lib/python3.6/site-packages/requests/packages/urllib3/util/connection.py\", line 83, in create_connection\n",
      "    raise err\n",
      "  File \"/home/ubuntu/.pyenv/versions/3.6.1/lib/python3.6/site-packages/requests/packages/urllib3/util/connection.py\", line 73, in create_connection\n",
      "    sock.connect(sa)\n",
      "TimeoutError: [Errno 110] Connection timed out\n",
      "\n",
      "During handling of the above exception, another exception occurred:\n",
      "\n",
      "Traceback (most recent call last):\n",
      "  File \"/home/ubuntu/.pyenv/versions/3.6.1/lib/python3.6/site-packages/requests/packages/urllib3/connectionpool.py\", line 600, in urlopen\n",
      "    chunked=chunked)\n",
      "  File \"/home/ubuntu/.pyenv/versions/3.6.1/lib/python3.6/site-packages/requests/packages/urllib3/connectionpool.py\", line 345, in _make_request\n",
      "    self._validate_conn(conn)\n",
      "  File \"/home/ubuntu/.pyenv/versions/3.6.1/lib/python3.6/site-packages/requests/packages/urllib3/connectionpool.py\", line 844, in _validate_conn\n",
      "    conn.connect()\n",
      "  File \"/home/ubuntu/.pyenv/versions/3.6.1/lib/python3.6/site-packages/requests/packages/urllib3/connection.py\", line 284, in connect\n",
      "    conn = self._new_conn()\n",
      "  File \"/home/ubuntu/.pyenv/versions/3.6.1/lib/python3.6/site-packages/requests/packages/urllib3/connection.py\", line 150, in _new_conn\n",
      "    self, \"Failed to establish a new connection: %s\" % e)\n",
      "requests.packages.urllib3.exceptions.NewConnectionError: <requests.packages.urllib3.connection.VerifiedHTTPSConnection object at 0x7f24b0b67860>: Failed to establish a new connection: [Errno 110] Connection timed out\n",
      "\n",
      "During handling of the above exception, another exception occurred:\n",
      "\n",
      "Traceback (most recent call last):\n",
      "  File \"/home/ubuntu/.pyenv/versions/3.6.1/lib/python3.6/site-packages/requests/adapters.py\", line 423, in send\n",
      "    timeout=timeout\n",
      "  File \"/home/ubuntu/.pyenv/versions/3.6.1/lib/python3.6/site-packages/requests/packages/urllib3/connectionpool.py\", line 649, in urlopen\n",
      "    _stacktrace=sys.exc_info()[2])\n",
      "  File \"/home/ubuntu/.pyenv/versions/3.6.1/lib/python3.6/site-packages/requests/packages/urllib3/util/retry.py\", line 376, in increment\n",
      "    raise MaxRetryError(_pool, url, error or ResponseError(cause))\n",
      "requests.packages.urllib3.exceptions.MaxRetryError: HTTPSConnectionPool(host='www.1111.com.tw', port=443): Max retries exceeded with url: /job/78598565/ (Caused by NewConnectionError('<requests.packages.urllib3.connection.VerifiedHTTPSConnection object at 0x7f24b0b67860>: Failed to establish a new connection: [Errno 110] Connection timed out',))\n",
      "\n",
      "During handling of the above exception, another exception occurred:\n",
      "\n",
      "Traceback (most recent call last):\n",
      "  File \"<ipython-input-2-564dd7be0a3d>\", line 10, in grab_content\n",
      "    res2 = requests.get(url, headers=HEADER)\n",
      "  File \"/home/ubuntu/.pyenv/versions/3.6.1/lib/python3.6/site-packages/requests/api.py\", line 70, in get\n",
      "    return request('get', url, params=params, **kwargs)\n",
      "  File \"/home/ubuntu/.pyenv/versions/3.6.1/lib/python3.6/site-packages/requests/api.py\", line 56, in request\n",
      "    return session.request(method=method, url=url, **kwargs)\n",
      "  File \"/home/ubuntu/.pyenv/versions/3.6.1/lib/python3.6/site-packages/requests/sessions.py\", line 488, in request\n",
      "    resp = self.send(prep, **send_kwargs)\n",
      "  File \"/home/ubuntu/.pyenv/versions/3.6.1/lib/python3.6/site-packages/requests/sessions.py\", line 609, in send\n",
      "    r = adapter.send(request, **kwargs)\n",
      "  File \"/home/ubuntu/.pyenv/versions/3.6.1/lib/python3.6/site-packages/requests/adapters.py\", line 487, in send\n",
      "    raise ConnectionError(e, request=request)\n",
      "requests.exceptions.ConnectionError: HTTPSConnectionPool(host='www.1111.com.tw', port=443): Max retries exceeded with url: /job/78598565/ (Caused by NewConnectionError('<requests.packages.urllib3.connection.VerifiedHTTPSConnection object at 0x7f24b0b67860>: Failed to establish a new connection: [Errno 110] Connection timed out',))\n",
      "\n",
      "During handling of the above exception, another exception occurred:\n",
      "\n",
      "Traceback (most recent call last):\n",
      "  File \"/home/ubuntu/.pyenv/versions/3.6.1/lib/python3.6/threading.py\", line 916, in _bootstrap_inner\n",
      "    self.run()\n",
      "  File \"/home/ubuntu/.pyenv/versions/3.6.1/lib/python3.6/threading.py\", line 864, in run\n",
      "    self._target(*self._args, **self._kwargs)\n",
      "  File \"<ipython-input-2-564dd7be0a3d>\", line 36, in grab_content\n",
      "    print ('Cannot retrieve contentfrom page {} Retry: {} Error; {} '.format(idx, 6 - count), e)\n",
      "IndexError: tuple index out of range\n",
      "\n",
      "Exception in thread Thread-470:\n",
      "Traceback (most recent call last):\n",
      "  File \"/home/ubuntu/.pyenv/versions/3.6.1/lib/python3.6/site-packages/requests/packages/urllib3/connection.py\", line 141, in _new_conn\n",
      "    (self.host, self.port), self.timeout, **extra_kw)\n",
      "  File \"/home/ubuntu/.pyenv/versions/3.6.1/lib/python3.6/site-packages/requests/packages/urllib3/util/connection.py\", line 83, in create_connection\n",
      "    raise err\n",
      "  File \"/home/ubuntu/.pyenv/versions/3.6.1/lib/python3.6/site-packages/requests/packages/urllib3/util/connection.py\", line 73, in create_connection\n",
      "    sock.connect(sa)\n",
      "TimeoutError: [Errno 110] Connection timed out\n",
      "\n",
      "During handling of the above exception, another exception occurred:\n",
      "\n",
      "Traceback (most recent call last):\n",
      "  File \"/home/ubuntu/.pyenv/versions/3.6.1/lib/python3.6/site-packages/requests/packages/urllib3/connectionpool.py\", line 600, in urlopen\n",
      "    chunked=chunked)\n",
      "  File \"/home/ubuntu/.pyenv/versions/3.6.1/lib/python3.6/site-packages/requests/packages/urllib3/connectionpool.py\", line 345, in _make_request\n",
      "    self._validate_conn(conn)\n",
      "  File \"/home/ubuntu/.pyenv/versions/3.6.1/lib/python3.6/site-packages/requests/packages/urllib3/connectionpool.py\", line 844, in _validate_conn\n",
      "    conn.connect()\n",
      "  File \"/home/ubuntu/.pyenv/versions/3.6.1/lib/python3.6/site-packages/requests/packages/urllib3/connection.py\", line 284, in connect\n",
      "    conn = self._new_conn()\n",
      "  File \"/home/ubuntu/.pyenv/versions/3.6.1/lib/python3.6/site-packages/requests/packages/urllib3/connection.py\", line 150, in _new_conn\n",
      "    self, \"Failed to establish a new connection: %s\" % e)\n",
      "requests.packages.urllib3.exceptions.NewConnectionError: <requests.packages.urllib3.connection.VerifiedHTTPSConnection object at 0x7f24f8449940>: Failed to establish a new connection: [Errno 110] Connection timed out\n",
      "\n",
      "During handling of the above exception, another exception occurred:\n",
      "\n",
      "Traceback (most recent call last):\n",
      "  File \"/home/ubuntu/.pyenv/versions/3.6.1/lib/python3.6/site-packages/requests/adapters.py\", line 423, in send\n",
      "    timeout=timeout\n",
      "  File \"/home/ubuntu/.pyenv/versions/3.6.1/lib/python3.6/site-packages/requests/packages/urllib3/connectionpool.py\", line 649, in urlopen\n",
      "    _stacktrace=sys.exc_info()[2])\n",
      "  File \"/home/ubuntu/.pyenv/versions/3.6.1/lib/python3.6/site-packages/requests/packages/urllib3/util/retry.py\", line 376, in increment\n",
      "    raise MaxRetryError(_pool, url, error or ResponseError(cause))\n",
      "requests.packages.urllib3.exceptions.MaxRetryError: HTTPSConnectionPool(host='www.1111.com.tw', port=443): Max retries exceeded with url: /job/78535228/ (Caused by NewConnectionError('<requests.packages.urllib3.connection.VerifiedHTTPSConnection object at 0x7f24f8449940>: Failed to establish a new connection: [Errno 110] Connection timed out',))\n",
      "\n",
      "During handling of the above exception, another exception occurred:\n",
      "\n",
      "Traceback (most recent call last):\n",
      "  File \"<ipython-input-2-564dd7be0a3d>\", line 10, in grab_content\n",
      "    res2 = requests.get(url, headers=HEADER)\n",
      "  File \"/home/ubuntu/.pyenv/versions/3.6.1/lib/python3.6/site-packages/requests/api.py\", line 70, in get\n",
      "    return request('get', url, params=params, **kwargs)\n",
      "  File \"/home/ubuntu/.pyenv/versions/3.6.1/lib/python3.6/site-packages/requests/api.py\", line 56, in request\n",
      "    return session.request(method=method, url=url, **kwargs)\n",
      "  File \"/home/ubuntu/.pyenv/versions/3.6.1/lib/python3.6/site-packages/requests/sessions.py\", line 488, in request\n",
      "    resp = self.send(prep, **send_kwargs)\n",
      "  File \"/home/ubuntu/.pyenv/versions/3.6.1/lib/python3.6/site-packages/requests/sessions.py\", line 609, in send\n",
      "    r = adapter.send(request, **kwargs)\n",
      "  File \"/home/ubuntu/.pyenv/versions/3.6.1/lib/python3.6/site-packages/requests/adapters.py\", line 487, in send\n",
      "    raise ConnectionError(e, request=request)\n",
      "requests.exceptions.ConnectionError: HTTPSConnectionPool(host='www.1111.com.tw', port=443): Max retries exceeded with url: /job/78535228/ (Caused by NewConnectionError('<requests.packages.urllib3.connection.VerifiedHTTPSConnection object at 0x7f24f8449940>: Failed to establish a new connection: [Errno 110] Connection timed out',))\n",
      "\n",
      "During handling of the above exception, another exception occurred:\n",
      "\n",
      "Traceback (most recent call last):\n",
      "  File \"/home/ubuntu/.pyenv/versions/3.6.1/lib/python3.6/threading.py\", line 916, in _bootstrap_inner\n",
      "    self.run()\n",
      "  File \"/home/ubuntu/.pyenv/versions/3.6.1/lib/python3.6/threading.py\", line 864, in run\n",
      "    self._target(*self._args, **self._kwargs)\n",
      "  File \"<ipython-input-2-564dd7be0a3d>\", line 36, in grab_content\n",
      "    print ('Cannot retrieve contentfrom page {} Retry: {} Error; {} '.format(idx, 6 - count), e)\n",
      "IndexError: tuple index out of range\n",
      "\n"
     ]
    },
    {
     "name": "stdout",
     "output_type": "stream",
     "text": [
      "1000 have been completed\n"
     ]
    },
    {
     "name": "stderr",
     "output_type": "stream",
     "text": [
      "Exception in thread Thread-461:\n",
      "Traceback (most recent call last):\n",
      "  File \"/home/ubuntu/.pyenv/versions/3.6.1/lib/python3.6/site-packages/requests/packages/urllib3/connectionpool.py\", line 600, in urlopen\n",
      "    chunked=chunked)\n",
      "  File \"/home/ubuntu/.pyenv/versions/3.6.1/lib/python3.6/site-packages/requests/packages/urllib3/connectionpool.py\", line 386, in _make_request\n",
      "    six.raise_from(e, None)\n",
      "  File \"<string>\", line 2, in raise_from\n",
      "  File \"/home/ubuntu/.pyenv/versions/3.6.1/lib/python3.6/site-packages/requests/packages/urllib3/connectionpool.py\", line 382, in _make_request\n",
      "    httplib_response = conn.getresponse()\n",
      "  File \"/home/ubuntu/.pyenv/versions/3.6.1/lib/python3.6/http/client.py\", line 1331, in getresponse\n",
      "    response.begin()\n",
      "  File \"/home/ubuntu/.pyenv/versions/3.6.1/lib/python3.6/http/client.py\", line 297, in begin\n",
      "    version, status, reason = self._read_status()\n",
      "  File \"/home/ubuntu/.pyenv/versions/3.6.1/lib/python3.6/http/client.py\", line 266, in _read_status\n",
      "    raise RemoteDisconnected(\"Remote end closed connection without\"\n",
      "http.client.RemoteDisconnected: Remote end closed connection without response\n",
      "\n",
      "During handling of the above exception, another exception occurred:\n",
      "\n",
      "Traceback (most recent call last):\n",
      "  File \"/home/ubuntu/.pyenv/versions/3.6.1/lib/python3.6/site-packages/requests/adapters.py\", line 423, in send\n",
      "    timeout=timeout\n",
      "  File \"/home/ubuntu/.pyenv/versions/3.6.1/lib/python3.6/site-packages/requests/packages/urllib3/connectionpool.py\", line 649, in urlopen\n",
      "    _stacktrace=sys.exc_info()[2])\n",
      "  File \"/home/ubuntu/.pyenv/versions/3.6.1/lib/python3.6/site-packages/requests/packages/urllib3/util/retry.py\", line 347, in increment\n",
      "    raise six.reraise(type(error), error, _stacktrace)\n",
      "  File \"/home/ubuntu/.pyenv/versions/3.6.1/lib/python3.6/site-packages/requests/packages/urllib3/packages/six.py\", line 685, in reraise\n",
      "    raise value.with_traceback(tb)\n",
      "  File \"/home/ubuntu/.pyenv/versions/3.6.1/lib/python3.6/site-packages/requests/packages/urllib3/connectionpool.py\", line 600, in urlopen\n",
      "    chunked=chunked)\n",
      "  File \"/home/ubuntu/.pyenv/versions/3.6.1/lib/python3.6/site-packages/requests/packages/urllib3/connectionpool.py\", line 386, in _make_request\n",
      "    six.raise_from(e, None)\n",
      "  File \"<string>\", line 2, in raise_from\n",
      "  File \"/home/ubuntu/.pyenv/versions/3.6.1/lib/python3.6/site-packages/requests/packages/urllib3/connectionpool.py\", line 382, in _make_request\n",
      "    httplib_response = conn.getresponse()\n",
      "  File \"/home/ubuntu/.pyenv/versions/3.6.1/lib/python3.6/http/client.py\", line 1331, in getresponse\n",
      "    response.begin()\n",
      "  File \"/home/ubuntu/.pyenv/versions/3.6.1/lib/python3.6/http/client.py\", line 297, in begin\n",
      "    version, status, reason = self._read_status()\n",
      "  File \"/home/ubuntu/.pyenv/versions/3.6.1/lib/python3.6/http/client.py\", line 266, in _read_status\n",
      "    raise RemoteDisconnected(\"Remote end closed connection without\"\n",
      "requests.packages.urllib3.exceptions.ProtocolError: ('Connection aborted.', RemoteDisconnected('Remote end closed connection without response',))\n",
      "\n",
      "During handling of the above exception, another exception occurred:\n",
      "\n",
      "Traceback (most recent call last):\n",
      "  File \"<ipython-input-2-564dd7be0a3d>\", line 10, in grab_content\n",
      "    res2 = requests.get(url, headers=HEADER)\n",
      "  File \"/home/ubuntu/.pyenv/versions/3.6.1/lib/python3.6/site-packages/requests/api.py\", line 70, in get\n",
      "    return request('get', url, params=params, **kwargs)\n",
      "  File \"/home/ubuntu/.pyenv/versions/3.6.1/lib/python3.6/site-packages/requests/api.py\", line 56, in request\n",
      "    return session.request(method=method, url=url, **kwargs)\n",
      "  File \"/home/ubuntu/.pyenv/versions/3.6.1/lib/python3.6/site-packages/requests/sessions.py\", line 488, in request\n",
      "    resp = self.send(prep, **send_kwargs)\n",
      "  File \"/home/ubuntu/.pyenv/versions/3.6.1/lib/python3.6/site-packages/requests/sessions.py\", line 609, in send\n",
      "    r = adapter.send(request, **kwargs)\n",
      "  File \"/home/ubuntu/.pyenv/versions/3.6.1/lib/python3.6/site-packages/requests/adapters.py\", line 473, in send\n",
      "    raise ConnectionError(err, request=request)\n",
      "requests.exceptions.ConnectionError: ('Connection aborted.', RemoteDisconnected('Remote end closed connection without response',))\n",
      "\n",
      "During handling of the above exception, another exception occurred:\n",
      "\n",
      "Traceback (most recent call last):\n",
      "  File \"/home/ubuntu/.pyenv/versions/3.6.1/lib/python3.6/threading.py\", line 916, in _bootstrap_inner\n",
      "    self.run()\n",
      "  File \"/home/ubuntu/.pyenv/versions/3.6.1/lib/python3.6/threading.py\", line 864, in run\n",
      "    self._target(*self._args, **self._kwargs)\n",
      "  File \"<ipython-input-2-564dd7be0a3d>\", line 36, in grab_content\n",
      "    print ('Cannot retrieve contentfrom page {} Retry: {} Error; {} '.format(idx, 6 - count), e)\n",
      "IndexError: tuple index out of range\n",
      "\n",
      "Exception in thread Thread-467:\n",
      "Traceback (most recent call last):\n",
      "  File \"/home/ubuntu/.pyenv/versions/3.6.1/lib/python3.6/site-packages/requests/packages/urllib3/connectionpool.py\", line 600, in urlopen\n",
      "    chunked=chunked)\n",
      "  File \"/home/ubuntu/.pyenv/versions/3.6.1/lib/python3.6/site-packages/requests/packages/urllib3/connectionpool.py\", line 386, in _make_request\n",
      "    six.raise_from(e, None)\n",
      "  File \"<string>\", line 2, in raise_from\n",
      "  File \"/home/ubuntu/.pyenv/versions/3.6.1/lib/python3.6/site-packages/requests/packages/urllib3/connectionpool.py\", line 382, in _make_request\n",
      "    httplib_response = conn.getresponse()\n",
      "  File \"/home/ubuntu/.pyenv/versions/3.6.1/lib/python3.6/http/client.py\", line 1331, in getresponse\n",
      "    response.begin()\n",
      "  File \"/home/ubuntu/.pyenv/versions/3.6.1/lib/python3.6/http/client.py\", line 297, in begin\n",
      "    version, status, reason = self._read_status()\n",
      "  File \"/home/ubuntu/.pyenv/versions/3.6.1/lib/python3.6/http/client.py\", line 266, in _read_status\n",
      "    raise RemoteDisconnected(\"Remote end closed connection without\"\n",
      "http.client.RemoteDisconnected: Remote end closed connection without response\n",
      "\n",
      "During handling of the above exception, another exception occurred:\n",
      "\n",
      "Traceback (most recent call last):\n",
      "  File \"/home/ubuntu/.pyenv/versions/3.6.1/lib/python3.6/site-packages/requests/adapters.py\", line 423, in send\n",
      "    timeout=timeout\n",
      "  File \"/home/ubuntu/.pyenv/versions/3.6.1/lib/python3.6/site-packages/requests/packages/urllib3/connectionpool.py\", line 649, in urlopen\n",
      "    _stacktrace=sys.exc_info()[2])\n",
      "  File \"/home/ubuntu/.pyenv/versions/3.6.1/lib/python3.6/site-packages/requests/packages/urllib3/util/retry.py\", line 347, in increment\n",
      "    raise six.reraise(type(error), error, _stacktrace)\n",
      "  File \"/home/ubuntu/.pyenv/versions/3.6.1/lib/python3.6/site-packages/requests/packages/urllib3/packages/six.py\", line 685, in reraise\n",
      "    raise value.with_traceback(tb)\n",
      "  File \"/home/ubuntu/.pyenv/versions/3.6.1/lib/python3.6/site-packages/requests/packages/urllib3/connectionpool.py\", line 600, in urlopen\n",
      "    chunked=chunked)\n",
      "  File \"/home/ubuntu/.pyenv/versions/3.6.1/lib/python3.6/site-packages/requests/packages/urllib3/connectionpool.py\", line 386, in _make_request\n",
      "    six.raise_from(e, None)\n",
      "  File \"<string>\", line 2, in raise_from\n",
      "  File \"/home/ubuntu/.pyenv/versions/3.6.1/lib/python3.6/site-packages/requests/packages/urllib3/connectionpool.py\", line 382, in _make_request\n",
      "    httplib_response = conn.getresponse()\n",
      "  File \"/home/ubuntu/.pyenv/versions/3.6.1/lib/python3.6/http/client.py\", line 1331, in getresponse\n",
      "    response.begin()\n",
      "  File \"/home/ubuntu/.pyenv/versions/3.6.1/lib/python3.6/http/client.py\", line 297, in begin\n",
      "    version, status, reason = self._read_status()\n",
      "  File \"/home/ubuntu/.pyenv/versions/3.6.1/lib/python3.6/http/client.py\", line 266, in _read_status\n",
      "    raise RemoteDisconnected(\"Remote end closed connection without\"\n",
      "requests.packages.urllib3.exceptions.ProtocolError: ('Connection aborted.', RemoteDisconnected('Remote end closed connection without response',))\n",
      "\n",
      "During handling of the above exception, another exception occurred:\n",
      "\n",
      "Traceback (most recent call last):\n",
      "  File \"<ipython-input-2-564dd7be0a3d>\", line 10, in grab_content\n",
      "    res2 = requests.get(url, headers=HEADER)\n",
      "  File \"/home/ubuntu/.pyenv/versions/3.6.1/lib/python3.6/site-packages/requests/api.py\", line 70, in get\n",
      "    return request('get', url, params=params, **kwargs)\n",
      "  File \"/home/ubuntu/.pyenv/versions/3.6.1/lib/python3.6/site-packages/requests/api.py\", line 56, in request\n",
      "    return session.request(method=method, url=url, **kwargs)\n",
      "  File \"/home/ubuntu/.pyenv/versions/3.6.1/lib/python3.6/site-packages/requests/sessions.py\", line 488, in request\n",
      "    resp = self.send(prep, **send_kwargs)\n",
      "  File \"/home/ubuntu/.pyenv/versions/3.6.1/lib/python3.6/site-packages/requests/sessions.py\", line 609, in send\n",
      "    r = adapter.send(request, **kwargs)\n",
      "  File \"/home/ubuntu/.pyenv/versions/3.6.1/lib/python3.6/site-packages/requests/adapters.py\", line 473, in send\n",
      "    raise ConnectionError(err, request=request)\n",
      "requests.exceptions.ConnectionError: ('Connection aborted.', RemoteDisconnected('Remote end closed connection without response',))\n",
      "\n",
      "During handling of the above exception, another exception occurred:\n",
      "\n",
      "Traceback (most recent call last):\n",
      "  File \"/home/ubuntu/.pyenv/versions/3.6.1/lib/python3.6/threading.py\", line 916, in _bootstrap_inner\n",
      "    self.run()\n",
      "  File \"/home/ubuntu/.pyenv/versions/3.6.1/lib/python3.6/threading.py\", line 864, in run\n",
      "    self._target(*self._args, **self._kwargs)\n",
      "  File \"<ipython-input-2-564dd7be0a3d>\", line 36, in grab_content\n",
      "    print ('Cannot retrieve contentfrom page {} Retry: {} Error; {} '.format(idx, 6 - count), e)\n",
      "IndexError: tuple index out of range\n",
      "\n",
      "Exception in thread Thread-479:\n",
      "Traceback (most recent call last):\n",
      "  File \"/home/ubuntu/.pyenv/versions/3.6.1/lib/python3.6/site-packages/requests/packages/urllib3/connectionpool.py\", line 600, in urlopen\n",
      "    chunked=chunked)\n",
      "  File \"/home/ubuntu/.pyenv/versions/3.6.1/lib/python3.6/site-packages/requests/packages/urllib3/connectionpool.py\", line 386, in _make_request\n",
      "    six.raise_from(e, None)\n",
      "  File \"<string>\", line 2, in raise_from\n",
      "  File \"/home/ubuntu/.pyenv/versions/3.6.1/lib/python3.6/site-packages/requests/packages/urllib3/connectionpool.py\", line 382, in _make_request\n",
      "    httplib_response = conn.getresponse()\n",
      "  File \"/home/ubuntu/.pyenv/versions/3.6.1/lib/python3.6/http/client.py\", line 1331, in getresponse\n",
      "    response.begin()\n",
      "  File \"/home/ubuntu/.pyenv/versions/3.6.1/lib/python3.6/http/client.py\", line 297, in begin\n",
      "    version, status, reason = self._read_status()\n",
      "  File \"/home/ubuntu/.pyenv/versions/3.6.1/lib/python3.6/http/client.py\", line 266, in _read_status\n",
      "    raise RemoteDisconnected(\"Remote end closed connection without\"\n",
      "http.client.RemoteDisconnected: Remote end closed connection without response\n",
      "\n",
      "During handling of the above exception, another exception occurred:\n",
      "\n",
      "Traceback (most recent call last):\n",
      "  File \"/home/ubuntu/.pyenv/versions/3.6.1/lib/python3.6/site-packages/requests/adapters.py\", line 423, in send\n",
      "    timeout=timeout\n",
      "  File \"/home/ubuntu/.pyenv/versions/3.6.1/lib/python3.6/site-packages/requests/packages/urllib3/connectionpool.py\", line 649, in urlopen\n",
      "    _stacktrace=sys.exc_info()[2])\n",
      "  File \"/home/ubuntu/.pyenv/versions/3.6.1/lib/python3.6/site-packages/requests/packages/urllib3/util/retry.py\", line 347, in increment\n",
      "    raise six.reraise(type(error), error, _stacktrace)\n",
      "  File \"/home/ubuntu/.pyenv/versions/3.6.1/lib/python3.6/site-packages/requests/packages/urllib3/packages/six.py\", line 685, in reraise\n",
      "    raise value.with_traceback(tb)\n",
      "  File \"/home/ubuntu/.pyenv/versions/3.6.1/lib/python3.6/site-packages/requests/packages/urllib3/connectionpool.py\", line 600, in urlopen\n",
      "    chunked=chunked)\n",
      "  File \"/home/ubuntu/.pyenv/versions/3.6.1/lib/python3.6/site-packages/requests/packages/urllib3/connectionpool.py\", line 386, in _make_request\n",
      "    six.raise_from(e, None)\n",
      "  File \"<string>\", line 2, in raise_from\n",
      "  File \"/home/ubuntu/.pyenv/versions/3.6.1/lib/python3.6/site-packages/requests/packages/urllib3/connectionpool.py\", line 382, in _make_request\n",
      "    httplib_response = conn.getresponse()\n",
      "  File \"/home/ubuntu/.pyenv/versions/3.6.1/lib/python3.6/http/client.py\", line 1331, in getresponse\n",
      "    response.begin()\n",
      "  File \"/home/ubuntu/.pyenv/versions/3.6.1/lib/python3.6/http/client.py\", line 297, in begin\n",
      "    version, status, reason = self._read_status()\n",
      "  File \"/home/ubuntu/.pyenv/versions/3.6.1/lib/python3.6/http/client.py\", line 266, in _read_status\n",
      "    raise RemoteDisconnected(\"Remote end closed connection without\"\n",
      "requests.packages.urllib3.exceptions.ProtocolError: ('Connection aborted.', RemoteDisconnected('Remote end closed connection without response',))\n",
      "\n",
      "During handling of the above exception, another exception occurred:\n",
      "\n",
      "Traceback (most recent call last):\n",
      "  File \"<ipython-input-2-564dd7be0a3d>\", line 10, in grab_content\n",
      "    res2 = requests.get(url, headers=HEADER)\n",
      "  File \"/home/ubuntu/.pyenv/versions/3.6.1/lib/python3.6/site-packages/requests/api.py\", line 70, in get\n",
      "    return request('get', url, params=params, **kwargs)\n",
      "  File \"/home/ubuntu/.pyenv/versions/3.6.1/lib/python3.6/site-packages/requests/api.py\", line 56, in request\n",
      "    return session.request(method=method, url=url, **kwargs)\n",
      "  File \"/home/ubuntu/.pyenv/versions/3.6.1/lib/python3.6/site-packages/requests/sessions.py\", line 488, in request\n",
      "    resp = self.send(prep, **send_kwargs)\n",
      "  File \"/home/ubuntu/.pyenv/versions/3.6.1/lib/python3.6/site-packages/requests/sessions.py\", line 609, in send\n",
      "    r = adapter.send(request, **kwargs)\n",
      "  File \"/home/ubuntu/.pyenv/versions/3.6.1/lib/python3.6/site-packages/requests/adapters.py\", line 473, in send\n",
      "    raise ConnectionError(err, request=request)\n",
      "requests.exceptions.ConnectionError: ('Connection aborted.', RemoteDisconnected('Remote end closed connection without response',))\n",
      "\n",
      "During handling of the above exception, another exception occurred:\n",
      "\n",
      "Traceback (most recent call last):\n",
      "  File \"/home/ubuntu/.pyenv/versions/3.6.1/lib/python3.6/threading.py\", line 916, in _bootstrap_inner\n",
      "    self.run()\n",
      "  File \"/home/ubuntu/.pyenv/versions/3.6.1/lib/python3.6/threading.py\", line 864, in run\n",
      "    self._target(*self._args, **self._kwargs)\n",
      "  File \"<ipython-input-2-564dd7be0a3d>\", line 36, in grab_content\n",
      "    print ('Cannot retrieve contentfrom page {} Retry: {} Error; {} '.format(idx, 6 - count), e)\n",
      "IndexError: tuple index out of range\n",
      "\n"
     ]
    }
   ],
   "source": [
    "#mainThread  \n",
    "#Get pageNum and Use thread to send pageLink then Use thread to send innerLink then write in csv\n",
    "\n",
    "HOST = 'https://www.1111.com.tw'\n",
    "HEADER = {'User-Agent':'Mozilla/5.0 (Windows NT 6.1; Win64; x64) AppleWebKit/537.36 (KHTML, like Gecko) Chrome/58.0.3029.96 Safari/537.36'}\n",
    "\n",
    "# global variable\n",
    "thread_list=[]\n",
    "alinks = []\n",
    "page_links = []\n",
    "wc = Counter()\n",
    "lock = threading.Lock()\n",
    "link_path = './link_1111.csv'\n",
    "#*********************************************************************************************************#\n",
    "\n",
    "#Get total pages\n",
    "url =  HOST + '/job-bank/job-index.asp?si=1&d0=140400,140200,140300&fs=1&ps=100&page=1'\n",
    "res = requests.get(url)\n",
    "soup = BeautifulSoup(res.text, 'lxml')\n",
    "page = int(soup.select_one('div.pagedata').text.split('/')[1].split('頁')[0]) + 1\n",
    "\n",
    "# Get all links from all pages\n",
    "for i in range(1,page):\n",
    "    url =  HOST + '/job-bank/job-index.asp?si=1&d0=140400,140200,140300&fs=1&ps=100&page={}'.format(i)\n",
    "    th = threading.Thread(target=get_innerlinks, args=(url, lock, i, link_path))\n",
    "    th.start()\n",
    "    time.sleep(0.3)\n",
    "    thread_list.append(th)\n",
    "else:                                       #  not error\n",
    "    print('[Debug] All threads are started')\n",
    "\n",
    "# Join all threads\n",
    "for thread in thread_list:\n",
    "    thread.join()\n",
    "\n",
    "thread_list2 = []\n",
    "\n",
    "# Not applicable to this case !!\n",
    "# Get all content from alllinks\n",
    "# with ThreadPoolExecutor(max_workers=5) as executor:\n",
    "#     for idx, link in enumerate(alinks):\n",
    "#         executor.submit(grab_content, link, lock, idx) \n",
    "\n",
    "for idx, link in enumerate(alinks):\n",
    "    th = threading.Thread(target=grab_content, args=(link, lock, idx ))\n",
    "    th.start()\n",
    "    time.sleep(0.2)\n",
    "    thread_list2.append(th)\n",
    "for thread in thread_list2:\n",
    "    thread.join()\n",
    "        \n",
    "# Wirte results to file\n",
    "with open('./1111.csv', 'w') as fw2:\n",
    "    for lang, counts in wc.most_common():\n",
    "        fw2.write('{},{}\\n'.format(lang,counts))\n",
    "#輸出成json檔\n",
    "with open('./1111.json', 'w') as fw3:\n",
    "    for lang, counts in wc.most_common():\n",
    "        json.dump(language, f)\n"
   ]
  },
  {
   "cell_type": "code",
   "execution_count": null,
   "metadata": {
    "collapsed": true
   },
   "outputs": [],
   "source": [
    "wc.most_common()"
   ]
  },
  {
   "cell_type": "code",
   "execution_count": null,
   "metadata": {
    "collapsed": true
   },
   "outputs": [],
   "source": []
  }
 ],
 "metadata": {
  "kernelspec": {
   "display_name": "Python 3",
   "language": "python",
   "name": "python3"
  },
  "language_info": {
   "codemirror_mode": {
    "name": "ipython",
    "version": 3
   },
   "file_extension": ".py",
   "mimetype": "text/x-python",
   "name": "python",
   "nbconvert_exporter": "python",
   "pygments_lexer": "ipython3",
   "version": "3.6.0"
  }
 },
 "nbformat": 4,
 "nbformat_minor": 2
}
